Workbook
Name \c: #N/A
Name \i: #N/A
Name \z: #N/A
Name __material_he_tubes_alternative: #REF!
Name __sf400: '[7]Pull-Down Menus'!$J$2486:$J$2491
Name __sf404: '[7]Pull-Down Menus'!$J$699:$J$701
Name _bal11: '[10]bal11'!$B$1:$AV$66
Name _bal12: '[10]bal12'!$B$1:$AU$66
Name _bal6: '[10]bal6'!$B$1:$CN$66
Name _DESIGN_MAT_SHELL: #REF!
Name _DESIGN_MAT_TUBES: #REF!
Name _DESIGN_TEMP_MAX_1: #REF!
Name _DESIGN_TEMP_MAX_2: #REF!
Name _DESIGN_TEMP_MIN_1: #REF!
Name _DESIGN_TEMP_MIN_2: #REF!
Name _DIMENSIONS_BOT: #REF!
Name _DIMENSIONS_MID: #REF!
Name _DIMENSIONS_PIPE_SHELL: #REF!
Name _DIMENSIONS_PIPE_TUBE: #REF!
Name _DIMENSIONS_TOP_MAIN: #REF!
Name _din24420: #REF!
Name _din28005: #REF!
Name _din28006: #REF!
Name _din28007: #REF!
Name _din28008: #REF!
Name _din28015: #REF!
Name _din28017: #REF!
Name _din28083: #REF!
Name _din28084: #REF!
Name _din28105: #REF!
Name _din28161: #REF!
Name _din28182: #REF!
Name _din4119: #REF!
Name _doc_foundation_plan_loads_digital: #REF!
Name _doc_foundation_plan_loads_paper: #REF!
Name _doc_foundation_plan_loads_week: #REF!
Name _installed_area_per_unit: #REF!
Name _Jos2: #REF!
Name _mat1: #REF!
Name _mat2: #REF!
Name _mat3: #REF!
Name _mat4: #REF!
Name _material_he_tubes: #REF!
Name _mc230: #REF!
Name _mc240: #REF!
Name _mc245: #REF!
Name _mc250: #REF!
Name _mc251: #REF!
Name _mc252: #REF!
Name _mc253: #REF!
Name _mc254: #REF!
Name _mc255: #REF!
Name _mc260: #REF!
Name _mc310: #REF!
Name _mc311: #REF!
Name _mc335: #REF!
Name _mc336: #REF!
Name _mc337: #REF!
Name _mc338: #REF!
Name _mc339: #REF!

Sheet PSR Overall Cycle
B2: Note: | C2: 1. All MR Issuance with Attached File to be used IFR version, some long lead item to be used FEED document as MR Issuance basis which listed in Remark
C3: 2. In principle, Datasheet - IFA version shall be issued before TBE issuance as much as possible to avoid the big gap of changes.
C4: 3.TBE- AFC and MR-AFC should be issued before PO issuance.
C5: 4.For the Steel Structural, TJE will sign the frame agreement with alternative vendors firstly, once the MTO&IFA drawing issuance, TJE will purchase order promptly
C6: 5.The 3rd line of Each procuremnt package with "Proposal from TJE" in column N , has been aligned with GCME about date of MR issuance with atteched relative documents, then forward schedule in procurement and leadtime to ETA, this line is the basis for schedule developing.
J8: LA | M8: 1 | N8: 10 | O8: 0 | P8: 0 | Q8: 0 | R8: 10 | S8: 17 | T8: 10 | V8: 9
J9: LB | M9: 1 | N9: 10 | O9: 0 | P9: 0 | Q9: 0 | R9: 10 | S9: 17 | T9: 10 | V9: 9
J10: LC | M10: 1 | N10: 10 | O10: 0 | P10: 0 | Q10: 0 | R10: 10 | S10: 13 | T10: 10 | V10: 9
J11: LD | M11: 1 | N11: 10 | O11: 0 | P11: 0 | Q11: 0 | R11: 5 | S11: 7 | T11: 10 | V11: 5
B12: ZM167 PTTEPI ASK Procurement Plan | J12: LA | M12: 1 | N12: 5 | O12: 1 | P12: 5 | R12: 10 | S12: 20 | T12: 3 | V12: 10 | W12: 2 | X12: 5 | Y12: 20 | Z12: 10 | AD12: 5 | AE12: 5
J13: LB | M13: 1 | N13: 5 | O13: 1 | P13: 5 | R13: 10 | S13: 20 | T13: 3 | V13: 10 | W13: 2 | X13: 5 | Y13: 20 | Z13: 10 | AD13: 5 | AE13: 5
J14: LC | M14: 3 | N14: 5 | O14: 1 | P14: 5 | R14: 10 | S14: 15 | T14: 3 | V14: 10 | W14: 2 | X14: 5 | Y14: 15 | Z14: 10 | AD14: 5 | AE14: 5
J15: LD | M15: 3 | N15: 5 | O15: 1 | P15: 3 | R15: 5 | S15: 7 | T15: 2 | V15: 5 | W15: 2 | X15: 5 | Y15: 10 | Z15: 10 | AD15: 5 | AE15: 5
A16: No. | B16: RFQ No. | C16: Package Name | D16: Deviation | E16: Total Weight | F16: CODE | G16: Discripline | H16: Long Lead Item (Y/N) | I16: Criticality Rating | J16: Priority Level | L16: Bidder List Approval | M16: MR Issued | N16: MR Approved | O16: RFQ Issued | P16: RFQ Approved | Q16: CFT Issuance | R16: Bid Closing Date | S16: TBE Issued | T16: TBE Approved | U16: LOA SIGN | V16: PO Issued | W16: Vendor Acknowledgement | X16: KOM | Y16: VD Submission | Z16: Approval of Key Vendor Documents | AA16: Delivery of Major Materials | AB16: PIM | AC16: Start Production | AD16: FAT | AE16: Ready for Shipment | AF16: Receipt at WORKSITE | AG16: Punch List Clearance | AH16: Approval of Final Documentation (To be confirmed later) | AI16: Delivery Duration (Weeks) | AJ16: Lead Time | AK16: ETA date | AL16: ROS date | AM16: Float | AP16: Remark | AQ16: Remark2
K17: Matrix | AP17: Installation
K18: Holiday | L18: China | M18: Thai | N18: Thai | O18: China | P18: Thai | R18: China | S18: Thai | T18: Thai | U18: China | V18: China | W18: China | X18: China | Y18: China | Z18: Thai
A19: 1 | B19: RFQ-MEC-001 | C19: Offshore Pedestal Crane | G19: Mechanical | J19: LA | K19: New Plan | M19: 46122 | N19: 46142 | O19: 46142 | P19: 46142 | Q19: 46145 | R19: 46157 | S19: 46184 | T19: 46198 | V19: 46211 | W19: 46213 | X19: 46220 | Y19: 46248 | Z19: 46262 | AA19: 46307 | AB19: 46310 | AC19: 46313 | AD19: 46496 | AE19: 46526 | AF19: 46540 | AG19: 46554 | AH19: 46570 | AI19: 47 | AJ19: =AI19*7 -> 329 | AK19: =V19+AJ19 -> 46540 | AL19: =AL20 -> 46540 | AM19: =AL20-AK19 -> 0 | AN19: Long Lead | AO19: WPA-01 | AP19: 46543
B20: RFQ-MEC-001 | C20: Offshore Pedestal Crane | F20: 4-2.1 | G20: Mechanical | H20: Y | I20: 2 | J20: LA | K20: Forecast | AA20: 46300 | AB20: =AA20 -> 46300 | AC20: 46301 | AD20: 46497 | AE20: 46521 | AF20: 46533 | AG20: 46547 | AH20: 46563 | AI20: 47 | AJ20: 329 | AK20: 46533 | AL20: =AP19-3 -> 46540 | AM20: =AL20-AK20 -> 7 | AN20: =AN19 -> Long Lead | AO20: WPA-02 | AP20: 46553
B21: RFQ-MEC-001 | C21: Offshore Pedestal Crane | G21: Mechanical | H21: Y | I21: 2 | J21: LA | K21: Actual | L21: 46120 | M21: 46122 | N21: 46139 | O21: =N21 -> 46139 | P21: =O21 -> 46139 | Q21: =P21 -> 46139 | R21: 46143 | S21: 46185 | T21: 46190 | U21: 46204 | V21: 46240 | W21: 46240 | X21: 46213 | Y21: =X21+1 -> 46214 | Z21: 46297 | AN21: =AN19 -> Long Lead | AP21: UPO-0003 | AQ21: Upper Deck
A22: 2 | B22: RFQ-MEC-002 | C22: Material Handling Equipment | G22: Mechanical | J22: LC | K22: New Plan | M22: 46203 | N22: 46217 | O22: 46217 | P22: 46217 | Q22: 46217 | R22: 46231 | S22: 46252 | T22: 46266 | V22: 46279 | W22: 46281 | X22: 46288 | Y22: 46317 | Z22: 46332 | AA22: 46377 | AB22: 46380 | AC22: 46381 | AD22: 46410 | AE22: 46440 | AF22: 46454 | AG22: 46468 | AH22: 46484 | AI22: 25 | AJ22: =AI22*7 -> 175 | AK22: =V22+AJ22 -> 46454 | AL22: =AL23 -> 46459 | AM22: =AL23-AK22 -> 5 | AO22: WPA-01 | AP22: 46462
B23: RFQ-MEC-002 | C23: Material Handling Equipment | F23: 4-2.2 | G23: Mechanical | H23: N | I23: 4 | J23: LC | K23: Forecast | V23: 46301 | X23: 46304 | Y23: 46317 | Z23: 46332 | AA23: 46377 | AB23: 46380 | AC23: 46381 | AD23: 46391 | AE23: 46421 | AF23: 46435 | AG23: 46449 | AH23: 46465 | AI23: 25 | AJ23: 175 | AK23: 46435 | AL23: =AP22-3 -> 46459 | AM23: =AL23-AK23 -> 24 | AO23: WPA-02 | AP23: 46490 | AQ23: check Location
B24: RFQ-MEC-002 | C24: Material Handling Equipment | G24: Mechanical | H24: N | I24: 4 | J24: LC | K24: Actual | M24: 46170 | N24: 46188 | O24: 46188 | P24: 46188 | Q24: 46191 | R24: 46204 | S24: 46242 | T24: 46288 | U24: 46260 | W24: 46260 | AP24: UPO-0025
A25: 3 | B25: RFQ-MEC-003 | C25: Instrument Gas Filter Coalescer | G25: Mechanical | J25: LA | K25: New Plan | M25: 46170 | N25: 46182 | O25: 46182 | P25: 46182 | Q25: 46190 | R25: 46204 | S25: 46224 | T25: 46240 | V25: 46253 | W25: 46255 | X25: 46262 | Y25: 46293 | Z25: 46307 | AA25: 46367 | AB25: 46370 | AC25: 46371 | AD25: 46402 | AE25: 46432 | AF25: 46433 | AG25: 46447 | AH25: 46463 | AI25: 25.714286 | AJ25: =AI25*7 -> 180 | AK25: =V25+AJ25 -> 46433 | AL25: =AL26 -> 46444 | AM25: =AL26-AK25 -> 11 | AO25: WPA-01 | AP25: 46447
B26: RFQ-MEC-003 | C26: Instrument Gas Filter Coalescer | F26: 4-2.4 | G26: Mechanical | H26: Y | I26: 3 | J26: LA | K26: Forecast | Z26: 46336 | AA26: 46345 | AB26: 46346 | AC26: 46347 | AD26: 46415 | AE26: 46417 | AF26: 46417 | AG26: 46431 | AH26: 46447 | AI26: 28.285714 | AJ26: 198 | AK26: 46417 | AL26: =AP25-3 -> 46444 | AM26: =AL26-AK26 -> 27 | AO26: WPA-02 | AP26: 46472
B27: RFQ-MEC-003 | C27: Instrument Gas Filter Coalescer | G27: Mechanical | H27: Y | I27: 3 | J27: LA | K27: Actual | L27: 46136 | M27: 46165 | N27: 46183 | O27: 46183 | P27: 46183 | Q27: 46183 | R27: 46192 | S27: 46220 | T27: 46224 | U27: 46219 | V27: 46219 | W27: 46219 | X27: 46226 | Y27: =X27+1 -> 46227 | AP27: UPO-0004 | AQ27: Lower Deck
A28: 4 | B28: RFQ-MEC-004 | C28: Test And Production Separator | G28: Mechanical | J28: LA | K28: New Plan | M28: 46154 | N28: 46162 | O28: 46162 | P28: 46162 | Q28: 46170 | R28: 46183 | S28: 46211 | T28: 46216 | V28: 46230 | W28: 46232 | X28: 46239 | Y28: 46267 | Z28: 46281 | AA28: 46341 | AB28: 46344 | AC28: 46345 | AD28: 46430 | AE28: 46433 | AF28: 46440 | AG28: 46454 | AH28: 46470 | AI28: 30 | AJ28: =AI28*7 -> 210 | AK28: =V28+AJ28 -> 46440 | AL28: =AL29 -> 46448 | AM28: =AL29-AK28 -> 8 | AN28: Long Lead | AO28: WPA-01 | AP28: 46451
B29: RFQ-MEC-004 | C29: Test And Production Separator | F29: 4-2.3 | G29: Mechanical | H29: Y | I29: 2 | J29: LA | K29: Forecast | Z29: 46336 | AA29: 46343 | AB29: 46344 | AC29: 46345 | AD29: 46430 | AE29: 46433 | AF29: 46433 | AG29: 46447 | AH29: 46463 | AI29: 30.571429 | AJ29: 214 | AK29: 46433 | AL29: =AP28-3 -> 46448 | AM29: =AL29-AK29 -> 15 | AN29: =AN28 -> Long Lead | AO29: WPA-02 | AP29: 46472
B30: RFQ-MEC-004 | C30: Test And Production Separator | G30: Mechanical | H30: Y | I30: 2 | J30: LA | K30: Actual | L30: 46136 | M30: 46157 | N30: 46182 | O30: 46182 | P30: 46182 | Q30: 46182 | R30: 46190 | S30: 46206 | T30: 46210 | U30: 46219 | V30: 46219 | W30: 46219 | X30: 46226 | Y30: 46260 | AN30: =AN28 -> Long Lead | AP30: UPO-0004 | AQ30: Lower Deck
A31: 5 | B31: RFQ-PIP-005 | C31: Quick Opening Closure | G31: Piping | J31: LA | K31: New Plan | M31: 46157 | N31: 46175 | O31: 46175 | P31: 46175 | Q31: 46176 | R31: 46189 | S31: 46217 | T31: 46227 | V31: 46234 | W31: 46238 | X31: 46245 | Y31: 46273 | Z31: 46287 | AA31: 46347 | AB31: 46350 | AC31: 46351 | AD31: 46427 | AE31: 46457 | AF31: 46458 | AG31: 46472 | AH31: 46488 | AI31: 32 | AJ31: =AI31*7 -> 224 | AK31: =V31+AJ31 -> 46458 | AL31: =AL32 -> 46466 | AM31: =AL32-AK31 -> 8 | AO31: WPA-01 | AP31: 46469
B32: RFQ-PIP-005 | C32: Quick Opening Closure | F32: 4-2.6 | G32: Piping | H32: Y | I32: 2 | J32: LA | K32: Forecast | Y32: 46300 | Z32: 46320 | AA32: 46300 | AB32: 46322 | AC32: 46323 | AD32: =AE32-7 -> 46454 | AE32: 46461 | AF32: 46471 | AI32: 20 | AJ32: 140 | AK32: =U33+AJ32 -> 46405 | AL32: =AP31-3 -> 46466 | AM32: =AL32-AK32 -> 61 | AO32: WPA-02 | AP32: 46472 | AQ32: Lower Deck
B33: RFQ-PIP-005 | C33: Quick Opening Closure | G33: Piping | H33: Y | I33: 2 | J33: LA | K33: Actual | L33: 46136 | M33: 46163 | N33: 46182 | O33: 46182 | P33: 46182 | Q33: 46182 | R33: 46199 | S33: 46225 | T33: 46240 | U33: 46265 | V33: 46289 | W33: 46241 | X33: 46248 | AP33: UPO-0020
A34: 6 | B34: RFQ-MEC-006 | C34: Chemical Injection Pumps Package | G34: Mechanical | J34: LA | K34: New Plan | M34: 46153 | N34: 46182 | O34: 46182 | P34: 46182 | Q34: 46169 | R34: 46183 | S34: 46210 | T34: 46213 | V34: 46227 | W34: 46231 | X34: 46238 | Y34: 46266 | Z34: 46280 | AA34: 46392 | AB34: 46395 | AC34: 46396 | AD34: 46421 | AE34: 46437 | AF34: 46451 | AG34: 46465 | AH34: 46481 | AI34: 32 | AJ34: =AI34*7 -> 224 | AK34: =V34+AJ34 -> 46451 | AL34: =AL35 -> 46451 | AM34: =AL35-AK34 -> 0 | AN34: Long Lead | AO34: WPA-01 | AP34: 46454
B35: RFQ-MEC-006 | C35: Chemical Injection Pumps Package | F35: 4-2.8 | G35: Mechanical | H35: Y | I35: 3 | J35: LA | K35: Forecast | Z35: 46339 | AA35: 46366 | AB35: 46366 | AC35: 46366 | AD35: 46469 | AE35: 46471 | AF35: 46476 | AG35: 46490 | AH35: 46506 | AI35: 35.142857 | AJ35: 246 | AK35: 46476 | AL35: =AP34-3 -> 46451 | AM35: =AL35-AK35 -> -25 | AN35: =AN34 -> Long Lead | AO35: WPA-02 | AP35: 46472
B36: RFQ-MEC-006 | C36: Chemical Injection Pumps Package | G36: Mechanical | H36: Y | I36: 3 | J36: LA | K36: Actual | L36: 46133 | M36: 46157 | N36: 46182 | O36: 46182 | P36: 46182 | Q36: 46182 | R36: 46183 | S36: 46206 | T36: 46210 | U36: 46230 | W36: 46230 | X36: 46237 | Y36: 46262 | AN36: =AN34 -> Long Lead | AP36: UPO-0008，RFQ-007 De-mulsifier / Water Clarifier Injection Pump & RFQ-044 Flow switch combined with RFQ-006 | AQ36: Lower Deck
A37: 8 | B37: RFQ-MEC-008 | C37: Deoiler Hydro Cyclone Package | G37: Mechanical | J37: LA | K37: New Plan | M37: 46141 | N37: 46153 | O37: 46153 | P37: 46161 | Q37: 46161 | R37: 46183 | S37: 46203 | T37: 46206 | V37: 46220 | W37: 46224 | X37: 46231 | Y37: 46259 | Z37: 46273 | AA37: 46340 | AB37: 46340 | AC37: 46340 | AD37: 46457 | AE37: 46461 | AF37: =AE37+3 -> 46464 | AG37: =AF37+14 -> 46478 | AH37: =AK37+30 -> 46494 | AI37: 34 | AJ37: =AI37*7 -> 238 | AK37: =AF37 -> 46464 | AL37: =AL38 -> 46469 | AM37: =AL38-AK37 -> 5 | AO37: WPA-01 | AP37: NA
B38: RFQ-MEC-008 | C38: Deoiler Hydro Cyclone Package | F38: 4-2.10 | G38: Mechanical | H38: Y | I38: 2 | J38: LA | K38: Forecast | Z38: 46380 | AA38: 46329 | AB38: 46329 | AC38: 46340 | AD38: 46461 | AE38: 46461 | AF38: 46461 | AG38: 46475 | AH38: 46491 | AI38: 34.571429 | AJ38: 242 | AK38: 46461 | AL38: =AP38-3 -> 46469 | AM38: =AL38-AK38 -> 8 | AO38: WPA-02 | AP38: 46472 | AQ38: only WPA02
B39: RFQ-MEC-008 | C39: Deoiler Hydro Cyclone Package | G39: Mechanical | H39: Y | I39: 2 | J39: LA | K39: Actual | L39: 46136 | M39: 46139 | N39: 46153 | O39: 46153 | P39: =N39 -> 46153 | Q39: =N39 -> 46153 | R39: 46182 | S39: 46200 | T39: 46202 | U39: 46219 | V39: 46219 | W39: 46219 | X39: 46226 | Y39: 46260 | AP39: UPO-0004 | AQ39: Lower Deck
A40: 9 | B40: RFQ-MEC-009 | C40: Degasser Drum | G40: Mechanical | J40: LA | K40: New Plan | M40: 46134 | N40: 46153 | O40: 46153 | P40: 46153 | Q40: 46154 | R40: 46167 | S40: 46197 | T40: 46202 | V40: 46216 | W40: 46218 | X40: 46225 | Y40: 46253 | Z40: 46267 | AA40: 46340 | AB40: 46340 | AC40: 46343 | AD40: 46453 | AE40: 46456 | AF40: =AE40+3 -> 46459 | AG40: =AF40+14 -> 46473 | AH40: =AK40+30 -> 46489 | AI40: 34 | AJ40: =AI40*7 -> 238 | AK40: =AF40 -> 46459 | AL40: =AL41 -> 46470 | AM40: =AL41-AK40 -> 11 | AO40: WPA-01 | AP40: NA
B41: RFQ-MEC-009 | C41: Degasser Drum | F41: 4-2.11 | G41: Mechanical | H41: Y | I41: 2 | J41: LA | K41: Forecast | Z41: 46380 | AA41: 46280 | AB41: 46281 | AC41: 46282 | AD41: 46451 | AE41: 46456 | AF41: 46456 | AG41: 46470 | AH41: 46486 | AI41: 33.857143 | AJ41: 237 | AK41: 46456 | AL41: =AP41-3 -> 46470 | AM41: =AL41-AK41 -> 14 | AO41: WPA-02 | AP41: 46473 | AQ41: only WPA02
B42: RFQ-MEC-009 | C42: Degasser Drum | G42: Mechanical | H42: Y | I42: 2 | J42: LA | K42: Actual | L42: 46135 | M42: 46135 | N42: 46151 | O42: 46151 | P42: =N42 -> 46151 | Q42: =N42 -> 46151 | R42: 46181 | S42: 46202 | T42: 46204 | U42: 46219 | V42: 46219 | W42: 46219 | X42: 46226 | Y42: 46260 | AP42: UPO-0004 | AQ42: Lower Deck
...

Sheet Sheet1
B1: RFQ No. | C1: Description | D1: PO Issued | E1: Delivery To Site | F1: Lead Time | G1: ROS date | H1: Float
B2: RFQ-MEC-001 | C2: Offshore Pedestal Crane | D2: 46211 | E2: 46540 | F2: 329 | G2: 46540 | H2: 0
B3: RFQ-MEC-003 | C3: Instrument Gas Filter Coalescer | D3: 46253 | E3: 46433 | F3: 180 | G3: 46444 | H3: 11
B4: RFQ-MEC-004 | C4: TEST AND PRODUCTION SEPARATOR | D4: 46230 | E4: 46440 | F4: 210 | G4: 46448 | H4: 8
B5: RFQ-MEC-006 | C5: CHEMICAL INJECTION PUMPS PACKAGE | D5: 46227 | E5: 46451 | F5: 224 | G5: 46451 | H5: 0
B6: RFQ-MEC-011 | C6: Closed Drain Sump Vessel | D6: 46231 | E6: 46413 | F6: 182 | G6: 46430 | H6: 17
B7: RFQ-MEC-013 | C7: Storage Tank | D7: 46254 | E7: 46422 | F7: 168 | G7: 46470 | H7: 48
B8: RFQ-MEC-014 | C8: CLOSED DRAIN SUMP PUMP AND RECOVERY WATER PUMP PACKAGE | D8: 46231 | E8: 46455 | F8: 224 | G8: 46477 | H8: 22
B9: RFQ-ELE-017 | C9: AC/DC Distribution Board | D9: 46226 | E9: 46478 | F9: 252 | G9: 46490 | H9: 12
B10: RFQ-ELE-018 | C10: Solar Power System | D10: 46226 | E10: 46485 | F10: 259 | G10: 46490 | H10: 5
B11: RFQ-ELE-019 | C11: Navigation Aid System | D11: 46247 | E11: 46499 | F11: 252 | G11: 46504 | H11: 5
B12: RFQ-INS-023 | C12: Actuated Choke Valve | D12: 46254 | E12: 46534 | F12: 280 | G12: 46550 | H12: 16
B13: RFQ-INS-024 | C13: Actuated Ball Valve | D13: 46267 | E13: 46519 | F13: 252 | G13: 46530 | H13: 11
... B22: RFQ-PIP-073 | C22: SS AND DSS PIPE | D22: 46258 | E22: 46426 | F22: 168 | G22: 46429 | H22: 3

Sheet P6
A1: ActivityID | B1: Activity Name | C1: Planned Duration | D1: Start | E1: Finish | F1: Total Float | G1: Calendar
A2: DETAILENGINEERINGFORWELLHEADPLATFORMS(WPA01ANDWPA02)(ASKPROJECT) | C2: 211 | D2: 46085 | E2: 46405 | F2: 0 | G2: PTTME Office 5dx8h
A3: PROJECTMILESTONE | C3: 211 | D3: 46085 | E3: 46405 | F3: 0 | G3: PTTME Office 5dx8h
A4: MI-1000 | B4: Project Start, KOM | C4: 0 | D4: 46085 | F4: -47 | G4: PTTME Office 5dx8h
A5: MI-1010 | B5: P&ID Issue for Review | C5: 0 | E5: 27-Apr-26* | F5: -7 | G5: PTTME Office 5dx8h
A6: MI-1020 | B6: 30% Model Review | C6: 2 | D6: 46155 | E6: 46156 | F6: 10 | G6: PTTME Office 5dx8h
A7: MI-1030 | B7: P&ID issue for HAZOP | C7: 0 | E7: 46170 | F7: 22 | G7: PTTME Office 5dx8h
A8: MI-1040 | B8: HAZID Review Meeting | C8: 2 | D8: 46162 | E8: 46163 | F8: 105 | G8: PTTME Office 5dx8h
A9: MI-1050 | B9: HAZOP Review Meeting | C9: 5 | D9: 46178 | E9: 46184 | F9: 22 | G9: PTTME Office 5dx8h
A10: MI-1060 | B10: SIL Review Meeting | C10: 2 | D10: 46192 | E10: 46195 | F10: 75 | G10: PTTME Office 5dx8h
A11: MI-1070 | B11: Structural - Primary MTO Issue for review | C11: 0 | E11: 26-May-26* | F11: 0 | G11: PTTME Office 5dx8h
A12: MI-1080 | B12: 60% Model Review | C12: 5 | D12: 46258 | E12: 46262 | F12: 0 | G12: PTTME Office 5dx8h
A13: MI-1090 | B13: 90% Model Review | C13: 1 | D13: 46321 | E13: 46321 | F13: 11 | G13: PTTME Office 5dx8h
A14: MI-1100 | B14: Issue all AFC Documents /Drawing | C14: 0 | E14: 46392 | F14: 0 | G14: PTTME Office 5dx8h
A15: MI-1110 | B15: Design Engineering Compilation | C15: 0 | E15: 46405 | F15: 0 | G15: PTTME Office 5dx8h
A16: GENERALSTUDIES | C16: 35 | D16: 46086 | E16: 46140 | F16: 166 | G16: PTTME Office 5dx8h
A17: PJ-1000 | B17: Master Deliverable Register - IFR | C17: 10 | D17: 46086 | E17: 46099 | F17: 166 | G17: PTTME Office 5dx8h
A18: PJ-1010 | B18: Master Deliverable Register - AFC | C18: 5 | D18: 46114 | E18: 46121 | F18: 171 | G18: PTTME Office 5dx8h
A19: PJ-1020 | B19: Engineering Master Schedule - IFR | C19: 10 | D19: 46100 | E19: 46113 | F19: 166 | G19: PTTME Office 5dx8h
A20: PJ-1030 | B20: Engineering Master Schedule - AFC | C20: 5 | D20: 46134 | E20: 46140 | F20: 166 | G20: PTTME Office 5dx8h
A21: PROCESSANDUTILITIESENGINEERING | C21: 80 | D21: 46106 | E21: 46226 | F21: 107 | G21: PTTME Office 5dx8h
A22: PR-1000 | B22: Process Basis of Design - IFR | C22: 10 | D22: 46113 | E22: 46132 | F22: 33 | G22: PTTME Office 5dx8h
A23: PR-1010 | B23: Process Basis of Design - IFA | C23: 5 | D23: 46148 | E23: 46154 | F23: 33 | G23: PTTME Office 5dx8h
A24: PR-1020 | B24: Process Basis of Design - AFC | C24: 5 | D24: 46169 | E24: 46177 | F24: 33 | G24: PTTME Office 5dx8h
A25: PR-1090 | B25: Process Simulation Report - IFR | C25: 5 | D25: 46185 | E25: 46191 | F25: 117 | G25: PTTME Office 5dx8h
A26: PR-1100 | B26: Process Simulation Report - AFC | C26: 5 | D26: 46206 | E26: 46212 | F26: 117 | G26: PTTME Office 5dx8h
A27: PR-1110 | B27: Utility Balance and Consumption Report - IFR | C27: 10 | D27: 46185 | E27: 46198 | F27: 112 | G27: PTTME Office 5dx8h
A28: PR-1120 | B28: Utility Balance and Consumption Report - AFC | C28: 5 | D28: 46213 | E28: 46219 | F28: 112 | G28: PTTME Office 5dx8h
A29: PR-1130 | B29: AIV And FIV Study Report - IFR | C29: 15 | D29: 46162 | E29: 46184 | F29: 109 | G29: PTTME Office 5dx8h
A30: PR-1140 | B30: AIV And FIV Study Report - AFC | C30: 5 | D30: 46199 | E30: 46205 | F30: 122 | G30: PTTME Office 5dx8h
A31: PR-1150 | B31: Depressurization and Low Temperature Study Report - IFR | C31: 20 | D31: 46175 | E31: 46203 | F31: 109 | G31: PTTME Office 5dx8h
A32: PR-1160 | B32: Depressurization and Low Temperature Study Report - AFC | C32: 5 | D32: 46218 | E32: 46224 | F32: 109 | G32: PTTME Office 5dx8h
A33: PR-1170 | B33: Vent Sizing and Relief Load Report - IFR | C33: 13 | D33: 46175 | E33: 46192 | F33: 116 | G33: PTTME Office 5dx8h
... A83: PR-1650 | B83: Transient Flow Assurance Study Report - AFC | C83: 5 | D83: 46220 | E83: 46226 | F83: 107 | G83: PTTME Office 5dx8h
A84: ProcessCalculationNote | C84: 45 | D84: 46140 | E84: 46205 | F84: -17 | G84: PTTME Office 5dx8h
A85: PR-1660 | B85: Process Calculation Note for Line Sizing - IFR | C85: 23 | D85: 46140 | E85: 46171 | F85: -10 | G85: PTTME Office 5dx8h
A86: PR-1670 | B86: Process Calculation Note for Line Sizing - AFC | C86: 5 | D86: 46199 | E86: 46205 | F86: -17 | G86: PTTME Office 5dx8h
A87: PR-1680 | B87: Process Calculation Note for Test Separator Sizing - IFR | C87: 15 | D87: 46140 | E87: 46161 | F87: -2 | G87: PTTME Office 5dx8h
A88: PR-1690 | B88: Process Calculation Note for Test Separator Sizing - AFC | C88: 5 | D88: 46199 | E88: 46205 | F88: -17 | G88: PTTME Office 5dx8h
A89: PR-1700 | B89: Process Calculation Note for Production Separator (V-01001) - IFR | C89: 15 | D89: 46140 | E89: 46161 | F89: -2 | G89: PTTME Office 5dx8h
...

Sheet Before Award
A1: ZM167 PTTEPI ASK Procurement Plan - Before Award
I12: LA | L12: 1 | M12: 5 | N12: 1 | O12: 5 | R12: 10 | S12: 20 | T12: 3 | U12: 10 | V12: 2 | W12: =SUM(L12:V12) -> 57 | AP12: 2 | AQ12: 4 | AR12: 5
I13: LB | L13: 1 | M13: 5 | N13: 1 | O13: 5 | R13: 10 | S13: 20 | T13: 3 | U13: 10 | V13: 2 | W13: =SUM(L13:V13) -> 57 | AP13: 2 | AQ13: 4 | AR13: 5
I14: LC | L14: 3 | M14: 10 | N14: 1 | O14: 10 | R14: 10 | S14: 15 | T14: 10 | U14: 10 | V14: 2 | W14: =SUM(L14:V14) -> 71 | AP14: 2 | AQ14: 2 | AR14: 5
I15: LD | L15: 3 | M15: 5 | N15: 1 | O15: 3 | R15: 5 | S15: 7 | T15: 2 | U15: 5 | V15: 2 | W15: =SUM(L15:V15) -> 33 | AP15: 2 | AQ15: 2 | AR15: 5
A16: No. | B16: MR.No | C16: RFQ No. | D16: Package Name | E16: PO NO. | F16: Discripline | G16: Long Lead Item (Y/N) | H16: Criticality Rating | I16: Priority Level | K16: Bidder List Approval | L16: MR Issued | M16: MR Approved | N16: RFQ Issued | O16: RFQ Approved | P16: Bidding Duration | Q16: CFT Issuance | R16: Bid Closing Date | S16: TBE Issued | T16: TBE Approved | U16: PO Issued | V16: Vendor Acknowledgement | W16: Delivery Duration (Weeks) | X16: Delivery Date | Y16: Lead Time (Days) | Z16: ROS date | AA16: Earlier ROS date | AB16: Float (Day) | AC16: 40329 | AD16: 40359 | AE16: 40390 | AF16: 40421 | AG16: 40451 | AH16: 40482 | AI16: 40512 | AJ16: 40543 | AK16: 40574 | AL16: 40602 | AM16: =TODAY() -> 46302 | AP16: Final&Best Proposal Submission | AQ16: TJE CBE approval (LOI Issue) | AR16: MRP | AS16: Transportation time
A17: 1 | C17: RFQ-001 | D17: Pedestal Crane | F17: Mechanical | G17: =IF(_xlfn.XLOOKUP(C17,'[36]Before Award'!D:D,'[36]Before Award'!AV:AV,"N/A")="N/A","N","Y") -> N | I17: LA | J17: Plan | K17: =WORKDAY(L17,-INDEX(L$12:L$15,MATCH($I17,$I$12:$I$15,0))) -> 46140 | L17: =WORKDAY(M17,-INDEX(M$12:M$15,MATCH($I17,$I$12:$I$15,0))) -> 46141 | M17: =WORKDAY(N17,-INDEX(N$12:N$15,MATCH($I17,$I$12:$I$15,0))) -> 46148 | N17: =WORKDAY(O17,-INDEX(O$12:O$15,MATCH($I17,$I$12:$I$15,0))) -> 46149 | O17: =WORKDAY(R17,-INDEX(R$12:R$15,MATCH($I17,$I$12:$I$15,0))) -> 46156 | P17: =U17-L17 -> 76 | R17: =WORKDAY(S17,-INDEX(S$12:S$15,MATCH($I17,$I$12:$I$15,0))) -> 46170 | S17: =WORKDAY(T17,-INDEX(T$12:T$15,MATCH($I17,$I$12:$I$15,0))) -> 46198 | T17: =WORKDAY(U17,-INDEX(U$12:U$15,MATCH($I17,$I$12:$I$15,0))) -> 46203 | U17: =X17-Y17 -> 46217 | V17: =WORKDAY(U17,INDEX(V$12:V$15,MATCH($I17,$I$12:$I$15,0))) -> 46219 | W17: =Y17/7 -> 50 | X17: =Z17 -> 46567 | Y17: 350 | Z17: 46567 | AA17: 46567 | AB17: =Z17-X18 -> 0 | AC17: =IF(ISERROR(LOOKUP(AC$16,$L17:$X17,#REF!)),0,(LOOKUP(AC$16,$L17:$X17,#REF!))) -> 0 | AD17: =IF(ISERROR(LOOKUP(AD$16,$L17:$X17,#REF!)),0,(LOOKUP(AD$16,$L17:$X17,#REF!))) -> 0 | AE17: =IF(ISERROR(LOOKUP(AE$16,$L17:$X17,#REF!)),0,(LOOKUP(AE$16,$L17:$X17,#REF!))) -> 0 | AF17: =IF(ISERROR(LOOKUP(AF$16,$L17:$X17,#REF!)),0,(LOOKUP(AF$16,$L17:$X17,#REF!))) -> 0 | AG17: =IF(ISERROR(LOOKUP(AG$16,$L17:$X17,#REF!)),0,(LOOKUP(AG$16,$L17:$X17,#REF!))) -> 0 | AH17: =IF(ISERROR(LOOKUP(AH$16,$L17:$X17,#REF!)),0,(LOOKUP(AH$16,$L17:$X17,#REF!))) -> 0 | AI17: =IF(ISERROR(LOOKUP(AI$16,$L17:$X17,#REF!)),0,(LOOKUP(AI$16,$L17:$X17,#REF!))) -> 0 | AJ17: =IF(ISERROR(LOOKUP(AJ$16,$L17:$X17,#REF!)),0,(LOOKUP(AJ$16,$L17:$X17,#REF!))) -> 0 | ... AM17: =IF(ISERROR(LOOKUP(AM$16,$L17:$X17,#REF!)),0,(LOOKUP(AM$16,$L17:$X17,#REF!))) -> 0 | AO17: =U17-T17 -> 14 | AP17: =WORKDAY(AQ17,-INDEX(AQ$12:AQ$15,MATCH($I17,$I$12:$I$15,0)),$AW$17:$AW$148) -> #REF! | AQ17: =WORKDAY(U17,-INDEX(U$12:U$15,MATCH($I17,$I$12:$I$15,0)),$AW$17:$AW$148) -> #REF! | AR17: =WORKDAY(U17,-INDEX(U$12:U$15,MATCH($I17,$I$12:$I$15,0)),$AW$17:$AW$148) -> #REF! | AS17: 14 | AW17: {='[36]Equipment List and MR List (3)'!$A$2:$A$80} -> #REF!
C18: =C17 -> RFQ-001 | D18: =D17 -> Pedestal Crane | I18: =I17 -> LA | J18: Forecast | K18: =K17 -> 46140 | L18: =WORKDAY(IF(K19="",K18,K19),INDEX(L$12:L$15,MATCH($I17,$I$12:$I$15,0))) -> 46141 | M18: =WORKDAY(IF(L19="",L18,L19),INDEX(M$12:M$15,MATCH($I17,$I$12:$I$15,0))) -> 46148 | N18: =WORKDAY(IF(M19="",M18,M19),INDEX(N$12:N$15,MATCH($I17,$I$12:$I$15,0))) -> 46149 | O18: =WORKDAY(IF(N19="",N18,N19),INDEX(O$12:O$15,MATCH($I17,$I$12:$I$15,0))) -> 46156 | R18: =WORKDAY(IF(O19="",O18,O19),INDEX(R$12:R$15,MATCH($I17,$I$12:$I$15,0))) -> 46170 | S18: =WORKDAY(IF(R19="",R18,R19),INDEX(S$12:S$15,MATCH($I17,$I$12:$I$15,0))) -> 46198 | T18: =WORKDAY(IF(S19="",S18,S19),INDEX(T$12:T$15,MATCH($I17,$I$12:$I$15,0))) -> 46203 | U18: =WORKDAY(IF(T19="",T18,T19),INDEX(U$12:U$15,MATCH($I17,$I$12:$I$15,0))) -> 46217 | V18: =WORKDAY(IF(U19="",U18,U19),INDEX(V$12:V$15,MATCH($I17,$I$12:$I$15,0))) -> 46219 | X18: =U18+Y17 -> 46567 | AC18: =IF(ISERROR(LOOKUP(AC$16,$L18:$X18,#REF!)),0,(LOOKUP(AC$16,$L18:$X18,#REF!))) -> 0 | AD18: =IF(ISERROR(LOOKUP(AD$16,$L18:$X18,#REF!)),0,(LOOKUP(AD$16,$L18:$X18,#REF!))) -> 0 | AE18: =IF(ISERROR(LOOKUP(AE$16,$L18:$X18,#REF!)),0,(LOOKUP(AE$16,$L18:$X18,#REF!))) -> 0 | AF18: =IF(ISERROR(LOOKUP(AF$16,$L18:$X18,#REF!)),0,(LOOKUP(AF$16,$L18:$X18,#REF!))) -> 0 | AG18: =IF(ISERROR(LOOKUP(AG$16,$L18:$X18,#REF!)),0,(LOOKUP(AG$16,$L18:$X18,#REF!))) -> 0 | AH18: =IF(ISERROR(LOOKUP(AH$16,$L18:$X18,#REF!)),0,(LOOKUP(AH$16,$L18:$X18,#REF!))) -> 0 | AI18: =IF(ISERROR(LOOKUP(AI$16,$L18:$X18,#REF!)),0,(LOOKUP(AI$16,$L18:$X18,#REF!))) -> 0 | AJ18: =IF(ISERROR(LOOKUP(AJ$16,$L18:$X18,#REF!)),0,(LOOKUP(AJ$16,$L18:$X18,#REF!))) -> 0 | ... AM18: =IF(ISERROR(LOOKUP(AM$16,$L18:$X18,#REF!)),0,(LOOKUP(AM$16,$L18:$X18,#REF!))) -> 0 | AO18: =U18-T18 -> 14 | AP18: =WORKDAY(IF(T19="",T18,T19),INDEX(AP$12:AP$15,MATCH($I17,$I$12:$I$15,0)),$AW$17:$AW$148) -> #REF! | AQ18: =WORKDAY(IF(AP19="",AP18,AP19),INDEX(AQ$12:AQ$15,MATCH($I17,$I$12:$I$15,0)),$AW$17:$AW$148) -> #REF! | AR18: =WORKDAY(IF(AQ19="",AQ18,AQ19),INDEX(AR$12:AR$15,MATCH($I17,$I$12:$I$15,0)),$AW$17:$AW$148) -> #REF! | AW18: #REF!
C19: =C17 -> RFQ-001 | D19: =D17 -> Pedestal Crane | I19: =I17 -> LA | J19: Actual | AC19: =IF(ISERROR(LOOKUP(AC$16,$L19:$X19,#REF!)),0,(LOOKUP(AC$16,$L19:$X19,#REF!))) -> 0 | AD19: =IF(ISERROR(LOOKUP(AD$16,$L19:$X19,#REF!)),0,(LOOKUP(AD$16,$L19:$X19,#REF!))) -> 0 | AE19: =IF(ISERROR(LOOKUP(AE$16,$L19:$X19,#REF!)),0,(LOOKUP(AE$16,$L19:$X19,#REF!))) -> 0 | AF19: =IF(ISERROR(LOOKUP(AF$16,$L19:$X19,#REF!)),0,(LOOKUP(AF$16,$L19:$X19,#REF!))) -> 0 | AG19: =IF(ISERROR(LOOKUP(AG$16,$L19:$X19,#REF!)),0,(LOOKUP(AG$16,$L19:$X19,#REF!))) -> 0 | AH19: =IF(ISERROR(LOOKUP(AH$16,$L19:$X19,#REF!)),0,(LOOKUP(AH$16,$L19:$X19,#REF!))) -> 0 | AI19: =IF(ISERROR(LOOKUP(AI$16,$L19:$X19,#REF!)),0,(LOOKUP(AI$16,$L19:$X19,#REF!))) -> 0 | AJ19: =IF(ISERROR(LOOKUP(AJ$16,$L19:$X19,#REF!)),0,(LOOKUP(AJ$16,$L19:$X19,#REF!))) -> 0 | ... AM19: =IF(ISERROR(LOOKUP(AM$16,$L19:$X19,#REF!)),0,(LOOKUP(AM$16,$L19:$X19,#REF!))) -> 0 | AO19: =U19-T19 -> 0 | AW19: #REF!
A20: =A17+1 -> 2 | C20: RFQ-002 | D20: Material Handling Equipment | F20: Mechanical | G20: N | I20: LC | J20: Plan | K20: =WORKDAY(L20,-INDEX(L$12:L$15,MATCH($I20,$I$12:$I$15,0))) -> 46296 | L20: =WORKDAY(M20,-INDEX(M$12:M$15,MATCH($I20,$I$12:$I$15,0))) -> 46301 | M20: =WORKDAY(N20,-INDEX(N$12:N$15,MATCH($I20,$I$12:$I$15,0))) -> 46315 | N20: =WORKDAY(O20,-INDEX(O$12:O$15,MATCH($I20,$I$12:$I$15,0))) -> 46316 | O20: =WORKDAY(R20,-INDEX(R$12:R$15,MATCH($I20,$I$12:$I$15,0))) -> 46330 | P20: =U20-L20 -> 92 | R20: =WORKDAY(S20,-INDEX(S$12:S$15,MATCH($I20,$I$12:$I$15,0))) -> 46344 | S20: =WORKDAY(T20,-INDEX(T$12:T$15,MATCH($I20,$I$12:$I$15,0))) -> 46365 | T20: =WORKDAY(U20,-INDEX(U$12:U$15,MATCH($I20,$I$12:$I$15,0))) -> 46379 | U20: =X20-Y20 -> 46393 | V20: =WORKDAY(U20,INDEX(V$12:V$15,MATCH($I20,$I$12:$I$15,0))) -> 46395 | W20: =Y20/7 -> 25 | X20: =Z20 -> 46568 | Y20: 175 | Z20: 46568 | AA20: 46568 | AB20: =Z20-X21 -> 0 | AC20: =IF(ISERROR(LOOKUP(AC$16,$L20:$X20,#REF!)),0,(LOOKUP(AC$16,$L20:$X20,#REF!))) -> 0 | AD20: =IF(ISERROR(LOOKUP(AD$16,$L20:$X20,#REF!)),0,(LOOKUP(AD$16,$L20:$X20,#REF!))) -> 0 | AE20: =IF(ISERROR(LOOKUP(AE$16,$L20:$X20,#REF!)),0,(LOOKUP(AE$16,$L20:$X20,#REF!))) -> 0 | AF20: =IF(ISERROR(LOOKUP(AF$16,$L20:$X20,#REF!)),0,(LOOKUP(AF$16,$L20:$X20,#REF!))) -> 0 | AG20: =IF(ISERROR(LOOKUP(AG$16,$L20:$X20,#REF!)),0,(LOOKUP(AG$16,$L20:$X20,#REF!))) -> 0 | AH20: =IF(ISERROR(LOOKUP(AH$16,$L20:$X20,#REF!)),0,(LOOKUP(AH$16,$L20:$X20,#REF!))) -> 0 | AI20: =IF(ISERROR(LOOKUP(AI$16,$L20:$X20,#REF!)),0,(LOOKUP(AI$16,$L20:$X20,#REF!))) -> 0 | AJ20: =IF(ISERROR(LOOKUP(AJ$16,$L20:$X20,#REF!)),0,(LOOKUP(AJ$16,$L20:$X20,#REF!))) -> 0 | ... AM20: =IF(ISERROR(LOOKUP(AM$16,$L20:$X20,#REF!)),0,(LOOKUP(AM$16,$L20:$X20,#REF!))) -> 0 | AO20: =U20-T20 -> 14 | AP20: =WORKDAY(AQ20,-INDEX(AQ$12:AQ$15,MATCH($I20,$I$12:$I$15,0)),$AW$17:$AW$148) -> #REF! | AQ20: =WORKDAY(U20,-INDEX(U$12:U$15,MATCH($I20,$I$12:$I$15,0)),$AW$17:$AW$148) -> #REF! | AR20: =WORKDAY(U20,-INDEX(U$12:U$15,MATCH($I20,$I$12:$I$15,0)),$AW$17:$AW$148) -> #REF! | AS20: 14 | AW20: #REF!
C21: =C20 -> RFQ-002 | D21: =D20 -> Material Handling Equipment | G21: =G20 -> N | I21: =I20 -> LC | J21: Forecast | K21: =K20 -> 46296 | L21: =WORKDAY(IF(K22="",K21,K22),INDEX(L$12:L$15,MATCH($I20,$I$12:$I$15,0))) -> 46301 | M21: =WORKDAY(IF(L22="",L21,L22),INDEX(M$12:M$15,MATCH($I20,$I$12:$I$15,0))) -> 46315 | N21: =WORKDAY(IF(M22="",M21,M22),INDEX(N$12:N$15,MATCH($I20,$I$12:$I$15,0))) -> 46316 | O21: =WORKDAY(IF(N22="",N21,N22),INDEX(O$12:O$15,MATCH($I20,$I$12:$I$15,0))) -> 46330 | R21: =WORKDAY(IF(O22="",O21,O22),INDEX(R$12:R$15,MATCH($I20,$I$12:$I$15,0))) -> 46344 | S21: =WORKDAY(IF(R22="",R21,R22),INDEX(S$12:S$15,MATCH($I20,$I$12:$I$15,0))) -> 46365 | T21: =WORKDAY(IF(S22="",S21,S22),INDEX(T$12:T$15,MATCH($I20,$I$12:$I$15,0))) -> 46379 | U21: =WORKDAY(IF(T22="",T21,T22),INDEX(U$12:U$15,MATCH($I20,$I$12:$I$15,0))) -> 46393 | V21: =WORKDAY(IF(U22="",U21,U22),INDEX(V$12:V$15,MATCH($I20,$I$12:$I$15,0))) -> 46395 | X21: =U21+Y20 -> 46568 | AC21: =IF(ISERROR(LOOKUP(AC$16,$L21:$X21,#REF!)),0,(LOOKUP(AC$16,$L21:$X21,#REF!))) -> 0 | AD21: =IF(ISERROR(LOOKUP(AD$16,$L21:$X21,#REF!)),0,(LOOKUP(AD$16,$L21:$X21,#REF!))) -> 0 | AE21: =IF(ISERROR(LOOKUP(AE$16,$L21:$X21,#REF!)),0,(LOOKUP(AE$16,$L21:$X21,#REF!))) -> 0 | AF21: =IF(ISERROR(LOOKUP(AF$16,$L21:$X21,#REF!)),0,(LOOKUP(AF$16,$L21:$X21,#REF!))) -> 0 | AG21: =IF(ISERROR(LOOKUP(AG$16,$L21:$X21,#REF!)),0,(LOOKUP(AG$16,$L21:$X21,#REF!))) -> 0 | AH21: =IF(ISERROR(LOOKUP(AH$16,$L21:$X21,#REF!)),0,(LOOKUP(AH$16,$L21:$X21,#REF!))) -> 0 | AI21: =IF(ISERROR(LOOKUP(AI$16,$L21:$X21,#REF!)),0,(LOOKUP(AI$16,$L21:$X21,#REF!))) -> 0 | AJ21: =IF(ISERROR(LOOKUP(AJ$16,$L21:$X21,#REF!)),0,(LOOKUP(AJ$16,$L21:$X21,#REF!))) -> 0 | ... AM21: =IF(ISERROR(LOOKUP(AM$16,$L21:$X21,#REF!)),0,(LOOKUP(AM$16,$L21:$X21,#REF!))) -> 0 | AO21: =U21-T21 -> 14 | AP21: =WORKDAY(IF(T22="",T21,T22),INDEX(AP$12:AP$15,MATCH($I20,$I$12:$I$15,0)),$AW$17:$AW$148) -> #REF! | AQ21: =WORKDAY(IF(AP22="",AP21,AP22),INDEX(AQ$12:AQ$15,MATCH($I20,$I$12:$I$15,0)),$AW$17:$AW$148) -> #REF! | AR21: =WORKDAY(IF(AQ22="",AQ21,AQ22),INDEX(AR$12:AR$15,MATCH($I20,$I$12:$I$15,0)),$AW$17:$AW$148) -> #REF! | AW21: #REF!
C22: =C20 -> RFQ-002 | D22: =D20 -> Material Handling Equipment | G22: =G20 -> N | I22: =I20 -> LC | J22: Actual | AC22: =IF(ISERROR(LOOKUP(AC$16,$L22:$X22,#REF!)),0,(LOOKUP(AC$16,$L22:$X22,#REF!))) -> 0 | AD22: =IF(ISERROR(LOOKUP(AD$16,$L22:$X22,#REF!)),0,(LOOKUP(AD$16,$L22:$X22,#REF!))) -> 0 | AE22: =IF(ISERROR(LOOKUP(AE$16,$L22:$X22,#REF!)),0,(LOOKUP(AE$16,$L22:$X22,#REF!))) -> 0 | AF22: =IF(ISERROR(LOOKUP(AF$16,$L22:$X22,#REF!)),0,(LOOKUP(AF$16,$L22:$X22,#REF!))) -> 0 | AG22: =IF(ISERROR(LOOKUP(AG$16,$L22:$X22,#REF!)),0,(LOOKUP(AG$16,$L22:$X22,#REF!))) -> 0 | AH22: =IF(ISERROR(LOOKUP(AH$16,$L22:$X22,#REF!)),0,(LOOKUP(AH$16,$L22:$X22,#REF!))) -> 0 | AI22: =IF(ISERROR(LOOKUP(AI$16,$L22:$X22,#REF!)),0,(LOOKUP(AI$16,$L22:$X22,#REF!))) -> 0 | AJ22: =IF(ISERROR(LOOKUP(AJ$16,$L22:$X22,#REF!)),0,(LOOKUP(AJ$16,$L22:$X22,#REF!))) -> 0 | ... AM22: =IF(ISERROR(LOOKUP(AM$16,$L22:$X22,#REF!)),0,(LOOKUP(AM$16,$L22:$X22,#REF!))) -> 0 | AO22: =U22-T22 -> 0 | AW22: #REF!
A23: =A20+1 -> 3 | C23: RFQ-003 | D23: Instrument Gas Filter Coalescer | F23: Mechanical | G23: Y | I23: LA | J23: Plan | K23: =WORKDAY(L23,-INDEX(L$12:L$15,MATCH($I23,$I$12:$I$15,0))) -> 46209 | L23: =WORKDAY(M23,-INDEX(M$12:M$15,MATCH($I23,$I$12:$I$15,0))) -> 46210 | M23: =WORKDAY(N23,-INDEX(N$12:N$15,MATCH($I23,$I$12:$I$15,0))) -> 46217 | N23: =WORKDAY(O23,-INDEX(O$12:O$15,MATCH($I23,$I$12:$I$15,0))) -> 46218 | O23: =WORKDAY(R23,-INDEX(R$12:R$15,MATCH($I23,$I$12:$I$15,0))) -> 46225 | P23: =U23-L23 -> 76 | R23: =WORKDAY(S23,-INDEX(S$12:S$15,MATCH($I23,$I$12:$I$15,0))) -> 46239 | S23: =WORKDAY(T23,-INDEX(T$12:T$15,MATCH($I23,$I$12:$I$15,0))) -> 46267 | T23: =WORKDAY(U23,-INDEX(U$12:U$15,MATCH($I23,$I$12:$I$15,0))) -> 46272 | U23: =X23-Y23 -> 46286 | V23: =WORKDAY(U23,INDEX(V$12:V$15,MATCH($I23,$I$12:$I$15,0))) -> 46288 | W23: =Y23/7 -> 25.714286 | X23: =Z23 -> 46466 | Y23: 180 | Z23: 46466 | AA23: 46466 | AB23: =Z23-X24 -> 0 | AC23: =IF(ISERROR(LOOKUP(AC$16,$L23:$X23,#REF!)),0,(LOOKUP(AC$16,$L23:$X23,#REF!))) -> 0 | AD23: =IF(ISERROR(LOOKUP(AD$16,$L23:$X23,#REF!)),0,(LOOKUP(AD$16,$L23:$X23,#REF!))) -> 0 | AE23: =IF(ISERROR(LOOKUP(AE$16,$L23:$X23,#REF!)),0,(LOOKUP(AE$16,$L23:$X23,#REF!))) -> 0 | AF23: =IF(ISERROR(LOOKUP(AF$16,$L23:$X23,#REF!)),0,(LOOKUP(AF$16,$L23:$X23,#REF!))) -> 0 | AG23: =IF(ISERROR(LOOKUP(AG$16,$L23:$X23,#REF!)),0,(LOOKUP(AG$16,$L23:$X23,#REF!))) -> 0 | AH23: =IF(ISERROR(LOOKUP(AH$16,$L23:$X23,#REF!)),0,(LOOKUP(AH$16,$L23:$X23,#REF!))) -> 0 | AI23: =IF(ISERROR(LOOKUP(AI$16,$L23:$X23,#REF!)),0,(LOOKUP(AI$16,$L23:$X23,#REF!))) -> 0 | AJ23: =IF(ISERROR(LOOKUP(AJ$16,$L23:$X23,#REF!)),0,(LOOKUP(AJ$16,$L23:$X23,#REF!))) -> 0 | ... AM23: =IF(ISERROR(LOOKUP(AM$16,$L23:$X23,#REF!)),0,(LOOKUP(AM$16,$L23:$X23,#REF!))) -> 0 | AO23: =U23-T23 -> 14 | AP23: =WORKDAY(AQ23,-INDEX(AQ$12:AQ$15,MATCH($I23,$I$12:$I$15,0)),$AW$17:$AW$148) -> #REF! | AQ23: =WORKDAY(U23,-INDEX(U$12:U$15,MATCH($I23,$I$12:$I$15,0)),$AW$17:$AW$148) -> #REF! | AR23: =WORKDAY(U23,-INDEX(U$12:U$15,MATCH($I23,$I$12:$I$15,0)),$AW$17:$AW$148) -> #REF! | AS23: 7 | AW23: #REF!
C24: =C23 -> RFQ-003 | D24: =D23 -> Instrument Gas Filter Coalescer | G24: =G23 -> Y | I24: =I23 -> LA | J24: Forecast | K24: =K23 -> 46209 | L24: =WORKDAY(IF(K25="",K24,K25),INDEX(L$12:L$15,MATCH($I23,$I$12:$I$15,0))) -> 46210 | M24: =WORKDAY(IF(L25="",L24,L25),INDEX(M$12:M$15,MATCH($I23,$I$12:$I$15,0))) -> 46217 | N24: =WORKDAY(IF(M25="",M24,M25),INDEX(N$12:N$15,MATCH($I23,$I$12:$I$15,0))) -> 46218 | O24: =WORKDAY(IF(N25="",N24,N25),INDEX(O$12:O$15,MATCH($I23,$I$12:$I$15,0))) -> 46225 | R24: =WORKDAY(IF(O25="",O24,O25),INDEX(R$12:R$15,MATCH($I23,$I$12:$I$15,0))) -> 46239 | S24: =WORKDAY(IF(R25="",R24,R25),INDEX(S$12:S$15,MATCH($I23,$I$12:$I$15,0))) -> 46267 | T24: =WORKDAY(IF(S25="",S24,S25),INDEX(T$12:T$15,MATCH($I23,$I$12:$I$15,0))) -> 46272 | U24: =WORKDAY(IF(T25="",T24,T25),INDEX(U$12:U$15,MATCH($I23,$I$12:$I$15,0))) -> 46286 | V24: =WORKDAY(IF(U25="",U24,U25),INDEX(V$12:V$15,MATCH($I23,$I$12:$I$15,0))) -> 46288 | X24: =U24+Y23 -> 46466 | AC24: =IF(ISERROR(LOOKUP(AC$16,$L24:$X24,#REF!)),0,(LOOKUP(AC$16,$L24:$X24,#REF!))) -> 0 | AD24: =IF(ISERROR(LOOKUP(AD$16,$L24:$X24,#REF!)),0,(LOOKUP(AD$16,$L24:$X24,#REF!))) -> 0 | AE24: =IF(ISERROR(LOOKUP(AE$16,$L24:$X24,#REF!)),0,(LOOKUP(AE$16,$L24:$X24,#REF!))) -> 0 | AF24: =IF(ISERROR(LOOKUP(AF$16,$L24:$X24,#REF!)),0,(LOOKUP(AF$16,$L24:$X24,#REF!))) -> 0 | AG24: =IF(ISERROR(LOOKUP(AG$16,$L24:$X24,#REF!)),0,(LOOKUP(AG$16,$L24:$X24,#REF!))) -> 0 | AH24: =IF(ISERROR(LOOKUP(AH$16,$L24:$X24,#REF!)),0,(LOOKUP(AH$16,$L24:$X24,#REF!))) -> 0 | AI24: =IF(ISERROR(LOOKUP(AI$16,$L24:$X24,#REF!)),0,(LOOKUP(AI$16,$L24:$X24,#REF!))) -> 0 | AJ24: =IF(ISERROR(LOOKUP(AJ$16,$L24:$X24,#REF!)),0,(LOOKUP(AJ$16,$L24:$X24,#REF!))) -> 0 | ... AM24: =IF(ISERROR(LOOKUP(AM$16,$L24:$X24,#REF!)),0,(LOOKUP(AM$16,$L24:$X24,#REF!))) -> 0 | AO24: =U24-T24 -> 14 | AP24: =WORKDAY(IF(T25="",T24,T25),INDEX(AP$12:AP$15,MATCH($I23,$I$12:$I$15,0)),$AW$17:$AW$148) -> #REF! | AQ24: =WORKDAY(IF(AP25="",AP24,AP25),INDEX(AQ$12:AQ$15,MATCH($I23,$I$12:$I$15,0)),$AW$17:$AW$148) -> #REF! | AR24: =WORKDAY(IF(AQ25="",AQ24,AQ25),INDEX(AR$12:AR$15,MATCH($I23,$I$12:$I$15,0)),$AW$17:$AW$148) -> #REF! | AW24: #REF!
C25: =C23 -> RFQ-003 | D25: =D23 -> Instrument Gas Filter Coalescer | G25: =G23 -> Y | I25: =I23 -> LA | J25: Actual | AC25: =IF(ISERROR(LOOKUP(AC$16,$L25:$X25,#REF!)),0,(LOOKUP(AC$16,$L25:$X25,#REF!))) -> 0 | AD25: =IF(ISERROR(LOOKUP(AD$16,$L25:$X25,#REF!)),0,(LOOKUP(AD$16,$L25:$X25,#REF!))) -> 0 | AE25: =IF(ISERROR(LOOKUP(AE$16,$L25:$X25,#REF!)),0,(LOOKUP(AE$16,$L25:$X25,#REF!))) -> 0 | AF25: =IF(ISERROR(LOOKUP(AF$16,$L25:$X25,#REF!)),0,(LOOKUP(AF$16,$L25:$X25,#REF!))) -> 0 | AG25: =IF(ISERROR(LOOKUP(AG$16,$L25:$X25,#REF!)),0,(LOOKUP(AG$16,$L25:$X25,#REF!))) -> 0 | AH25: =IF(ISERROR(LOOKUP(AH$16,$L25:$X25,#REF!)),0,(LOOKUP(AH$16,$L25:$X25,#REF!))) -> 0 | AI25: =IF(ISERROR(LOOKUP(AI$16,$L25:$X25,#REF!)),0,(LOOKUP(AI$16,$L25:$X25,#REF!))) -> 0 | AJ25: =IF(ISERROR(LOOKUP(AJ$16,$L25:$X25,#REF!)),0,(LOOKUP(AJ$16,$L25:$X25,#REF!))) -> 0 | ... AM25: =IF(ISERROR(LOOKUP(AM$16,$L25:$X25,#REF!)),0,(LOOKUP(AM$16,$L25:$X25,#REF!))) -> 0 | AO25: =U25-T25 -> 0 | AW25: #REF!
A26: =A23+1 -> 4 | C26: RFQ-004 | D26: Production & Test Seperator | F26: Mechanical | G26: =IF(_xlfn.XLOOKUP(C26,'[36]Before Award'!D:D,'[36]Before Award'!AV:AV,"N/A")="N/A","N","Y") -> N | I26: LA | J26: Plan | K26: 46211 | L26: 46212 | M26: 46217 | N26: 46218 | O26: 46223 | P26: =U26-L26 -> 71 | R26: 46237 | S26: 46265 | T26: 46268 | U26: 46283 | V26: 46290 | W26: 26 | X26: 46466 | Y26: =W26*7 -> 182 | Z26: 46466 | AA26: 46466 | AB26: =Z26-X27 -> 0 | AC26: =IF(ISERROR(LOOKUP(AC$16,$L26:$X26,#REF!)),0,(LOOKUP(AC$16,$L26:$X26,#REF!))) -> 0 | AD26: =IF(ISERROR(LOOKUP(AD$16,$L26:$X26,#REF!)),0,(LOOKUP(AD$16,$L26:$X26,#REF!))) -> 0 | AE26: =IF(ISERROR(LOOKUP(AE$16,$L26:$X26,#REF!)),0,(LOOKUP(AE$16,$L26:$X26,#REF!))) -> 0 | AF26: =IF(ISERROR(LOOKUP(AF$16,$L26:$X26,#REF!)),0,(LOOKUP(AF$16,$L26:$X26,#REF!))) -> 0 | AG26: =IF(ISERROR(LOOKUP(AG$16,$L26:$X26,#REF!)),0,(LOOKUP(AG$16,$L26:$X26,#REF!))) -> 0 | AH26: =IF(ISERROR(LOOKUP(AH$16,$L26:$X26,#REF!)),0,(LOOKUP(AH$16,$L26:$X26,#REF!))) -> 0 | AI26: =IF(ISERROR(LOOKUP(AI$16,$L26:$X26,#REF!)),0,(LOOKUP(AI$16,$L26:$X26,#REF!))) -> 0 | AJ26: =IF(ISERROR(LOOKUP(AJ$16,$L26:$X26,#REF!)),0,(LOOKUP(AJ$16,$L26:$X26,#REF!))) -> 0 | ... AM26: =IF(ISERROR(LOOKUP(AM$16,$L26:$X26,#REF!)),0,(LOOKUP(AM$16,$L26:$X26,#REF!))) -> 0 | AO26: =U26-T26 -> 15 | AP26: 46272 | AQ26: 46276 | AR26: 46276 | AS26: 14 | AW26: #REF!
C27: =C26 -> RFQ-004 | D27: =D26 -> Production & Test Seperator | G27: =G26 -> N | I27: =I26 -> LA | J27: Forecast | K27: 46211 | L27: 46212 | M27: 46217 | N27: 46218 | O27: 46223 | R27: 46237 | S27: 46265 | T27: 46268 | U27: 46283 | V27: 46290 | X27: 46466 | AC27: =IF(ISERROR(LOOKUP(AC$16,$L27:$X27,#REF!)),0,(LOOKUP(AC$16,$L27:$X27,#REF!))) -> 0 | AD27: =IF(ISERROR(LOOKUP(AD$16,$L27:$X27,#REF!)),0,(LOOKUP(AD$16,$L27:$X27,#REF!))) -> 0 | AE27: =IF(ISERROR(LOOKUP(AE$16,$L27:$X27,#REF!)),0,(LOOKUP(AE$16,$L27:$X27,#REF!))) -> 0 | AF27: =IF(ISERROR(LOOKUP(AF$16,$L27:$X27,#REF!)),0,(LOOKUP(AF$16,$L27:$X27,#REF!))) -> 0 | AG27: =IF(ISERROR(LOOKUP(AG$16,$L27:$X27,#REF!)),0,(LOOKUP(AG$16,$L27:$X27,#REF!))) -> 0 | AH27: =IF(ISERROR(LOOKUP(AH$16,$L27:$X27,#REF!)),0,(LOOKUP(AH$16,$L27:$X27,#REF!))) -> 0 | AI27: =IF(ISERROR(LOOKUP(AI$16,$L27:$X27,#REF!)),0,(LOOKUP(AI$16,$L27:$X27,#REF!))) -> 0 | AJ27: =IF(ISERROR(LOOKUP(AJ$16,$L27:$X27,#REF!)),0,(LOOKUP(AJ$16,$L27:$X27,#REF!))) -> 0 | ... AM27: =IF(ISERROR(LOOKUP(AM$16,$L27:$X27,#REF!)),0,(LOOKUP(AM$16,$L27:$X27,#REF!))) -> 0 | AO27: =U27-T27 -> 15 | AP27: 46272 | AQ27: 46276 | AR27: 46283 | AW27: #REF!
C28: =C26 -> RFQ-004 | D28: =D26 -> Production & Test Seperator | G28: =G26 -> N | I28: =I26 -> LA | J28: Actual | AC28: =IF(ISERROR(LOOKUP(AC$16,$L28:$X28,#REF!)),0,(LOOKUP(AC$16,$L28:$X28,#REF!))) -> 0 | AD28: =IF(ISERROR(LOOKUP(AD$16,$L28:$X28,#REF!)),0,(LOOKUP(AD$16,$L28:$X28,#REF!))) -> 0 | AE28: =IF(ISERROR(LOOKUP(AE$16,$L28:$X28,#REF!)),0,(LOOKUP(AE$16,$L28:$X28,#REF!))) -> 0 | AF28: =IF(ISERROR(LOOKUP(AF$16,$L28:$X28,#REF!)),0,(LOOKUP(AF$16,$L28:$X28,#REF!))) -> 0 | AG28: =IF(ISERROR(LOOKUP(AG$16,$L28:$X28,#REF!)),0,(LOOKUP(AG$16,$L28:$X28,#REF!))) -> 0 | AH28: =IF(ISERROR(LOOKUP(AH$16,$L28:$X28,#REF!)),0,(LOOKUP(AH$16,$L28:$X28,#REF!))) -> 0 | AI28: =IF(ISERROR(LOOKUP(AI$16,$L28:$X28,#REF!)),0,(LOOKUP(AI$16,$L28:$X28,#REF!))) -> 0 | AJ28: =IF(ISERROR(LOOKUP(AJ$16,$L28:$X28,#REF!)),0,(LOOKUP(AJ$16,$L28:$X28,#REF!))) -> 0 | ... AM28: =IF(ISERROR(LOOKUP(AM$16,$L28:$X28,#REF!)),0,(LOOKUP(AM$16,$L28:$X28,#REF!))) -> 0 | AO28: =U28-T28 -> 0 | AW28: #REF!
A29: =A26+1 -> 5 | C29: RFQ-005 | D29: Pig Launcher and Receiver | F29: Piping | G29: Y | I29: LA | J29: Plan | K29: 46176 | L29: 46177 | M29: 46182 | N29: 46183 | O29: 46188 | P29: =U29-L29 -> 71 | R29: 46202 | S29: 46230 | T29: 46233 | U29: 46248 | V29: 46255 | W29: 32 | X29: 46472 | Y29: =W29*7 -> 224 | Z29: 46472 | AA29: 46472 | AB29: =Z29-X30 -> 0 | AC29: =IF(ISERROR(LOOKUP(AC$16,$L29:$X29,#REF!)),0,(LOOKUP(AC$16,$L29:$X29,#REF!))) -> 0 | AD29: =IF(ISERROR(LOOKUP(AD$16,$L29:$X29,#REF!)),0,(LOOKUP(AD$16,$L29:$X29,#REF!))) -> 0 | AE29: =IF(ISERROR(LOOKUP(AE$16,$L29:$X29,#REF!)),0,(LOOKUP(AE$16,$L29:$X29,#REF!))) -> 0 | AF29: =IF(ISERROR(LOOKUP(AF$16,$L29:$X29,#REF!)),0,(LOOKUP(AF$16,$L29:$X29,#REF!))) -> 0 | AG29: =IF(ISERROR(LOOKUP(AG$16,$L29:$X29,#REF!)),0,(LOOKUP(AG$16,$L29:$X29,#REF!))) -> 0 | AH29: =IF(ISERROR(LOOKUP(AH$16,$L29:$X29,#REF!)),0,(LOOKUP(AH$16,$L29:$X29,#REF!))) -> 0 | AI29: =IF(ISERROR(LOOKUP(AI$16,$L29:$X29,#REF!)),0,(LOOKUP(AI$16,$L29:$X29,#REF!))) -> 0 | AJ29: =IF(ISERROR(LOOKUP(AJ$16,$L29:$X29,#REF!)),0,(LOOKUP(AJ$16,$L29:$X29,#REF!))) -> 0 | ... AM29: =IF(ISERROR(LOOKUP(AM$16,$L29:$X29,#REF!)),0,(LOOKUP(AM$16,$L29:$X29,#REF!))) -> 0 | AO29: =U29-T29 -> 15 | AP29: 46237 | AQ29: 46241 | AR29: 46241 | AS29: 14 | AW29: #REF!
C30: =C29 -> RFQ-005 | D30: =D29 -> Pig Launcher and Receiver | F30: =F29 -> Piping | G30: =G29 -> Y | I30: =I29 -> LA | J30: Forecast | K30: 46176 | L30: 46177 | M30: 46182 | N30: 46183 | O30: 46188 | R30: 46202 | S30: 46230 | T30: 46233 | U30: 46248 | V30: 46255 | X30: 46472 | AC30: =IF(ISERROR(LOOKUP(AC$16,$L30:$X30,#REF!)),0,(LOOKUP(AC$16,$L30:$X30,#REF!))) -> 0 | AD30: =IF(ISERROR(LOOKUP(AD$16,$L30:$X30,#REF!)),0,(LOOKUP(AD$16,$L30:$X30,#REF!))) -> 0 | AE30: =IF(ISERROR(LOOKUP(AE$16,$L30:$X30,#REF!)),0,(LOOKUP(AE$16,$L30:$X30,#REF!))) -> 0 | AF30: =IF(ISERROR(LOOKUP(AF$16,$L30:$X30,#REF!)),0,(LOOKUP(AF$16,$L30:$X30,#REF!))) -> 0 | AG30: =IF(ISERROR(LOOKUP(AG$16,$L30:$X30,#REF!)),0,(LOOKUP(AG$16,$L30:$X30,#REF!))) -> 0 | AH30: =IF(ISERROR(LOOKUP(AH$16,$L30:$X30,#REF!)),0,(LOOKUP(AH$16,$L30:$X30,#REF!))) -> 0 | AI30: =IF(ISERROR(LOOKUP(AI$16,$L30:$X30,#REF!)),0,(LOOKUP(AI$16,$L30:$X30,#REF!))) -> 0 | AJ30: =IF(ISERROR(LOOKUP(AJ$16,$L30:$X30,#REF!)),0,(LOOKUP(AJ$16,$L30:$X30,#REF!))) -> 0 | ... AM30: =IF(ISERROR(LOOKUP(AM$16,$L30:$X30,#REF!)),0,(LOOKUP(AM$16,$L30:$X30,#REF!))) -> 0 | AO30: =U30-T30 -> 15 | AP30: 46237 | AQ30: 46241 | AR30: 46248 | AW30: #REF!
C31: =C29 -> RFQ-005 | D31: =D29 -> Pig Launcher and Receiver | F31: =F29 -> Piping | G31: =G29 -> Y | I31: =I29 -> LA | J31: Actual | AC31: =IF(ISERROR(LOOKUP(AC$16,$L31:$X31,#REF!)),0,(LOOKUP(AC$16,$L31:$X31,#REF!))) -> 0 | AD31: =IF(ISERROR(LOOKUP(AD$16,$L31:$X31,#REF!)),0,(LOOKUP(AD$16,$L31:$X31,#REF!))) -> 0 | AE31: =IF(ISERROR(LOOKUP(AE$16,$L31:$X31,#REF!)),0,(LOOKUP(AE$16,$L31:$X31,#REF!))) -> 0 | AF31: =IF(ISERROR(LOOKUP(AF$16,$L31:$X31,#REF!)),0,(LOOKUP(AF$16,$L31:$X31,#REF!))) -> 0 | AG31: =IF(ISERROR(LOOKUP(AG$16,$L31:$X31,#REF!)),0,(LOOKUP(AG$16,$L31:$X31,#REF!))) -> 0 | AH31: =IF(ISERROR(LOOKUP(AH$16,$L31:$X31,#REF!)),0,(LOOKUP(AH$16,$L31:$X31,#REF!))) -> 0 | AI31: =IF(ISERROR(LOOKUP(AI$16,$L31:$X31,#REF!)),0,(LOOKUP(AI$16,$L31:$X31,#REF!))) -> 0 | AJ31: =IF(ISERROR(LOOKUP(AJ$16,$L31:$X31,#REF!)),0,(LOOKUP(AJ$16,$L31:$X31,#REF!))) -> 0 | ... AM31: =IF(ISERROR(LOOKUP(AM$16,$L31:$X31,#REF!)),0,(LOOKUP(AM$16,$L31:$X31,#REF!))) -> 0 | AO31: =U31-T31 -> 0 | AW31: #REF!
A32: =A29+1 -> 6 | C32: RFQ-006 | D32: Corrosion Inhibitor Injection Pump | F32: Mechanical | G32: N | I32: LA | J32: Plan | K32: =WORKDAY(L32,-INDEX(L$12:L$15,MATCH($I32,$I$12:$I$15,0))) -> 46143 | L32: =WORKDAY(M32,-INDEX(M$12:M$15,MATCH($I32,$I$12:$I$15,0))) -> 46146 | M32: =WORKDAY(N32,-INDEX(N$12:N$15,MATCH($I32,$I$12:$I$15,0))) -> 46153 | N32: =WORKDAY(O32,-INDEX(O$12:O$15,MATCH($I32,$I$12:$I$15,0))) -> 46154 | O32: =WORKDAY(R32,-INDEX(R$12:R$15,MATCH($I32,$I$12:$I$15,0))) -> 46161 | P32: =U32-L32 -> 74 | R32: =WORKDAY(S32,-INDEX(S$12:S$15,MATCH($I32,$I$12:$I$15,0))) -> 46175 | S32: =WORKDAY(T32,-INDEX(T$12:T$15,MATCH($I32,$I$12:$I$15,0))) -> 46203 | T32: =WORKDAY(U32,-INDEX(U$12:U$15,MATCH($I32,$I$12:$I$15,0))) -> 46206 | U32: =X32-Y32 -> 46220 | V32: =WORKDAY(U32,INDEX(V$12:V$15,MATCH($I32,$I$12:$I$15,0))) -> 46224 | W32: =Y32/7 -> 32 | X32: =Z32 -> 46444 | Y32: =32*7 -> 224 | Z32: 46444 | AA32: 46444 | AB32: =Z32-X33 -> 0 | AC32: =IF(ISERROR(LOOKUP(AC$16,$L32:$X32,#REF!)),0,(LOOKUP(AC$16,$L32:$X32,#REF!))) -> 0 | AD32: =IF(ISERROR(LOOKUP(AD$16,$L32:$X32,#REF!)),0,(LOOKUP(AD$16,$L32:$X32,#REF!))) -> 0 | AE32: =IF(ISERROR(LOOKUP(AE$16,$L32:$X32,#REF!)),0,(LOOKUP(AE$16,$L32:$X32,#REF!))) -> 0 | AF32: =IF(ISERROR(LOOKUP(AF$16,$L32:$X32,#REF!)),0,(LOOKUP(AF$16,$L32:$X32,#REF!))) -> 0 | AG32: =IF(ISERROR(LOOKUP(AG$16,$L32:$X32,#REF!)),0,(LOOKUP(AG$16,$L32:$X32,#REF!))) -> 0 | AH32: =IF(ISERROR(LOOKUP(AH$16,$L32:$X32,#REF!)),0,(LOOKUP(AH$16,$L32:$X32,#REF!))) -> 0 | AI32: =IF(ISERROR(LOOKUP(AI$16,$L32:$X32,#REF!)),0,(LOOKUP(AI$16,$L32:$X32,#REF!))) -> 0 | AJ32: =IF(ISERROR(LOOKUP(AJ$16,$L32:$X32,#REF!)),0,(LOOKUP(AJ$16,$L32:$X32,#REF!))) -> 0 | ... AM32: =IF(ISERROR(LOOKUP(AM$16,$L32:$X32,#REF!)),0,(LOOKUP(AM$16,$L32:$X32,#REF!))) -> 0 | AO32: =U32-T32 -> 14 | AP32: =WORKDAY(AQ32,-INDEX(AQ$12:AQ$15,MATCH($I32,$I$12:$I$15,0)),$AW$17:$AW$148) -> #REF! | AQ32: =WORKDAY(U32,-INDEX(U$12:U$15,MATCH($I32,$I$12:$I$15,0)),$AW$17:$AW$148) -> #REF! | AR32: =WORKDAY(U32,-INDEX(U$12:U$15,MATCH($I32,$I$12:$I$15,0)),$AW$17:$AW$148) -> #REF! | AS32: 14 | AW32: #REF!
C33: =C32 -> RFQ-006 | G33: =G32 -> N | I33: =I32 -> LA | J33: Forecast | K33: =K32 -> 46143 | L33: =WORKDAY(IF(K34="",K33,K34),INDEX(L$12:L$15,MATCH($I32,$I$12:$I$15,0))) -> 46146 | M33: =WORKDAY(IF(L34="",L33,L34),INDEX(M$12:M$15,MATCH($I32,$I$12:$I$15,0))) -> 46153 | N33: =WORKDAY(IF(M34="",M33,M34),INDEX(N$12:N$15,MATCH($I32,$I$12:$I$15,0))) -> 46154 | O33: =WORKDAY(IF(N34="",N33,N34),INDEX(O$12:O$15,MATCH($I32,$I$12:$I$15,0))) -> 46161 | R33: =WORKDAY(IF(O34="",O33,O34),INDEX(R$12:R$15,MATCH($I32,$I$12:$I$15,0))) -> 46175 | S33: =WORKDAY(IF(R34="",R33,R34),INDEX(S$12:S$15,MATCH($I32,$I$12:$I$15,0))) -> 46203 | T33: =WORKDAY(IF(S34="",S33,S34),INDEX(T$12:T$15,MATCH($I32,$I$12:$I$15,0))) -> 46206 | U33: =WORKDAY(IF(T34="",T33,T34),INDEX(U$12:U$15,MATCH($I32,$I$12:$I$15,0))) -> 46220 | V33: =WORKDAY(IF(U34="",U33,U34),INDEX(V$12:V$15,MATCH($I32,$I$12:$I$15,0))) -> 46224 | X33: =U33+Y32 -> 46444 | AC33: =IF(ISERROR(LOOKUP(AC$16,$L33:$X33,#REF!)),0,(LOOKUP(AC$16,$L33:$X33,#REF!))) -> 0 | AD33: =IF(ISERROR(LOOKUP(AD$16,$L33:$X33,#REF!)),0,(LOOKUP(AD$16,$L33:$X33,#REF!))) -> 0 | AE33: =IF(ISERROR(LOOKUP(AE$16,$L33:$X33,#REF!)),0,(LOOKUP(AE$16,$L33:$X33,#REF!))) -> 0 | AF33: =IF(ISERROR(LOOKUP(AF$16,$L33:$X33,#REF!)),0,(LOOKUP(AF$16,$L33:$X33,#REF!))) -> 0 | AG33: =IF(ISERROR(LOOKUP(AG$16,$L33:$X33,#REF!)),0,(LOOKUP(AG$16,$L33:$X33,#REF!))) -> 0 | AH33: =IF(ISERROR(LOOKUP(AH$16,$L33:$X33,#REF!)),0,(LOOKUP(AH$16,$L33:$X33,#REF!))) -> 0 | AI33: =IF(ISERROR(LOOKUP(AI$16,$L33:$X33,#REF!)),0,(LOOKUP(AI$16,$L33:$X33,#REF!))) -> 0 | AJ33: =IF(ISERROR(LOOKUP(AJ$16,$L33:$X33,#REF!)),0,(LOOKUP(AJ$16,$L33:$X33,#REF!))) -> 0 | ... AM33: =IF(ISERROR(LOOKUP(AM$16,$L33:$X33,#REF!)),0,(LOOKUP(AM$16,$L33:$X33,#REF!))) -> 0 | AO33: =U33-T33 -> 14 | AP33: =WORKDAY(IF(T34="",T33,T34),INDEX(AP$12:AP$15,MATCH($I32,$I$12:$I$15,0)),$AW$17:$AW$148) -> #REF! | AQ33: =WORKDAY(IF(AP34="",AP33,AP34),INDEX(AQ$12:AQ$15,MATCH($I32,$I$12:$I$15,0)),$AW$17:$AW$148) -> #REF! | AR33: =WORKDAY(IF(AQ34="",AQ33,AQ34),INDEX(AR$12:AR$15,MATCH($I32,$I$12:$I$15,0)),$AW$17:$AW$148) -> #REF! | AW33: #REF!
C34: =C32 -> RFQ-006 | G34: =G32 -> N | I34: =I32 -> LA | J34: Actual | AC34: =IF(ISERROR(LOOKUP(AC$16,$L34:$X34,#REF!)),0,(LOOKUP(AC$16,$L34:$X34,#REF!))) -> 0 | AD34: =IF(ISERROR(LOOKUP(AD$16,$L34:$X34,#REF!)),0,(LOOKUP(AD$16,$L34:$X34,#REF!))) -> 0 | AE34: =IF(ISERROR(LOOKUP(AE$16,$L34:$X34,#REF!)),0,(LOOKUP(AE$16,$L34:$X34,#REF!))) -> 0 | AF34: =IF(ISERROR(LOOKUP(AF$16,$L34:$X34,#REF!)),0,(LOOKUP(AF$16,$L34:$X34,#REF!))) -> 0 | AG34: =IF(ISERROR(LOOKUP(AG$16,$L34:$X34,#REF!)),0,(LOOKUP(AG$16,$L34:$X34,#REF!))) -> 0 | AH34: =IF(ISERROR(LOOKUP(AH$16,$L34:$X34,#REF!)),0,(LOOKUP(AH$16,$L34:$X34,#REF!))) -> 0 | AI34: =IF(ISERROR(LOOKUP(AI$16,$L34:$X34,#REF!)),0,(LOOKUP(AI$16,$L34:$X34,#REF!))) -> 0 | AJ34: =IF(ISERROR(LOOKUP(AJ$16,$L34:$X34,#REF!)),0,(LOOKUP(AJ$16,$L34:$X34,#REF!))) -> 0 | ... AM34: =IF(ISERROR(LOOKUP(AM$16,$L34:$X34,#REF!)),0,(LOOKUP(AM$16,$L34:$X34,#REF!))) -> 0 | AO34: =U34-T34 -> 0 | AW34: #REF!
A35: =A32+1 -> 7 | C35: RFQ-007 | D35: Demulsifier/Water Clarifier Injection Pump | F35: Mechanical | G35: N | I35: LA | J35: Plan | K35: =WORKDAY(L35,-INDEX(L$12:L$15,MATCH($I35,$I$12:$I$15,0))) -> 46176 | L35: =WORKDAY(M35,-INDEX(M$12:M$15,MATCH($I35,$I$12:$I$15,0))) -> 46177 | M35: =WORKDAY(N35,-INDEX(N$12:N$15,MATCH($I35,$I$12:$I$15,0))) -> 46184 | N35: =WORKDAY(O35,-INDEX(O$12:O$15,MATCH($I35,$I$12:$I$15,0))) -> 46185 | O35: =WORKDAY(R35,-INDEX(R$12:R$15,MATCH($I35,$I$12:$I$15,0))) -> 46192 | P35: =U35-L35 -> 76 | R35: =WORKDAY(S35,-INDEX(S$12:S$15,MATCH($I35,$I$12:$I$15,0))) -> 46206 | S35: =WORKDAY(T35,-INDEX(T$12:T$15,MATCH($I35,$I$12:$I$15,0))) -> 46234 | T35: =WORKDAY(U35,-INDEX(U$12:U$15,MATCH($I35,$I$12:$I$15,0))) -> 46239 | U35: =X35-Y35 -> 46253 | V35: =WORKDAY(U35,INDEX(V$12:V$15,MATCH($I35,$I$12:$I$15,0))) -> 46255 | W35: =Y35/7 -> 32 | X35: =Z35 -> 46477 | Y35: =32*7 -> 224 | Z35: 46477 | AA35: 46477 | AB35: =Z35-X36 -> 0 | AC35: =IF(ISERROR(LOOKUP(AC$16,$L35:$X35,#REF!)),0,(LOOKUP(AC$16,$L35:$X35,#REF!))) -> 0 | AD35: =IF(ISERROR(LOOKUP(AD$16,$L35:$X35,#REF!)),0,(LOOKUP(AD$16,$L35:$X35,#REF!))) -> 0 | AE35: =IF(ISERROR(LOOKUP(AE$16,$L35:$X35,#REF!)),0,(LOOKUP(AE$16,$L35:$X35,#REF!))) -> 0 | AF35: =IF(ISERROR(LOOKUP(AF$16,$L35:$X35,#REF!)),0,(LOOKUP(AF$16,$L35:$X35,#REF!))) -> 0 | AG35: =IF(ISERROR(LOOKUP(AG$16,$L35:$X35,#REF!)),0,(LOOKUP(AG$16,$L35:$X35,#REF!))) -> 0 | AH35: =IF(ISERROR(LOOKUP(AH$16,$L35:$X35,#REF!)),0,(LOOKUP(AH$16,$L35:$X35,#REF!))) -> 0 | AI35: =IF(ISERROR(LOOKUP(AI$16,$L35:$X35,#REF!)),0,(LOOKUP(AI$16,$L35:$X35,#REF!))) -> 0 | AJ35: =IF(ISERROR(LOOKUP(AJ$16,$L35:$X35,#REF!)),0,(LOOKUP(AJ$16,$L35:$X35,#REF!))) -> 0 | ... AM35: =IF(ISERROR(LOOKUP(AM$16,$L35:$X35,#REF!)),0,(LOOKUP(AM$16,$L35:$X35,#REF!))) -> 0 | AO35: =U35-T35 -> 14 | AP35: =WORKDAY(AQ35,-INDEX(AQ$12:AQ$15,MATCH($I35,$I$12:$I$15,0)),$AW$17:$AW$148) -> #REF! | AQ35: =WORKDAY(U35,-INDEX(U$12:U$15,MATCH($I35,$I$12:$I$15,0)),$AW$17:$AW$148) -> #REF! | AR35: =WORKDAY(U35,-INDEX(U$12:U$15,MATCH($I35,$I$12:$I$15,0)),$AW$17:$AW$148) -> #REF! | AS35: 14 | AW35: #REF!
C36: =C35 -> RFQ-007 | D36: =D35 -> Demulsifier/Water Clarifier Injection Pump | G36: =G35 -> N | I36: =I35 -> LA | J36: Forecast | K36: =K35 -> 46176 | L36: =WORKDAY(IF(K37="",K36,K37),INDEX(L$12:L$15,MATCH($I35,$I$12:$I$15,0))) -> 46177 | M36: =WORKDAY(IF(L37="",L36,L37),INDEX(M$12:M$15,MATCH($I35,$I$12:$I$15,0))) -> 46184 | N36: =WORKDAY(IF(M37="",M36,M37),INDEX(N$12:N$15,MATCH($I35,$I$12:$I$15,0))) -> 46185 | O36: =WORKDAY(IF(N37="",N36,N37),INDEX(O$12:O$15,MATCH($I35,$I$12:$I$15,0))) -> 46192 | R36: =WORKDAY(IF(O37="",O36,O37),INDEX(R$12:R$15,MATCH($I35,$I$12:$I$15,0))) -> 46206 | S36: =WORKDAY(IF(R37="",R36,R37),INDEX(S$12:S$15,MATCH($I35,$I$12:$I$15,0))) -> 46234 | T36: =WORKDAY(IF(S37="",S36,S37),INDEX(T$12:T$15,MATCH($I35,$I$12:$I$15,0))) -> 46239 | U36: =WORKDAY(IF(T37="",T36,T37),INDEX(U$12:U$15,MATCH($I35,$I$12:$I$15,0))) -> 46253 | V36: =WORKDAY(IF(U37="",U36,U37),INDEX(V$12:V$15,MATCH($I35,$I$12:$I$15,0))) -> 46255 | X36: =U36+Y35 -> 46477 | AC36: =IF(ISERROR(LOOKUP(AC$16,$L36:$X36,#REF!)),0,(LOOKUP(AC$16,$L36:$X36,#REF!))) -> 0 | AD36: =IF(ISERROR(LOOKUP(AD$16,$L36:$X36,#REF!)),0,(LOOKUP(AD$16,$L36:$X36,#REF!))) -> 0 | AE36: =IF(ISERROR(LOOKUP(AE$16,$L36:$X36,#REF!)),0,(LOOKUP(AE$16,$L36:$X36,#REF!))) -> 0 | AF36: =IF(ISERROR(LOOKUP(AF$16,$L36:$X36,#REF!)),0,(LOOKUP(AF$16,$L36:$X36,#REF!))) -> 0 | AG36: =IF(ISERROR(LOOKUP(AG$16,$L36:$X36,#REF!)),0,(LOOKUP(AG$16,$L36:$X36,#REF!))) -> 0 | AH36: =IF(ISERROR(LOOKUP(AH$16,$L36:$X36,#REF!)),0,(LOOKUP(AH$16,$L36:$X36,#REF!))) -> 0 | AI36: =IF(ISERROR(LOOKUP(AI$16,$L36:$X36,#REF!)),0,(LOOKUP(AI$16,$L36:$X36,#REF!))) -> 0 | AJ36: =IF(ISERROR(LOOKUP(AJ$16,$L36:$X36,#REF!)),0,(LOOKUP(AJ$16,$L36:$X36,#REF!))) -> 0 | ... AM36: =IF(ISERROR(LOOKUP(AM$16,$L36:$X36,#REF!)),0,(LOOKUP(AM$16,$L36:$X36,#REF!))) -> 0 | AO36: =U36-T36 -> 14 | AP36: =WORKDAY(IF(T37="",T36,T37),INDEX(AP$12:AP$15,MATCH($I35,$I$12:$I$15,0)),$AW$17:$AW$148) -> #REF! | AQ36: =WORKDAY(IF(AP37="",AP36,AP37),INDEX(AQ$12:AQ$15,MATCH($I35,$I$12:$I$15,0)),$AW$17:$AW$148) -> #REF! | AR36: =WORKDAY(IF(AQ37="",AQ36,AQ37),INDEX(AR$12:AR$15,MATCH($I35,$I$12:$I$15,0)),$AW$17:$AW$148) -> #REF! | AW36: #REF!
C37: =C35 -> RFQ-007 | D37: =D35 -> Demulsifier/Water Clarifier Injection Pump | G37: =G35 -> N | I37: =I35 -> LA | J37: Actual | AC37: =IF(ISERROR(LOOKUP(AC$16,$L37:$X37,#REF!)),0,(LOOKUP(AC$16,$L37:$X37,#REF!))) -> 0 | AD37: =IF(ISERROR(LOOKUP(AD$16,$L37:$X37,#REF!)),0,(LOOKUP(AD$16,$L37:$X37,#REF!))) -> 0 | AE37: =IF(ISERROR(LOOKUP(AE$16,$L37:$X37,#REF!)),0,(LOOKUP(AE$16,$L37:$X37,#REF!))) -> 0 | AF37: =IF(ISERROR(LOOKUP(AF$16,$L37:$X37,#REF!)),0,(LOOKUP(AF$16,$L37:$X37,#REF!))) -> 0 | AG37: =IF(ISERROR(LOOKUP(AG$16,$L37:$X37,#REF!)),0,(LOOKUP(AG$16,$L37:$X37,#REF!))) -> 0 | AH37: =IF(ISERROR(LOOKUP(AH$16,$L37:$X37,#REF!)),0,(LOOKUP(AH$16,$L37:$X37,#REF!))) -> 0 | AI37: =IF(ISERROR(LOOKUP(AI$16,$L37:$X37,#REF!)),0,(LOOKUP(AI$16,$L37:$X37,#REF!))) -> 0 | AJ37: =IF(ISERROR(LOOKUP(AJ$16,$L37:$X37,#REF!)),0,(LOOKUP(AJ$16,$L37:$X37,#REF!))) -> 0 | ... AM37: =IF(ISERROR(LOOKUP(AM$16,$L37:$X37,#REF!)),0,(LOOKUP(AM$16,$L37:$X37,#REF!))) -> 0 | AO37: =U37-T37 -> 0 | AW37: #REF!
A38: =A35+1 -> 8 | C38: RFQ-008 | D38: De-Oiler Hydrocyclone | F38: Mechanical | G38: =IF(_xlfn.XLOOKUP(C38,'[36]Before Award'!D:D,'[36]Before Award'!AV:AV,"N/A")="N/A","N","Y") -> N | J38: Plan | K38: 46162 | L38: 46163 | M38: 46168 | N38: 46169 | O38: 46174 | P38: =U38-L38 -> 71 | R38: 46188 | S38: 46216 | T38: 46219 | U38: 46234 | V38: 46241 | W38: 26 | X38: 46416 | Y38: =W38*7 -> 182 | Z38: 46416 | AA38: 46416 | AB38: =Z38-X39 -> 0 | AC38: =IF(ISERROR(LOOKUP(AC$16,$L38:$X38,#REF!)),0,(LOOKUP(AC$16,$L38:$X38,#REF!))) -> 0 | AD38: =IF(ISERROR(LOOKUP(AD$16,$L38:$X38,#REF!)),0,(LOOKUP(AD$16,$L38:$X38,#REF!))) -> 0 | AE38: =IF(ISERROR(LOOKUP(AE$16,$L38:$X38,#REF!)),0,(LOOKUP(AE$16,$L38:$X38,#REF!))) -> 0 | AF38: =IF(ISERROR(LOOKUP(AF$16,$L38:$X38,#REF!)),0,(LOOKUP(AF$16,$L38:$X38,#REF!))) -> 0 | AG38: =IF(ISERROR(LOOKUP(AG$16,$L38:$X38,#REF!)),0,(LOOKUP(AG$16,$L38:$X38,#REF!))) -> 0 | AH38: =IF(ISERROR(LOOKUP(AH$16,$L38:$X38,#REF!)),0,(LOOKUP(AH$16,$L38:$X38,#REF!))) -> 0 | AI38: =IF(ISERROR(LOOKUP(AI$16,$L38:$X38,#REF!)),0,(LOOKUP(AI$16,$L38:$X38,#REF!))) -> 0 | AJ38: =IF(ISERROR(LOOKUP(AJ$16,$L38:$X38,#REF!)),0,(LOOKUP(AJ$16,$L38:$X38,#REF!))) -> 0 | ... AM38: =IF(ISERROR(LOOKUP(AM$16,$L38:$X38,#REF!)),0,(LOOKUP(AM$16,$L38:$X38,#REF!))) -> 0 | AO38: =U38-T38 -> 15 | AP38: 46223 | AQ38: 46227 | AR38: 46227 | AS38: 14 | AW38: #REF!
C39: =C38 -> RFQ-008 | D39: =D38 -> De-Oiler Hydrocyclone | G39: =G38 -> N | I39: =I38 | J39: Forecast | K39: 46162 | L39: 46163 | M39: 46168 | N39: 46169 | O39: 46174 | R39: 46188 | S39: 46216 | T39: 46219 | U39: 46234 | V39: 46241 | X39: 46416 | AC39: =IF(ISERROR(LOOKUP(AC$16,$L39:$X39,#REF!)),0,(LOOKUP(AC$16,$L39:$X39,#REF!))) -> 0 | AD39: =IF(ISERROR(LOOKUP(AD$16,$L39:$X39,#REF!)),0,(LOOKUP(AD$16,$L39:$X39,#REF!))) -> 0 | AE39: =IF(ISERROR(LOOKUP(AE$16,$L39:$X39,#REF!)),0,(LOOKUP(AE$16,$L39:$X39,#REF!))) -> 0 | AF39: =IF(ISERROR(LOOKUP(AF$16,$L39:$X39,#REF!)),0,(LOOKUP(AF$16,$L39:$X39,#REF!))) -> 0 | AG39: =IF(ISERROR(LOOKUP(AG$16,$L39:$X39,#REF!)),0,(LOOKUP(AG$16,$L39:$X39,#REF!))) -> 0 | AH39: =IF(ISERROR(LOOKUP(AH$16,$L39:$X39,#REF!)),0,(LOOKUP(AH$16,$L39:$X39,#REF!))) -> 0 | AI39: =IF(ISERROR(LOOKUP(AI$16,$L39:$X39,#REF!)),0,(LOOKUP(AI$16,$L39:$X39,#REF!))) -> 0 | AJ39: =IF(ISERROR(LOOKUP(AJ$16,$L39:$X39,#REF!)),0,(LOOKUP(AJ$16,$L39:$X39,#REF!))) -> 0 | ... AM39: =IF(ISERROR(LOOKUP(AM$16,$L39:$X39,#REF!)),0,(LOOKUP(AM$16,$L39:$X39,#REF!))) -> 0 | AO39: =U39-T39 -> 15 | AP39: 46223 | AQ39: 46227 | AR39: 46234 | AW39: #REF!
C40: =C38 -> RFQ-008 | D40: =D38 -> De-Oiler Hydrocyclone | G40: =G38 -> N | I40: =I38 | J40: Actual | AC40: =IF(ISERROR(LOOKUP(AC$16,$L40:$X40,#REF!)),0,(LOOKUP(AC$16,$L40:$X40,#REF!))) -> 0 | AD40: =IF(ISERROR(LOOKUP(AD$16,$L40:$X40,#REF!)),0,(LOOKUP(AD$16,$L40:$X40,#REF!))) -> 0 | AE40: =IF(ISERROR(LOOKUP(AE$16,$L40:$X40,#REF!)),0,(LOOKUP(AE$16,$L40:$X40,#REF!))) -> 0 | AF40: =IF(ISERROR(LOOKUP(AF$16,$L40:$X40,#REF!)),0,(LOOKUP(AF$16,$L40:$X40,#REF!))) -> 0 | AG40: =IF(ISERROR(LOOKUP(AG$16,$L40:$X40,#REF!)),0,(LOOKUP(AG$16,$L40:$X40,#REF!))) -> 0 | AH40: =IF(ISERROR(LOOKUP(AH$16,$L40:$X40,#REF!)),0,(LOOKUP(AH$16,$L40:$X40,#REF!))) -> 0 | AI40: =IF(ISERROR(LOOKUP(AI$16,$L40:$X40,#REF!)),0,(LOOKUP(AI$16,$L40:$X40,#REF!))) -> 0 | AJ40: =IF(ISERROR(LOOKUP(AJ$16,$L40:$X40,#REF!)),0,(LOOKUP(AJ$16,$L40:$X40,#REF!))) -> 0 | ... AM40: =IF(ISERROR(LOOKUP(AM$16,$L40:$X40,#REF!)),0,(LOOKUP(AM$16,$L40:$X40,#REF!))) -> 0 | AO40: =U40-T40 -> 0 | AW40: #REF!
