Workbook

Sheet PSR
A1: PROVISION OF ENGINEERING, PROCUREMENT, CONSTRUCTION AND COMMISSIONING FOR WELLHEAD PLATFORMS, ASSOCIATED PIPLINES AND BROWNFIELD MODIFICATIONS FOR ZAWTIKA DEVELOPMENT PROJECT PHASE 1F
A2: Procurement Plan
K6: LA | L6: Most complexity RFQ | P6: 1 | Q6: 10 | R6: 0 | S6: 0 | T6: 10 | U6: 17 | V6: 10 | W6: 9 | X6: 2 | Y6: 5 | Z6: 20 | AA6: 10 | AQ6: 3 | AS6: 10 | AT6: 2
K7: LB | L7: High complexity RFQ | P7: 1 | Q7: 10 | R7: 0 | S7: 0 | T7: 10 | U7: 17 | V7: 10 | W7: 9 | X7: 2 | Y7: 5 | Z7: 20 | AA7: 10 | AQ7: 3 | AS7: 10 | AT7: 2
K8: LC | L8: Normal complexity RFQ | P8: 1 | Q8: 10 | R8: 0 | S8: 0 | T8: 10 | U8: 13 | V8: 10 | W8: 9 | X8: 2 | Y8: 5 | Z8: 15 | AA8: 10 | AQ8: 3 | AS8: 10 | AT8: 2
A9: Contract no: MMC25-5001 | K9: LD | L9: Low complexity RFQ | P9: 1 | Q9: 10 | R9: 0 | S9: 0 | T9: 5 | U9: 7 | V9: 10 | W9: 5 | X9: 2 | Y9: 5 | Z9: 10 | AA9: 10 | AP9: Update: 3-Jul-2026 | AQ9: 2 | AS9: 5 | AT9: 2
A10: No. | B10: MR No. | C10: RFQ No. | D10: Package Name | E10: Tag No. | F10: Q'ty | G10: CODE | H10: DIS | I10: LLI (Y/N) | J10: CR | K10: Priority Level | L10: PO description | M10: Owner | N10: P/F/A | O10: Bidder list Approval | P10: MR Issued (IFR) | Q10: MR Approved | R10: RFQ Issued | S10: RFQ Approved | T10: Bid Closing Date | U10: TBE Issued | V10: TBE Approved | W10: PO Issued | X10: Vendor Acknowledgement | Y10: KOM | Z10: VDB Submission | AA10: Approval of Key VP | AB10: Main Material Arrived | AC10: PIM | AD10: Start Production | AE10: FAT | AF10: Ready for Shipment | AG10: Receipt at WORKSITE | AH10: Punch List Clearance(all punch clearance before Tag Equipment Ready for Shipping ) | AI10: Approval of Final Documentation (To be confirmed later) | AJ10: Delivery Duration (Weeks) | AK10: days | AL10: Delivery Date(1st Batch for ZWP21) | AM10: ROS Date | AN10: Float | AO10: Responder | AP10: Remarks | AQ10: 40329 | AR10: 40359 | AS10: 40390 | AT10: 40421 | AU10: 40451 | AV10: 40482 | AW10: 40512 | AX10: 40543 | AY10: 40574 | AZ10: 40602 | BA10: =TODAY() -> 46209
N11: Matrix | O11: PTTEP | P11: ENG | Q11: PTTEP | R11: TJE PRC | S11: PTTEP | T11: TJE PRC | U11: ENG | V11: PTTEP | W11: TJE PRC | X11: BIDDER | Y11: TJE PRC | Z11: Vendor | AA11: ENG | AB11: Vendor | AC11: TJE QA/QC | AD11: Vendor | AE11: TJE QA/QC | AF11: Vendor | AG11: THE Worksite | AH11: TJE QA/QC | AI11: TJE PRC | AL11: TJE PRC
N12: Holiday | O12: China | P12: Thai | Q12: Thai | R12: China | S12: Thai | T12: China | U12: Thai | V12: Thai | W12: China | X12: China | Y12: China | Z12: China | AA12: Thai | AQ12: Thai | AS12: China | AT12: China
A13: 1 | B13: MM-ZTK-1F-GEN-MEC-MR-0001 | C13: RFQ-MA-001 | D13: Offshore Pedestal Crane | E13: CR7001 | F13: 1*4 | G13: 4-2 | H13: MA | I13: Y | J13: L2 | K13: LA | M13: SH | N13: P | O13: 46133 | P13: 46133 | Q13: 46136 | R13: 46139 | S13: 46148 | T13: 46159 | U13: 46184 | V13: 46198 | W13: 46211 | X13: 46213 | Y13: 46220 | Z13: 46248 | AA13: 46262 | AB13: 46352 | AC13: 46357 | AD13: 46360 | AE13: 46501 | AF13: 46531 | AG13: 46561 | AH13: 46564 | AI13: 46591 | AJ13: 50 | AK13: 350 | AL13: 46561 | AM13: 46567 | AN13: =AM13-AL14 -> 6 | AO13: Sun liheng | AP13: 2026.4.16: Issued RFQ 2026.4.28-5.1: Received Bid 2026.5.7: TC 2026.5.19: Vendor will reply TC 2026.2.26-27 Hold TC meeting | AQ13: =IF(ISERROR(LOOKUP(AQ$10,$O13:$AP13,#REF!)),0,(LOOKUP(AQ$10,$O13:$AP13,#REF!))) -> 0 | AR13: =IF(ISERROR(LOOKUP(AR$10,$O13:$AP13,#REF!)),0,(LOOKUP(AR$10,$O13:$AP13,#REF!))) -> 0 | AS13: =IF(ISERROR(LOOKUP(AS$10,$O13:$AP13,#REF!)),0,(LOOKUP(AS$10,$O13:$AP13,#REF!))) -> 0 | AT13: =IF(ISERROR(LOOKUP(AT$10,$O13:$AP13,#REF!)),0,(LOOKUP(AT$10,$O13:$AP13,#REF!))) -> 0 | AU13: =IF(ISERROR(LOOKUP(AU$10,$O13:$AP13,#REF!)),0,(LOOKUP(AU$10,$O13:$AP13,#REF!))) -> 0 | AV13: =IF(ISERROR(LOOKUP(AV$10,$O13:$AP13,#REF!)),0,(LOOKUP(AV$10,$O13:$AP13,#REF!))) -> 0 | AW13: =IF(ISERROR(LOOKUP(AW$10,$O13:$AP13,#REF!)),0,(LOOKUP(AW$10,$O13:$AP13,#REF!))) -> 0 | AX13: =IF(ISERROR(LOOKUP(AX$10,$O13:$AP13,#REF!)),0,(LOOKUP(AX$10,$O13:$AP13,#REF!))) -> 0 | ... BA13: =IF(ISERROR(LOOKUP(BA$10,$O13:$AP13,#REF!)),0,(LOOKUP(BA$10,$O13:$AP13,#REF!))) -> 0 | BB13: Bidder1 | BC13: Ex-work: Pedestal-28 weeks | BD13: Crane:38 weeks
B14: MM-ZTK-1F-GEN-MEC-MR-0001 | C14: RFQ-MA-001 | D14: Offshore Pedestal Crane | G14: 4-2 | H14: MA | I14: Y | J14: L2 | K14: LA | M14: SH | N14: F | W14: =W13 -> 46211 | X14: =WORKDAY(W14, X6, IF(X12="China",'China Holidays'!$A$2:$A$84,'Thai Holidays'!$A$2:$A$65)) -> 46213 | Y14: =WORKDAY(X14, Y6, IF(Y12="China",'China Holidays'!$A$2:$A$84,'Thai Holidays'!$A$2:$A$65)) -> 46220 | Z14: =WORKDAY(Y14, Z6, IF(Z12="China",'China Holidays'!$A$2:$A$84,'Thai Holidays'!$A$2:$A$65)) -> 46248 | AA14: =WORKDAY(Z14, AA6, IF(AA12="China",'China Holidays'!$A$2:$A$84,'Thai Holidays'!$A$2:$A$65)) -> 46262 | AB14: =AB13 -> 46352 | AC14: 46357 | AD14: 46360 | AE14: 46501 | AF14: =AG14-30 -> 46531 | AG14: =AL13 -> 46561 | AH14: =AL13+3 -> 46564 | AI14: =AL13+30 -> 46591 | AL14: =W14+AK13 -> 46561 | AQ14: =IF(ISERROR(LOOKUP(AQ$10,$O14:$AP14,#REF!)),0,(LOOKUP(AQ$10,$O14:$AP14,#REF!))) -> 0 | AR14: =IF(ISERROR(LOOKUP(AR$10,$O14:$AP14,#REF!)),0,(LOOKUP(AR$10,$O14:$AP14,#REF!))) -> 0 | AS14: =IF(ISERROR(LOOKUP(AS$10,$O14:$AP14,#REF!)),0,(LOOKUP(AS$10,$O14:$AP14,#REF!))) -> 0 | AT14: =IF(ISERROR(LOOKUP(AT$10,$O14:$AP14,#REF!)),0,(LOOKUP(AT$10,$O14:$AP14,#REF!))) -> 0 | AU14: =IF(ISERROR(LOOKUP(AU$10,$O14:$AP14,#REF!)),0,(LOOKUP(AU$10,$O14:$AP14,#REF!))) -> 0 | AV14: =IF(ISERROR(LOOKUP(AV$10,$O14:$AP14,#REF!)),0,(LOOKUP(AV$10,$O14:$AP14,#REF!))) -> 0 | AW14: =IF(ISERROR(LOOKUP(AW$10,$O14:$AP14,#REF!)),0,(LOOKUP(AW$10,$O14:$AP14,#REF!))) -> 0 | AX14: =IF(ISERROR(LOOKUP(AX$10,$O14:$AP14,#REF!)),0,(LOOKUP(AX$10,$O14:$AP14,#REF!))) -> 0 | ... BA14: =IF(ISERROR(LOOKUP(BA$10,$O14:$AP14,#REF!)),0,(LOOKUP(BA$10,$O14:$AP14,#REF!))) -> 0 | BB14: Bidder2 | BC14: After receive dowm payment: 30 weeks FAT, CIF 39 weeks
B15: MM-ZTK-1F-GEN-MEC-MR-0001 | C15: RFQ-MA-001 | D15: Offshore Pedestal Crane | G15: 4-2 | H15: MA | I15: Y | J15: L2 | K15: LA | M15: SH | N15: A | O15: 46120 | P15: 46125 | Q15: 46135 | R15: 46136 | S15: 46136 | T15: 46143 | U15: 46192 | V15: 46201 | AQ15: =IF(ISERROR(LOOKUP(AQ$10,$O15:$AP15,#REF!)),0,(LOOKUP(AQ$10,$O15:$AP15,#REF!))) -> 0 | AR15: =IF(ISERROR(LOOKUP(AR$10,$O15:$AP15,#REF!)),0,(LOOKUP(AR$10,$O15:$AP15,#REF!))) -> 0 | AS15: =IF(ISERROR(LOOKUP(AS$10,$O15:$AP15,#REF!)),0,(LOOKUP(AS$10,$O15:$AP15,#REF!))) -> 0 | AT15: =IF(ISERROR(LOOKUP(AT$10,$O15:$AP15,#REF!)),0,(LOOKUP(AT$10,$O15:$AP15,#REF!))) -> 0 | AU15: =IF(ISERROR(LOOKUP(AU$10,$O15:$AP15,#REF!)),0,(LOOKUP(AU$10,$O15:$AP15,#REF!))) -> 0 | AV15: =IF(ISERROR(LOOKUP(AV$10,$O15:$AP15,#REF!)),0,(LOOKUP(AV$10,$O15:$AP15,#REF!))) -> 0 | AW15: =IF(ISERROR(LOOKUP(AW$10,$O15:$AP15,#REF!)),0,(LOOKUP(AW$10,$O15:$AP15,#REF!))) -> 0 | AX15: =IF(ISERROR(LOOKUP(AX$10,$O15:$AP15,#REF!)),0,(LOOKUP(AX$10,$O15:$AP15,#REF!))) -> 0 | ... BA15: =IF(ISERROR(LOOKUP(BA$10,$O15:$AP15,#REF!)),0,(LOOKUP(BA$10,$O15:$AP15,#REF!))) -> 0
A16: =A13+1 -> 2 | B16: MM-ZTK-1F-GEN-MEC-MR-0002 | C16: RFQ-MA-002-1 | D16: Closed Drain Sump Vessel | E16: V-5001 | F16: 1*4 | G16: 4-10 | H16: MA | I16: Y | J16: L3 | K16: LA | L16: Zhuhai Jutal | M16: SH | N16: P | O16: 46167 | P16: 46168 | Q16: 46177 | R16: 46178 | S16: 46185 | T16: 46197 | U16: 46197 | V16: 46211 | W16: 46218 | X16: 46220 | Y16: 46227 | Z16: 46255 | AA16: 46269 | AB16: 46329 | AC16: 46331 | AD16: 46333 | AE16: 46408 | AF16: 46423 | AG16: 46433 | AH16: 46436 | AI16: 46463 | AJ16: 26 | AK16: 182 | AL16: 46433 | AM16: 46438 | AN16: =AM16-AL17 -> 43 | AO16: HuangWei | AP16: 2026.5.6 Issued RFQ to Zhuhai yard | AQ16: =IF(ISERROR(LOOKUP(AQ$10,$O16:$AP16,#REF!)),0,(LOOKUP(AQ$10,$O16:$AP16,#REF!))) -> 0 | AR16: =IF(ISERROR(LOOKUP(AR$10,$O16:$AP16,#REF!)),0,(LOOKUP(AR$10,$O16:$AP16,#REF!))) -> 0 | AS16: =IF(ISERROR(LOOKUP(AS$10,$O16:$AP16,#REF!)),0,(LOOKUP(AS$10,$O16:$AP16,#REF!))) -> 0 | AT16: =IF(ISERROR(LOOKUP(AT$10,$O16:$AP16,#REF!)),0,(LOOKUP(AT$10,$O16:$AP16,#REF!))) -> 0 | AU16: =IF(ISERROR(LOOKUP(AU$10,$O16:$AP16,#REF!)),0,(LOOKUP(AU$10,$O16:$AP16,#REF!))) -> 0 | AV16: =IF(ISERROR(LOOKUP(AV$10,$O16:$AP16,#REF!)),0,(LOOKUP(AV$10,$O16:$AP16,#REF!))) -> 0 | AW16: =IF(ISERROR(LOOKUP(AW$10,$O16:$AP16,#REF!)),0,(LOOKUP(AW$10,$O16:$AP16,#REF!))) -> 0 | AX16: =IF(ISERROR(LOOKUP(AX$10,$O16:$AP16,#REF!)),0,(LOOKUP(AX$10,$O16:$AP16,#REF!))) -> 0 | ... BA16: =IF(ISERROR(LOOKUP(BA$10,$O16:$AP16,#REF!)),0,(LOOKUP(BA$10,$O16:$AP16,#REF!))) -> 0
B17: MM-ZTK-1F-GEN-MEC-MR-0002 | C17: RFQ-MA-002-1 | D17: Closed Drain Sump Vessel | G17: 4-10 | H17: MA | I17: Y | J17: L3 | K17: LA | M17: SH | N17: F | V17: =WORKDAY(U18, V6, IF(V12="China",'China Holidays'!$A$2:$A$84,'Thai Holidays'!$A$2:$A$65)) -> 46213 | W17: =V17 -> 46213 | X17: =W17+2 -> 46215 | Y17: =WORKDAY(X17, Y6, IF(Y12="China",'China Holidays'!$A$2:$A$84,'Thai Holidays'!$A$2:$A$65)) -> 46220 | Z17: =WORKDAY(Y17, Z6, IF(Z12="China",'China Holidays'!$A$2:$A$84,'Thai Holidays'!$A$2:$A$65)) -> 46248 | AA17: =WORKDAY(Z17, AA6, IF(AA12="China",'China Holidays'!$A$2:$A$84,'Thai Holidays'!$A$2:$A$65)) -> 46262 | AB17: =AA17+60 -> 46322 | AC17: =AB17+2 -> 46324 | AD17: =AC17+2 -> 46326 | AE17: =AF17-15 -> 46379 | AF17: =AG17-1 -> 46394 | AG17: =AL17 -> 46395 | AH17: =AL16+3 -> 46436 | AI17: =AL16+30 -> 46463 | AL17: =W17+AK16 -> 46395 | AQ17: =IF(ISERROR(LOOKUP(AQ$10,$O17:$AP17,#REF!)),0,(LOOKUP(AQ$10,$O17:$AP17,#REF!))) -> 0 | AR17: =IF(ISERROR(LOOKUP(AR$10,$O17:$AP17,#REF!)),0,(LOOKUP(AR$10,$O17:$AP17,#REF!))) -> 0 | AS17: =IF(ISERROR(LOOKUP(AS$10,$O17:$AP17,#REF!)),0,(LOOKUP(AS$10,$O17:$AP17,#REF!))) -> 0 | AT17: =IF(ISERROR(LOOKUP(AT$10,$O17:$AP17,#REF!)),0,(LOOKUP(AT$10,$O17:$AP17,#REF!))) -> 0 | AU17: =IF(ISERROR(LOOKUP(AU$10,$O17:$AP17,#REF!)),0,(LOOKUP(AU$10,$O17:$AP17,#REF!))) -> 0 | AV17: =IF(ISERROR(LOOKUP(AV$10,$O17:$AP17,#REF!)),0,(LOOKUP(AV$10,$O17:$AP17,#REF!))) -> 0 | AW17: =IF(ISERROR(LOOKUP(AW$10,$O17:$AP17,#REF!)),0,(LOOKUP(AW$10,$O17:$AP17,#REF!))) -> 0 | AX17: =IF(ISERROR(LOOKUP(AX$10,$O17:$AP17,#REF!)),0,(LOOKUP(AX$10,$O17:$AP17,#REF!))) -> 0 | ... BA17: =IF(ISERROR(LOOKUP(BA$10,$O17:$AP17,#REF!)),0,(LOOKUP(BA$10,$O17:$AP17,#REF!))) -> 0
B18: MM-ZTK-1F-GEN-MEC-MR-0002 | C18: RFQ-MA-002-1 | D18: Closed Drain Sump Vessel | G18: 4-10 | H18: MA | I18: Y | J18: L3 | K18: LA | M18: SH | N18: A | P18: 46129 | Q18: 46143 | R18: 46148 | S18: =R18 -> 46148 | T18: 46183 | U18: 46200 | AQ18: =IF(ISERROR(LOOKUP(AQ$10,$O18:$AP18,#REF!)),0,(LOOKUP(AQ$10,$O18:$AP18,#REF!))) -> 0 | AR18: =IF(ISERROR(LOOKUP(AR$10,$O18:$AP18,#REF!)),0,(LOOKUP(AR$10,$O18:$AP18,#REF!))) -> 0 | AS18: =IF(ISERROR(LOOKUP(AS$10,$O18:$AP18,#REF!)),0,(LOOKUP(AS$10,$O18:$AP18,#REF!))) -> 0 | AT18: =IF(ISERROR(LOOKUP(AT$10,$O18:$AP18,#REF!)),0,(LOOKUP(AT$10,$O18:$AP18,#REF!))) -> 0 | AU18: =IF(ISERROR(LOOKUP(AU$10,$O18:$AP18,#REF!)),0,(LOOKUP(AU$10,$O18:$AP18,#REF!))) -> 0 | AV18: =IF(ISERROR(LOOKUP(AV$10,$O18:$AP18,#REF!)),0,(LOOKUP(AV$10,$O18:$AP18,#REF!))) -> 0 | AW18: =IF(ISERROR(LOOKUP(AW$10,$O18:$AP18,#REF!)),0,(LOOKUP(AW$10,$O18:$AP18,#REF!))) -> 0 | AX18: =IF(ISERROR(LOOKUP(AX$10,$O18:$AP18,#REF!)),0,(LOOKUP(AX$10,$O18:$AP18,#REF!))) -> 0 | ... BA18: =IF(ISERROR(LOOKUP(BA$10,$O18:$AP18,#REF!)),0,(LOOKUP(BA$10,$O18:$AP18,#REF!))) -> 0
A19: =A16+1 -> 3 | B19: MM-ZTK-1F-GEN-MEC-MR-0002 | C19: RFQ-MA-002-2 | D19: Test Separator | E19: V-1001 | F19: 1*4 | G19: 4-8 | H19: MA | I19: Y | J19: L2 | K19: LA | L19: Zhuhai Jutal | M19: SH | N19: P | O19: 46135 | P19: 46136 | Q19: 46147 | R19: 46148 | S19: 46155 | T19: 46197 | U19: 46197 | V19: 46211 | W19: 46218 | X19: 46220 | Y19: 46227 | Z19: 46255 | AA19: 46269 | AB19: 46329 | AC19: 46331 | AD19: 46333 | AE19: 46429 | AF19: 46444 | AG19: 46449 | AH19: 46452 | AI19: 46479 | AJ19: 33 | AK19: 231 | AL19: 46449 | AM19: 46466 | AN19: =AM19-AL20 -> 17 | AO19: HuangWei | AP19: 2026.5.6 Issued RFQ to Zhuhai yard | AQ19: =IF(ISERROR(LOOKUP(AQ$10,$O19:$AP19,#REF!)),0,(LOOKUP(AQ$10,$O19:$AP19,#REF!))) -> 0 | AR19: =IF(ISERROR(LOOKUP(AR$10,$O19:$AP19,#REF!)),0,(LOOKUP(AR$10,$O19:$AP19,#REF!))) -> 0 | AS19: =IF(ISERROR(LOOKUP(AS$10,$O19:$AP19,#REF!)),0,(LOOKUP(AS$10,$O19:$AP19,#REF!))) -> 0 | AT19: =IF(ISERROR(LOOKUP(AT$10,$O19:$AP19,#REF!)),0,(LOOKUP(AT$10,$O19:$AP19,#REF!))) -> 0 | AU19: =IF(ISERROR(LOOKUP(AU$10,$O19:$AP19,#REF!)),0,(LOOKUP(AU$10,$O19:$AP19,#REF!))) -> 0 | AV19: =IF(ISERROR(LOOKUP(AV$10,$O19:$AP19,#REF!)),0,(LOOKUP(AV$10,$O19:$AP19,#REF!))) -> 0 | AW19: =IF(ISERROR(LOOKUP(AW$10,$O19:$AP19,#REF!)),0,(LOOKUP(AW$10,$O19:$AP19,#REF!))) -> 0 | AX19: =IF(ISERROR(LOOKUP(AX$10,$O19:$AP19,#REF!)),0,(LOOKUP(AX$10,$O19:$AP19,#REF!))) -> 0 | ... BA19: =IF(ISERROR(LOOKUP(BA$10,$O19:$AP19,#REF!)),0,(LOOKUP(BA$10,$O19:$AP19,#REF!))) -> 0
B20: MM-ZTK-1F-GEN-MEC-MR-0002 | C20: RFQ-MA-002-2 | D20: Test Separator | G20: 4-8 | H20: MA | I20: Y | J20: L2 | K20: LA | M20: SH | N20: F | V20: =WORKDAY(U21, V6, IF(V15="China",'China Holidays'!$A$2:$A$84,'Thai Holidays'!$A$2:$A$65)) -> 46213 | W20: =W19 -> 46218 | X20: =W20+2 -> 46220 | Y20: =WORKDAY(X20,Y6, IF(Y12="China",'China Holidays'!$A$2:$A$84,'Thai Holidays'!$A$2:$A$65)) -> 46227 | Z20: =WORKDAY(Y20,Z6, IF(Z12="China",'China Holidays'!$A$2:$A$84,'Thai Holidays'!$A$2:$A$65)) -> 46255 | AA20: =WORKDAY(Z20,AA6, IF(AA12="China",'China Holidays'!$A$2:$A$84,'Thai Holidays'!$A$2:$A$65)) -> 46269 | AB20: =AA20+60 -> 46329 | AC20: =AB20+2 -> 46331 | AD20: =AC20+2 -> 46333 | AE20: =AF20-15 -> 46429 | AF20: =AG20-5 -> 46444 | AG20: =AL20 -> 46449 | AH20: =AL19+3 -> 46452 | AI20: =AL19+30 -> 46479 | AL20: =W20+AK19 -> 46449 | AQ20: =IF(ISERROR(LOOKUP(AQ$10,$O20:$AP20,#REF!)),0,(LOOKUP(AQ$10,$O20:$AP20,#REF!))) -> 0 | AR20: =IF(ISERROR(LOOKUP(AR$10,$O20:$AP20,#REF!)),0,(LOOKUP(AR$10,$O20:$AP20,#REF!))) -> 0 | AS20: =IF(ISERROR(LOOKUP(AS$10,$O20:$AP20,#REF!)),0,(LOOKUP(AS$10,$O20:$AP20,#REF!))) -> 0 | AT20: =IF(ISERROR(LOOKUP(AT$10,$O20:$AP20,#REF!)),0,(LOOKUP(AT$10,$O20:$AP20,#REF!))) -> 0 | AU20: =IF(ISERROR(LOOKUP(AU$10,$O20:$AP20,#REF!)),0,(LOOKUP(AU$10,$O20:$AP20,#REF!))) -> 0 | AV20: =IF(ISERROR(LOOKUP(AV$10,$O20:$AP20,#REF!)),0,(LOOKUP(AV$10,$O20:$AP20,#REF!))) -> 0 | AW20: =IF(ISERROR(LOOKUP(AW$10,$O20:$AP20,#REF!)),0,(LOOKUP(AW$10,$O20:$AP20,#REF!))) -> 0 | AX20: =IF(ISERROR(LOOKUP(AX$10,$O20:$AP20,#REF!)),0,(LOOKUP(AX$10,$O20:$AP20,#REF!))) -> 0 | ... BA20: =IF(ISERROR(LOOKUP(BA$10,$O20:$AP20,#REF!)),0,(LOOKUP(BA$10,$O20:$AP20,#REF!))) -> 0
B21: MM-ZTK-1F-GEN-MEC-MR-0002 | C21: RFQ-MA-002-2 | D21: Test Separator | G21: 4-8 | H21: MA | I21: Y | J21: L2 | K21: LA | M21: SH | N21: A | P21: 46129 | Q21: 46143 | R21: 46148 | S21: =R21 -> 46148 | T21: 46183 | U21: 46200 | AQ21: =IF(ISERROR(LOOKUP(AQ$10,$O21:$AP21,#REF!)),0,(LOOKUP(AQ$10,$O21:$AP21,#REF!))) -> 0 | AR21: =IF(ISERROR(LOOKUP(AR$10,$O21:$AP21,#REF!)),0,(LOOKUP(AR$10,$O21:$AP21,#REF!))) -> 0 | AS21: =IF(ISERROR(LOOKUP(AS$10,$O21:$AP21,#REF!)),0,(LOOKUP(AS$10,$O21:$AP21,#REF!))) -> 0 | AT21: =IF(ISERROR(LOOKUP(AT$10,$O21:$AP21,#REF!)),0,(LOOKUP(AT$10,$O21:$AP21,#REF!))) -> 0 | AU21: =IF(ISERROR(LOOKUP(AU$10,$O21:$AP21,#REF!)),0,(LOOKUP(AU$10,$O21:$AP21,#REF!))) -> 0 | AV21: =IF(ISERROR(LOOKUP(AV$10,$O21:$AP21,#REF!)),0,(LOOKUP(AV$10,$O21:$AP21,#REF!))) -> 0 | AW21: =IF(ISERROR(LOOKUP(AW$10,$O21:$AP21,#REF!)),0,(LOOKUP(AW$10,$O21:$AP21,#REF!))) -> 0 | AX21: =IF(ISERROR(LOOKUP(AX$10,$O21:$AP21,#REF!)),0,(LOOKUP(AX$10,$O21:$AP21,#REF!))) -> 0 | ... BA21: =IF(ISERROR(LOOKUP(BA$10,$O21:$AP21,#REF!)),0,(LOOKUP(BA$10,$O21:$AP21,#REF!))) -> 0
A22: =A19+1 -> 4 | B22: MM-ZTK-1F-GEN-MEC-MR-0002 | C22: RFQ-MA-002-3 | D22: Instrument Gas Filter Coalescer | E22: V-3001 | F22: 1*4 | G22: 4-11 | H22: MA | I22: Y | J22: L2 | K22: LA | L22: Zhuhai Jutal | M22: SH | N22: P | O22: 46177 | P22: 46178 | Q22: 46185 | R22: 46188 | S22: 46195 | T22: 46197 | U22: 46197 | V22: 46211 | W22: 46218 | X22: 46220 | Y22: 46227 | Z22: 46255 | AA22: 46269 | AB22: 46329 | AC22: 46331 | AD22: 46333 | AE22: 46408 | AF22: 46423 | AG22: 46438 | AH22: 46441 | AI22: 46468 | AJ22: 26 | AK22: 180 | AL22: 46438 | AM22: 46466 | AN22: =AM22-AL23 -> 75 | AO22: HuangWei | AP22: 2026.5.6 Issued RFQ to Zhuhai yard | AQ22: =IF(ISERROR(LOOKUP(AQ$10,$O22:$AP22,#REF!)),0,(LOOKUP(AQ$10,$O22:$AP22,#REF!))) -> 0 | AR22: =IF(ISERROR(LOOKUP(AR$10,$O22:$AP22,#REF!)),0,(LOOKUP(AR$10,$O22:$AP22,#REF!))) -> 0 | AS22: =IF(ISERROR(LOOKUP(AS$10,$O22:$AP22,#REF!)),0,(LOOKUP(AS$10,$O22:$AP22,#REF!))) -> 0 | AT22: =IF(ISERROR(LOOKUP(AT$10,$O22:$AP22,#REF!)),0,(LOOKUP(AT$10,$O22:$AP22,#REF!))) -> 0 | AU22: =IF(ISERROR(LOOKUP(AU$10,$O22:$AP22,#REF!)),0,(LOOKUP(AU$10,$O22:$AP22,#REF!))) -> 0 | AV22: =IF(ISERROR(LOOKUP(AV$10,$O22:$AP22,#REF!)),0,(LOOKUP(AV$10,$O22:$AP22,#REF!))) -> 0 | AW22: =IF(ISERROR(LOOKUP(AW$10,$O22:$AP22,#REF!)),0,(LOOKUP(AW$10,$O22:$AP22,#REF!))) -> 0 | AX22: =IF(ISERROR(LOOKUP(AX$10,$O22:$AP22,#REF!)),0,(LOOKUP(AX$10,$O22:$AP22,#REF!))) -> 0 | ... BA22: =IF(ISERROR(LOOKUP(BA$10,$O22:$AP22,#REF!)),0,(LOOKUP(BA$10,$O22:$AP22,#REF!))) -> 0
B23: MM-ZTK-1F-GEN-MEC-MR-0002 | C23: RFQ-MA-002-3 | D23: Instrument Gas Filter Coalescer | G23: 4-11 | H23: MA | I23: Y | J23: L2 | K23: LA | M23: SH | N23: F | V23: =WORKDAY(U24, V6, IF(V18="China",'China Holidays'!$A$2:$A$84,'Thai Holidays'!$A$2:$A$65)) -> 46213 | W23: =V22 -> 46211 | X23: =W23+2 -> 46213 | Y23: 46227 | Z23: =WORKDAY(Y23, Z6, IF(Z12="China",'China Holidays'!$A$2:$A$84,'Thai Holidays'!$A$2:$A$65)) -> 46255 | AA23: =WORKDAY(Z23, AA6, IF(AA12="China",'China Holidays'!$A$2:$A$84,'Thai Holidays'!$A$2:$A$65)) -> 46269 | AB23: =AA23+60 -> 46329 | AC23: =AB23+2 -> 46331 | AD23: =AC23+2 -> 46333 | AE23: =AF23-15 -> 46408 | AF23: 46423 | AG23: =AL22 -> 46438 | AH23: =AL22+3 -> 46441 | AI23: =AL22+30 -> 46468 | AL23: =W23+AK22 -> 46391 | AQ23: =IF(ISERROR(LOOKUP(AQ$10,$O23:$AP23,#REF!)),0,(LOOKUP(AQ$10,$O23:$AP23,#REF!))) -> 0 | AR23: =IF(ISERROR(LOOKUP(AR$10,$O23:$AP23,#REF!)),0,(LOOKUP(AR$10,$O23:$AP23,#REF!))) -> 0 | AS23: =IF(ISERROR(LOOKUP(AS$10,$O23:$AP23,#REF!)),0,(LOOKUP(AS$10,$O23:$AP23,#REF!))) -> 0 | AT23: =IF(ISERROR(LOOKUP(AT$10,$O23:$AP23,#REF!)),0,(LOOKUP(AT$10,$O23:$AP23,#REF!))) -> 0 | AU23: =IF(ISERROR(LOOKUP(AU$10,$O23:$AP23,#REF!)),0,(LOOKUP(AU$10,$O23:$AP23,#REF!))) -> 0 | AV23: =IF(ISERROR(LOOKUP(AV$10,$O23:$AP23,#REF!)),0,(LOOKUP(AV$10,$O23:$AP23,#REF!))) -> 0 | AW23: =IF(ISERROR(LOOKUP(AW$10,$O23:$AP23,#REF!)),0,(LOOKUP(AW$10,$O23:$AP23,#REF!))) -> 0 | AX23: =IF(ISERROR(LOOKUP(AX$10,$O23:$AP23,#REF!)),0,(LOOKUP(AX$10,$O23:$AP23,#REF!))) -> 0 | ... BA23: =IF(ISERROR(LOOKUP(BA$10,$O23:$AP23,#REF!)),0,(LOOKUP(BA$10,$O23:$AP23,#REF!))) -> 0
B24: MM-ZTK-1F-GEN-MEC-MR-0002 | C24: RFQ-MA-002-3 | D24: Instrument Gas Filter Coalescer | G24: 4-11 | H24: MA | I24: Y | J24: L2 | K24: LA | M24: SH | N24: A | P24: 46141 | Q24: 46143 | R24: 46148 | S24: 46148 | T24: 46191 | U24: 46200 | AQ24: =IF(ISERROR(LOOKUP(AQ$10,$O24:$AP24,#REF!)),0,(LOOKUP(AQ$10,$O24:$AP24,#REF!))) -> 0 | AR24: =IF(ISERROR(LOOKUP(AR$10,$O24:$AP24,#REF!)),0,(LOOKUP(AR$10,$O24:$AP24,#REF!))) -> 0 | AS24: =IF(ISERROR(LOOKUP(AS$10,$O24:$AP24,#REF!)),0,(LOOKUP(AS$10,$O24:$AP24,#REF!))) -> 0 | AT24: =IF(ISERROR(LOOKUP(AT$10,$O24:$AP24,#REF!)),0,(LOOKUP(AT$10,$O24:$AP24,#REF!))) -> 0 | AU24: =IF(ISERROR(LOOKUP(AU$10,$O24:$AP24,#REF!)),0,(LOOKUP(AU$10,$O24:$AP24,#REF!))) -> 0 | AV24: =IF(ISERROR(LOOKUP(AV$10,$O24:$AP24,#REF!)),0,(LOOKUP(AV$10,$O24:$AP24,#REF!))) -> 0 | AW24: =IF(ISERROR(LOOKUP(AW$10,$O24:$AP24,#REF!)),0,(LOOKUP(AW$10,$O24:$AP24,#REF!))) -> 0 | AX24: =IF(ISERROR(LOOKUP(AX$10,$O24:$AP24,#REF!)),0,(LOOKUP(AX$10,$O24:$AP24,#REF!))) -> 0 | ... BA24: =IF(ISERROR(LOOKUP(BA$10,$O24:$AP24,#REF!)),0,(LOOKUP(BA$10,$O24:$AP24,#REF!))) -> 0
A25: =A22+1 -> 5 | B25: MM-ZTK-1F-GEN-MEC-MR-0003 | C25: RFQ-MA-003 | D25: Closed Drain Sump Pump skids | F25: 1*4 | G25: 4-18 | H25: MA | I25: Y | J25: L3 | K25: LA | M25: SH | N25: P | O25: 46140 | P25: 46141 | Q25: 46150 | R25: 46153 | S25: 46160 | T25: 46168 | U25: 46195 | V25: 46209 | W25: 46220 | X25: 46224 | Y25: 46231 | Z25: 46259 | AA25: 46273 | AB25: 46363 | AC25: 46363 | AD25: 46366 | AE25: 46401 | AF25: 46416 | AG25: 46444 | AH25: 46447 | AI25: 46474 | AJ25: 32 | AK25: 224 | AL25: 46444 | AM25: 46476 | AN25: =AM25-AL26 -> 32 | AO25: Sun liheng | AP25: 2026.5.6 Issued RFQ bid due day:22-May | AQ25: =IF(ISERROR(LOOKUP(AQ$10,$O25:$AP25,#REF!)),0,(LOOKUP(AQ$10,$O25:$AP25,#REF!))) -> 0 | AR25: =IF(ISERROR(LOOKUP(AR$10,$O25:$AP25,#REF!)),0,(LOOKUP(AR$10,$O25:$AP25,#REF!))) -> 0 | AS25: =IF(ISERROR(LOOKUP(AS$10,$O25:$AP25,#REF!)),0,(LOOKUP(AS$10,$O25:$AP25,#REF!))) -> 0 | AT25: =IF(ISERROR(LOOKUP(AT$10,$O25:$AP25,#REF!)),0,(LOOKUP(AT$10,$O25:$AP25,#REF!))) -> 0 | AU25: =IF(ISERROR(LOOKUP(AU$10,$O25:$AP25,#REF!)),0,(LOOKUP(AU$10,$O25:$AP25,#REF!))) -> 0 | AV25: =IF(ISERROR(LOOKUP(AV$10,$O25:$AP25,#REF!)),0,(LOOKUP(AV$10,$O25:$AP25,#REF!))) -> 0 | AW25: =IF(ISERROR(LOOKUP(AW$10,$O25:$AP25,#REF!)),0,(LOOKUP(AW$10,$O25:$AP25,#REF!))) -> 0 | AX25: =IF(ISERROR(LOOKUP(AX$10,$O25:$AP25,#REF!)),0,(LOOKUP(AX$10,$O25:$AP25,#REF!))) -> 0 | ... BA25: =IF(ISERROR(LOOKUP(BA$10,$O25:$AP25,#REF!)),0,(LOOKUP(BA$10,$O25:$AP25,#REF!))) -> 0 | BB25: Bidder1 | BC25: DDP: 28 weeks
B26: MM-ZTK-1F-GEN-MEC-MR-0003 | C26: RFQ-MA-003 | D26: Closed Drain Sump Pump skids | G26: 4-18 | H26: MA | I26: Y | J26: L3 | K26: LA | M26: SH | N26: F | V26: =WORKDAY(U27, V6, IF(V12="China",'China Holidays'!$A$2:$A$84,'Thai Holidays'!$A$2:$A$65)) -> 46220 | W26: =W25 -> 46220 | X26: =WORKDAY(W26, X6, IF(X12="China",'China Holidays'!$A$2:$A$84,'Thai Holidays'!$A$2:$A$65)) -> 46224 | Y26: =WORKDAY(X26, Y6, IF(Y12="China",'China Holidays'!$A$2:$A$84,'Thai Holidays'!$A$2:$A$65)) -> 46231 | Z26: =WORKDAY(Y26, Z6, IF(Z12="China",'China Holidays'!$A$2:$A$84,'Thai Holidays'!$A$2:$A$65)) -> 46259 | AA26: =WORKDAY(Z26,AA6, IF( AA12="China",'China Holidays'!$A$2:$A$84,'Thai Holidays'!$A$2:$A$65)) -> 46273 | AB26: =AA26+90 -> 46363 | AC26: =AB26 -> 46363 | AD26: =AC26+3 -> 46366 | AE26: =AF26-15 -> 46401 | AF26: =AG26-28 -> 46416 | AG26: =AL25 -> 46444 | AH26: =AL25+3 -> 46447 | AI26: =AL25+30 -> 46474 | AL26: =W26+AK25 -> 46444 | AQ26: =IF(ISERROR(LOOKUP(AQ$10,$O26:$AP26,#REF!)),0,(LOOKUP(AQ$10,$O26:$AP26,#REF!))) -> 0 | AR26: =IF(ISERROR(LOOKUP(AR$10,$O26:$AP26,#REF!)),0,(LOOKUP(AR$10,$O26:$AP26,#REF!))) -> 0 | AS26: =IF(ISERROR(LOOKUP(AS$10,$O26:$AP26,#REF!)),0,(LOOKUP(AS$10,$O26:$AP26,#REF!))) -> 0 | AT26: =IF(ISERROR(LOOKUP(AT$10,$O26:$AP26,#REF!)),0,(LOOKUP(AT$10,$O26:$AP26,#REF!))) -> 0 | AU26: =IF(ISERROR(LOOKUP(AU$10,$O26:$AP26,#REF!)),0,(LOOKUP(AU$10,$O26:$AP26,#REF!))) -> 0 | AV26: =IF(ISERROR(LOOKUP(AV$10,$O26:$AP26,#REF!)),0,(LOOKUP(AV$10,$O26:$AP26,#REF!))) -> 0 | AW26: =IF(ISERROR(LOOKUP(AW$10,$O26:$AP26,#REF!)),0,(LOOKUP(AW$10,$O26:$AP26,#REF!))) -> 0 | AX26: =IF(ISERROR(LOOKUP(AX$10,$O26:$AP26,#REF!)),0,(LOOKUP(AX$10,$O26:$AP26,#REF!))) -> 0 | ... BA26: =IF(ISERROR(LOOKUP(BA$10,$O26:$AP26,#REF!)),0,(LOOKUP(BA$10,$O26:$AP26,#REF!))) -> 0 | BB26: Bidder2 | BC26: DDP: 24-26 weeks
B27: MM-ZTK-1F-GEN-MEC-MR-0003 | C27: RFQ-MA-003 | D27: Closed Drain Sump Pump skids | G27: 4-18 | H27: MA | I27: Y | J27: L3 | K27: LA | M27: SH | N27: A | O27: 46133 | P27: 46130 | Q27: 46149 | R27: 46150 | S27: 46150 | T27: 46164 | U27: 46206 | AQ27: =IF(ISERROR(LOOKUP(AQ$10,$O27:$AP27,#REF!)),0,(LOOKUP(AQ$10,$O27:$AP27,#REF!))) -> 0 | AR27: =IF(ISERROR(LOOKUP(AR$10,$O27:$AP27,#REF!)),0,(LOOKUP(AR$10,$O27:$AP27,#REF!))) -> 0 | AS27: =IF(ISERROR(LOOKUP(AS$10,$O27:$AP27,#REF!)),0,(LOOKUP(AS$10,$O27:$AP27,#REF!))) -> 0 | AT27: =IF(ISERROR(LOOKUP(AT$10,$O27:$AP27,#REF!)),0,(LOOKUP(AT$10,$O27:$AP27,#REF!))) -> 0 | AU27: =IF(ISERROR(LOOKUP(AU$10,$O27:$AP27,#REF!)),0,(LOOKUP(AU$10,$O27:$AP27,#REF!))) -> 0 | AV27: =IF(ISERROR(LOOKUP(AV$10,$O27:$AP27,#REF!)),0,(LOOKUP(AV$10,$O27:$AP27,#REF!))) -> 0 | AW27: =IF(ISERROR(LOOKUP(AW$10,$O27:$AP27,#REF!)),0,(LOOKUP(AW$10,$O27:$AP27,#REF!))) -> 0 | AX27: =IF(ISERROR(LOOKUP(AX$10,$O27:$AP27,#REF!)),0,(LOOKUP(AX$10,$O27:$AP27,#REF!))) -> 0 | ... BA27: =IF(ISERROR(LOOKUP(BA$10,$O27:$AP27,#REF!)),0,(LOOKUP(BA$10,$O27:$AP27,#REF!))) -> 0
A28: =A25+1 -> 6 | B28: MM-ZTK-1F-GEN-MEC-MR-0004 | C28: RFQ-MA-004 | D28: Chemical injection pump skid | F28: 1*4 | G28: 4-4 | H28: MA | I28: Y | J28: L3 | K28: LA | M28: SH | N28: P | O28: 46140 | P28: 46141 | Q28: 46150 | R28: 46153 | S28: 46160 | T28: 46168 | U28: 46195 | V28: 46209 | W28: 46220 | X28: 46224 | Y28: 46231 | Z28: 46259 | AA28: 46273 | AB28: 46363 | AC28: 46363 | AD28: 46366 | AE28: 46424 | AF28: 46439 | AG28: 46444 | AH28: 46447 | AI28: 46474 | AJ28: 34 | AK28: 238 | AL28: 46458 | AM28: 46464 | AN28: =AM28-AL29 -> 6 | AO28: Sun liheng | AP28: 2026.5.6 Issued RFQ bid due day:22-May 2025.5.31-6.5 TC | AQ28: =IF(ISERROR(LOOKUP(AQ$10,$O28:$AP28,#REF!)),0,(LOOKUP(AQ$10,$O28:$AP28,#REF!))) -> 0 | AR28: =IF(ISERROR(LOOKUP(AR$10,$O28:$AP28,#REF!)),0,(LOOKUP(AR$10,$O28:$AP28,#REF!))) -> 0 | AS28: =IF(ISERROR(LOOKUP(AS$10,$O28:$AP28,#REF!)),0,(LOOKUP(AS$10,$O28:$AP28,#REF!))) -> 0 | AT28: =IF(ISERROR(LOOKUP(AT$10,$O28:$AP28,#REF!)),0,(LOOKUP(AT$10,$O28:$AP28,#REF!))) -> 0 | AU28: =IF(ISERROR(LOOKUP(AU$10,$O28:$AP28,#REF!)),0,(LOOKUP(AU$10,$O28:$AP28,#REF!))) -> 0 | AV28: =IF(ISERROR(LOOKUP(AV$10,$O28:$AP28,#REF!)),0,(LOOKUP(AV$10,$O28:$AP28,#REF!))) -> 0 | AW28: =IF(ISERROR(LOOKUP(AW$10,$O28:$AP28,#REF!)),0,(LOOKUP(AW$10,$O28:$AP28,#REF!))) -> 0 | AX28: =IF(ISERROR(LOOKUP(AX$10,$O28:$AP28,#REF!)),0,(LOOKUP(AX$10,$O28:$AP28,#REF!))) -> 0 | ... BA28: =IF(ISERROR(LOOKUP(BA$10,$O28:$AP28,#REF!)),0,(LOOKUP(BA$10,$O28:$AP28,#REF!))) -> 0 | BB28: Bidder1 | BC28: Ex-work 22 weeks
B29: MM-ZTK-1F-GEN-MEC-MR-0004 | C29: RFQ-MA-004 | D29: Chemical injection pump skid | G29: 4-4 | H29: MA | I29: Y | J29: L3 | K29: LA | M29: SH | N29: F | V29: =WORKDAY(U30, V6, IF(V12="China",'China Holidays'!$A$2:$A$84,'Thai Holidays'!$A$2:$A$65)) -> 46216 | W29: =W28 -> 46220 | X29: =WORKDAY(W29, X6, IF(X12="China",'China Holidays'!$A$2:$A$84,'Thai Holidays'!$A$2:$A$65)) -> 46224 | Y29: =WORKDAY(X29, Y6, IF(Y12="China",'China Holidays'!$A$2:$A$84,'Thai Holidays'!$A$2:$A$65)) -> 46231 | Z29: =WORKDAY(Y29, Z6, IF(Z12="China",'China Holidays'!$A$2:$A$84,'Thai Holidays'!$A$2:$A$65)) -> 46259 | AA29: =WORKDAY(Z29, AA6, IF(AA12="China",'China Holidays'!$A$2:$A$84,'Thai Holidays'!$A$2:$A$65)) -> 46273 | AB29: =AA29+90 -> 46363 | AC29: =AB29 -> 46363 | AD29: =AC29+3 -> 46366 | AE29: =AF29-15 -> 46415 | AF29: =AG29-28 -> 46430 | AG29: =AL28 -> 46458 | AH29: =AL28+3 -> 46461 | AI29: =AL28+30 -> 46488 | AL29: =W29+AK28 -> 46458 | AQ29: =IF(ISERROR(LOOKUP(AQ$10,$O29:$AP29,#REF!)),0,(LOOKUP(AQ$10,$O29:$AP29,#REF!))) -> 0 | AR29: =IF(ISERROR(LOOKUP(AR$10,$O29:$AP29,#REF!)),0,(LOOKUP(AR$10,$O29:$AP29,#REF!))) -> 0 | AS29: =IF(ISERROR(LOOKUP(AS$10,$O29:$AP29,#REF!)),0,(LOOKUP(AS$10,$O29:$AP29,#REF!))) -> 0 | AT29: =IF(ISERROR(LOOKUP(AT$10,$O29:$AP29,#REF!)),0,(LOOKUP(AT$10,$O29:$AP29,#REF!))) -> 0 | AU29: =IF(ISERROR(LOOKUP(AU$10,$O29:$AP29,#REF!)),0,(LOOKUP(AU$10,$O29:$AP29,#REF!))) -> 0 | AV29: =IF(ISERROR(LOOKUP(AV$10,$O29:$AP29,#REF!)),0,(LOOKUP(AV$10,$O29:$AP29,#REF!))) -> 0 | AW29: =IF(ISERROR(LOOKUP(AW$10,$O29:$AP29,#REF!)),0,(LOOKUP(AW$10,$O29:$AP29,#REF!))) -> 0 | AX29: =IF(ISERROR(LOOKUP(AX$10,$O29:$AP29,#REF!)),0,(LOOKUP(AX$10,$O29:$AP29,#REF!))) -> 0 | ... BA29: =IF(ISERROR(LOOKUP(BA$10,$O29:$AP29,#REF!)),0,(LOOKUP(BA$10,$O29:$AP29,#REF!))) -> 0 | BB29: Bidder2 | BC29: Ex-work 24 weeks
B30: MM-ZTK-1F-GEN-MEC-MR-0004 | C30: RFQ-MA-004 | D30: Chemical injection pump skid | G30: 4-4 | H30: MA | I30: Y | J30: L3 | K30: LA | M30: SH | N30: A | O30: 46133 | P30: 46130 | Q30: 46149 | R30: 46150 | S30: 46150 | T30: 46164 | U30: 46202 | AQ30: =IF(ISERROR(LOOKUP(AQ$10,$O30:$AP30,#REF!)),0,(LOOKUP(AQ$10,$O30:$AP30,#REF!))) -> 0 | AR30: =IF(ISERROR(LOOKUP(AR$10,$O30:$AP30,#REF!)),0,(LOOKUP(AR$10,$O30:$AP30,#REF!))) -> 0 | AS30: =IF(ISERROR(LOOKUP(AS$10,$O30:$AP30,#REF!)),0,(LOOKUP(AS$10,$O30:$AP30,#REF!))) -> 0 | AT30: =IF(ISERROR(LOOKUP(AT$10,$O30:$AP30,#REF!)),0,(LOOKUP(AT$10,$O30:$AP30,#REF!))) -> 0 | AU30: =IF(ISERROR(LOOKUP(AU$10,$O30:$AP30,#REF!)),0,(LOOKUP(AU$10,$O30:$AP30,#REF!))) -> 0 | AV30: =IF(ISERROR(LOOKUP(AV$10,$O30:$AP30,#REF!)),0,(LOOKUP(AV$10,$O30:$AP30,#REF!))) -> 0 | AW30: =IF(ISERROR(LOOKUP(AW$10,$O30:$AP30,#REF!)),0,(LOOKUP(AW$10,$O30:$AP30,#REF!))) -> 0 | AX30: =IF(ISERROR(LOOKUP(AX$10,$O30:$AP30,#REF!)),0,(LOOKUP(AX$10,$O30:$AP30,#REF!))) -> 0 | ... BA30: =IF(ISERROR(LOOKUP(BA$10,$O30:$AP30,#REF!)),0,(LOOKUP(BA$10,$O30:$AP30,#REF!))) -> 0 | BB30: Bidder3 | BC30: Ex-work 30 weeks
A31: =A28+1 -> 7 | B31: MM-ZTK-1F-GEN-MEC-MR-0005 | C31: RFQ-MA-005 | D31: Chemical storage tank | F31: 2*4 | G31: 4-39 | H31: MA | I31: Y | J31: L3 | K31: LA | L31: Zhuhai Jutal | M31: SH | N31: P | O31: 46153 | P31: 46154 | Q31: 46166 | R31: 46166 | S31: 46166 | T31: 46203 | U31: 46203 | V31: 46217 | W31: 46230 | X31: 46232 | Y31: 46239 | Z31: 46267 | AA31: 46281 | AB31: 46311 | AC31: 46314 | AD31: 46317 | AE31: 46387 | AF31: 46397 | AG31: 46398 | AH31: 46401 | AI31: 46428 | AJ31: 24 | AK31: 168 | AL31: 46398 | AM31: 46433 | AN31: =AM31-AL32 -> 35 | AO31: HuangWei | AP31: 2026.5.6 Issued RFQ to Zhuhai yard | AQ31: =IF(ISERROR(LOOKUP(AQ$10,$O31:$AP31,#REF!)),0,(LOOKUP(AQ$10,$O31:$AP31,#REF!))) -> 0 | AR31: =IF(ISERROR(LOOKUP(AR$10,$O31:$AP31,#REF!)),0,(LOOKUP(AR$10,$O31:$AP31,#REF!))) -> 0 | AS31: =IF(ISERROR(LOOKUP(AS$10,$O31:$AP31,#REF!)),0,(LOOKUP(AS$10,$O31:$AP31,#REF!))) -> 0 | AT31: =IF(ISERROR(LOOKUP(AT$10,$O31:$AP31,#REF!)),0,(LOOKUP(AT$10,$O31:$AP31,#REF!))) -> 0 | AU31: =IF(ISERROR(LOOKUP(AU$10,$O31:$AP31,#REF!)),0,(LOOKUP(AU$10,$O31:$AP31,#REF!))) -> 0 | AV31: =IF(ISERROR(LOOKUP(AV$10,$O31:$AP31,#REF!)),0,(LOOKUP(AV$10,$O31:$AP31,#REF!))) -> 0 | AW31: =IF(ISERROR(LOOKUP(AW$10,$O31:$AP31,#REF!)),0,(LOOKUP(AW$10,$O31:$AP31,#REF!))) -> 0 | AX31: =IF(ISERROR(LOOKUP(AX$10,$O31:$AP31,#REF!)),0,(LOOKUP(AX$10,$O31:$AP31,#REF!))) -> 0 | ... BA31: =IF(ISERROR(LOOKUP(BA$10,$O31:$AP31,#REF!)),0,(LOOKUP(BA$10,$O31:$AP31,#REF!))) -> 0
B32: MM-ZTK-1F-GEN-MEC-MR-0005 | C32: RFQ-MA-005 | D32: Chemical storage tank | G32: 4-39 | H32: MA | I32: Y | J32: L3 | K32: LA | M32: SH | N32: F | V32: =WORKDAY(U33, V6, IF(V12="China",'China Holidays'!$A$2:$A$84,'Thai Holidays'!$A$2:$A$65)) -> 46218 | W32: =W31 -> 46230 | X32: =W32 -> 46230 | Y32: =WORKDAY(X32, Y6, IF(Y12="China",'China Holidays'!$A$2:$A$84,'Thai Holidays'!$A$2:$A$65)) -> 46237 | Z32: =WORKDAY(Y32, Z6, IF(Z12="China",'China Holidays'!$A$2:$A$84,'Thai Holidays'!$A$2:$A$65)) -> 46265 | AA32: =WORKDAY(Z32, AA6, IF(AA12="China",'China Holidays'!$A$2:$A$84,'Thai Holidays'!$A$2:$A$65)) -> 46279 | AB32: =AA32+30 -> 46309 | AC32: =AB32+3 -> 46312 | AD32: =AC32+3 -> 46315 | AE32: =AF32-10 -> 46387 | AF32: =AG32-1 -> 46397 | AG32: =AL31 -> 46398 | AH32: =AL31+3 -> 46401 | AI32: =AL31+30 -> 46428 | AL32: =W32+AK31 -> 46398 | AQ32: =IF(ISERROR(LOOKUP(AQ$10,$O32:$AP32,#REF!)),0,(LOOKUP(AQ$10,$O32:$AP32,#REF!))) -> 0 | AR32: =IF(ISERROR(LOOKUP(AR$10,$O32:$AP32,#REF!)),0,(LOOKUP(AR$10,$O32:$AP32,#REF!))) -> 0 | AS32: =IF(ISERROR(LOOKUP(AS$10,$O32:$AP32,#REF!)),0,(LOOKUP(AS$10,$O32:$AP32,#REF!))) -> 0 | AT32: =IF(ISERROR(LOOKUP(AT$10,$O32:$AP32,#REF!)),0,(LOOKUP(AT$10,$O32:$AP32,#REF!))) -> 0 | AU32: =IF(ISERROR(LOOKUP(AU$10,$O32:$AP32,#REF!)),0,(LOOKUP(AU$10,$O32:$AP32,#REF!))) -> 0 | AV32: =IF(ISERROR(LOOKUP(AV$10,$O32:$AP32,#REF!)),0,(LOOKUP(AV$10,$O32:$AP32,#REF!))) -> 0 | AW32: =IF(ISERROR(LOOKUP(AW$10,$O32:$AP32,#REF!)),0,(LOOKUP(AW$10,$O32:$AP32,#REF!))) -> 0 | AX32: =IF(ISERROR(LOOKUP(AX$10,$O32:$AP32,#REF!)),0,(LOOKUP(AX$10,$O32:$AP32,#REF!))) -> 0 | ... BA32: =IF(ISERROR(LOOKUP(BA$10,$O32:$AP32,#REF!)),0,(LOOKUP(BA$10,$O32:$AP32,#REF!))) -> 0
B33: MM-ZTK-1F-GEN-MEC-MR-0005 | C33: RFQ-MA-005 | D33: Chemical storage tank | G33: 4-39 | H33: MA | I33: Y | J33: L3 | K33: LA | M33: SH | N33: A | P33: 46133 | Q33: 46150 | R33: 46150 | S33: 46150 | T33: 46181 | U33: 46204 | AQ33: =IF(ISERROR(LOOKUP(AQ$10,$O33:$AP33,#REF!)),0,(LOOKUP(AQ$10,$O33:$AP33,#REF!))) -> 0 | AR33: =IF(ISERROR(LOOKUP(AR$10,$O33:$AP33,#REF!)),0,(LOOKUP(AR$10,$O33:$AP33,#REF!))) -> 0 | AS33: =IF(ISERROR(LOOKUP(AS$10,$O33:$AP33,#REF!)),0,(LOOKUP(AS$10,$O33:$AP33,#REF!))) -> 0 | AT33: =IF(ISERROR(LOOKUP(AT$10,$O33:$AP33,#REF!)),0,(LOOKUP(AT$10,$O33:$AP33,#REF!))) -> 0 | AU33: =IF(ISERROR(LOOKUP(AU$10,$O33:$AP33,#REF!)),0,(LOOKUP(AU$10,$O33:$AP33,#REF!))) -> 0 | AV33: =IF(ISERROR(LOOKUP(AV$10,$O33:$AP33,#REF!)),0,(LOOKUP(AV$10,$O33:$AP33,#REF!))) -> 0 | AW33: =IF(ISERROR(LOOKUP(AW$10,$O33:$AP33,#REF!)),0,(LOOKUP(AW$10,$O33:$AP33,#REF!))) -> 0 | AX33: =IF(ISERROR(LOOKUP(AX$10,$O33:$AP33,#REF!)),0,(LOOKUP(AX$10,$O33:$AP33,#REF!))) -> 0 | ... BA33: =IF(ISERROR(LOOKUP(BA$10,$O33:$AP33,#REF!)),0,(LOOKUP(BA$10,$O33:$AP33,#REF!))) -> 0
A34: =A31+1 -> 8 | B34: MM-ZTK-1F-GEN-MEC-MR-0006 | C34: RFQ-MA-006 | D34: Material Handling Equipment | F34: 6*4 | G34: 4-7 | H34: MA | I34: N | J34: L4 | K34: LC | M34: SH | N34: P | O34: 46182 | P34: 46182 | Q34: 46196 | R34: 46196 | S34: 46196 | T34: 46203 | U34: 46212 | V34: 46226 | W34: 46259 | X34: 46261 | Y34: =X34 -> 46261 | Z34: 46275 | AA34: 46295 | AB34: 46325 | AC34: 46328 | AD34: 46331 | AE34: 46391 | AF34: 46406 | AG34: 46434 | AH34: 46437 | AI34: 46464 | AJ34: 25 | AK34: 175 | AL34: 46434 | AM34: 46469 | AN34: =AM34-AL35 -> 35 | AO34: Sun liheng | AQ34: =IF(ISERROR(LOOKUP(AQ$10,$O34:$AP34,#REF!)),0,(LOOKUP(AQ$10,$O34:$AP34,#REF!))) -> 0 | AR34: =IF(ISERROR(LOOKUP(AR$10,$O34:$AP34,#REF!)),0,(LOOKUP(AR$10,$O34:$AP34,#REF!))) -> 0 | AS34: =IF(ISERROR(LOOKUP(AS$10,$O34:$AP34,#REF!)),0,(LOOKUP(AS$10,$O34:$AP34,#REF!))) -> 0 | AT34: =IF(ISERROR(LOOKUP(AT$10,$O34:$AP34,#REF!)),0,(LOOKUP(AT$10,$O34:$AP34,#REF!))) -> 0 | AU34: =IF(ISERROR(LOOKUP(AU$10,$O34:$AP34,#REF!)),0,(LOOKUP(AU$10,$O34:$AP34,#REF!))) -> 0 | AV34: =IF(ISERROR(LOOKUP(AV$10,$O34:$AP34,#REF!)),0,(LOOKUP(AV$10,$O34:$AP34,#REF!))) -> 0 | AW34: =IF(ISERROR(LOOKUP(AW$10,$O34:$AP34,#REF!)),0,(LOOKUP(AW$10,$O34:$AP34,#REF!))) -> 0 | AX34: =IF(ISERROR(LOOKUP(AX$10,$O34:$AP34,#REF!)),0,(LOOKUP(AX$10,$O34:$AP34,#REF!))) -> 0 | ... BA34: =IF(ISERROR(LOOKUP(BA$10,$O34:$AP34,#REF!)),0,(LOOKUP(BA$10,$O34:$AP34,#REF!))) -> 0 | BB34: Bidder1 | BC34: DDP : 20 weeks
B35: MM-ZTK-1F-GEN-MEC-MR-0006 | C35: RFQ-MA-006 | D35: Material Handling Equipment | F35: 4 | G35: 4-7 | H35: MA | I35: N | J35: L4 | K35: LC | M35: SH | N35: F | T35: 46210 | U35: =WORKDAY(T35, U9, IF(U12="China",'China Holidays'!$A$2:$A$84,'Thai Holidays'!$A$2:$A$65)) -> 46219 | V35: =V34 -> 46226 | W35: =W34 -> 46259 | X35: =WORKDAY(W35, X9, IF(X12="China",'China Holidays'!$A$2:$A$84,'Thai Holidays'!$A$2:$A$65)) -> 46261 | Y35: =WORKDAY(X35, Y9, IF(Y12="China",'China Holidays'!$A$2:$A$84,'Thai Holidays'!$A$2:$A$65)) -> 46268 | Z35: =WORKDAY(Y35, Z9, IF(Z12="China",'China Holidays'!$A$2:$A$84,'Thai Holidays'!$A$2:$A$65)) -> 46282 | AA35: =WORKDAY(Z35, AA9, IF(AA12="China",'China Holidays'!$A$2:$A$84,'Thai Holidays'!$A$2:$A$65)) -> 46296 | AB35: =AA35+30 -> 46326 | AC35: =AB35+3 -> 46329 | AD35: =AC35+3 -> 46332 | AE35: =AF35-15 -> 46391 | AF35: =AG35-28 -> 46406 | AG35: =AL34 -> 46434 | AH35: =AL34+3 -> 46437 | AI35: =AL34+30 -> 46464 | AL35: =W35+AK34 -> 46434 | AQ35: =IF(ISERROR(LOOKUP(AQ$10,$O35:$AP35,#REF!)),0,(LOOKUP(AQ$10,$O35:$AP35,#REF!))) -> 0 | AR35: =IF(ISERROR(LOOKUP(AR$10,$O35:$AP35,#REF!)),0,(LOOKUP(AR$10,$O35:$AP35,#REF!))) -> 0 | AS35: =IF(ISERROR(LOOKUP(AS$10,$O35:$AP35,#REF!)),0,(LOOKUP(AS$10,$O35:$AP35,#REF!))) -> 0 | AT35: =IF(ISERROR(LOOKUP(AT$10,$O35:$AP35,#REF!)),0,(LOOKUP(AT$10,$O35:$AP35,#REF!))) -> 0 | AU35: =IF(ISERROR(LOOKUP(AU$10,$O35:$AP35,#REF!)),0,(LOOKUP(AU$10,$O35:$AP35,#REF!))) -> 0 | AV35: =IF(ISERROR(LOOKUP(AV$10,$O35:$AP35,#REF!)),0,(LOOKUP(AV$10,$O35:$AP35,#REF!))) -> 0 | AW35: =IF(ISERROR(LOOKUP(AW$10,$O35:$AP35,#REF!)),0,(LOOKUP(AW$10,$O35:$AP35,#REF!))) -> 0 | AX35: =IF(ISERROR(LOOKUP(AX$10,$O35:$AP35,#REF!)),0,(LOOKUP(AX$10,$O35:$AP35,#REF!))) -> 0 | ... BA35: =IF(ISERROR(LOOKUP(BA$10,$O35:$AP35,#REF!)),0,(LOOKUP(BA$10,$O35:$AP35,#REF!))) -> 0 | BB35: Bidder2 | BC35: DDP: 50 days after drawing approve
B36: MM-ZTK-1F-GEN-MEC-MR-0006 | C36: RFQ-MA-006 | D36: Material Handling Equipment | G36: 4-7 | H36: MA | I36: N | J36: L4 | K36: LC | M36: SH | N36: A | O36: 46192 | P36: 46154 | Q36: 46170 | R36: 46196 | S36: 46196 | AQ36: =IF(ISERROR(LOOKUP(AQ$10,$O36:$AP36,#REF!)),0,(LOOKUP(AQ$10,$O36:$AP36,#REF!))) -> 0 | AR36: =IF(ISERROR(LOOKUP(AR$10,$O36:$AP36,#REF!)),0,(LOOKUP(AR$10,$O36:$AP36,#REF!))) -> 0 | AS36: =IF(ISERROR(LOOKUP(AS$10,$O36:$AP36,#REF!)),0,(LOOKUP(AS$10,$O36:$AP36,#REF!))) -> 0 | AT36: =IF(ISERROR(LOOKUP(AT$10,$O36:$AP36,#REF!)),0,(LOOKUP(AT$10,$O36:$AP36,#REF!))) -> 0 | AU36: =IF(ISERROR(LOOKUP(AU$10,$O36:$AP36,#REF!)),0,(LOOKUP(AU$10,$O36:$AP36,#REF!))) -> 0 | AV36: =IF(ISERROR(LOOKUP(AV$10,$O36:$AP36,#REF!)),0,(LOOKUP(AV$10,$O36:$AP36,#REF!))) -> 0 | AW36: =IF(ISERROR(LOOKUP(AW$10,$O36:$AP36,#REF!)),0,(LOOKUP(AW$10,$O36:$AP36,#REF!))) -> 0 | AX36: =IF(ISERROR(LOOKUP(AX$10,$O36:$AP36,#REF!)),0,(LOOKUP(AX$10,$O36:$AP36,#REF!))) -> 0 | ... BA36: =IF(ISERROR(LOOKUP(BA$10,$O36:$AP36,#REF!)),0,(LOOKUP(BA$10,$O36:$AP36,#REF!))) -> 0
A37: =A34+1 -> 9 | B37: MM-ZTK-1F-GEN-SAF-MR-0001 | C37: RFQ-SA-001 | D37: Fire Fighting, Safety Equipment (Including Lifesaving) | G37: 4-38 | H37: SA | I37: N | J37: L3 | K37: LD | M37: SH | N37: P | O37: 46201 | P37: 46201 | Q37: 46213 | R37: 46213 | S37: 46213 | T37: 46220 | U37: 46233 | V37: 46248 | W37: 46255 | X37: 46259 | Y37: =X37 -> 46259 | Z37: 46273 | AA37: 46287 | AB37: 46347 | AC37: 46347 | AD37: 46350 | AE37: 46420 | AF37: 46435 | AG37: 46465 | AH37: 46468 | AI37: 46495 | AJ37: 30 | AK37: 210 | AL37: 46465 | AM37: 46517 | AN37: =AM37-AL38 -> 52 | AO37: Sun liheng | AQ37: =IF(ISERROR(LOOKUP(AQ$10,$O37:$AP37,#REF!)),0,(LOOKUP(AQ$10,$O37:$AP37,#REF!))) -> 0 | AR37: =IF(ISERROR(LOOKUP(AR$10,$O37:$AP37,#REF!)),0,(LOOKUP(AR$10,$O37:$AP37,#REF!))) -> 0 | AS37: =IF(ISERROR(LOOKUP(AS$10,$O37:$AP37,#REF!)),0,(LOOKUP(AS$10,$O37:$AP37,#REF!))) -> 0 | AT37: =IF(ISERROR(LOOKUP(AT$10,$O37:$AP37,#REF!)),0,(LOOKUP(AT$10,$O37:$AP37,#REF!))) -> 0 | AU37: =IF(ISERROR(LOOKUP(AU$10,$O37:$AP37,#REF!)),0,(LOOKUP(AU$10,$O37:$AP37,#REF!))) -> 0 | AV37: =IF(ISERROR(LOOKUP(AV$10,$O37:$AP37,#REF!)),0,(LOOKUP(AV$10,$O37:$AP37,#REF!))) -> 0 | AW37: =IF(ISERROR(LOOKUP(AW$10,$O37:$AP37,#REF!)),0,(LOOKUP(AW$10,$O37:$AP37,#REF!))) -> 0 | AX37: =IF(ISERROR(LOOKUP(AX$10,$O37:$AP37,#REF!)),0,(LOOKUP(AX$10,$O37:$AP37,#REF!))) -> 0 | ... BA37: =IF(ISERROR(LOOKUP(BA$10,$O37:$AP37,#REF!)),0,(LOOKUP(BA$10,$O37:$AP37,#REF!))) -> 0
B38: MM-ZTK-1F-GEN-SAF-MR-0001 | C38: RFQ-SA-001 | D38: Fire Fighting, Safety Equipment (Including Lifesaving) | G38: 4-38 | H38: SA | I38: N | J38: L3 | K38: LD | M38: SH | N38: F | O38: 46210 | R38: =R37 -> 46213 | S38: =WORKDAY(R38,S9,IF(S12="China",'China Holidays'!$A$2:$A$84,'Thai Holidays'!$A$2:$A$65)) -> 46213 | T38: =WORKDAY(S38,T9,IF(T12="China",'China Holidays'!$A$2:$A$84,'Thai Holidays'!$A$2:$A$65)) -> 46220 | U38: =WORKDAY(T38,U9,IF(U12="China",'China Holidays'!$A$2:$A$84,'Thai Holidays'!$A$2:$A$65)) -> 46233 | V38: =WORKDAY(U38,V9,IF(V12="China",'China Holidays'!$A$2:$A$84,'Thai Holidays'!$A$2:$A$65)) -> 46248 | W38: =WORKDAY(V38,W9,IF(W12="China",'China Holidays'!$A$2:$A$84,'Thai Holidays'!$A$2:$A$65)) -> 46255 | X38: =WORKDAY(W38,X9,IF(X12="China",'China Holidays'!$A$2:$A$84,'Thai Holidays'!$A$2:$A$65)) -> 46259 | Y38: =X38 -> 46259 | Z38: =WORKDAY(Y38,Z9,IF(Z12="China",'China Holidays'!$A$2:$A$84,'Thai Holidays'!$A$2:$A$65)) -> 46273 | AA38: =WORKDAY(Z38,AA9,IF(AA12="China",'China Holidays'!$A$2:$A$84,'Thai Holidays'!$A$2:$A$65)) -> 46287 | AB38: =AA38+60 -> 46347 | AC38: =AB38 -> 46347 | AD38: =AC38+3 -> 46350 | AE38: =AF38-15 -> 46420 | AF38: =AG38-30 -> 46435 | AG38: =AL37 -> 46465 | AH38: =AL37+3 -> 46468 | AI38: =AL37+30 -> 46495 | AL38: =W38+AK37 -> 46465 | AQ38: =IF(ISERROR(LOOKUP(AQ$10,$O38:$AP38,#REF!)),0,(LOOKUP(AQ$10,$O38:$AP38,#REF!))) -> 0 | AR38: =IF(ISERROR(LOOKUP(AR$10,$O38:$AP38,#REF!)),0,(LOOKUP(AR$10,$O38:$AP38,#REF!))) -> 0 | AS38: =IF(ISERROR(LOOKUP(AS$10,$O38:$AP38,#REF!)),0,(LOOKUP(AS$10,$O38:$AP38,#REF!))) -> 0 | AT38: =IF(ISERROR(LOOKUP(AT$10,$O38:$AP38,#REF!)),0,(LOOKUP(AT$10,$O38:$AP38,#REF!))) -> 0 | AU38: =IF(ISERROR(LOOKUP(AU$10,$O38:$AP38,#REF!)),0,(LOOKUP(AU$10,$O38:$AP38,#REF!))) -> 0 | AV38: =IF(ISERROR(LOOKUP(AV$10,$O38:$AP38,#REF!)),0,(LOOKUP(AV$10,$O38:$AP38,#REF!))) -> 0 | AW38: =IF(ISERROR(LOOKUP(AW$10,$O38:$AP38,#REF!)),0,(LOOKUP(AW$10,$O38:$AP38,#REF!))) -> 0 | AX38: =IF(ISERROR(LOOKUP(AX$10,$O38:$AP38,#REF!)),0,(LOOKUP(AX$10,$O38:$AP38,#REF!))) -> 0 | ... BA38: =IF(ISERROR(LOOKUP(BA$10,$O38:$AP38,#REF!)),0,(LOOKUP(BA$10,$O38:$AP38,#REF!))) -> 0
B39: MM-ZTK-1F-GEN-SAF-MR-0001 | C39: RFQ-SA-001 | D39: Fire Fighting, Safety Equipment (Including Lifesaving) | G39: 4-38 | H39: SA | I39: N | J39: L3 | K39: LD | M39: SH | N39: A | P39: 46183 | Q39: 46197 | AQ39: =IF(ISERROR(LOOKUP(AQ$10,$O39:$AP39,#REF!)),0,(LOOKUP(AQ$10,$O39:$AP39,#REF!))) -> 0 | AR39: =IF(ISERROR(LOOKUP(AR$10,$O39:$AP39,#REF!)),0,(LOOKUP(AR$10,$O39:$AP39,#REF!))) -> 0 | AS39: =IF(ISERROR(LOOKUP(AS$10,$O39:$AP39,#REF!)),0,(LOOKUP(AS$10,$O39:$AP39,#REF!))) -> 0 | AT39: =IF(ISERROR(LOOKUP(AT$10,$O39:$AP39,#REF!)),0,(LOOKUP(AT$10,$O39:$AP39,#REF!))) -> 0 | AU39: =IF(ISERROR(LOOKUP(AU$10,$O39:$AP39,#REF!)),0,(LOOKUP(AU$10,$O39:$AP39,#REF!))) -> 0 | AV39: =IF(ISERROR(LOOKUP(AV$10,$O39:$AP39,#REF!)),0,(LOOKUP(AV$10,$O39:$AP39,#REF!))) -> 0 | AW39: =IF(ISERROR(LOOKUP(AW$10,$O39:$AP39,#REF!)),0,(LOOKUP(AW$10,$O39:$AP39,#REF!))) -> 0 | AX39: =IF(ISERROR(LOOKUP(AX$10,$O39:$AP39,#REF!)),0,(LOOKUP(AX$10,$O39:$AP39,#REF!))) -> 0 | ... BA39: =IF(ISERROR(LOOKUP(BA$10,$O39:$AP39,#REF!)),0,(LOOKUP(BA$10,$O39:$AP39,#REF!))) -> 0
A40: =A37+1 -> 10 | B40: MM-ZTK-1F-GEN-SAF-MR-0002 | C40: RFQ-SA-002 | D40: Safety Signs | G40: 4-38 | H40: SA | I40: N | J40: L3 | K40: LD | M40: ZH | N40: P | O40: =P40 -> 46381 | P40: 46381 | Q40: 46399 | R40: 46399 | S40: 46399 | T40: 46406 | U40: 46415 | V40: 46429 | W40: 46437 | X40: 46441 | Y40: 46448 | Z40: 46462 | AA40: 46476 | AB40: 46491 | AC40: 46491 | AD40: 46493 | AE40: 46523 | AF40: 46525 | AG40: 46530 | AH40: 46533 | AI40: 46560 | AJ40: 5 | AK40: 35 | AL40: 46530 | AM40: 46530 | AN40: =AM40-AL41 -> 58 | AO40: Liu bin | AP40: 2026.6.10 Issued RFQ to Zhuhai yard | AQ40: =IF(ISERROR(LOOKUP(AQ$10,$O40:$AP40,#REF!)),0,(LOOKUP(AQ$10,$O40:$AP40,#REF!))) -> 0 | AR40: =IF(ISERROR(LOOKUP(AR$10,$O40:$AP40,#REF!)),0,(LOOKUP(AR$10,$O40:$AP40,#REF!))) -> 0 | AS40: =IF(ISERROR(LOOKUP(AS$10,$O40:$AP40,#REF!)),0,(LOOKUP(AS$10,$O40:$AP40,#REF!))) -> 0 | AT40: =IF(ISERROR(LOOKUP(AT$10,$O40:$AP40,#REF!)),0,(LOOKUP(AT$10,$O40:$AP40,#REF!))) -> 0 | AU40: =IF(ISERROR(LOOKUP(AU$10,$O40:$AP40,#REF!)),0,(LOOKUP(AU$10,$O40:$AP40,#REF!))) -> 0 | AV40: =IF(ISERROR(LOOKUP(AV$10,$O40:$AP40,#REF!)),0,(LOOKUP(AV$10,$O40:$AP40,#REF!))) -> 0 | AW40: =IF(ISERROR(LOOKUP(AW$10,$O40:$AP40,#REF!)),0,(LOOKUP(AW$10,$O40:$AP40,#REF!))) -> 0 | AX40: =IF(ISERROR(LOOKUP(AX$10,$O40:$AP40,#REF!)),0,(LOOKUP(AX$10,$O40:$AP40,#REF!))) -> 0 | ... BA40: =IF(ISERROR(LOOKUP(BA$10,$O40:$AP40,#REF!)),0,(LOOKUP(BA$10,$O40:$AP40,#REF!))) -> 0
B41: MM-ZTK-1F-GEN-SAF-MR-0002 | C41: RFQ-SA-002 | D41: Safety Signs | G41: 4-38 | H41: SA | I41: N | J41: L3 | K41: LD | M41: ZH | N41: F | O41: =O40 -> 46381 | R41: =R40 -> 46399 | S41: =WORKDAY(R41, S9, IF(S12="China",'China Holidays'!$A$2:$A$84,'Thai Holidays'!$A$2:$A$65)) -> 46399 | T41: =WORKDAY(S41, T9, IF(T12="China",'China Holidays'!$A$2:$A$84,'Thai Holidays'!$A$2:$A$65)) -> 46406 | U41: =WORKDAY(T41, U9, IF(U12="China",'China Holidays'!$A$2:$A$84,'Thai Holidays'!$A$2:$A$65)) -> 46415 | V41: =WORKDAY(U41, V9, IF(V12="China",'China Holidays'!$A$2:$A$84,'Thai Holidays'!$A$2:$A$65)) -> 46429 | W41: =WORKDAY(V41, W9, IF(W12="China",'China Holidays'!$A$2:$A$84,'Thai Holidays'!$A$2:$A$65)) -> 46437 | X41: =WORKDAY(W41, X9, IF(X12="China",'China Holidays'!$A$2:$A$84,'Thai Holidays'!$A$2:$A$65)) -> 46441 | Y41: =WORKDAY(X41, Y9, IF(Y12="China",'China Holidays'!$A$2:$A$84,'Thai Holidays'!$A$2:$A$65)) -> 46448 | Z41: =WORKDAY(Y41, Z9, IF(Z12="China",'China Holidays'!$A$2:$A$84,'Thai Holidays'!$A$2:$A$65)) -> 46462 | AA41: =WORKDAY(Z41, AA9, IF(AA12="China",'China Holidays'!$A$2:$A$84,'Thai Holidays'!$A$2:$A$65)) -> 46476 | AB41: =AA41+15 -> 46491 | AC41: =AB41 -> 46491 | AD41: =AC41+2 -> 46493 | AE41: =AD41+30 -> 46523 | AF41: =AE41+2 -> 46525 | AG41: =AF41+5 -> 46530 | AH41: =AL40+3 -> 46533 | AI41: =AL40+30 -> 46560 | AL41: =W41+AK40 -> 46472 | AQ41: =IF(ISERROR(LOOKUP(AQ$10,$O41:$AP41,#REF!)),0,(LOOKUP(AQ$10,$O41:$AP41,#REF!))) -> 0 | AR41: =IF(ISERROR(LOOKUP(AR$10,$O41:$AP41,#REF!)),0,(LOOKUP(AR$10,$O41:$AP41,#REF!))) -> 0 | AS41: =IF(ISERROR(LOOKUP(AS$10,$O41:$AP41,#REF!)),0,(LOOKUP(AS$10,$O41:$AP41,#REF!))) -> 0 | AT41: =IF(ISERROR(LOOKUP(AT$10,$O41:$AP41,#REF!)),0,(LOOKUP(AT$10,$O41:$AP41,#REF!))) -> 0 | AU41: =IF(ISERROR(LOOKUP(AU$10,$O41:$AP41,#REF!)),0,(LOOKUP(AU$10,$O41:$AP41,#REF!))) -> 0 | AV41: =IF(ISERROR(LOOKUP(AV$10,$O41:$AP41,#REF!)),0,(LOOKUP(AV$10,$O41:$AP41,#REF!))) -> 0 | AW41: =IF(ISERROR(LOOKUP(AW$10,$O41:$AP41,#REF!)),0,(LOOKUP(AW$10,$O41:$AP41,#REF!))) -> 0 | AX41: =IF(ISERROR(LOOKUP(AX$10,$O41:$AP41,#REF!)),0,(LOOKUP(AX$10,$O41:$AP41,#REF!))) -> 0 | ... BA41: =IF(ISERROR(LOOKUP(BA$10,$O41:$AP41,#REF!)),0,(LOOKUP(BA$10,$O41:$AP41,#REF!))) -> 0
B42: MM-ZTK-1F-GEN-SAF-MR-0002 | C42: RFQ-SA-002 | D42: Safety Signs | G42: 4-38 | H42: SA | I42: N | J42: L3 | K42: LD | M42: ZH | N42: A | P42: 46174 | Q42: 46182 | AQ42: =IF(ISERROR(LOOKUP(AQ$10,$O42:$AP42,#REF!)),0,(LOOKUP(AQ$10,$O42:$AP42,#REF!))) -> 0 | AR42: =IF(ISERROR(LOOKUP(AR$10,$O42:$AP42,#REF!)),0,(LOOKUP(AR$10,$O42:$AP42,#REF!))) -> 0 | AS42: =IF(ISERROR(LOOKUP(AS$10,$O42:$AP42,#REF!)),0,(LOOKUP(AS$10,$O42:$AP42,#REF!))) -> 0 | AT42: =IF(ISERROR(LOOKUP(AT$10,$O42:$AP42,#REF!)),0,(LOOKUP(AT$10,$O42:$AP42,#REF!))) -> 0 | AU42: =IF(ISERROR(LOOKUP(AU$10,$O42:$AP42,#REF!)),0,(LOOKUP(AU$10,$O42:$AP42,#REF!))) -> 0 | AV42: =IF(ISERROR(LOOKUP(AV$10,$O42:$AP42,#REF!)),0,(LOOKUP(AV$10,$O42:$AP42,#REF!))) -> 0 | AW42: =IF(ISERROR(LOOKUP(AW$10,$O42:$AP42,#REF!)),0,(LOOKUP(AW$10,$O42:$AP42,#REF!))) -> 0 | AX42: =IF(ISERROR(LOOKUP(AX$10,$O42:$AP42,#REF!)),0,(LOOKUP(AX$10,$O42:$AP42,#REF!))) -> 0 | ... BA42: =IF(ISERROR(LOOKUP(BA$10,$O42:$AP42,#REF!)),0,(LOOKUP(BA$10,$O42:$AP42,#REF!))) -> 0
A43: =A40+1 -> 11 | B43: MM-ZTK-1F-GEN-PIP-MR-0001 | C43: RFQ-PIP-001 | D43: Ball Valve (Flange End) | E43: 150#-148 | F43: 355 | G43: 4-19 | H43: PI | I43: N | J43: L3 | K43: LC | M43: SH | N43: P | O43: 46174 | P43: 46177 | Q43: 46185 | R43: 46185 | S43: 46185 | T43: 46202 | U43: 46219 | V43: 46237 | W43: 46248 | X43: 46252 | Y43: 46259 | Z43: 46280 | AA43: 46294 | AB43: 46324 | AC43: 46327 | AD43: 46330 | AE43: 46422 | AF43: 46437 | AG43: 46444 | AH43: 46447 | AI43: 46474 | AJ43: 28 | AK43: 196 | AL43: 46444 | AM43: 46476 | AN43: =AM43-AL44 -> 32 | AO43: Lin Yazhen | AQ43: =IF(ISERROR(LOOKUP(AQ$10,$O43:$AP43,#REF!)),0,(LOOKUP(AQ$10,$O43:$AP43,#REF!))) -> 0 | AR43: =IF(ISERROR(LOOKUP(AR$10,$O43:$AP43,#REF!)),0,(LOOKUP(AR$10,$O43:$AP43,#REF!))) -> 0 | AS43: =IF(ISERROR(LOOKUP(AS$10,$O43:$AP43,#REF!)),0,(LOOKUP(AS$10,$O43:$AP43,#REF!))) -> 0 | AT43: =IF(ISERROR(LOOKUP(AT$10,$O43:$AP43,#REF!)),0,(LOOKUP(AT$10,$O43:$AP43,#REF!))) -> 0 | AU43: =IF(ISERROR(LOOKUP(AU$10,$O43:$AP43,#REF!)),0,(LOOKUP(AU$10,$O43:$AP43,#REF!))) -> 0 | AV43: =IF(ISERROR(LOOKUP(AV$10,$O43:$AP43,#REF!)),0,(LOOKUP(AV$10,$O43:$AP43,#REF!))) -> 0 | AW43: =IF(ISERROR(LOOKUP(AW$10,$O43:$AP43,#REF!)),0,(LOOKUP(AW$10,$O43:$AP43,#REF!))) -> 0 | AX43: =IF(ISERROR(LOOKUP(AX$10,$O43:$AP43,#REF!)),0,(LOOKUP(AX$10,$O43:$AP43,#REF!))) -> 0 | ... BA43: =IF(ISERROR(LOOKUP(BA$10,$O43:$AP43,#REF!)),0,(LOOKUP(BA$10,$O43:$AP43,#REF!))) -> 0
...

Sheet Thai Holidays
A1: Date | B1: Holiday Name
A2: 45996 | B2: Father's Day
A3: 46001 | B3: Constitution Day
A4: 46020 | B4: New Year's Day
A5: 46021 | B5: New Year's Day
A6: 46022 | B6: New Year's Day
A7: 46023 | B7: New Year's Day
A8: 46024 | B8: New Year's Day
A9: 46065 | B9: The Buddha Day
A10: 46118 | B10: Kutkuri Dynasty Memorial Day
A11: 46125 | B11: Songkran Festival
A12: 46126 | B12: Songkran Festival
A13: 46127 | B13: Songkran Festival
... A17: 46146 | B17: The anniversary of the King's accession to the throne
A18: 46174
A19: 46176
A20: 46231
A21: 46232
A22: 46246 | B22: Mother's Day
A23: 46308 | B23: The anniversary of the death of the 9th King
A24: 46318 | B24: The anniversary of the death of the 5th King Father's Day
A25: 46363 | B25: Father's Day
A26: 46387 | B26: New Year's Day
A27: 46388 | B27: New Year's Day | C27: 佛历节日，日期为预测
A28: 46389
A29: 46439 | B29: The Buddha Day
A30: 46440
A31: 46483 | B31: Kutkuri Dynasty Memorial Day
A32: 46490 | B32: Songkran Festival
A33: 46491 | B33: Songkran Festival
A34: 46492 | B34: Songkran Festival | C34: 佛历节日，日期为预测
A35: 46508 | B35: International Workers' Day
A36: 46511 | B36: The anniversary of the King's accession to the throne
A37: 46527 | B37: Vesak Festival
A38: 46541 | B38: The Birthday Anniversary of the Queen
A39: 46611 | B39: Mother's Day | C39: 佛历节日，日期为预测
A40: 46673 | B40: The anniversary of the death of the 9th King
A41: 46683 | B41: The anniversary of the death of the 5th King Father's Day | D41: The anniversary of the death of the 5th King Father's Day
A42: 46685
A43: 46726 | B43: Father's Day
...

Sheet China Holidays
A1: Date | B1: Holiday Name
A2: 46023 | B2: New Year's Day
A3: 46024 | B3: New Year's Day
A4: 46025 | B4: New Year's Day
A5: 46068 | B5: Spring Festival
A6: 46069 | B6: Spring Festival
A7: 46070 | B7: Spring Festival
A8: 46071 | B8: Spring Festival
A9: 46072 | B9: Spring Festival
A10: 46073 | B10: Spring Festival
A11: 46074 | B11: Spring Festival
A12: 46116 | B12: Qingming Festival
A13: 46117 | B13: Qingming Festival
... A84: 47033 | B84: National Day

Sheet STR MR
A1: Document No. | B1: Document Title | E1: Rev. | F1: Document Status Code | G1: Distribution Date | H1: Approver Actual Finish | I1: Return Status Name
A2: MM-ZTK-1F-GEN-STR-MR-1021 | B2: MATERIAL REQUISITION FOR TOPSIDES HIGH STRENGTH STEEL PLATES | C2: RFQ-STR-001 | D2: Topside Primary Steel- Plate | E2: A1 | F2: IFR | G2: 20-May-2026 18:20:49 | H2: 22-May-2026 01:16:45 | I2: Approved with Comment (Proceed to Rev.C)
A3: MM-ZTK-1F-GEN-STR-MR-1011 | B3: MATERIAL REǪUISITION FOR TOPSIDES HIGH STRENGTH HOT-ROLLED STEEL SECTIONS (SHAPE | C3: RFQ-STR-002 | D3: Topside Primary Steel-Beam | E3: A1 | F3: IFR | G3: 08-May-2026 13:17:04 | H3: 15-May-2026 23:34:18 | I3: Approved with Comment (Proceed to Rev.C)
A4: MM-ZTK-1F-GEN-STR-MR-1001 | B4: MATERIAL REǪUISITION FOR TOPSIDES HIGH STRENGTH TUBULAR STEEL | C4: RFQ-STR-003 RFQ-STR-016 | D4: Topside Primary Steel- Tubular TUBULARS (SAW + SEAMLESS) | E4: A1 | F4: IFR | G4: 04-May-2026 13:07:12 | H4: 15-May-2026 23:30:40 | I4: Approved with Comment (Proceed to Rev.C)
A5: MM-ZTK-1F-GEN-STR-MR-1012 | B5: MATERIAL REQUISITION FOR TOPSIDES SECONDARY AND TERTIARY HOT-ROLLED STEEL | C5: RFQ-STR-004 RFQ-STR-005 | D5: Topside Secondary and Tertiary Steel BEAMS | E5: A1 | F5: IFR | G5: 23-May-2026 09:31:31 | H5: 25-May-2026 20:37:08 | I5: Approved with Comment (Proceed to Rev.C)
A6: MM-ZTK-1F-GEN-STR-MR-1002 | B6: MATERIAL REQUISITION FOR TOPSIDES SECONDARY AND TERTIARY TUBULAR STEEL | C6: RFQ-STR-004 RFQ-STR-005 | D6: Topside Secondary and Tertiary Steel TUBULARS (SEAMLESS) | E6: A1 | F6: IFR | G6: 23-May-2026 08:52:07 | H6: 25-May-2026 20:36:04 | I6: Approved with Comment (Proceed to Rev.C)
A7: MM-ZTK-1F-GEN-STR-MR-1022 | B7: MATERIAL REQUISITION FOR TOPSIDE LOW STRENGTH STEEL PLATE | C7: RFQ-STR-005 | D7: Topside Tertiary Steel-Plate | E7: A1 | F7: IFR | G7: 29-May-2026 19:06:31 | H7: 01-Jun-2026 09:19:45 | I7: Approved with Comment (Proceed to Rev.C)
A8: MM-ZTK-1F-ZWP20-STR-MR-2002 | B8: MATERIAL REǪUISITION FOR ZWP20 JACKET PRIMARY STEEL (PLATE) | C8: RFQ-STR-006 | D8: Jacket Primary Steel-Plate | E8: A1 | F8: IFR | G8: 06-May-2026 10:31:53 | H8: 15-May-2026 23:20:12 | I8: Approved with Comment (Proceed to Rev.C)
A9: MM-ZTK-1F-ZWP21-STR-MR-2002 | B9: MATERIAL REǪUISITION FOR ZWP21 JACKET PRIMARY STEEL (PLATE) | C9: RFQ-STR-006 | D9: Jacket Primary Steel-Plate | E9: A1 | F9: IFR | G9: 06-May-2026 10:32:08 | H9: 15-May-2026 23:33:14 | I9: Approved with Comment (Proceed to Rev.C)
A10: MM-ZTK-1F-ZWP22-STR-MR-2002 | B10: MATERIAL REǪUISITION FOR ZWP22 JACKET PRIMARY STEEL (PLATE) | C10: RFQ-STR-006 | D10: Jacket Primary Steel-Plate | E10: A1 | F10: IFR | G10: 06-May-2026 10:32:27 | H10: 15-May-2026 23:22:53 | I10: Approved with Comment (Proceed to Rev.C)
A11: MM-ZTK-1F-ZWP23-STR-MR-2002 | B11: MATERIAL REǪUISITION FOR ZWP23 JACKET PRIMARY STEEL (PLATE) | C11: RFQ-STR-006 | D11: Jacket Primary Steel-Plate | E11: A1 | F11: IFR | G11: 06-May-2026 10:32:43 | H11: 15-May-2026 23:25:28 | I11: Approved with Comment (Proceed to Rev.C)
A12: MM-ZTK-1F-ZWP20-STR-MR-2001 | B12: MATERIAL REǪUISITION FOR ZWP20 JACKET PRIMARY TUBULAR STEEL | C12: RFQ-STR-007 | D12: Jacket Primary Steel-Tubular TUBULARS - SAW PIPE | E12: A1 | F12: IFR | G12: 04-May-2026 13:11:09 | H12: 15-May-2026 22:45:39 | I12: Approved with Comment
A13: MM-ZTK-1F-ZWP21-STR-MR-2001 | B13: MATERIAL REǪUISITION FOR ZWP21 JACKET PRIMARY TUBULAR STEEL | C13: RFQ-STR-007 | D13: Jacket Primary Steel-Tubular TUBULARS - SAW PIPE | E13: A1 | F13: IFR | G13: 04-May-2026 13:11:25 | H13: 15-May-2026 23:19:31 | I13: Approved with Comment (Proceed to Rev.C)
... A15: MM-ZTK-1F-ZWP23-STR-MR-2001 | B15: MATERIAL REǪUISITION FOR ZWP23 JACKET PRIMARY TUBULAR STEEL | C15: RFQ-STR-007 | D15: Jacket Primary Steel-Tubular TUBULARS - SAW PIPE | E15: A1 | F15: IFR | G15: 04-May-2026 13:11:55 | H15: 15-May-2026 23:33:47 | I15: Approved with Comment (Proceed to Rev.C)

Sheet Primary steel-plate
A1: Plateform | B1: Drawing No. | C1: REV | D1: Drawing Name | E1: Vendor | F1: Weight (T) | G1: Ordered(T) | H1: Rest | I1: Order No. | J1: Order Date | K1: Remark
A2: ZWP21 | B2: ZM169-SE-ST-ML-004 | C2: REV. 4 | D2: Steel Plate for ZWP21 Launch Cradle and Vertical Framing Internal Ring Stiffener | E2: XISC | F2: 420.97 | G2: =225296/1000 -> 225.296 | H2: =F2-G2 -> 195.674 | I2: ZH26FA001(02) | J2: 46195
A3: ZWP21 | B3: ZM169-ZWP21-ST-ML-001 | C3: REV. 4 | D3: ZWP21 Jacket Primary, TRB Rolling Plate | E3: XISC | F3: 1877.39 | G3: =1296894.01/1000 -> 1296.894 | H3: =F3-G3-G4 -> 13.64197 | I3: ZH26FA001(03) | J3: 46195
A4: ZWP21 | B4: ZM169-ZWP21-ST-ML-001 | C4: REV. 5 | D4: ZWP22 Jacket Primary, TRB Rolling Plate | E4: XISC | G4: =566854.02/1000 -> 566.85402 | I4: ZH26FA001(16) | J4: 46204
A5: ZWP21 | B5: ZM169-ZWP21-ST-ML-002 | C5: REV. 2 | D5: ZWP21 Jacket Primary, JCOE Rolling Plate | E5: XISC | F5: 1581.53 | G5: =1049591.95/1000 -> 1049.5919 | H5: =F5-G5 -> 531.93805 | I5: ZH26FA001(04) | J5: 46195
A6: ZWP21 | B6: ZM169-ZWP21-ST-ML-007 | C6: REV. 2 | D6: ZWP21 Jacket Primary, Cone Plate | E6: XISC | F6: 65 | G6: =55551.55/1000 -> 55.55155 | H6: =F6-G6 -> 9.44845 | I6: ZH26FA001(05) | J6: 46195
A7: ZWP21 | B7: ZM169-ZWP21-ST-ML-007 | C7: Rev.1 | D7: ZWP21 Jacket Primary, Cone Plate | E7: XISC
A8: ZWP21 | B8: ZM169-ZWP21-ST-ML-007 | C8: REV. 3 | D8: ZWP22 Jacket Primary, Cone Plate | E8: XISC | G8: =36790.01/1000 -> 36.79001 | I8: ZH26FA001(14) | J8: 46204
A9: ZWP21 | B9: ZM169-ZWP21-ST-ML-008 | D9: ZWP21 Jacket Hydro static Ring Stiff Plates | E9: XISC | F9: 25.756 | G9: =9397.71/1000 -> 9.39771 | H9: =F9-G9 -> 16.35829 | I9: ZH26FA001(10) | J9: 46195
A10: ZWP21 | B10: ZM169-ZWP21-ST-ML-009 | D10: ZWP21 Jacket Leg Partition/Closure Plates | E10: XISC | F10: 17.117 | H10: =F10-G10 -> 17.117
A11: ZWP21 | B11: ZM169-ZWP21-ST-ML-010 | D11: ZWP21 Jacket Piles Sleeve Plate | E11: XISC | F11: 437.539 | G11: =271819.08/1000 -> 271.81908 | H11: =F11-G11 -> 165.71992 | I11: ZH26FA001(07) | J11: 46195
F12: =SUM(F2:F11) -> 4425.302 | G12: =SUM(G2:G11) -> 3512.1943 | H12: =F12-G12 -> 913.10767
A13: ZWP23 | B13: ZM169-ZWP23-ST-ML-001 | D13: ZWP23 Jacket Primary, TRB Rolling Plate | E13: XISC | F13: 1761
A14: ZWP23 | B14: ZM169-ZWP23-ST-ML-002 | D14: ZWP23 Jacket Primary, JCOE Rolling Plate | E14: XISC | F14: 1514
A15: ZWP23 | B15: ZM169-ZWP23-ST-ML-007 | D15: ZWP23 Jacket Primary, Cone Plate | E15: XISC | F15: 65 | G15: =22701.82/1000 -> 22.70182 | H15: =F15-G15 -> 42.29818 | I15: ZH26FA001(06) | J15: 46183
A16: ZWP23 | B16: ZM169-ZWP23-ST-ML-008 | D16: ZWP23 Jacket Hydro static Ring Stiff Plates | E16: XISC | K16: No drawing to SE
A17: ZWP23 | B17: ZM169-ZWP23-ST-ML-009 | D17: ZWP23 Jacket Leg Partition/Closure Plates | E17: XISC | F17: 17.117
A18: ZWP23 | B18: ZM169-ZWP23-ST-ML-010 | D18: ZWP23 Jacket Piles Sleeve Plate | E18: XISC | F18: 437.539
A19: ZWP23 | B19: ZM169-ZWP23-ST-ML-011 | D19: ZWP23 Jacket Launch Cradle Plates+Ring Stiff Plates | E19: XISC | F19: 427.221
A21: ZWP20 | B21: ZM169-ZWP20-ST-ML-001 | D21: ZWP20 Jacket Primary, TRB Rolling Plate | E21: XISC | F21: 1641
A22: ZWP20 | B22: ZM169-ZWP20-ST-ML-002 | D22: ZWP20 Jacket Primary, JCOE Rolling Plate | E22: XISC | F22: 1439
A23: ZWP20 | B23: ZM169-ZWP20-ST-ML-007 | D23: ZWP20 Jacket Primary, Cone Plate | E23: XISC | F23: 65
A24: ZWP20 | B24: ZM169-ZWP20-ST-ML-008 | D24: ZWP20 Jacket Hydro static Ring Stiff Plates | E24: XISC | K24: No drawing to SE
A25: ZWP20 | B25: ZM169-ZWP20-ST-ML-009 | D25: ZWP20 Jacket Leg Partition/Closure Plates | E25: XISC | F25: 17.117
A26: ZWP20 | B26: ZM169-ZWP20-ST-ML-010 | D26: ZWP20 Jacket Piles Sleeve Plate | E26: XISC | F26: 465.604
A27: ZWP20 | B27: ZM169-ZWP20-ST-ML-011 | D27: ZWP20 Jacket Launch Cradle Plates+Ring Stiff Plates | E27: XISC | F27: 393.737
A29: ZWP22 | B29: ZM169-ZWP22-ST-ML-001 | D29: ZWP22 Jacket Primary, TRB Rolling Plate | E29: XISC | F29: 1696
A30: ZWP22 | B30: ZM169-ZWP22-ST-ML-002 | D30: ZWP22 Jacket Primary, JCOE Rolling Plate | E30: XISC | F30: 1425
A31: ZWP22 | B31: ZM169-ZWP22-ST-ML-007 | D31: ZWP22 Jacket Primary, Cone Plate | E31: XISC | F31: 65
A32: ZWP22 | B32: ZM169-ZWP22-ST-ML-008 | D32: ZWP22 Jacket Hydro static Ring Stiff Plates | E32: XISC | K32: No drawing to SE
A33: ZWP22 | B33: ZM169-ZWP22-ST-ML-009 | D33: ZWP22 Jacket Leg Partition/Closure Plates | E33: XISC | F33: 17.117
A34: ZWP22 | B34: ZM169-ZWP22-ST-ML-010 | D34: ZWP22 Jacket Piles Sleeve Plate | E34: XISC | F34: 456.604
A35: ZWP22 | B35: ZM169-ZWP22-ST-ML-011 | D35: ZWP22 Jacket Launch Cradle Plates+Ring Stiff Plates | E35: XISC | F35: 410.177
A40: Plateform | B40: Drawing No. | D40: Drawing Name | E40: Vendor | F40: Weight (T) | G40: Ordered(T) | H40: Rest | I40: Order No. | J40: Order Date | K40: Remark
A41: Topside | B41: ZM169-SE-ST-ML-010 | D41: Topside Primary, TRB Rolling Plate (ZWP20, 21, 22, 23) | E41: XISC | F41: 260.332 | G41: =310332.39/1000 -> 310.33239 | H41: =F41-G41 -> -50.00039 | I41: ZH26FA001(09) | J41: 46189
A42: Topside | B42: ZM169-SE-ST-ML-011 | D42: Topside Primary, JCOE Rolling Plate (ZWP20, 21, 22, 23) | E42: XISC | F42: 349.148 | G42: =90494.53/1000 -> 90.49453 | H42: =F42-G42 -> 258.65347 | I42: ZH26FA001(08) | J42: 46189
A43: Topside | B43: ZM169-SE-ST-ML-012 | D43: Topside Primary, Plate (ZWP20, 21, 22, 23) | E43: XISC | F43: 458.056 | G43: =660782.29/1000 -> 660.78229 | H43: =F43-G43 -> -202.72629 | I43: ZH26FA001(11)
F44: =SUM(F41:F43) -> 1067.536 | G44: =SUM(G41:G43) -> 1061.6092

Sheet Sheet3
A1: RFQ No. | B1: Package Name | C1: PO No. | D1: TBE Issued
A2: RFQ-MA-002-1 | B2: Closed Drain Sump Vessel | D2: 46197
A3: RFQ-MA-002-2 | B3: Test Separator | D3: 46197
A4: RFQ-MA-002-3 | B4: Instrument Gas Filter Coalescer | D4: 46197
A5: RFQ-MA-003 | B5: Closed Drain Sump Pump skids | D5: 46195
A6: RFQ-MA-004 | B6: Chemical injection pump skid | D6: 46195
A7: RFQ-MA-005 | B7: Chemical storage tank | D7: 46203
A8: RFQ-MA-006 | B8: Material Handling Equipment | D8: 46212
A9: RFQ-SA-001 | B9: Fire Fighting, Safety Equipment (Including Lifesaving) | D9: 46233
A10: RFQ-SA-002 | B10: Safety Signs | D10: 46415
A11: RFQ-PIP-001 | B11: Ball Valve (Flange End) | D11: 46219
A12: RFQ-PIP-021 | B12: Ball Valve (Welded End) | D12: 46219
