Workbook

Sheet PSR
A1: PROVISION OF ENGINEERING, PROCUREMENT, CONSTRUCTION AND COMMISSIONING FOR WELLHEAD PLATFORMS, ASSOCIATED PIPLINES AND BROWNFIELD MODIFICATIONS FOR ZAWTIKA DEVELOPMENT PROJECT PHASE 1F
A2: Procurement Plan
K6: LA | L6: Most complexity RFQ | P6: 1 | Q6: 10 | R6: 0 | S6: 0 | T6: 10 | U6: 17 | V6: 10 | X6: 9 | Y6: 2 | Z6: 5 | AA6: 20 | AB6: 10 | AR6: 3 | AT6: 10 | AU6: 2
K7: LB | L7: High complexity RFQ | P7: 1 | Q7: 10 | R7: 0 | S7: 0 | T7: 10 | U7: 17 | V7: 10 | X7: 9 | Y7: 2 | Z7: 5 | AA7: 20 | AB7: 10 | AR7: 3 | AT7: 10 | AU7: 2
K8: LC | L8: Normal complexity RFQ | P8: 1 | Q8: 10 | R8: 0 | S8: 0 | T8: 10 | U8: 13 | V8: 10 | X8: 9 | Y8: 2 | Z8: 5 | AA8: 15 | AB8: 10 | AR8: 3 | AT8: 10 | AU8: 2
A9: Contract no: MMC25-5001 | K9: LD | L9: Low complexity RFQ | P9: 1 | Q9: 10 | R9: 0 | S9: 0 | T9: 5 | U9: 7 | V9: 10 | X9: 5 | Y9: 2 | Z9: 5 | AA9: 10 | AB9: 10 | AQ9: Update: 31-Jul-2026 | AR9: 2 | AT9: 5 | AU9: 2
A10: No. | B10: MR No. | C10: RFQ No. | D10: Package Name | E10: Tag No. | F10: Q'ty | G10: CODE | H10: DIS | I10: LLI (Y/N) | J10: CR | K10: Priority Level | L10: PO description | M10: Owner | N10: P/F/A | O10: Bidder list Approval | P10: MR Issued (IFR) | Q10: MR Approved | R10: RFQ Issued | S10: RFQ Approved | T10: Bid Closing Date | U10: TBE Issued | V10: TBE Approved | W10: LOA issued | X10: PO Issued | Y10: Vendor Acknowledgement | Z10: KOM | AA10: VDB Submission | AB10: Approval of Key VP | AC10: Main Material Arrived | AD10: PIM | AE10: Start Production | AF10: FAT | AG10: Ready for Shipment | AH10: Receipt at WORKSITE | AI10: Punch List Clearance(all punch clearance before Tag Equipment Ready for Shipping ) | AJ10: Approval of Final Documentation (To be confirmed later) | AK10: Delivery Duration (Weeks) | AL10: days | AM10: Delivery Date(1st Batch for ZWP21) | AN10: ROS Date | AO10: Float | AP10: Responder | AQ10: Remarks | AR10: 40329 | AS10: 40359 | AT10: 40390 | AU10: 40421 | AV10: 40451 | AW10: 40482 | AX10: 40512 | AY10: 40543 | AZ10: 40574 | BA10: 40602 | BB10: =TODAY() -> 46236
N11: Matrix | O11: PTTEP | P11: ENG | Q11: PTTEP | R11: TJE PRC | S11: PTTEP | T11: TJE PRC | U11: ENG | V11: PTTEP | W11: TJE PRC | X11: TJE PRC | Y11: BIDDER | Z11: TJE PRC | AA11: Vendor | AB11: ENG | AC11: Vendor | AD11: TJE QA/QC | AE11: Vendor | AF11: TJE QA/QC | AG11: Vendor | AH11: THE Worksite | AI11: TJE QA/QC | AJ11: TJE PRC | AM11: TJE PRC
N12: Holiday | O12: China | P12: Thai | Q12: Thai | R12: China | S12: Thai | T12: China | U12: Thai | V12: Thai | W12: China | X12: China | Y12: China | Z12: China | AA12: China | AB12: Thai | AR12: Thai | AT12: China | AU12: China
A13: 1 | B13: MM-ZTK-1F-GEN-MEC-MR-0001 | C13: RFQ-MA-001 | D13: Offshore Pedestal Crane | E13: CR7001 | F13: 1*4 | G13: 4-2 | H13: MA | I13: Y | J13: L2 | K13: LA | L13: Favelle Favco | M13: SH | N13: P | O13: 46133 | P13: 46133 | Q13: 46136 | R13: 46139 | S13: 46148 | T13: 46159 | U13: 46184 | V13: 46198 | X13: 46211 | Y13: 46213 | Z13: 46220 | AA13: 46248 | AB13: 46262 | AC13: 46352 | AD13: 46357 | AE13: 46360 | AF13: 46501 | AG13: 46531 | AH13: 46561 | AI13: 46564 | AJ13: 46591 | AK13: 50 | AL13: 350 | AM13: 46561 | AN13: 46567 | AO13: =AN13-AM14 -> 46217 | AP13: Sun liheng | AQ13: 2026.4.16: Issued RFQ 2026.4.28-5.1: Received Bid 2026.5.7: TC 2026.5.19: Vendor will reply TC 2026.2.26-27 Hold TC meeting | AR13: =IF(ISERROR(LOOKUP(AR$10,$O13:$AQ13,#REF!)),0,(LOOKUP(AR$10,$O13:$AQ13,#REF!))) -> 0 | AS13: =IF(ISERROR(LOOKUP(AS$10,$O13:$AQ13,#REF!)),0,(LOOKUP(AS$10,$O13:$AQ13,#REF!))) -> 0 | AT13: =IF(ISERROR(LOOKUP(AT$10,$O13:$AQ13,#REF!)),0,(LOOKUP(AT$10,$O13:$AQ13,#REF!))) -> 0 | AU13: =IF(ISERROR(LOOKUP(AU$10,$O13:$AQ13,#REF!)),0,(LOOKUP(AU$10,$O13:$AQ13,#REF!))) -> 0 | AV13: =IF(ISERROR(LOOKUP(AV$10,$O13:$AQ13,#REF!)),0,(LOOKUP(AV$10,$O13:$AQ13,#REF!))) -> 0 | AW13: =IF(ISERROR(LOOKUP(AW$10,$O13:$AQ13,#REF!)),0,(LOOKUP(AW$10,$O13:$AQ13,#REF!))) -> 0 | AX13: =IF(ISERROR(LOOKUP(AX$10,$O13:$AQ13,#REF!)),0,(LOOKUP(AX$10,$O13:$AQ13,#REF!))) -> 0 | AY13: =IF(ISERROR(LOOKUP(AY$10,$O13:$AQ13,#REF!)),0,(LOOKUP(AY$10,$O13:$AQ13,#REF!))) -> 0 | ... BB13: =IF(ISERROR(LOOKUP(BB$10,$O13:$AQ13,#REF!)),0,(LOOKUP(BB$10,$O13:$AQ13,#REF!))) -> 0 | BC13: Bidder1 | BD13: Ex-work: Pedestal-28 weeks | BE13: Crane:38 weeks
B14: MM-ZTK-1F-GEN-MEC-MR-0001 | C14: RFQ-MA-001 | D14: Offshore Pedestal Crane | G14: 4-2 | H14: MA | I14: Y | J14: L2 | K14: LA | L14: ZM169-WP1-PO-MEC-001 | M14: SH | N14: F | AA14: =WORKDAY(Z15,AA6,IF(AA12="China",'China Holidays'!$A$2:$A$84,'Thai Holidays'!$A$2:$A$65)) -> 46248 | AB14: =WORKDAY(AA14,AB6,IF(AB12="China",'China Holidays'!$A$2:$A$84,'Thai Holidays'!$A$2:$A$65)) -> 46262 | AC14: =AC13 -> 46352 | AD14: 46357 | AE14: 46360 | AF14: 46501 | AG14: =AH14-30 -> 46531 | AH14: =AM13 -> 46561 | AI14: =AM13+3 -> 46564 | AJ14: =AM13+30 -> 46591 | AM14: =X14+AL13 -> 350 | AR14: =IF(ISERROR(LOOKUP(AR$10,$O14:$AQ14,#REF!)),0,(LOOKUP(AR$10,$O14:$AQ14,#REF!))) -> 0 | AS14: =IF(ISERROR(LOOKUP(AS$10,$O14:$AQ14,#REF!)),0,(LOOKUP(AS$10,$O14:$AQ14,#REF!))) -> 0 | AT14: =IF(ISERROR(LOOKUP(AT$10,$O14:$AQ14,#REF!)),0,(LOOKUP(AT$10,$O14:$AQ14,#REF!))) -> 0 | AU14: =IF(ISERROR(LOOKUP(AU$10,$O14:$AQ14,#REF!)),0,(LOOKUP(AU$10,$O14:$AQ14,#REF!))) -> 0 | AV14: =IF(ISERROR(LOOKUP(AV$10,$O14:$AQ14,#REF!)),0,(LOOKUP(AV$10,$O14:$AQ14,#REF!))) -> 0 | AW14: =IF(ISERROR(LOOKUP(AW$10,$O14:$AQ14,#REF!)),0,(LOOKUP(AW$10,$O14:$AQ14,#REF!))) -> 0 | AX14: =IF(ISERROR(LOOKUP(AX$10,$O14:$AQ14,#REF!)),0,(LOOKUP(AX$10,$O14:$AQ14,#REF!))) -> 0 | AY14: =IF(ISERROR(LOOKUP(AY$10,$O14:$AQ14,#REF!)),0,(LOOKUP(AY$10,$O14:$AQ14,#REF!))) -> 0 | ... BB14: =IF(ISERROR(LOOKUP(BB$10,$O14:$AQ14,#REF!)),0,(LOOKUP(BB$10,$O14:$AQ14,#REF!))) -> 0 | BC14: Bidder2 | BD14: After receive dowm payment: 30 weeks FAT, CIF 39 weeks
B15: MM-ZTK-1F-GEN-MEC-MR-0001 | C15: RFQ-MA-001 | D15: Offshore Pedestal Crane | G15: 4-2 | H15: MA | I15: Y | J15: L2 | K15: LA | M15: SH | N15: A | O15: 46120 | P15: 46125 | Q15: 46135 | R15: 46136 | S15: 46136 | T15: 46143 | U15: 46192 | V15: 46201 | W15: 46216 | X15: 46220 | Y15: 46227 | Z15: 46220 | AR15: =IF(ISERROR(LOOKUP(AR$10,$O15:$AQ15,#REF!)),0,(LOOKUP(AR$10,$O15:$AQ15,#REF!))) -> 0 | AS15: =IF(ISERROR(LOOKUP(AS$10,$O15:$AQ15,#REF!)),0,(LOOKUP(AS$10,$O15:$AQ15,#REF!))) -> 0 | AT15: =IF(ISERROR(LOOKUP(AT$10,$O15:$AQ15,#REF!)),0,(LOOKUP(AT$10,$O15:$AQ15,#REF!))) -> 0 | AU15: =IF(ISERROR(LOOKUP(AU$10,$O15:$AQ15,#REF!)),0,(LOOKUP(AU$10,$O15:$AQ15,#REF!))) -> 0 | AV15: =IF(ISERROR(LOOKUP(AV$10,$O15:$AQ15,#REF!)),0,(LOOKUP(AV$10,$O15:$AQ15,#REF!))) -> 0 | AW15: =IF(ISERROR(LOOKUP(AW$10,$O15:$AQ15,#REF!)),0,(LOOKUP(AW$10,$O15:$AQ15,#REF!))) -> 0 | AX15: =IF(ISERROR(LOOKUP(AX$10,$O15:$AQ15,#REF!)),0,(LOOKUP(AX$10,$O15:$AQ15,#REF!))) -> 0 | AY15: =IF(ISERROR(LOOKUP(AY$10,$O15:$AQ15,#REF!)),0,(LOOKUP(AY$10,$O15:$AQ15,#REF!))) -> 0 | ... BB15: =IF(ISERROR(LOOKUP(BB$10,$O15:$AQ15,#REF!)),0,(LOOKUP(BB$10,$O15:$AQ15,#REF!))) -> 0 | BC15: Bidder3 | BD15: Ex-work: 42 weeks
A16: =A13+1 -> 2 | B16: MM-ZTK-1F-GEN-MEC-MR-0002 | C16: RFQ-MA-002-1 | D16: Closed Drain Sump Vessel | E16: V-5001 | F16: 1*4 | G16: 4-10 | H16: MA | I16: Y | J16: L3 | K16: LA | L16: Zhuhai Jutal | M16: SH | N16: P | O16: 46167 | P16: 46168 | Q16: 46177 | R16: 46178 | S16: 46185 | T16: 46197 | U16: 46197 | V16: 46211 | X16: 46218 | Y16: 46220 | Z16: 46227 | AA16: 46255 | AB16: 46269 | AC16: 46329 | AD16: 46331 | AE16: 46333 | AF16: 46408 | AG16: 46423 | AH16: 46433 | AI16: 46436 | AJ16: 46463 | AK16: 26 | AL16: 182 | AM16: 46433 | AN16: 46438 | AO16: =AN16-AM17 -> 46256 | AP16: HuangWei | AQ16: 2026.5.6 Issued RFQ to Zhuhai yard | AR16: =IF(ISERROR(LOOKUP(AR$10,$O16:$AQ16,#REF!)),0,(LOOKUP(AR$10,$O16:$AQ16,#REF!))) -> 0 | AS16: =IF(ISERROR(LOOKUP(AS$10,$O16:$AQ16,#REF!)),0,(LOOKUP(AS$10,$O16:$AQ16,#REF!))) -> 0 | AT16: =IF(ISERROR(LOOKUP(AT$10,$O16:$AQ16,#REF!)),0,(LOOKUP(AT$10,$O16:$AQ16,#REF!))) -> 0 | AU16: =IF(ISERROR(LOOKUP(AU$10,$O16:$AQ16,#REF!)),0,(LOOKUP(AU$10,$O16:$AQ16,#REF!))) -> 0 | AV16: =IF(ISERROR(LOOKUP(AV$10,$O16:$AQ16,#REF!)),0,(LOOKUP(AV$10,$O16:$AQ16,#REF!))) -> 0 | AW16: =IF(ISERROR(LOOKUP(AW$10,$O16:$AQ16,#REF!)),0,(LOOKUP(AW$10,$O16:$AQ16,#REF!))) -> 0 | AX16: =IF(ISERROR(LOOKUP(AX$10,$O16:$AQ16,#REF!)),0,(LOOKUP(AX$10,$O16:$AQ16,#REF!))) -> 0 | AY16: =IF(ISERROR(LOOKUP(AY$10,$O16:$AQ16,#REF!)),0,(LOOKUP(AY$10,$O16:$AQ16,#REF!))) -> 0 | ... BB16: =IF(ISERROR(LOOKUP(BB$10,$O16:$AQ16,#REF!)),0,(LOOKUP(BB$10,$O16:$AQ16,#REF!))) -> 0
B17: MM-ZTK-1F-GEN-MEC-MR-0002 | C17: RFQ-MA-002-1 | D17: Closed Drain Sump Vessel | G17: 4-10 | H17: MA | I17: Y | J17: L3 | K17: LA | L17: ZM169-WP1-PO-MEC-002 | M17: SH | N17: F | AA17: =WORKDAY(Z18,AA6,IF(AA12="China",'China Holidays'!$A$2:$A$84,'Thai Holidays'!$A$2:$A$65)) -> 46248 | AB17: =WORKDAY(AA17,AB6,IF(AB12="China",'China Holidays'!$A$2:$A$84,'Thai Holidays'!$A$2:$A$65)) -> 46262 | AC17: =AB17+60 -> 46322 | AD17: =AC17+2 -> 46324 | AE17: =AD17+2 -> 46326 | AF17: =AG17-15 -> 166 | AG17: =AH17-1 -> 181 | AH17: =AM17 -> 182 | AI17: =AM16+3 -> 46436 | AJ17: =AM16+30 -> 46463 | AM17: =X17+AL16 -> 182 | AR17: =IF(ISERROR(LOOKUP(AR$10,$O17:$AQ17,#REF!)),0,(LOOKUP(AR$10,$O17:$AQ17,#REF!))) -> 0 | AS17: =IF(ISERROR(LOOKUP(AS$10,$O17:$AQ17,#REF!)),0,(LOOKUP(AS$10,$O17:$AQ17,#REF!))) -> 0 | AT17: =IF(ISERROR(LOOKUP(AT$10,$O17:$AQ17,#REF!)),0,(LOOKUP(AT$10,$O17:$AQ17,#REF!))) -> 0 | AU17: =IF(ISERROR(LOOKUP(AU$10,$O17:$AQ17,#REF!)),0,(LOOKUP(AU$10,$O17:$AQ17,#REF!))) -> 0 | AV17: =IF(ISERROR(LOOKUP(AV$10,$O17:$AQ17,#REF!)),0,(LOOKUP(AV$10,$O17:$AQ17,#REF!))) -> 0 | AW17: =IF(ISERROR(LOOKUP(AW$10,$O17:$AQ17,#REF!)),0,(LOOKUP(AW$10,$O17:$AQ17,#REF!))) -> 0 | AX17: =IF(ISERROR(LOOKUP(AX$10,$O17:$AQ17,#REF!)),0,(LOOKUP(AX$10,$O17:$AQ17,#REF!))) -> 0 | AY17: =IF(ISERROR(LOOKUP(AY$10,$O17:$AQ17,#REF!)),0,(LOOKUP(AY$10,$O17:$AQ17,#REF!))) -> 0 | ... BB17: =IF(ISERROR(LOOKUP(BB$10,$O17:$AQ17,#REF!)),0,(LOOKUP(BB$10,$O17:$AQ17,#REF!))) -> 0
B18: MM-ZTK-1F-GEN-MEC-MR-0002 | C18: RFQ-MA-002-1 | D18: Closed Drain Sump Vessel | G18: 4-10 | H18: MA | I18: Y | J18: L3 | K18: LA | M18: SH | N18: A | P18: 46129 | Q18: 46143 | R18: 46148 | S18: =R18 -> 46148 | T18: 46183 | U18: 46200 | V18: 46211 | W18: N/A | X18: 46217 | Y18: 46218 | Z18: 46220 | AR18: =IF(ISERROR(LOOKUP(AR$10,$O18:$AQ18,#REF!)),0,(LOOKUP(AR$10,$O18:$AQ18,#REF!))) -> 0 | AS18: =IF(ISERROR(LOOKUP(AS$10,$O18:$AQ18,#REF!)),0,(LOOKUP(AS$10,$O18:$AQ18,#REF!))) -> 0 | AT18: =IF(ISERROR(LOOKUP(AT$10,$O18:$AQ18,#REF!)),0,(LOOKUP(AT$10,$O18:$AQ18,#REF!))) -> 0 | AU18: =IF(ISERROR(LOOKUP(AU$10,$O18:$AQ18,#REF!)),0,(LOOKUP(AU$10,$O18:$AQ18,#REF!))) -> 0 | AV18: =IF(ISERROR(LOOKUP(AV$10,$O18:$AQ18,#REF!)),0,(LOOKUP(AV$10,$O18:$AQ18,#REF!))) -> 0 | AW18: =IF(ISERROR(LOOKUP(AW$10,$O18:$AQ18,#REF!)),0,(LOOKUP(AW$10,$O18:$AQ18,#REF!))) -> 0 | AX18: =IF(ISERROR(LOOKUP(AX$10,$O18:$AQ18,#REF!)),0,(LOOKUP(AX$10,$O18:$AQ18,#REF!))) -> 0 | AY18: =IF(ISERROR(LOOKUP(AY$10,$O18:$AQ18,#REF!)),0,(LOOKUP(AY$10,$O18:$AQ18,#REF!))) -> 0 | ... BB18: =IF(ISERROR(LOOKUP(BB$10,$O18:$AQ18,#REF!)),0,(LOOKUP(BB$10,$O18:$AQ18,#REF!))) -> 0
A19: =A16+1 -> 3 | B19: MM-ZTK-1F-GEN-MEC-MR-0002 | C19: RFQ-MA-002-2 | D19: Test Separator | E19: V-1001 | F19: 1*4 | G19: 4-8 | H19: MA | I19: Y | J19: L2 | K19: LA | L19: Zhuhai Jutal | M19: SH | N19: P | O19: 46135 | P19: 46136 | Q19: 46147 | R19: 46148 | S19: 46155 | T19: 46197 | U19: 46197 | V19: 46211 | X19: 46218 | Y19: 46220 | Z19: 46227 | AA19: 46255 | AB19: 46269 | AC19: 46329 | AD19: 46331 | AE19: 46333 | AF19: 46429 | AG19: 46444 | AH19: 46449 | AI19: 46452 | AJ19: 46479 | AK19: 33 | AL19: 231 | AM19: 46449 | AN19: 46466 | AO19: =AN19-AM20 -> 249 | AP19: HuangWei | AQ19: 2026.5.6 Issued RFQ to Zhuhai yard | AR19: =IF(ISERROR(LOOKUP(AR$10,$O19:$AQ19,#REF!)),0,(LOOKUP(AR$10,$O19:$AQ19,#REF!))) -> 0 | AS19: =IF(ISERROR(LOOKUP(AS$10,$O19:$AQ19,#REF!)),0,(LOOKUP(AS$10,$O19:$AQ19,#REF!))) -> 0 | AT19: =IF(ISERROR(LOOKUP(AT$10,$O19:$AQ19,#REF!)),0,(LOOKUP(AT$10,$O19:$AQ19,#REF!))) -> 0 | AU19: =IF(ISERROR(LOOKUP(AU$10,$O19:$AQ19,#REF!)),0,(LOOKUP(AU$10,$O19:$AQ19,#REF!))) -> 0 | AV19: =IF(ISERROR(LOOKUP(AV$10,$O19:$AQ19,#REF!)),0,(LOOKUP(AV$10,$O19:$AQ19,#REF!))) -> 0 | AW19: =IF(ISERROR(LOOKUP(AW$10,$O19:$AQ19,#REF!)),0,(LOOKUP(AW$10,$O19:$AQ19,#REF!))) -> 0 | AX19: =IF(ISERROR(LOOKUP(AX$10,$O19:$AQ19,#REF!)),0,(LOOKUP(AX$10,$O19:$AQ19,#REF!))) -> 0 | AY19: =IF(ISERROR(LOOKUP(AY$10,$O19:$AQ19,#REF!)),0,(LOOKUP(AY$10,$O19:$AQ19,#REF!))) -> 0 | ... BB19: =IF(ISERROR(LOOKUP(BB$10,$O19:$AQ19,#REF!)),0,(LOOKUP(BB$10,$O19:$AQ19,#REF!))) -> 0
B20: MM-ZTK-1F-GEN-MEC-MR-0002 | C20: RFQ-MA-002-2 | D20: Test Separator | G20: 4-8 | H20: MA | I20: Y | J20: L2 | K20: LA | L20: ZM169-WP1-PO-MEC-002 | M20: SH | N20: F | AA20: =WORKDAY(Z21,AA6,IF(AA12="China",'China Holidays'!$A$2:$A$84,'Thai Holidays'!$A$2:$A$65)) -> 46248 | AB20: =WORKDAY(AA20,AB6,IF(AB12="China",'China Holidays'!$A$2:$A$84,'Thai Holidays'!$A$2:$A$65)) -> 46262 | AC20: =AB20+60 -> 46322 | AD20: =AC20+2 -> 46324 | AE20: =AD20+2 -> 46326 | AF20: =AG20-15 -> 46197 | AG20: =AH20-5 -> 46212 | AH20: =AM20 -> 46217 | AI20: =AM19+3 -> 46452 | AJ20: =AM19+30 -> 46479 | AM20: =X20+X21 -> 46217 | AR20: =IF(ISERROR(LOOKUP(AR$10,$O20:$AQ20,#REF!)),0,(LOOKUP(AR$10,$O20:$AQ20,#REF!))) -> 0 | AS20: =IF(ISERROR(LOOKUP(AS$10,$O20:$AQ20,#REF!)),0,(LOOKUP(AS$10,$O20:$AQ20,#REF!))) -> 0 | AT20: =IF(ISERROR(LOOKUP(AT$10,$O20:$AQ20,#REF!)),0,(LOOKUP(AT$10,$O20:$AQ20,#REF!))) -> 0 | AU20: =IF(ISERROR(LOOKUP(AU$10,$O20:$AQ20,#REF!)),0,(LOOKUP(AU$10,$O20:$AQ20,#REF!))) -> 0 | AV20: =IF(ISERROR(LOOKUP(AV$10,$O20:$AQ20,#REF!)),0,(LOOKUP(AV$10,$O20:$AQ20,#REF!))) -> 0 | AW20: =IF(ISERROR(LOOKUP(AW$10,$O20:$AQ20,#REF!)),0,(LOOKUP(AW$10,$O20:$AQ20,#REF!))) -> 0 | AX20: =IF(ISERROR(LOOKUP(AX$10,$O20:$AQ20,#REF!)),0,(LOOKUP(AX$10,$O20:$AQ20,#REF!))) -> 0 | AY20: =IF(ISERROR(LOOKUP(AY$10,$O20:$AQ20,#REF!)),0,(LOOKUP(AY$10,$O20:$AQ20,#REF!))) -> 0 | ... BB20: =IF(ISERROR(LOOKUP(BB$10,$O20:$AQ20,#REF!)),0,(LOOKUP(BB$10,$O20:$AQ20,#REF!))) -> 0
B21: MM-ZTK-1F-GEN-MEC-MR-0002 | C21: RFQ-MA-002-2 | D21: Test Separator | G21: 4-8 | H21: MA | I21: Y | J21: L2 | K21: LA | M21: SH | N21: A | P21: 46129 | Q21: 46143 | R21: 46148 | S21: =R21 -> 46148 | T21: 46183 | U21: 46200 | V21: 46211 | W21: N/A | X21: 46217 | Y21: 46218 | Z21: 46220 | AR21: =IF(ISERROR(LOOKUP(AR$10,$O21:$AQ21,#REF!)),0,(LOOKUP(AR$10,$O21:$AQ21,#REF!))) -> 0 | AS21: =IF(ISERROR(LOOKUP(AS$10,$O21:$AQ21,#REF!)),0,(LOOKUP(AS$10,$O21:$AQ21,#REF!))) -> 0 | AT21: =IF(ISERROR(LOOKUP(AT$10,$O21:$AQ21,#REF!)),0,(LOOKUP(AT$10,$O21:$AQ21,#REF!))) -> 0 | AU21: =IF(ISERROR(LOOKUP(AU$10,$O21:$AQ21,#REF!)),0,(LOOKUP(AU$10,$O21:$AQ21,#REF!))) -> 0 | AV21: =IF(ISERROR(LOOKUP(AV$10,$O21:$AQ21,#REF!)),0,(LOOKUP(AV$10,$O21:$AQ21,#REF!))) -> 0 | AW21: =IF(ISERROR(LOOKUP(AW$10,$O21:$AQ21,#REF!)),0,(LOOKUP(AW$10,$O21:$AQ21,#REF!))) -> 0 | AX21: =IF(ISERROR(LOOKUP(AX$10,$O21:$AQ21,#REF!)),0,(LOOKUP(AX$10,$O21:$AQ21,#REF!))) -> 0 | AY21: =IF(ISERROR(LOOKUP(AY$10,$O21:$AQ21,#REF!)),0,(LOOKUP(AY$10,$O21:$AQ21,#REF!))) -> 0 | ... BB21: =IF(ISERROR(LOOKUP(BB$10,$O21:$AQ21,#REF!)),0,(LOOKUP(BB$10,$O21:$AQ21,#REF!))) -> 0
A22: =A19+1 -> 4 | B22: MM-ZTK-1F-GEN-MEC-MR-0002 | C22: RFQ-MA-002-3 | D22: Instrument Gas Filter Coalescer | E22: V-3001 | F22: 1*4 | G22: 4-11 | H22: MA | I22: Y | J22: L2 | K22: LA | L22: Zhuhai Jutal | M22: SH | N22: P | O22: 46177 | P22: 46178 | Q22: 46185 | R22: 46188 | S22: 46195 | T22: 46197 | U22: 46197 | V22: 46211 | X22: 46218 | Y22: 46220 | Z22: 46227 | AA22: 46255 | AB22: 46269 | AC22: 46329 | AD22: 46331 | AE22: 46333 | AF22: 46408 | AG22: 46423 | AH22: 46438 | AI22: 46441 | AJ22: 46468 | AK22: 26 | AL22: 180 | AM22: 46438 | AN22: 46466 | AO22: =AN22-AM23 -> 249 | AP22: HuangWei | AQ22: 2026.5.6 Issued RFQ to Zhuhai yard | AR22: =IF(ISERROR(LOOKUP(AR$10,$O22:$AQ22,#REF!)),0,(LOOKUP(AR$10,$O22:$AQ22,#REF!))) -> 0 | AS22: =IF(ISERROR(LOOKUP(AS$10,$O22:$AQ22,#REF!)),0,(LOOKUP(AS$10,$O22:$AQ22,#REF!))) -> 0 | AT22: =IF(ISERROR(LOOKUP(AT$10,$O22:$AQ22,#REF!)),0,(LOOKUP(AT$10,$O22:$AQ22,#REF!))) -> 0 | AU22: =IF(ISERROR(LOOKUP(AU$10,$O22:$AQ22,#REF!)),0,(LOOKUP(AU$10,$O22:$AQ22,#REF!))) -> 0 | AV22: =IF(ISERROR(LOOKUP(AV$10,$O22:$AQ22,#REF!)),0,(LOOKUP(AV$10,$O22:$AQ22,#REF!))) -> 0 | AW22: =IF(ISERROR(LOOKUP(AW$10,$O22:$AQ22,#REF!)),0,(LOOKUP(AW$10,$O22:$AQ22,#REF!))) -> 0 | AX22: =IF(ISERROR(LOOKUP(AX$10,$O22:$AQ22,#REF!)),0,(LOOKUP(AX$10,$O22:$AQ22,#REF!))) -> 0 | AY22: =IF(ISERROR(LOOKUP(AY$10,$O22:$AQ22,#REF!)),0,(LOOKUP(AY$10,$O22:$AQ22,#REF!))) -> 0 | ... BB22: =IF(ISERROR(LOOKUP(BB$10,$O22:$AQ22,#REF!)),0,(LOOKUP(BB$10,$O22:$AQ22,#REF!))) -> 0
B23: MM-ZTK-1F-GEN-MEC-MR-0002 | C23: RFQ-MA-002-3 | D23: Instrument Gas Filter Coalescer | G23: 4-11 | H23: MA | I23: Y | J23: L2 | K23: LA | L23: ZM169-WP1-PO-MEC-002 | M23: SH | N23: F | AA23: =WORKDAY(Z24,AA6,IF(AA12="China",'China Holidays'!$A$2:$A$84,'Thai Holidays'!$A$2:$A$65)) -> 46248 | AB23: =WORKDAY(AA23,AB6,IF(AB12="China",'China Holidays'!$A$2:$A$84,'Thai Holidays'!$A$2:$A$65)) -> 46262 | AC23: =AB23+60 -> 46322 | AD23: =AC23+2 -> 46324 | AE23: =AD23+2 -> 46326 | AF23: =AG23-15 -> 46408 | AG23: 46423 | AH23: =AM22 -> 46438 | AI23: =AM22+3 -> 46441 | AJ23: =AM22+30 -> 46468 | AM23: =X23+X24 -> 46217 | AR23: =IF(ISERROR(LOOKUP(AR$10,$O23:$AQ23,#REF!)),0,(LOOKUP(AR$10,$O23:$AQ23,#REF!))) -> 0 | AS23: =IF(ISERROR(LOOKUP(AS$10,$O23:$AQ23,#REF!)),0,(LOOKUP(AS$10,$O23:$AQ23,#REF!))) -> 0 | AT23: =IF(ISERROR(LOOKUP(AT$10,$O23:$AQ23,#REF!)),0,(LOOKUP(AT$10,$O23:$AQ23,#REF!))) -> 0 | AU23: =IF(ISERROR(LOOKUP(AU$10,$O23:$AQ23,#REF!)),0,(LOOKUP(AU$10,$O23:$AQ23,#REF!))) -> 0 | AV23: =IF(ISERROR(LOOKUP(AV$10,$O23:$AQ23,#REF!)),0,(LOOKUP(AV$10,$O23:$AQ23,#REF!))) -> 0 | AW23: =IF(ISERROR(LOOKUP(AW$10,$O23:$AQ23,#REF!)),0,(LOOKUP(AW$10,$O23:$AQ23,#REF!))) -> 0 | AX23: =IF(ISERROR(LOOKUP(AX$10,$O23:$AQ23,#REF!)),0,(LOOKUP(AX$10,$O23:$AQ23,#REF!))) -> 0 | AY23: =IF(ISERROR(LOOKUP(AY$10,$O23:$AQ23,#REF!)),0,(LOOKUP(AY$10,$O23:$AQ23,#REF!))) -> 0 | ... BB23: =IF(ISERROR(LOOKUP(BB$10,$O23:$AQ23,#REF!)),0,(LOOKUP(BB$10,$O23:$AQ23,#REF!))) -> 0
B24: MM-ZTK-1F-GEN-MEC-MR-0002 | C24: RFQ-MA-002-3 | D24: Instrument Gas Filter Coalescer | G24: 4-11 | H24: MA | I24: Y | J24: L2 | K24: LA | M24: SH | N24: A | P24: 46141 | Q24: 46143 | R24: 46148 | S24: 46148 | T24: 46191 | U24: 46200 | V24: 46211 | W24: N/A | X24: 46217 | Y24: 46218 | Z24: 46220 | AR24: =IF(ISERROR(LOOKUP(AR$10,$O24:$AQ24,#REF!)),0,(LOOKUP(AR$10,$O24:$AQ24,#REF!))) -> 0 | AS24: =IF(ISERROR(LOOKUP(AS$10,$O24:$AQ24,#REF!)),0,(LOOKUP(AS$10,$O24:$AQ24,#REF!))) -> 0 | AT24: =IF(ISERROR(LOOKUP(AT$10,$O24:$AQ24,#REF!)),0,(LOOKUP(AT$10,$O24:$AQ24,#REF!))) -> 0 | AU24: =IF(ISERROR(LOOKUP(AU$10,$O24:$AQ24,#REF!)),0,(LOOKUP(AU$10,$O24:$AQ24,#REF!))) -> 0 | AV24: =IF(ISERROR(LOOKUP(AV$10,$O24:$AQ24,#REF!)),0,(LOOKUP(AV$10,$O24:$AQ24,#REF!))) -> 0 | AW24: =IF(ISERROR(LOOKUP(AW$10,$O24:$AQ24,#REF!)),0,(LOOKUP(AW$10,$O24:$AQ24,#REF!))) -> 0 | AX24: =IF(ISERROR(LOOKUP(AX$10,$O24:$AQ24,#REF!)),0,(LOOKUP(AX$10,$O24:$AQ24,#REF!))) -> 0 | AY24: =IF(ISERROR(LOOKUP(AY$10,$O24:$AQ24,#REF!)),0,(LOOKUP(AY$10,$O24:$AQ24,#REF!))) -> 0 | ... BB24: =IF(ISERROR(LOOKUP(BB$10,$O24:$AQ24,#REF!)),0,(LOOKUP(BB$10,$O24:$AQ24,#REF!))) -> 0
A25: =A22+1 -> 5 | B25: MM-ZTK-1F-GEN-MEC-MR-0003 | C25: RFQ-MA-003 | D25: Closed Drain Sump Pump skids | F25: 1*4 | G25: 4-18 | H25: MA | I25: Y | J25: L3 | K25: LA | L25: Multipahse | M25: SH | N25: P | O25: 46140 | P25: 46141 | Q25: 46150 | R25: 46153 | S25: 46160 | T25: 46168 | U25: 46195 | V25: 46209 | X25: 46220 | Y25: 46224 | Z25: 46231 | AA25: 46259 | AB25: 46273 | AC25: 46363 | AD25: 46363 | AE25: 46366 | AF25: 46401 | AG25: 46416 | AH25: 46444 | AI25: 46447 | AJ25: 46474 | AK25: 32 | AL25: 224 | AM25: 46444 | AN25: 46476 | AO25: =AN25-AM26 -> 40 | AP25: Sun liheng | AQ25: 2026.5.6 Issued RFQ bid due day:22-May | AR25: =IF(ISERROR(LOOKUP(AR$10,$O25:$AQ25,#REF!)),0,(LOOKUP(AR$10,$O25:$AQ25,#REF!))) -> 0 | AS25: =IF(ISERROR(LOOKUP(AS$10,$O25:$AQ25,#REF!)),0,(LOOKUP(AS$10,$O25:$AQ25,#REF!))) -> 0 | AT25: =IF(ISERROR(LOOKUP(AT$10,$O25:$AQ25,#REF!)),0,(LOOKUP(AT$10,$O25:$AQ25,#REF!))) -> 0 | AU25: =IF(ISERROR(LOOKUP(AU$10,$O25:$AQ25,#REF!)),0,(LOOKUP(AU$10,$O25:$AQ25,#REF!))) -> 0 | AV25: =IF(ISERROR(LOOKUP(AV$10,$O25:$AQ25,#REF!)),0,(LOOKUP(AV$10,$O25:$AQ25,#REF!))) -> 0 | AW25: =IF(ISERROR(LOOKUP(AW$10,$O25:$AQ25,#REF!)),0,(LOOKUP(AW$10,$O25:$AQ25,#REF!))) -> 0 | AX25: =IF(ISERROR(LOOKUP(AX$10,$O25:$AQ25,#REF!)),0,(LOOKUP(AX$10,$O25:$AQ25,#REF!))) -> 0 | AY25: =IF(ISERROR(LOOKUP(AY$10,$O25:$AQ25,#REF!)),0,(LOOKUP(AY$10,$O25:$AQ25,#REF!))) -> 0 | ... BB25: =IF(ISERROR(LOOKUP(BB$10,$O25:$AQ25,#REF!)),0,(LOOKUP(BB$10,$O25:$AQ25,#REF!))) -> 0 | BC25: Bidder1 | BD25: DDP: 28 weeks
B26: MM-ZTK-1F-GEN-MEC-MR-0003 | C26: RFQ-MA-003 | D26: Closed Drain Sump Pump skids | G26: 4-18 | H26: MA | I26: Y | J26: L3 | K26: LA | L26: ZM169-WP1-PO-MEC-003 | M26: SH | N26: F | X26: 46240 | Y26: =WORKDAY(X26,Y6,IF(Y12="China",'China Holidays'!$A$2:$A$84,'Thai Holidays'!$A$2:$A$65)) -> 46244 | Z26: =WORKDAY(Y26,Z6,IF(Z12="China",'China Holidays'!$A$2:$A$84,'Thai Holidays'!$A$2:$A$65)) -> 46251 | AA26: =WORKDAY(Z26,AA6,IF(AA12="China",'China Holidays'!$A$2:$A$84,'Thai Holidays'!$A$2:$A$65)) -> 46279 | AB26: =WORKDAY(AA26,AB6,IF(AB12="China",'China Holidays'!$A$2:$A$84,'Thai Holidays'!$A$2:$A$65)) -> 46293 | AC26: =AB26+90 -> 46383 | AD26: =AC26 -> 46383 | AE26: =AD26+3 -> 46386 | AF26: =AG26-15 -> 46401 | AG26: =AH26-28 -> 46416 | AH26: =AM25 -> 46444 | AI26: =AM25+3 -> 46447 | AJ26: =AM25+30 -> 46474 | AK26: 28 | AL26: =AK26*7 -> 196 | AM26: =X26+AL26 -> 46436 | AR26: =IF(ISERROR(LOOKUP(AR$10,$O26:$AQ26,#REF!)),0,(LOOKUP(AR$10,$O26:$AQ26,#REF!))) -> 0 | AS26: =IF(ISERROR(LOOKUP(AS$10,$O26:$AQ26,#REF!)),0,(LOOKUP(AS$10,$O26:$AQ26,#REF!))) -> 0 | AT26: =IF(ISERROR(LOOKUP(AT$10,$O26:$AQ26,#REF!)),0,(LOOKUP(AT$10,$O26:$AQ26,#REF!))) -> 0 | AU26: =IF(ISERROR(LOOKUP(AU$10,$O26:$AQ26,#REF!)),0,(LOOKUP(AU$10,$O26:$AQ26,#REF!))) -> 0 | AV26: =IF(ISERROR(LOOKUP(AV$10,$O26:$AQ26,#REF!)),0,(LOOKUP(AV$10,$O26:$AQ26,#REF!))) -> 0 | AW26: =IF(ISERROR(LOOKUP(AW$10,$O26:$AQ26,#REF!)),0,(LOOKUP(AW$10,$O26:$AQ26,#REF!))) -> 0 | AX26: =IF(ISERROR(LOOKUP(AX$10,$O26:$AQ26,#REF!)),0,(LOOKUP(AX$10,$O26:$AQ26,#REF!))) -> 0 | AY26: =IF(ISERROR(LOOKUP(AY$10,$O26:$AQ26,#REF!)),0,(LOOKUP(AY$10,$O26:$AQ26,#REF!))) -> 0 | ... BB26: =IF(ISERROR(LOOKUP(BB$10,$O26:$AQ26,#REF!)),0,(LOOKUP(BB$10,$O26:$AQ26,#REF!))) -> 0 | BC26: Bidder2 | BD26: DDP: 24-26 weeks
B27: MM-ZTK-1F-GEN-MEC-MR-0003 | C27: RFQ-MA-003 | D27: Closed Drain Sump Pump skids | G27: 4-18 | H27: MA | I27: Y | J27: L3 | K27: LA | M27: SH | N27: A | O27: 46133 | P27: 46130 | Q27: 46149 | R27: 46150 | S27: 46150 | T27: 46164 | U27: 46206 | V27: 46220 | AR27: =IF(ISERROR(LOOKUP(AR$10,$O27:$AQ27,#REF!)),0,(LOOKUP(AR$10,$O27:$AQ27,#REF!))) -> 0 | AS27: =IF(ISERROR(LOOKUP(AS$10,$O27:$AQ27,#REF!)),0,(LOOKUP(AS$10,$O27:$AQ27,#REF!))) -> 0 | AT27: =IF(ISERROR(LOOKUP(AT$10,$O27:$AQ27,#REF!)),0,(LOOKUP(AT$10,$O27:$AQ27,#REF!))) -> 0 | AU27: =IF(ISERROR(LOOKUP(AU$10,$O27:$AQ27,#REF!)),0,(LOOKUP(AU$10,$O27:$AQ27,#REF!))) -> 0 | AV27: =IF(ISERROR(LOOKUP(AV$10,$O27:$AQ27,#REF!)),0,(LOOKUP(AV$10,$O27:$AQ27,#REF!))) -> 0 | AW27: =IF(ISERROR(LOOKUP(AW$10,$O27:$AQ27,#REF!)),0,(LOOKUP(AW$10,$O27:$AQ27,#REF!))) -> 0 | AX27: =IF(ISERROR(LOOKUP(AX$10,$O27:$AQ27,#REF!)),0,(LOOKUP(AX$10,$O27:$AQ27,#REF!))) -> 0 | AY27: =IF(ISERROR(LOOKUP(AY$10,$O27:$AQ27,#REF!)),0,(LOOKUP(AY$10,$O27:$AQ27,#REF!))) -> 0 | ... BB27: =IF(ISERROR(LOOKUP(BB$10,$O27:$AQ27,#REF!)),0,(LOOKUP(BB$10,$O27:$AQ27,#REF!))) -> 0
A28: =A25+1 -> 6 | B28: MM-ZTK-1F-GEN-MEC-MR-0004 | C28: RFQ-MA-004 | D28: Chemical injection pump skid | F28: 1*4 | G28: 4-4 | H28: MA | I28: Y | J28: L3 | K28: LA | L28: Multipahse | M28: SH | N28: P | O28: 46140 | P28: 46141 | Q28: 46150 | R28: 46153 | S28: 46160 | T28: 46168 | U28: 46195 | V28: 46209 | X28: 46220 | Y28: 46224 | Z28: 46231 | AA28: 46259 | AB28: 46273 | AC28: 46363 | AD28: 46363 | AE28: 46366 | AF28: 46424 | AG28: 46439 | AH28: 46444 | AI28: 46447 | AJ28: 46474 | AK28: 34 | AL28: 238 | AM28: 46458 | AN28: 46464 | AO28: =AN28-AM29 -> -4 | AP28: Sun liheng | AQ28: 2026.5.6 Issued RFQ bid due day:22-May 2025.5.31-6.5 TC | AR28: =IF(ISERROR(LOOKUP(AR$10,$O28:$AQ28,#REF!)),0,(LOOKUP(AR$10,$O28:$AQ28,#REF!))) -> 0 | AS28: =IF(ISERROR(LOOKUP(AS$10,$O28:$AQ28,#REF!)),0,(LOOKUP(AS$10,$O28:$AQ28,#REF!))) -> 0 | AT28: =IF(ISERROR(LOOKUP(AT$10,$O28:$AQ28,#REF!)),0,(LOOKUP(AT$10,$O28:$AQ28,#REF!))) -> 0 | AU28: =IF(ISERROR(LOOKUP(AU$10,$O28:$AQ28,#REF!)),0,(LOOKUP(AU$10,$O28:$AQ28,#REF!))) -> 0 | AV28: =IF(ISERROR(LOOKUP(AV$10,$O28:$AQ28,#REF!)),0,(LOOKUP(AV$10,$O28:$AQ28,#REF!))) -> 0 | AW28: =IF(ISERROR(LOOKUP(AW$10,$O28:$AQ28,#REF!)),0,(LOOKUP(AW$10,$O28:$AQ28,#REF!))) -> 0 | AX28: =IF(ISERROR(LOOKUP(AX$10,$O28:$AQ28,#REF!)),0,(LOOKUP(AX$10,$O28:$AQ28,#REF!))) -> 0 | AY28: =IF(ISERROR(LOOKUP(AY$10,$O28:$AQ28,#REF!)),0,(LOOKUP(AY$10,$O28:$AQ28,#REF!))) -> 0 | ... BB28: =IF(ISERROR(LOOKUP(BB$10,$O28:$AQ28,#REF!)),0,(LOOKUP(BB$10,$O28:$AQ28,#REF!))) -> 0 | BC28: Bidder1 | BD28: Ex-work 22 weeks
B29: MM-ZTK-1F-GEN-MEC-MR-0004 | C29: RFQ-MA-004 | D29: Chemical injection pump skid | G29: 4-4 | H29: MA | I29: Y | J29: L3 | K29: LA | L29: ZM169-WP1-PO-MEC-003 | M29: SH | N29: F | V29: 46240 | W29: 46240 | X29: 46244 | Y29: =WORKDAY(X29,Y6,IF(Y12="China",'China Holidays'!$A$2:$A$84,'Thai Holidays'!$A$2:$A$65)) -> 46246 | Z29: =WORKDAY(Y29,Z6,IF(Z12="China",'China Holidays'!$A$2:$A$84,'Thai Holidays'!$A$2:$A$65)) -> 46253 | AA29: =WORKDAY(Z29,AA6,IF(AA12="China",'China Holidays'!$A$2:$A$84,'Thai Holidays'!$A$2:$A$65)) -> 46281 | AB29: =WORKDAY(AA29,AB6,IF(AB12="China",'China Holidays'!$A$2:$A$84,'Thai Holidays'!$A$2:$A$65)) -> 46295 | AC29: =AB29+90 -> 46385 | AD29: =AC29 -> 46385 | AE29: =AD29+3 -> 46388 | AF29: =AG29-15 -> 46415 | AG29: =AH29-28 -> 46430 | AH29: =AM28 -> 46458 | AI29: =AM28+3 -> 46461 | AJ29: =AM28+30 -> 46488 | AK29: 32 | AL29: =AK29*7 -> 224 | AM29: =X29+AL29 -> 46468 | AR29: =IF(ISERROR(LOOKUP(AR$10,$O29:$AQ29,#REF!)),0,(LOOKUP(AR$10,$O29:$AQ29,#REF!))) -> 0 | AS29: =IF(ISERROR(LOOKUP(AS$10,$O29:$AQ29,#REF!)),0,(LOOKUP(AS$10,$O29:$AQ29,#REF!))) -> 0 | AT29: =IF(ISERROR(LOOKUP(AT$10,$O29:$AQ29,#REF!)),0,(LOOKUP(AT$10,$O29:$AQ29,#REF!))) -> 0 | AU29: =IF(ISERROR(LOOKUP(AU$10,$O29:$AQ29,#REF!)),0,(LOOKUP(AU$10,$O29:$AQ29,#REF!))) -> 0 | AV29: =IF(ISERROR(LOOKUP(AV$10,$O29:$AQ29,#REF!)),0,(LOOKUP(AV$10,$O29:$AQ29,#REF!))) -> 0 | AW29: =IF(ISERROR(LOOKUP(AW$10,$O29:$AQ29,#REF!)),0,(LOOKUP(AW$10,$O29:$AQ29,#REF!))) -> 0 | AX29: =IF(ISERROR(LOOKUP(AX$10,$O29:$AQ29,#REF!)),0,(LOOKUP(AX$10,$O29:$AQ29,#REF!))) -> 0 | AY29: =IF(ISERROR(LOOKUP(AY$10,$O29:$AQ29,#REF!)),0,(LOOKUP(AY$10,$O29:$AQ29,#REF!))) -> 0 | ... BB29: =IF(ISERROR(LOOKUP(BB$10,$O29:$AQ29,#REF!)),0,(LOOKUP(BB$10,$O29:$AQ29,#REF!))) -> 0 | BC29: Bidder2 | BD29: Ex-work 24 weeks
B30: MM-ZTK-1F-GEN-MEC-MR-0004 | C30: RFQ-MA-004 | D30: Chemical injection pump skid | G30: 4-4 | H30: MA | I30: Y | J30: L3 | K30: LA | M30: SH | N30: A | O30: 46133 | P30: 46130 | Q30: 46149 | R30: 46150 | S30: 46150 | T30: 46164 | U30: 46202 | AR30: =IF(ISERROR(LOOKUP(AR$10,$O30:$AQ30,#REF!)),0,(LOOKUP(AR$10,$O30:$AQ30,#REF!))) -> 0 | AS30: =IF(ISERROR(LOOKUP(AS$10,$O30:$AQ30,#REF!)),0,(LOOKUP(AS$10,$O30:$AQ30,#REF!))) -> 0 | AT30: =IF(ISERROR(LOOKUP(AT$10,$O30:$AQ30,#REF!)),0,(LOOKUP(AT$10,$O30:$AQ30,#REF!))) -> 0 | AU30: =IF(ISERROR(LOOKUP(AU$10,$O30:$AQ30,#REF!)),0,(LOOKUP(AU$10,$O30:$AQ30,#REF!))) -> 0 | AV30: =IF(ISERROR(LOOKUP(AV$10,$O30:$AQ30,#REF!)),0,(LOOKUP(AV$10,$O30:$AQ30,#REF!))) -> 0 | AW30: =IF(ISERROR(LOOKUP(AW$10,$O30:$AQ30,#REF!)),0,(LOOKUP(AW$10,$O30:$AQ30,#REF!))) -> 0 | AX30: =IF(ISERROR(LOOKUP(AX$10,$O30:$AQ30,#REF!)),0,(LOOKUP(AX$10,$O30:$AQ30,#REF!))) -> 0 | AY30: =IF(ISERROR(LOOKUP(AY$10,$O30:$AQ30,#REF!)),0,(LOOKUP(AY$10,$O30:$AQ30,#REF!))) -> 0 | ... BB30: =IF(ISERROR(LOOKUP(BB$10,$O30:$AQ30,#REF!)),0,(LOOKUP(BB$10,$O30:$AQ30,#REF!))) -> 0 | BC30: Bidder3 | BD30: Ex-work 30 weeks
A31: =A28+1 -> 7 | B31: MM-ZTK-1F-GEN-MEC-MR-0005 | C31: RFQ-MA-005 | D31: Chemical storage tank | F31: 2*4 | G31: 4-39 | H31: MA | I31: Y | J31: L3 | K31: LA | L31: Zhuhai Jutal | M31: SH | N31: P | O31: 46153 | P31: 46154 | Q31: 46166 | R31: 46166 | S31: 46166 | T31: 46203 | U31: 46203 | V31: 46217 | X31: 46230 | Y31: 46232 | Z31: 46239 | AA31: 46267 | AB31: 46281 | AC31: 46311 | AD31: 46314 | AE31: 46317 | AF31: 46387 | AG31: 46397 | AH31: 46398 | AI31: 46401 | AJ31: 46428 | AK31: 24 | AL31: 168 | AM31: 46398 | AN31: 46433 | AO31: =AN31-AM32 -> 46265 | AP31: HuangWei | AQ31: 2026.5.6 Issued RFQ to Zhuhai yard | AR31: =IF(ISERROR(LOOKUP(AR$10,$O31:$AQ31,#REF!)),0,(LOOKUP(AR$10,$O31:$AQ31,#REF!))) -> 0 | AS31: =IF(ISERROR(LOOKUP(AS$10,$O31:$AQ31,#REF!)),0,(LOOKUP(AS$10,$O31:$AQ31,#REF!))) -> 0 | AT31: =IF(ISERROR(LOOKUP(AT$10,$O31:$AQ31,#REF!)),0,(LOOKUP(AT$10,$O31:$AQ31,#REF!))) -> 0 | AU31: =IF(ISERROR(LOOKUP(AU$10,$O31:$AQ31,#REF!)),0,(LOOKUP(AU$10,$O31:$AQ31,#REF!))) -> 0 | AV31: =IF(ISERROR(LOOKUP(AV$10,$O31:$AQ31,#REF!)),0,(LOOKUP(AV$10,$O31:$AQ31,#REF!))) -> 0 | AW31: =IF(ISERROR(LOOKUP(AW$10,$O31:$AQ31,#REF!)),0,(LOOKUP(AW$10,$O31:$AQ31,#REF!))) -> 0 | AX31: =IF(ISERROR(LOOKUP(AX$10,$O31:$AQ31,#REF!)),0,(LOOKUP(AX$10,$O31:$AQ31,#REF!))) -> 0 | AY31: =IF(ISERROR(LOOKUP(AY$10,$O31:$AQ31,#REF!)),0,(LOOKUP(AY$10,$O31:$AQ31,#REF!))) -> 0 | ... BB31: =IF(ISERROR(LOOKUP(BB$10,$O31:$AQ31,#REF!)),0,(LOOKUP(BB$10,$O31:$AQ31,#REF!))) -> 0
B32: MM-ZTK-1F-GEN-MEC-MR-0005 | C32: RFQ-MA-005 | D32: Chemical storage tank | G32: 4-39 | H32: MA | I32: Y | J32: L3 | K32: LA | L32: ZM169-WP1-PO-MEC-005 | M32: SH | N32: F | AA32: =WORKDAY(Z33,AA6,IF(AA12="China",'China Holidays'!$A$2:$A$84,'Thai Holidays'!$A$2:$A$65)) -> 46248 | AB32: =WORKDAY(AA32,AB6,IF(AB12="China",'China Holidays'!$A$2:$A$84,'Thai Holidays'!$A$2:$A$65)) -> 46262 | AC32: =AB32+30 -> 46292 | AD32: =AC32+3 -> 46295 | AE32: =AD32+3 -> 46298 | AF32: =AG32-10 -> 46387 | AG32: =AH32-1 -> 46397 | AH32: =AM31 -> 46398 | AI32: =AM31+3 -> 46401 | AJ32: =AM31+30 -> 46428 | AM32: =X32+AL31 -> 168 | AR32: =IF(ISERROR(LOOKUP(AR$10,$O32:$AQ32,#REF!)),0,(LOOKUP(AR$10,$O32:$AQ32,#REF!))) -> 0 | AS32: =IF(ISERROR(LOOKUP(AS$10,$O32:$AQ32,#REF!)),0,(LOOKUP(AS$10,$O32:$AQ32,#REF!))) -> 0 | AT32: =IF(ISERROR(LOOKUP(AT$10,$O32:$AQ32,#REF!)),0,(LOOKUP(AT$10,$O32:$AQ32,#REF!))) -> 0 | AU32: =IF(ISERROR(LOOKUP(AU$10,$O32:$AQ32,#REF!)),0,(LOOKUP(AU$10,$O32:$AQ32,#REF!))) -> 0 | AV32: =IF(ISERROR(LOOKUP(AV$10,$O32:$AQ32,#REF!)),0,(LOOKUP(AV$10,$O32:$AQ32,#REF!))) -> 0 | AW32: =IF(ISERROR(LOOKUP(AW$10,$O32:$AQ32,#REF!)),0,(LOOKUP(AW$10,$O32:$AQ32,#REF!))) -> 0 | AX32: =IF(ISERROR(LOOKUP(AX$10,$O32:$AQ32,#REF!)),0,(LOOKUP(AX$10,$O32:$AQ32,#REF!))) -> 0 | AY32: =IF(ISERROR(LOOKUP(AY$10,$O32:$AQ32,#REF!)),0,(LOOKUP(AY$10,$O32:$AQ32,#REF!))) -> 0 | ... BB32: =IF(ISERROR(LOOKUP(BB$10,$O32:$AQ32,#REF!)),0,(LOOKUP(BB$10,$O32:$AQ32,#REF!))) -> 0
B33: MM-ZTK-1F-GEN-MEC-MR-0005 | C33: RFQ-MA-005 | D33: Chemical storage tank | G33: 4-39 | H33: MA | I33: Y | J33: L3 | K33: LA | M33: SH | N33: A | P33: 46133 | Q33: 46150 | R33: 46150 | S33: 46150 | T33: 46181 | U33: 46204 | V33: 46211 | W33: N/A | X33: 46217 | Y33: 46218 | Z33: 46220 | AR33: =IF(ISERROR(LOOKUP(AR$10,$O33:$AQ33,#REF!)),0,(LOOKUP(AR$10,$O33:$AQ33,#REF!))) -> 0 | AS33: =IF(ISERROR(LOOKUP(AS$10,$O33:$AQ33,#REF!)),0,(LOOKUP(AS$10,$O33:$AQ33,#REF!))) -> 0 | AT33: =IF(ISERROR(LOOKUP(AT$10,$O33:$AQ33,#REF!)),0,(LOOKUP(AT$10,$O33:$AQ33,#REF!))) -> 0 | AU33: =IF(ISERROR(LOOKUP(AU$10,$O33:$AQ33,#REF!)),0,(LOOKUP(AU$10,$O33:$AQ33,#REF!))) -> 0 | AV33: =IF(ISERROR(LOOKUP(AV$10,$O33:$AQ33,#REF!)),0,(LOOKUP(AV$10,$O33:$AQ33,#REF!))) -> 0 | AW33: =IF(ISERROR(LOOKUP(AW$10,$O33:$AQ33,#REF!)),0,(LOOKUP(AW$10,$O33:$AQ33,#REF!))) -> 0 | AX33: =IF(ISERROR(LOOKUP(AX$10,$O33:$AQ33,#REF!)),0,(LOOKUP(AX$10,$O33:$AQ33,#REF!))) -> 0 | AY33: =IF(ISERROR(LOOKUP(AY$10,$O33:$AQ33,#REF!)),0,(LOOKUP(AY$10,$O33:$AQ33,#REF!))) -> 0 | ... BB33: =IF(ISERROR(LOOKUP(BB$10,$O33:$AQ33,#REF!)),0,(LOOKUP(BB$10,$O33:$AQ33,#REF!))) -> 0
A34: =A31+1 -> 8 | B34: MM-ZTK-1F-GEN-MEC-MR-0006 | C34: RFQ-MA-006 | D34: Material Handling Equipment | F34: 6*4 | G34: 4-7 | H34: MA | I34: N | J34: L4 | K34: LC | M34: SH | N34: P | O34: 46182 | P34: 46182 | Q34: 46196 | R34: 46196 | S34: 46196 | T34: 46203 | U34: 46212 | V34: 46226 | X34: 46259 | Y34: 46261 | Z34: =Y34 -> 46261 | AA34: 46275 | AB34: 46295 | AC34: 46325 | AD34: 46328 | AE34: 46331 | AF34: 46391 | AG34: 46406 | AH34: 46434 | AI34: 46437 | AJ34: 46464 | AK34: 25 | AL34: 175 | AM34: 46434 | AN34: 46469 | AO34: =AN34-AM35 -> 35 | AP34: Sun liheng | AR34: =IF(ISERROR(LOOKUP(AR$10,$O34:$AQ34,#REF!)),0,(LOOKUP(AR$10,$O34:$AQ34,#REF!))) -> 0 | AS34: =IF(ISERROR(LOOKUP(AS$10,$O34:$AQ34,#REF!)),0,(LOOKUP(AS$10,$O34:$AQ34,#REF!))) -> 0 | AT34: =IF(ISERROR(LOOKUP(AT$10,$O34:$AQ34,#REF!)),0,(LOOKUP(AT$10,$O34:$AQ34,#REF!))) -> 0 | AU34: =IF(ISERROR(LOOKUP(AU$10,$O34:$AQ34,#REF!)),0,(LOOKUP(AU$10,$O34:$AQ34,#REF!))) -> 0 | AV34: =IF(ISERROR(LOOKUP(AV$10,$O34:$AQ34,#REF!)),0,(LOOKUP(AV$10,$O34:$AQ34,#REF!))) -> 0 | AW34: =IF(ISERROR(LOOKUP(AW$10,$O34:$AQ34,#REF!)),0,(LOOKUP(AW$10,$O34:$AQ34,#REF!))) -> 0 | AX34: =IF(ISERROR(LOOKUP(AX$10,$O34:$AQ34,#REF!)),0,(LOOKUP(AX$10,$O34:$AQ34,#REF!))) -> 0 | AY34: =IF(ISERROR(LOOKUP(AY$10,$O34:$AQ34,#REF!)),0,(LOOKUP(AY$10,$O34:$AQ34,#REF!))) -> 0 | ... BB34: =IF(ISERROR(LOOKUP(BB$10,$O34:$AQ34,#REF!)),0,(LOOKUP(BB$10,$O34:$AQ34,#REF!))) -> 0 | BC34: Bidder1 | BD34: DDP : 20 weeks
B35: MM-ZTK-1F-GEN-MEC-MR-0006 | C35: RFQ-MA-006 | D35: Material Handling Equipment | F35: 4 | G35: 4-7 | H35: MA | I35: N | J35: L4 | K35: LC | M35: SH | N35: F | V35: =WORKDAY(U36,V9,IF(V12="China",'China Holidays'!$A$2:$A$84,'Thai Holidays'!$A$2:$A$65)) -> 46238 | X35: =X34 -> 46259 | Y35: =WORKDAY(X35,Y9,IF(Y12="China",'China Holidays'!$A$2:$A$84,'Thai Holidays'!$A$2:$A$65)) -> 46261 | Z35: =Z34 -> 46261 | AA35: =WORKDAY(Z35,AA9,IF(AA12="China",'China Holidays'!$A$2:$A$84,'Thai Holidays'!$A$2:$A$65)) -> 46275 | AB35: =WORKDAY(AA35,AB9,IF(AB12="China",'China Holidays'!$A$2:$A$84,'Thai Holidays'!$A$2:$A$65)) -> 46289 | AC35: =AB35+30 -> 46319 | AD35: =AC35+3 -> 46322 | AE35: =AD35+3 -> 46325 | AF35: =AG35-15 -> 46391 | AG35: =AH35-28 -> 46406 | AH35: =AM34 -> 46434 | AI35: =AM34+3 -> 46437 | AJ35: =AM34+30 -> 46464 | AM35: =X35+AL34 -> 46434 | AR35: =IF(ISERROR(LOOKUP(AR$10,$O35:$AQ35,#REF!)),0,(LOOKUP(AR$10,$O35:$AQ35,#REF!))) -> 0 | AS35: =IF(ISERROR(LOOKUP(AS$10,$O35:$AQ35,#REF!)),0,(LOOKUP(AS$10,$O35:$AQ35,#REF!))) -> 0 | AT35: =IF(ISERROR(LOOKUP(AT$10,$O35:$AQ35,#REF!)),0,(LOOKUP(AT$10,$O35:$AQ35,#REF!))) -> 0 | AU35: =IF(ISERROR(LOOKUP(AU$10,$O35:$AQ35,#REF!)),0,(LOOKUP(AU$10,$O35:$AQ35,#REF!))) -> 0 | AV35: =IF(ISERROR(LOOKUP(AV$10,$O35:$AQ35,#REF!)),0,(LOOKUP(AV$10,$O35:$AQ35,#REF!))) -> 0 | AW35: =IF(ISERROR(LOOKUP(AW$10,$O35:$AQ35,#REF!)),0,(LOOKUP(AW$10,$O35:$AQ35,#REF!))) -> 0 | AX35: =IF(ISERROR(LOOKUP(AX$10,$O35:$AQ35,#REF!)),0,(LOOKUP(AX$10,$O35:$AQ35,#REF!))) -> 0 | AY35: =IF(ISERROR(LOOKUP(AY$10,$O35:$AQ35,#REF!)),0,(LOOKUP(AY$10,$O35:$AQ35,#REF!))) -> 0 | ... BB35: =IF(ISERROR(LOOKUP(BB$10,$O35:$AQ35,#REF!)),0,(LOOKUP(BB$10,$O35:$AQ35,#REF!))) -> 0 | BC35: Bidder2 | BD35: DDP: 50 days after drawing approve
B36: MM-ZTK-1F-GEN-MEC-MR-0006 | C36: RFQ-MA-006 | D36: Material Handling Equipment | G36: 4-7 | H36: MA | I36: N | J36: L4 | K36: LC | M36: SH | N36: A | O36: 46192 | P36: 46154 | Q36: 46170 | R36: 46196 | S36: 46196 | T36: 46203 | U36: 46220 | AR36: =IF(ISERROR(LOOKUP(AR$10,$O36:$AQ36,#REF!)),0,(LOOKUP(AR$10,$O36:$AQ36,#REF!))) -> 0 | AS36: =IF(ISERROR(LOOKUP(AS$10,$O36:$AQ36,#REF!)),0,(LOOKUP(AS$10,$O36:$AQ36,#REF!))) -> 0 | AT36: =IF(ISERROR(LOOKUP(AT$10,$O36:$AQ36,#REF!)),0,(LOOKUP(AT$10,$O36:$AQ36,#REF!))) -> 0 | AU36: =IF(ISERROR(LOOKUP(AU$10,$O36:$AQ36,#REF!)),0,(LOOKUP(AU$10,$O36:$AQ36,#REF!))) -> 0 | AV36: =IF(ISERROR(LOOKUP(AV$10,$O36:$AQ36,#REF!)),0,(LOOKUP(AV$10,$O36:$AQ36,#REF!))) -> 0 | AW36: =IF(ISERROR(LOOKUP(AW$10,$O36:$AQ36,#REF!)),0,(LOOKUP(AW$10,$O36:$AQ36,#REF!))) -> 0 | AX36: =IF(ISERROR(LOOKUP(AX$10,$O36:$AQ36,#REF!)),0,(LOOKUP(AX$10,$O36:$AQ36,#REF!))) -> 0 | AY36: =IF(ISERROR(LOOKUP(AY$10,$O36:$AQ36,#REF!)),0,(LOOKUP(AY$10,$O36:$AQ36,#REF!))) -> 0 | ... BB36: =IF(ISERROR(LOOKUP(BB$10,$O36:$AQ36,#REF!)),0,(LOOKUP(BB$10,$O36:$AQ36,#REF!))) -> 0
A37: =A34+1 -> 9 | B37: MM-ZTK-1F-GEN-SAF-MR-0001 | C37: RFQ-SA-001 | D37: Fire Fighting, Safety Equipment (Including Lifesaving) | G37: 4-38 | H37: SA | I37: N | J37: L3 | K37: LD | M37: SH | N37: P | O37: 46213 | P37: 46201 | Q37: 46213 | R37: 46283 | S37: 46283 | T37: 46290 | U37: 46303 | V37: 46318 | X37: 46325 | Y37: 46329 | Z37: 46329 | AA37: 46343 | AB37: 46357 | AC37: 46417 | AD37: 46417 | AE37: 46420 | AF37: 46490 | AG37: 46505 | AH37: 46535 | AI37: 46538 | AJ37: 46565 | AK37: 30 | AL37: 210 | AM37: 46535 | AN37: 46568 | AO37: =AN37-AM38 -> 50 | AP37: Sun liheng | AR37: =IF(ISERROR(LOOKUP(AR$10,$O37:$AQ37,#REF!)),0,(LOOKUP(AR$10,$O37:$AQ37,#REF!))) -> 0 | AS37: =IF(ISERROR(LOOKUP(AS$10,$O37:$AQ37,#REF!)),0,(LOOKUP(AS$10,$O37:$AQ37,#REF!))) -> 0 | AT37: =IF(ISERROR(LOOKUP(AT$10,$O37:$AQ37,#REF!)),0,(LOOKUP(AT$10,$O37:$AQ37,#REF!))) -> 0 | AU37: =IF(ISERROR(LOOKUP(AU$10,$O37:$AQ37,#REF!)),0,(LOOKUP(AU$10,$O37:$AQ37,#REF!))) -> 0 | AV37: =IF(ISERROR(LOOKUP(AV$10,$O37:$AQ37,#REF!)),0,(LOOKUP(AV$10,$O37:$AQ37,#REF!))) -> 0 | AW37: =IF(ISERROR(LOOKUP(AW$10,$O37:$AQ37,#REF!)),0,(LOOKUP(AW$10,$O37:$AQ37,#REF!))) -> 0 | AX37: =IF(ISERROR(LOOKUP(AX$10,$O37:$AQ37,#REF!)),0,(LOOKUP(AX$10,$O37:$AQ37,#REF!))) -> 0 | AY37: =IF(ISERROR(LOOKUP(AY$10,$O37:$AQ37,#REF!)),0,(LOOKUP(AY$10,$O37:$AQ37,#REF!))) -> 0 | ... BB37: =IF(ISERROR(LOOKUP(BB$10,$O37:$AQ37,#REF!)),0,(LOOKUP(BB$10,$O37:$AQ37,#REF!))) -> 0
B38: MM-ZTK-1F-GEN-SAF-MR-0001 | C38: RFQ-SA-001 | D38: Fire Fighting, Safety Equipment (Including Lifesaving) | G38: 4-38 | H38: SA | I38: N | J38: L3 | K38: LD | M38: SH | N38: F | T38: 46248 | U38: =WORKDAY(T38,U6,IF(U12="China",'China Holidays'!$A$2:$A$84,'Thai Holidays'!$A$2:$A$65)) -> 46273 | V38: =WORKDAY(U38,V6,IF(V12="China",'China Holidays'!$A$2:$A$84,'Thai Holidays'!$A$2:$A$65)) -> 46287 | X38: =WORKDAY(V38,X6,IF(X12="China",'China Holidays'!$A$2:$A$84,'Thai Holidays'!$A$2:$A$65)) -> 46308 | Y38: =WORKDAY(X38,Y6,IF(Y12="China",'China Holidays'!$A$2:$A$84,'Thai Holidays'!$A$2:$A$65)) -> 46310 | Z38: =WORKDAY(Y38,Z6,IF(Z12="China",'China Holidays'!$A$2:$A$84,'Thai Holidays'!$A$2:$A$65)) -> 46317 | AA38: =WORKDAY(Z38,AA6,IF(AA12="China",'China Holidays'!$A$2:$A$84,'Thai Holidays'!$A$2:$A$65)) -> 46345 | AB38: =WORKDAY(AA38,AB6,IF(AB12="China",'China Holidays'!$A$2:$A$84,'Thai Holidays'!$A$2:$A$65)) -> 46359 | AC38: 46417 | AD38: 46417 | AE38: 46420 | AF38: 46490 | AG38: 46505 | AH38: 46535 | AI38: 46538 | AJ38: 46565 | AM38: =X38+AL37 -> 46518 | AR38: =IF(ISERROR(LOOKUP(AR$10,$O38:$AQ38,#REF!)),0,(LOOKUP(AR$10,$O38:$AQ38,#REF!))) -> 0 | AS38: =IF(ISERROR(LOOKUP(AS$10,$O38:$AQ38,#REF!)),0,(LOOKUP(AS$10,$O38:$AQ38,#REF!))) -> 0 | AT38: =IF(ISERROR(LOOKUP(AT$10,$O38:$AQ38,#REF!)),0,(LOOKUP(AT$10,$O38:$AQ38,#REF!))) -> 0 | AU38: =IF(ISERROR(LOOKUP(AU$10,$O38:$AQ38,#REF!)),0,(LOOKUP(AU$10,$O38:$AQ38,#REF!))) -> 0 | AV38: =IF(ISERROR(LOOKUP(AV$10,$O38:$AQ38,#REF!)),0,(LOOKUP(AV$10,$O38:$AQ38,#REF!))) -> 0 | AW38: =IF(ISERROR(LOOKUP(AW$10,$O38:$AQ38,#REF!)),0,(LOOKUP(AW$10,$O38:$AQ38,#REF!))) -> 0 | AX38: =IF(ISERROR(LOOKUP(AX$10,$O38:$AQ38,#REF!)),0,(LOOKUP(AX$10,$O38:$AQ38,#REF!))) -> 0 | AY38: =IF(ISERROR(LOOKUP(AY$10,$O38:$AQ38,#REF!)),0,(LOOKUP(AY$10,$O38:$AQ38,#REF!))) -> 0 | ... BB38: =IF(ISERROR(LOOKUP(BB$10,$O38:$AQ38,#REF!)),0,(LOOKUP(BB$10,$O38:$AQ38,#REF!))) -> 0
B39: MM-ZTK-1F-GEN-SAF-MR-0001 | C39: RFQ-SA-001 | D39: Fire Fighting, Safety Equipment (Including Lifesaving) | G39: 4-38 | H39: SA | I39: N | J39: L3 | K39: LD | M39: SH | N39: A | O39: 46230 | P39: 46183 | Q39: 46197 | R39: 46231 | S39: 46231 | AR39: =IF(ISERROR(LOOKUP(AR$10,$O39:$AQ39,#REF!)),0,(LOOKUP(AR$10,$O39:$AQ39,#REF!))) -> 0 | AS39: =IF(ISERROR(LOOKUP(AS$10,$O39:$AQ39,#REF!)),0,(LOOKUP(AS$10,$O39:$AQ39,#REF!))) -> 0 | AT39: =IF(ISERROR(LOOKUP(AT$10,$O39:$AQ39,#REF!)),0,(LOOKUP(AT$10,$O39:$AQ39,#REF!))) -> 0 | AU39: =IF(ISERROR(LOOKUP(AU$10,$O39:$AQ39,#REF!)),0,(LOOKUP(AU$10,$O39:$AQ39,#REF!))) -> 0 | AV39: =IF(ISERROR(LOOKUP(AV$10,$O39:$AQ39,#REF!)),0,(LOOKUP(AV$10,$O39:$AQ39,#REF!))) -> 0 | AW39: =IF(ISERROR(LOOKUP(AW$10,$O39:$AQ39,#REF!)),0,(LOOKUP(AW$10,$O39:$AQ39,#REF!))) -> 0 | AX39: =IF(ISERROR(LOOKUP(AX$10,$O39:$AQ39,#REF!)),0,(LOOKUP(AX$10,$O39:$AQ39,#REF!))) -> 0 | AY39: =IF(ISERROR(LOOKUP(AY$10,$O39:$AQ39,#REF!)),0,(LOOKUP(AY$10,$O39:$AQ39,#REF!))) -> 0 | ... BB39: =IF(ISERROR(LOOKUP(BB$10,$O39:$AQ39,#REF!)),0,(LOOKUP(BB$10,$O39:$AQ39,#REF!))) -> 0
A40: =A37+1 -> 10 | B40: MM-ZTK-1F-GEN-SAF-MR-0002 | C40: RFQ-SA-002 | D40: Safety Signs | G40: 4-38 | H40: SA | I40: N | J40: L3 | K40: LD | M40: ZH | N40: P | O40: =P40 -> 46381 | P40: 46381 | Q40: 46399 | R40: 46399 | S40: 46399 | T40: 46406 | U40: 46415 | V40: 46429 | X40: 46437 | Y40: 46441 | Z40: 46448 | AA40: 46462 | AB40: 46476 | AC40: 46491 | AD40: 46491 | AE40: 46493 | AF40: 46523 | AG40: 46525 | AH40: 46530 | AI40: 46533 | AJ40: 46560 | AK40: 5 | AL40: 35 | AM40: 46530 | AN40: 46568 | AO40: =AN40-AM41 -> 265 | AP40: Liu bin | AQ40: 2026.6.10 Issued RFQ to Zhuhai yard | AR40: =IF(ISERROR(LOOKUP(AR$10,$O40:$AQ40,#REF!)),0,(LOOKUP(AR$10,$O40:$AQ40,#REF!))) -> 0 | AS40: =IF(ISERROR(LOOKUP(AS$10,$O40:$AQ40,#REF!)),0,(LOOKUP(AS$10,$O40:$AQ40,#REF!))) -> 0 | AT40: =IF(ISERROR(LOOKUP(AT$10,$O40:$AQ40,#REF!)),0,(LOOKUP(AT$10,$O40:$AQ40,#REF!))) -> 0 | AU40: =IF(ISERROR(LOOKUP(AU$10,$O40:$AQ40,#REF!)),0,(LOOKUP(AU$10,$O40:$AQ40,#REF!))) -> 0 | AV40: =IF(ISERROR(LOOKUP(AV$10,$O40:$AQ40,#REF!)),0,(LOOKUP(AV$10,$O40:$AQ40,#REF!))) -> 0 | AW40: =IF(ISERROR(LOOKUP(AW$10,$O40:$AQ40,#REF!)),0,(LOOKUP(AW$10,$O40:$AQ40,#REF!))) -> 0 | AX40: =IF(ISERROR(LOOKUP(AX$10,$O40:$AQ40,#REF!)),0,(LOOKUP(AX$10,$O40:$AQ40,#REF!))) -> 0 | AY40: =IF(ISERROR(LOOKUP(AY$10,$O40:$AQ40,#REF!)),0,(LOOKUP(AY$10,$O40:$AQ40,#REF!))) -> 0 | ... BB40: =IF(ISERROR(LOOKUP(BB$10,$O40:$AQ40,#REF!)),0,(LOOKUP(BB$10,$O40:$AQ40,#REF!))) -> 0
B41: MM-ZTK-1F-GEN-SAF-MR-0002 | C41: RFQ-SA-002 | D41: Safety Signs | G41: 4-38 | H41: SA | I41: N | J41: L3 | K41: LD | M41: ZH | N41: F | T41: =WORKDAY(S42,T9,IF(T12="China",'China Holidays'!$A$2:$A$84,'Thai Holidays'!$A$2:$A$65)) -> 46237 | U41: =WORKDAY(T41,U9,IF(U12="China",'China Holidays'!$A$2:$A$84,'Thai Holidays'!$A$2:$A$65)) -> 46247 | V41: =WORKDAY(U41,V9,IF(V12="China",'China Holidays'!$A$2:$A$84,'Thai Holidays'!$A$2:$A$65)) -> 46261 | X41: =WORKDAY(V41,X9,IF(X12="China",'China Holidays'!$A$2:$A$84,'Thai Holidays'!$A$2:$A$65)) -> 46268 | Y41: =WORKDAY(X41,Y9,IF(Y12="China",'China Holidays'!$A$2:$A$84,'Thai Holidays'!$A$2:$A$65)) -> 46272 | Z41: =WORKDAY(Y41,Z9,IF(Z12="China",'China Holidays'!$A$2:$A$84,'Thai Holidays'!$A$2:$A$65)) -> 46279 | AA41: =WORKDAY(Z41,AA9,IF(AA12="China",'China Holidays'!$A$2:$A$84,'Thai Holidays'!$A$2:$A$65)) -> 46294 | AB41: =WORKDAY(AA41,AB9,IF(AB12="China",'China Holidays'!$A$2:$A$84,'Thai Holidays'!$A$2:$A$65)) -> 46309 | AC41: =AB41+15 -> 46324 | AD41: =AC41 -> 46324 | AE41: =AD41+2 -> 46326 | AF41: =AE41+30 -> 46356 | AG41: =AF41+2 -> 46358 | AH41: =AG41+5 -> 46363 | AI41: =AM40+3 -> 46533 | AJ41: =AM40+30 -> 46560 | AM41: =X41+AL40 -> 46303 | AR41: =IF(ISERROR(LOOKUP(AR$10,$O41:$AQ41,#REF!)),0,(LOOKUP(AR$10,$O41:$AQ41,#REF!))) -> 0 | AS41: =IF(ISERROR(LOOKUP(AS$10,$O41:$AQ41,#REF!)),0,(LOOKUP(AS$10,$O41:$AQ41,#REF!))) -> 0 | AT41: =IF(ISERROR(LOOKUP(AT$10,$O41:$AQ41,#REF!)),0,(LOOKUP(AT$10,$O41:$AQ41,#REF!))) -> 0 | AU41: =IF(ISERROR(LOOKUP(AU$10,$O41:$AQ41,#REF!)),0,(LOOKUP(AU$10,$O41:$AQ41,#REF!))) -> 0 | AV41: =IF(ISERROR(LOOKUP(AV$10,$O41:$AQ41,#REF!)),0,(LOOKUP(AV$10,$O41:$AQ41,#REF!))) -> 0 | AW41: =IF(ISERROR(LOOKUP(AW$10,$O41:$AQ41,#REF!)),0,(LOOKUP(AW$10,$O41:$AQ41,#REF!))) -> 0 | AX41: =IF(ISERROR(LOOKUP(AX$10,$O41:$AQ41,#REF!)),0,(LOOKUP(AX$10,$O41:$AQ41,#REF!))) -> 0 | AY41: =IF(ISERROR(LOOKUP(AY$10,$O41:$AQ41,#REF!)),0,(LOOKUP(AY$10,$O41:$AQ41,#REF!))) -> 0 | ... BB41: =IF(ISERROR(LOOKUP(BB$10,$O41:$AQ41,#REF!)),0,(LOOKUP(BB$10,$O41:$AQ41,#REF!))) -> 0
B42: MM-ZTK-1F-GEN-SAF-MR-0002 | C42: RFQ-SA-002 | D42: Safety Signs | G42: 4-38 | H42: SA | I42: N | J42: L3 | K42: LD | M42: ZH | N42: A | O42: 46217 | P42: 46174 | Q42: 46182 | R42: 46230 | S42: 46230 | AR42: =IF(ISERROR(LOOKUP(AR$10,$O42:$AQ42,#REF!)),0,(LOOKUP(AR$10,$O42:$AQ42,#REF!))) -> 0 | AS42: =IF(ISERROR(LOOKUP(AS$10,$O42:$AQ42,#REF!)),0,(LOOKUP(AS$10,$O42:$AQ42,#REF!))) -> 0 | AT42: =IF(ISERROR(LOOKUP(AT$10,$O42:$AQ42,#REF!)),0,(LOOKUP(AT$10,$O42:$AQ42,#REF!))) -> 0 | AU42: =IF(ISERROR(LOOKUP(AU$10,$O42:$AQ42,#REF!)),0,(LOOKUP(AU$10,$O42:$AQ42,#REF!))) -> 0 | AV42: =IF(ISERROR(LOOKUP(AV$10,$O42:$AQ42,#REF!)),0,(LOOKUP(AV$10,$O42:$AQ42,#REF!))) -> 0 | AW42: =IF(ISERROR(LOOKUP(AW$10,$O42:$AQ42,#REF!)),0,(LOOKUP(AW$10,$O42:$AQ42,#REF!))) -> 0 | AX42: =IF(ISERROR(LOOKUP(AX$10,$O42:$AQ42,#REF!)),0,(LOOKUP(AX$10,$O42:$AQ42,#REF!))) -> 0 | AY42: =IF(ISERROR(LOOKUP(AY$10,$O42:$AQ42,#REF!)),0,(LOOKUP(AY$10,$O42:$AQ42,#REF!))) -> 0 | ... BB42: =IF(ISERROR(LOOKUP(BB$10,$O42:$AQ42,#REF!)),0,(LOOKUP(BB$10,$O42:$AQ42,#REF!))) -> 0
A43: =A40+1 -> 11 | B43: MM-ZTK-1F-GEN-PIP-MR-0001 | C43: RFQ-PIP-001 | D43: Ball Valve (Flange End) | E43: 150#-148 | F43: 355 | G43: 4-19 | H43: PI | I43: N | J43: L3 | K43: LC | M43: SH | N43: P | O43: 46174 | P43: 46177 | Q43: 46185 | R43: 46185 | S43: 46185 | T43: 46202 | U43: 46219 | V43: 46237 | X43: 46248 | Y43: 46252 | Z43: 46259 | AA43: 46280 | AB43: 46294 | AC43: 46324 | AD43: 46327 | AE43: 46330 | AF43: 46422 | AG43: 46437 | AH43: 46444 | AI43: 46447 | AJ43: 46474 | AK43: 28 | AL43: 196 | AM43: 46444 | AN43: 46476 | AO43: =AN43-AM44 -> 32 | AP43: Lin Yazhen | AR43: =IF(ISERROR(LOOKUP(AR$10,$O43:$AQ43,#REF!)),0,(LOOKUP(AR$10,$O43:$AQ43,#REF!))) -> 0 | AS43: =IF(ISERROR(LOOKUP(AS$10,$O43:$AQ43,#REF!)),0,(LOOKUP(AS$10,$O43:$AQ43,#REF!))) -> 0 | AT43: =IF(ISERROR(LOOKUP(AT$10,$O43:$AQ43,#REF!)),0,(LOOKUP(AT$10,$O43:$AQ43,#REF!))) -> 0 | AU43: =IF(ISERROR(LOOKUP(AU$10,$O43:$AQ43,#REF!)),0,(LOOKUP(AU$10,$O43:$AQ43,#REF!))) -> 0 | AV43: =IF(ISERROR(LOOKUP(AV$10,$O43:$AQ43,#REF!)),0,(LOOKUP(AV$10,$O43:$AQ43,#REF!))) -> 0 | AW43: =IF(ISERROR(LOOKUP(AW$10,$O43:$AQ43,#REF!)),0,(LOOKUP(AW$10,$O43:$AQ43,#REF!))) -> 0 | AX43: =IF(ISERROR(LOOKUP(AX$10,$O43:$AQ43,#REF!)),0,(LOOKUP(AX$10,$O43:$AQ43,#REF!))) -> 0 | AY43: =IF(ISERROR(LOOKUP(AY$10,$O43:$AQ43,#REF!)),0,(LOOKUP(AY$10,$O43:$AQ43,#REF!))) -> 0 | ... BB43: =IF(ISERROR(LOOKUP(BB$10,$O43:$AQ43,#REF!)),0,(LOOKUP(BB$10,$O43:$AQ43,#REF!))) -> 0
...

Sheet Thai Holidays
A1: Date | B1: Holiday Name
A2: 45996 | B2: Father's Day
A3: 46001 | B3: Constitution Day
A4: 46020 | B4: New Year's Day
A5: 46021 | B5: New Year's Day
A6: 46022 | B6: New Year's Day
A7: 46023 | B7: New Year's Day
A8: 46024 | B8: New Year's Day
A9: 46065 | B9: The Buddha Day
A10: 46118 | B10: Kutkuri Dynasty Memorial Day
A11: 46125 | B11: Songkran Festival
A12: 46126 | B12: Songkran Festival
A13: 46127 | B13: Songkran Festival
... A17: 46146 | B17: The anniversary of the King's accession to the throne
A18: 46174
A19: 46176
A20: 46231
A21: 46232
A22: 46246 | B22: Mother's Day
A23: 46308 | B23: The anniversary of the death of the 9th King
A24: 46318 | B24: The anniversary of the death of the 5th King Father's Day
A25: 46363 | B25: Father's Day
A26: 46387 | B26: New Year's Day
A27: 46388 | B27: New Year's Day | C27: 佛历节日，日期为预测
A28: 46389
A29: 46439 | B29: The Buddha Day
A30: 46440
A31: 46483 | B31: Kutkuri Dynasty Memorial Day
A32: 46490 | B32: Songkran Festival
A33: 46491 | B33: Songkran Festival
A34: 46492 | B34: Songkran Festival | C34: 佛历节日，日期为预测
A35: 46508 | B35: International Workers' Day
A36: 46511 | B36: The anniversary of the King's accession to the throne
A37: 46527 | B37: Vesak Festival
A38: 46541 | B38: The Birthday Anniversary of the Queen
A39: 46611 | B39: Mother's Day | C39: 佛历节日，日期为预测
A40: 46673 | B40: The anniversary of the death of the 9th King
A41: 46683 | B41: The anniversary of the death of the 5th King Father's Day | D41: The anniversary of the death of the 5th King Father's Day
A42: 46685
A43: 46726 | B43: Father's Day
...

Sheet China Holidays
A1: Date | B1: Holiday Name
A2: 46023 | B2: New Year's Day
A3: 46024 | B3: New Year's Day
A4: 46025 | B4: New Year's Day
A5: 46068 | B5: Spring Festival
A6: 46069 | B6: Spring Festival
A7: 46070 | B7: Spring Festival
A8: 46071 | B8: Spring Festival
A9: 46072 | B9: Spring Festival
A10: 46073 | B10: Spring Festival
A11: 46074 | B11: Spring Festival
A12: 46116 | B12: Qingming Festival
A13: 46117 | B13: Qingming Festival
... A84: 47033 | B84: National Day

Sheet STR MR
A1: Document No. | B1: Document Title | E1: Rev. | F1: Document Status Code | G1: Distribution Date | H1: Approver Actual Finish | I1: Return Status Name
A2: MM-ZTK-1F-GEN-STR-MR-1021 | B2: MATERIAL REQUISITION FOR TOPSIDES HIGH STRENGTH STEEL PLATES | C2: RFQ-STR-001 | D2: Topside Primary Steel- Plate | E2: A1 | F2: IFR | G2: 20-May-2026 18:20:49 | H2: 22-May-2026 01:16:45 | I2: Approved with Comment (Proceed to Rev.C)
A3: MM-ZTK-1F-GEN-STR-MR-1011 | B3: MATERIAL REǪUISITION FOR TOPSIDES HIGH STRENGTH HOT-ROLLED STEEL SECTIONS (SHAPE | C3: RFQ-STR-002 | D3: Topside Primary Steel-Beam | E3: A1 | F3: IFR | G3: 08-May-2026 13:17:04 | H3: 15-May-2026 23:34:18 | I3: Approved with Comment (Proceed to Rev.C)
A4: MM-ZTK-1F-GEN-STR-MR-1001 | B4: MATERIAL REǪUISITION FOR TOPSIDES HIGH STRENGTH TUBULAR STEEL | C4: RFQ-STR-003 RFQ-STR-016 | D4: Topside Primary Steel- Tubular TUBULARS (SAW + SEAMLESS) | E4: A1 | F4: IFR | G4: 04-May-2026 13:07:12 | H4: 15-May-2026 23:30:40 | I4: Approved with Comment (Proceed to Rev.C)
A5: MM-ZTK-1F-GEN-STR-MR-1012 | B5: MATERIAL REQUISITION FOR TOPSIDES SECONDARY AND TERTIARY HOT-ROLLED STEEL | C5: RFQ-STR-004 RFQ-STR-005 | D5: Topside Secondary and Tertiary Steel BEAMS | E5: A1 | F5: IFR | G5: 23-May-2026 09:31:31 | H5: 25-May-2026 20:37:08 | I5: Approved with Comment (Proceed to Rev.C)
A6: MM-ZTK-1F-GEN-STR-MR-1002 | B6: MATERIAL REQUISITION FOR TOPSIDES SECONDARY AND TERTIARY TUBULAR STEEL | C6: RFQ-STR-004 RFQ-STR-005 | D6: Topside Secondary and Tertiary Steel TUBULARS (SEAMLESS) | E6: A1 | F6: IFR | G6: 23-May-2026 08:52:07 | H6: 25-May-2026 20:36:04 | I6: Approved with Comment (Proceed to Rev.C)
A7: MM-ZTK-1F-GEN-STR-MR-1022 | B7: MATERIAL REQUISITION FOR TOPSIDE LOW STRENGTH STEEL PLATE | C7: RFQ-STR-005 | D7: Topside Tertiary Steel-Plate | E7: A1 | F7: IFR | G7: 29-May-2026 19:06:31 | H7: 01-Jun-2026 09:19:45 | I7: Approved with Comment (Proceed to Rev.C)
A8: MM-ZTK-1F-ZWP20-STR-MR-2002 | B8: MATERIAL REǪUISITION FOR ZWP20 JACKET PRIMARY STEEL (PLATE) | C8: RFQ-STR-006 | D8: Jacket Primary Steel-Plate | E8: A1 | F8: IFR | G8: 06-May-2026 10:31:53 | H8: 15-May-2026 23:20:12 | I8: Approved with Comment (Proceed to Rev.C)
A9: MM-ZTK-1F-ZWP21-STR-MR-2002 | B9: MATERIAL REǪUISITION FOR ZWP21 JACKET PRIMARY STEEL (PLATE) | C9: RFQ-STR-006 | D9: Jacket Primary Steel-Plate | E9: A1 | F9: IFR | G9: 06-May-2026 10:32:08 | H9: 15-May-2026 23:33:14 | I9: Approved with Comment (Proceed to Rev.C)
A10: MM-ZTK-1F-ZWP22-STR-MR-2002 | B10: MATERIAL REǪUISITION FOR ZWP22 JACKET PRIMARY STEEL (PLATE) | C10: RFQ-STR-006 | D10: Jacket Primary Steel-Plate | E10: A1 | F10: IFR | G10: 06-May-2026 10:32:27 | H10: 15-May-2026 23:22:53 | I10: Approved with Comment (Proceed to Rev.C)
A11: MM-ZTK-1F-ZWP23-STR-MR-2002 | B11: MATERIAL REǪUISITION FOR ZWP23 JACKET PRIMARY STEEL (PLATE) | C11: RFQ-STR-006 | D11: Jacket Primary Steel-Plate | E11: A1 | F11: IFR | G11: 06-May-2026 10:32:43 | H11: 15-May-2026 23:25:28 | I11: Approved with Comment (Proceed to Rev.C)
A12: MM-ZTK-1F-ZWP20-STR-MR-2001 | B12: MATERIAL REǪUISITION FOR ZWP20 JACKET PRIMARY TUBULAR STEEL | C12: RFQ-STR-007 | D12: Jacket Primary Steel-Tubular TUBULARS - SAW PIPE | E12: A1 | F12: IFR | G12: 04-May-2026 13:11:09 | H12: 15-May-2026 22:45:39 | I12: Approved with Comment
A13: MM-ZTK-1F-ZWP21-STR-MR-2001 | B13: MATERIAL REǪUISITION FOR ZWP21 JACKET PRIMARY TUBULAR STEEL | C13: RFQ-STR-007 | D13: Jacket Primary Steel-Tubular TUBULARS - SAW PIPE | E13: A1 | F13: IFR | G13: 04-May-2026 13:11:25 | H13: 15-May-2026 23:19:31 | I13: Approved with Comment (Proceed to Rev.C)
... A15: MM-ZTK-1F-ZWP23-STR-MR-2001 | B15: MATERIAL REǪUISITION FOR ZWP23 JACKET PRIMARY TUBULAR STEEL | C15: RFQ-STR-007 | D15: Jacket Primary Steel-Tubular TUBULARS - SAW PIPE | E15: A1 | F15: IFR | G15: 04-May-2026 13:11:55 | H15: 15-May-2026 23:33:47 | I15: Approved with Comment (Proceed to Rev.C)

Sheet Primary steel-plate
A1: Plateform | B1: Drawing No. | C1: REV | D1: Drawing Name | E1: Vendor | F1: Weight (T) | G1: Ordered(T) | H1: Rest | I1: Order No. | J1: Order Date | K1: Remark
A2: ZWP21 | B2: ZM169-SE-ST-ML-004 | C2: REV. 4 | D2: Steel Plate for ZWP21 Launch Cradle and Vertical Framing Internal Ring Stiffener | E2: XISC | F2: 420.97 | G2: =225296/1000 -> 225.296 | H2: =F2-G2-G3 -> -2.14316 | I2: ZH26FA001(02) | J2: 46195
A3: ZWP21 | B3: ZM169-SE-ST-ML-004 | C3: REV. 5 | D3: Steel Plate for ZWP22 Launch Cradle and Vertical Framing Internal Ring Stiffener | E3: XISC | G3: =197817.16/1000 -> 197.81716 | I3: ZH26FA001(19) | J3: 46205
A4: ZWP21 | B4: ZM169-ZWP21-ST-ML-001 | C4: REV. 4 | D4: ZWP21 Jacket Primary, TRB Rolling Plate | E4: XISC | F4: 1877.39 | G4: =1296894.01/1000 -> 1296.894 | H4: =F4-G4-G5 -> 13.64197 | I4: ZH26FA001(03) | J4: 46195
A5: ZWP21 | B5: ZM169-ZWP21-ST-ML-001 | C5: REV. 5 | D5: ZWP21 Jacket Primary, TRB Rolling Plate | E5: XISC | G5: =566854.02/1000 -> 566.85402 | I5: ZH26FA001(16) | J5: 46204
A6: ZWP21 | B6: ZM169-ZWP21-ST-ML-002 | C6: REV. 2 | D6: ZWP21 Jacket Primary, JCOE Rolling Plate | E6: XISC | F6: 1581.53 | G6: =1049591.95/1000 -> 1049.5919 | H6: =F6-G6-G7-G8 -> -14.13334 | I6: ZH26FA001(04) | J6: 46195
A7: ZWP21 | B7: ZM169-ZWP21-ST-ML-002 | C7: REV. 3 | D7: ZWP21 Jacket Primary, JCOE Rolling Plate | E7: XISC | G7: =530026.49/1000 -> 530.02649 | I7: ZH26FA001(21) | J7: 46205
A8: ZWP21 | B8: ZM169-ZWP21-ST-ML-002 | C8: REV. 4 | D8: ZWP21 Jacket Primary, JCOE Rolling Plate | E8: XISC | G8: =16044.9/1000 -> 16.0449 | I8: ZH26FA001(40) | J8: 46230
A9: ZWP21 | B9: ZM169-ZWP21-ST-ML-007 | C9: REV. 2 | D9: ZWP21 Jacket Primary, Cone Plate | E9: XISC | F9: 65 | G9: =55551.55/1000 -> 55.55155 | H9: =F9-G9-G11 -> -27.34156 | I9: ZH26FA001(05) | J9: 46195
A10: ZWP21 | B10: ZM169-ZWP21-ST-ML-007 | C10: REV.1 | D10: ZWP21 Jacket Primary, Cone Plate | E10: XISC
A11: ZWP21 | B11: ZM169-ZWP21-ST-ML-007 | C11: REV. 3 | D11: ZWP21 Jacket Primary, Cone Plate | E11: XISC | G11: =36790.01/1000 -> 36.79001 | I11: ZH26FA001(14) | J11: 46204
A12: ZWP21 | B12: ZM169-ZWP21-ST-ML-008 | D12: ZWP21 Jacket Hydro static Ring Stiff Plates | E12: XISC | F12: 25.756 | G12: =9397.71/1000 -> 9.39771 | H12: =F12-G12-G13 -> -20.22544 | I12: ZH26FA001(10) | J12: 46195
A13: ZWP21 | B13: ZM169-ZWP21-ST-ML-008 | C13: REV.1 | D13: ZWP21 Jacket Hydro static Ring Stiff Plates | E13: XISC | G13: =36583.73/1000 -> 36.58373 | I13: ZH26FA001(20) | J13: 46205
A14: ZWP21 | B14: ZM169-ZWP21-ST-ML-009 | C14: REV.0 | D14: ZWP21 Jacket Leg Partition/Closure Plates | E14: XISC | F14: 17.117 | G14: =47355.14/1000 -> 47.35514 | H14: =F14-G14 -> -30.23814 | I14: ZH26FA001(24) | J14: 46209
A15: ZWP21 | B15: ZM169-ZWP21-ST-ML-010 | C15: REV.0 | D15: ZWP21 Jacket Piles Sleeve Plate | E15: XISC | F15: 437.539 | G15: =271819.08/1000 -> 271.81908 | H15: =F15-G15 -> 165.71992 | I15: ZH26FA001(07) | J15: 46195
F16: =SUM(F2:F15) -> 4425.302 | G16: =SUM(G2:G15) -> 4340.0217 | H16: =F16-G16 -> 85.28025
A17: ZWP23 | B17: ZM169-ZWP23-ST-ML-001 | C17: REV.0 | D17: ZWP23 Jacket Primary, TRB Rolling Plate | E17: XISC | F17: 1761 | G17: =1316780.78/1000 -> 1316.7808 | H17: =F17-G17-G18 -> -67.38582 | I17: ZH26FA001(13) | J17: 46199
A18: ZWP23 | B18: ZM169-ZWP23-ST-ML-001 | C18: REV.1 | D18: ZWP23 Jacket Primary, TRB Rolling Plate | E18: XISC | G18: =511605.04/1000 -> 511.60504 | I18: ZH26FA001(23) | J18: 46206
A19: ZWP23 | B19: ZM169-ZWP23-ST-ML-002 | C19: REV.0 | D19: ZWP23 Jacket Primary, JCOE Rolling Plate | E19: XISC | F19: 1514 | G19: =1555768.28/1000 -> 1555.7683 | H19: =F19-G19-G20 -> -57.81318 | I19: ZH26FA001(22) | J19: 46206
A20: ZWP23 | B20: ZM169-ZWP23-ST-ML-002 | C20: REV.1 | D20: ZWP23 Jacket Primary, JCOE Rolling Plate | E20: XISC | G20: =16044.9/1000 -> 16.0449 | I20: ZH26FA001(41) | J20: 46230
A21: ZWP23 | B21: ZM169-ZWP23-ST-ML-007 | C21: REV.1 | D21: ZWP23 Jacket Primary, Cone Plate | E21: XISC | F21: 65 | G21: =22701.82/1000 -> 22.70182 | H21: =F21-G21-G22 -> -27.34156 | I21: ZH26FA001(06) | J21: 46183
A22: ZWP23 | B22: ZM169-ZWP23-ST-ML-007 | C22: REV.2 | D22: ZWP23 Jacket Primary, Cone Plate | E22: XISC | G22: =69639.74/1000 -> 69.63974 | I22: ZH26FA001(15) | J22: 46204
A23: ZWP23 | B23: ZM169-ZWP23-ST-ML-008 | C23: REV.0 | D23: ZWP23 Jacket Hydro static Ring Stiff Plates | E23: XISC | G23: =49730.22/1000 -> 49.73022 | H23: =F23-G23 -> -49.73022 | I23: ZH26FA001(18) | J23: 46205
A24: ZWP23 | B24: ZM169-ZWP23-ST-ML-009 | C24: REV.0 | D24: ZWP23 Jacket Leg Partition/Closure Plates | E24: XISC | F24: 17.117 | G24: =47403.05/1000 -> 47.40305 | H24: =F24-G24 -> -30.28605 | I24: ZH26FA001(42) | J24: 46230
A25: ZWP23 | B25: ZM169-ZWP23-ST-ML-010 | C25: REV.0 | D25: ZWP23 Jacket Piles Sleeve Plate | E25: XISC | F25: 437.539 | G25: =271857.2161/1000 -> 271.85722 | H25: =F25-G25-G26 -> -116.69586 | I25: ZH26FA001(28) | J25: 46217
A26: ZWP23 | B26: ZM169-ZWP23-ST-ML-010 | C26: REV.1 | D26: ZWP23 Jacket Piles Sleeve Plate | E26: XISC | G26: =282377.64/1000 -> 282.37764 | I26: ZH26FA001(37) | J26: 46223
A27: ZWP23 | B27: ZM169-ZWP23-ST-ML-011 | C27: REV.0 | D27: ZWP23 Jacket Launch Cradle Plates+Ring Stiff Plates | E27: XISC | F27: 427.221 | G27: =274628/1000 -> 274.628 | H27: =F27-G27-G28 -> 24.51883 | I27: ZH26FA001(12) | J27: 46199
A28: ZWP23 | B28: ZM169-ZWP23-ST-ML-011 | C28: REV.1 | D28: ZWP23 Jacket Launch Cradle Plates+Ring Stiff Plates | E28: XISC | G28: =128074.17/1000 -> 128.07417 | I28: ZH26FA001(17) | J28: 46205
F29: =SUM(F17:F28) -> 4221.877 | G29: =SUM(G17:G28) -> 4546.6109 | H29: =F29-G29 -> -324.73386
A30: ZWP20 | B30: ZM169-ZWP20-ST-ML-001 | C30: Rev.0 | D30: ZWP20 Jacket Primary, TRB Rolling Plate | E30: XISC | F30: 1641 | G30: =1359541.23/1000 -> 1359.5412 | H30: =F30-G30 -> 281.45877 | I30: ZH26FA006 (34) | J30: 46223
A31: ZWP20 | B31: ZM169-ZWP20-ST-ML-002 | C31: Rev.0 | D31: ZWP20 Jacket Primary, JCOE Rolling Plate | E31: XISC | F31: 1439 | G31: =1031183.39/1000 -> 1031.1834 | H31: =F31-G31 -> 407.81661 | I31: ZH26FA006 (33) | J31: 46223
A32: ZWP20 | B32: ZM169-ZWP20-ST-ML-007 | C32: Rev.0 | D32: ZWP20 Jacket Primary, Cone Plate | E32: XISC | F32: 65 | G32: =76812.9879/1000 -> 76.812988 | H32: =F32-G32 -> -11.812988 | I32: ZH26FA006 (31) | J32: 46219
A33: ZWP20 | B33: ZM169-ZWP20-ST-ML-008 | D33: ZWP20 Jacket Hydro static Ring Stiff Plates | E33: XISC | K33: No drawing to SE
A34: ZWP20 | B34: ZM169-ZWP20-ST-ML-009 | D34: ZWP20 Jacket Leg Partition/Closure Plates | E34: XISC | F34: 17.117
A35: ZWP20 | B35: ZM169-ZWP20-ST-ML-010 | D35: ZWP20 Jacket Piles Sleeve Plate | E35: XISC | F35: 465.604
A36: ZWP20 | B36: ZM169-ZWP20-ST-ML-011 | D36: ZWP20 Jacket Launch Cradle Plates+Ring Stiff Plates | E36: XISC | F36: 393.737
A37: ZWP20 | B37: ZM169-ZWP20-ST-ML-012 | C37: Rev.0 | E37: XISC | G37: =23566.05/1000 -> 23.56605 | I37: ZH26FA006 (36) | J37: 46223
G38: =SUM(G30:G37) -> 2491.1037
A39: ZWP22 | B39: ZM169-ZWP22-ST-ML-001 | C39: Rev.0 | D39: ZWP22 Jacket Primary, TRB Rolling Plate | E39: XISC | F39: 1696 | G39: =1359541.23/1000 -> 1359.5412 | H39: =F39-G39 -> 336.45877 | I39: ZH26FA006 (27) | J39: 46216
