Workbook

Sheet PSR
A1: PROVISION OF ENGINEERING, PROCUREMENT, CONSTRUCTION AND COMMISSIONING FOR WELLHEAD PLATFORMS, ASSOCIATED PIPLINES AND BROWNFIELD MODIFICATIONS FOR ZAWTIKA DEVELOPMENT PROJECT PHASE 1F
A2: Procurement Plan
I6: LA | J6: Most complexity RFQ | S6: 1 | T6: 10 | U6: 0 | V6: 0 | W6: 10 | X6: 17 | Y6: 10 | AA6: 9 | AB6: 2 | AC6: 5 | AD6: 20 | AE6: 10 | AU6: 3 | AW6: 10 | AX6: 2
I7: LB | J7: High complexity RFQ | S7: 1 | T7: 10 | U7: 0 | V7: 0 | W7: 10 | X7: 17 | Y7: 10 | AA7: 9 | AB7: 2 | AC7: 5 | AD7: 20 | AE7: 10 | AU7: 3 | AW7: 10 | AX7: 2
I8: LC | J8: Normal complexity RFQ | S8: 1 | T8: 10 | U8: 0 | V8: 0 | W8: 10 | X8: 13 | Y8: 10 | AA8: 9 | AB8: 2 | AC8: 5 | AD8: 15 | AE8: 10 | AU8: 3 | AW8: 10 | AX8: 2
A9: Contract no: MMC25-5001 | I9: LD | J9: Low complexity RFQ | S9: 1 | T9: 10 | U9: 0 | V9: 0 | W9: 5 | X9: 7 | Y9: 10 | AA9: 5 | AB9: 2 | AC9: 5 | AD9: 10 | AE9: 10 | AT9: Update:18-Sep-2026 | AU9: 2 | AW9: 5 | AX9: 2
A10: No. | B10: MR No. | C10: RFQ No. | D10: Package Name | E10: CODE | F10: DIS | G10: LLI (Y/N) | H10: CR | I10: Priority Level | J10: PO description | K10: Bidders | L10: TC | M10: TBE | N10: Price bid | O10: Price Negotiation | P10: Owner | Q10: P/F/A | R10: Bidder list Approval | S10: MR Issued (IFR) | T10: MR Approved | U10: RFQ Issued | V10: RFQ Approved | W10: Bid Closing Date | X10: TBE Issued | Y10: TBE Approved | Z10: LOA issued | AA10: PO Issued | AB10: Vendor Acknowledgement | AC10: KOM | AD10: VDB Submission | AE10: Approval of Key VP | AF10: Main Material Arrived | AG10: PIM | AH10: Start Production | AI10: FAT | AJ10: Ready for Shipment | AK10: Receipt at WORKSITE | AL10: Punch List Clearance(all punch clearance before Tag Equipment Ready for Shipping ) | AM10: Approval of Final Documentation (To be confirmed later) | AN10: Delivery Duration (Weeks) | AO10: days | AP10: Delivery Date(1st Batch for ZWP21) | AQ10: ROS Date | AR10: Float | AS10: Responder | AT10: Remarks | AU10: 40329 | AV10: 40359 | AW10: 40390 | AX10: 40421 | AY10: 40451 | AZ10: 40482 | BA10: 40512 | BB10: 40543 | BC10: 40574 | BD10: 40602 | BE10: =TODAY() -> 46287 | BF10: Palteform | BG10: PO Delivery date | BH10: Puchase Qty
Q11: Matrix | R11: PTTEP | S11: ENG | T11: PTTEP | U11: TJE PRC | V11: PTTEP | W11: TJE PRC | X11: ENG | Y11: PTTEP | Z11: TJE PRC | AA11: TJE PRC | AB11: BIDDER | AC11: TJE PRC | AD11: Vendor | AE11: ENG | AF11: Vendor | AG11: TJE QA/QC | AH11: Vendor | AI11: TJE QA/QC | AJ11: Vendor | AK11: THE Worksite | AL11: TJE QA/QC | AM11: TJE PRC | AP11: TJE PRC
Q12: Holiday | R12: China | S12: Thai | T12: Thai | U12: China | V12: Thai | W12: China | X12: Thai | Y12: Thai | Z12: China | AA12: China | AB12: China | AC12: China | AD12: China | AE12: Thai | AU12: Thai | AW12: China | AX12: China
A13: 1 | B13: MM-ZTK-1F-GEN-MEC-MR-0001 | C13: RFQ-MA-001 | D13: Offshore Pedestal Crane | E13: 4-2 | F13: MA | G13: Y | H13: L2 | I13: LA | J13: Favelle Favco | K13: Oil State | L13: Oil State | M13: Oil State | N13: Oil State | O13: Oil State | P13: SH | Q13: P | R13: 46133 | S13: 46133 | T13: 46136 | U13: 46139 | V13: 46148 | W13: 46159 | X13: 46184 | Y13: 46198 | AA13: 46211 | AB13: 46213 | AC13: 46220 | AD13: 46248 | AE13: 46262 | AF13: 46352 | AG13: 46357 | AH13: 46360 | AI13: 46501 | AJ13: 46531 | AK13: 46561 | AL13: 46564 | AM13: 46591 | AN13: 50 | AO13: 350 | AP13: 46561 | AS13: Chris | AT13: 2026.4.16: Issued RFQ 2026.4.28-5.1: Received Bid 2026.5.7: TC 2026.5.19: Vendor will reply TC 2026.2.26-27 Hold TC meeting (ZWP21)1st Unit of Pedestal Adaptor = 42 Weeks after LOA (3-May-2027) (ZWP21)1st Unit of 100RL = 46 Weeks after LOA (31-May-2027) (ZWP23)2nd Unit of Pedestal Adaptor = 45 Weeks after LOA (24-May-2027) (ZWP23)2nd Unit of 100RL = 49 Weeks after LOA (21-Jun-2027) (ZWP22)3rd Unit of Pedestal Adaptor = 48 Weeks after LOA (14-Jun-2027) (ZWP22)3rd Unit of 100RL = 52 Weeks after LOA (12-Jul-2027) (ZWP20)4th Unit of Pedestal Adaptor = 51 Weeks after LOA (5-Jul-2027) (ZWP20)4th Unit of 100RL = 55 Weeks after LOA (2-Aug-2027) 2026.8.9 Expedite drawings by e-mail 2026.9.10: GA drawing submitted to CPY to review | AU13: =IF(ISERROR(LOOKUP(AU$10,$R13:$AT13,#REF!)),0,(LOOKUP(AU$10,$R13:$AT13,#REF!))) -> 0 | AV13: =IF(ISERROR(LOOKUP(AV$10,$R13:$AT13,#REF!)),0,(LOOKUP(AV$10,$R13:$AT13,#REF!))) -> 0 | AW13: =IF(ISERROR(LOOKUP(AW$10,$R13:$AT13,#REF!)),0,(LOOKUP(AW$10,$R13:$AT13,#REF!))) -> 0 | AX13: =IF(ISERROR(LOOKUP(AX$10,$R13:$AT13,#REF!)),0,(LOOKUP(AX$10,$R13:$AT13,#REF!))) -> 0 | AY13: =IF(ISERROR(LOOKUP(AY$10,$R13:$AT13,#REF!)),0,(LOOKUP(AY$10,$R13:$AT13,#REF!))) -> 0 | AZ13: =IF(ISERROR(LOOKUP(AZ$10,$R13:$AT13,#REF!)),0,(LOOKUP(AZ$10,$R13:$AT13,#REF!))) -> 0 | BA13: =IF(ISERROR(LOOKUP(BA$10,$R13:$AT13,#REF!)),0,(LOOKUP(BA$10,$R13:$AT13,#REF!))) -> 0 | BB13: =IF(ISERROR(LOOKUP(BB$10,$R13:$AT13,#REF!)),0,(LOOKUP(BB$10,$R13:$AT13,#REF!))) -> 0 | ... BE13: =IF(ISERROR(LOOKUP(BE$10,$R13:$AT13,#REF!)),0,(LOOKUP(BE$10,$R13:$AT13,#REF!))) -> 0
B14: MM-ZTK-1F-GEN-MEC-MR-0001 | C14: RFQ-MA-001 | D14: Offshore Pedestal Crane | E14: 4-2 | F14: MA | G14: Y | H14: L2 | I14: LA | J14: ZM169-WP1-PO-MEC-001 | K14: TOS (PVL) | L14: TOS | M14: TOS | N14: TOS | O14: TOS | P14: SH | Q14: F | AE14: 46289 | AF14: 46301 | AG14: 46301 | AH14: 46360 | AI14: 46501 | AJ14: =AK14-14 -> 46538 | AK14: =AP14+7 -> 46552 | AL14: =AP13+3 -> 46564 | AM14: =AP13+30 -> 46591 | AN14: 46 | AO14: =AN14*7 -> 322 | AP14: =BG14+7 -> 46545 | AQ14: 46560 | AR14: =AQ14-AP14 -> 15 | AS14: CIF Zhuhai Port | AU14: =IF(ISERROR(LOOKUP(AU$10,$R14:$AT14,#REF!)),0,(LOOKUP(AU$10,$R14:$AT14,#REF!))) -> 0 | AV14: =IF(ISERROR(LOOKUP(AV$10,$R14:$AT14,#REF!)),0,(LOOKUP(AV$10,$R14:$AT14,#REF!))) -> 0 | AW14: =IF(ISERROR(LOOKUP(AW$10,$R14:$AT14,#REF!)),0,(LOOKUP(AW$10,$R14:$AT14,#REF!))) -> 0 | AX14: =IF(ISERROR(LOOKUP(AX$10,$R14:$AT14,#REF!)),0,(LOOKUP(AX$10,$R14:$AT14,#REF!))) -> 0 | AY14: =IF(ISERROR(LOOKUP(AY$10,$R14:$AT14,#REF!)),0,(LOOKUP(AY$10,$R14:$AT14,#REF!))) -> 0 | AZ14: =IF(ISERROR(LOOKUP(AZ$10,$R14:$AT14,#REF!)),0,(LOOKUP(AZ$10,$R14:$AT14,#REF!))) -> 0 | BA14: =IF(ISERROR(LOOKUP(BA$10,$R14:$AT14,#REF!)),0,(LOOKUP(BA$10,$R14:$AT14,#REF!))) -> 0 | BB14: =IF(ISERROR(LOOKUP(BB$10,$R14:$AT14,#REF!)),0,(LOOKUP(BB$10,$R14:$AT14,#REF!))) -> 0 | ... BE14: =IF(ISERROR(LOOKUP(BE$10,$R14:$AT14,#REF!)),0,(LOOKUP(BE$10,$R14:$AT14,#REF!))) -> 0 | BF14: ZWP21 | BG14: 46538
B15: MM-ZTK-1F-GEN-MEC-MR-0001 | C15: RFQ-MA-001 | D15: Offshore Pedestal Crane | F15: MA | G15: Y | H15: L2 | I15: LA | K15: Favelle Favco | L15: Favelle Favco | M15: Favelle Favco | N15: Favelle Favco | O15: Favelle Favco | P15: SH | Q15: F | AN15: 49 | AO15: =AN15*7 -> 343 | AP15: =BG15+7 -> 46566 | AQ15: 46569 | AR15: =AQ15-AP15 -> 3 | AS15: CIF Zhuhai Port | BF15: ZWP23 | BG15: 46559
B16: MM-ZTK-1F-GEN-MEC-MR-0001 | C16: RFQ-MA-001 | D16: Offshore Pedestal Crane | F16: MA | G16: Y | H16: L2 | I16: LA | K16: Huanan | P16: SH | Q16: F | AN16: 52 | AO16: =AN16*7 -> 364 | AP16: =BG16+7 -> 46587 | AQ16: 46609 | AR16: =AQ16-AP16 -> 22 | AS16: CIF Zhuhai Port | BF16: ZWP22 | BG16: 46580
B17: MM-ZTK-1F-GEN-MEC-MR-0001 | C17: RFQ-MA-001 | D17: Offshore Pedestal Crane | F17: MA | G17: Y | H17: L2 | I17: LA | P17: SH | Q17: F | AN17: 55 | AO17: =AN17*7 -> 385 | AP17: =BG17+7 -> 46608 | AQ17: 46625 | AR17: =AQ17-AP17 -> 17 | AS17: CIF Zhuhai Port | BF17: ZWP20 | BG17: 46601
B18: MM-ZTK-1F-GEN-MEC-MR-0001 | C18: RFQ-MA-001 | D18: Offshore Pedestal Crane | E18: 4-2 | F18: MA | G18: Y | H18: L2 | I18: LA | P18: SH | Q18: A | R18: 46120 | S18: 46125 | T18: 46135 | U18: 46136 | V18: 46136 | W18: 46143 | X18: 46192 | Y18: 46216 | Z18: 46216 | AA18: 46220 | AB18: 46227 | AC18: 46220 | AD18: 46248 | AP18: CD+7 | AU18: =IF(ISERROR(LOOKUP(AU$10,$R18:$AT18,#REF!)),0,(LOOKUP(AU$10,$R18:$AT18,#REF!))) -> 0 | AV18: =IF(ISERROR(LOOKUP(AV$10,$R18:$AT18,#REF!)),0,(LOOKUP(AV$10,$R18:$AT18,#REF!))) -> 0 | AW18: =IF(ISERROR(LOOKUP(AW$10,$R18:$AT18,#REF!)),0,(LOOKUP(AW$10,$R18:$AT18,#REF!))) -> 0 | AX18: =IF(ISERROR(LOOKUP(AX$10,$R18:$AT18,#REF!)),0,(LOOKUP(AX$10,$R18:$AT18,#REF!))) -> 0 | AY18: =IF(ISERROR(LOOKUP(AY$10,$R18:$AT18,#REF!)),0,(LOOKUP(AY$10,$R18:$AT18,#REF!))) -> 0 | AZ18: =IF(ISERROR(LOOKUP(AZ$10,$R18:$AT18,#REF!)),0,(LOOKUP(AZ$10,$R18:$AT18,#REF!))) -> 0 | BA18: =IF(ISERROR(LOOKUP(BA$10,$R18:$AT18,#REF!)),0,(LOOKUP(BA$10,$R18:$AT18,#REF!))) -> 0 | BB18: =IF(ISERROR(LOOKUP(BB$10,$R18:$AT18,#REF!)),0,(LOOKUP(BB$10,$R18:$AT18,#REF!))) -> 0 | ... BE18: =IF(ISERROR(LOOKUP(BE$10,$R18:$AT18,#REF!)),0,(LOOKUP(BE$10,$R18:$AT18,#REF!))) -> 0
A19: =A13+1 -> 2 | B19: MM-ZTK-1F-GEN-MEC-MR-0002 | C19: RFQ-MA-002-1 | D19: Closed Drain Sump Vessel | E19: 4-10 | F19: MA | G19: Y | H19: L3 | I19: LA | J19: Zhuhai Jutal | K19: Zhuhai Jutal | P19: SH | Q19: P | R19: 46167 | S19: 46168 | T19: 46177 | U19: 46178 | V19: 46185 | W19: 46197 | X19: 46197 | Y19: 46211 | AA19: 46218 | AB19: 46220 | AC19: 46227 | AD19: 46255 | AE19: 46269 | AF19: 46329 | AG19: 46331 | AH19: 46333 | AI19: 46408 | AJ19: 46423 | AK19: 46433 | AL19: 46436 | AM19: 46463 | AN19: 26 | AO19: 182 | AP19: 46433 | AQ19: 46448 | AR19: =AQ19-AP20 -> 15 | AS19: HuangWei | AT19: 2026.5.6 Issued RFQ to Zhuhai yard | AU19: =IF(ISERROR(LOOKUP(AU$10,$R19:$AT19,#REF!)),0,(LOOKUP(AU$10,$R19:$AT19,#REF!))) -> 0 | AV19: =IF(ISERROR(LOOKUP(AV$10,$R19:$AT19,#REF!)),0,(LOOKUP(AV$10,$R19:$AT19,#REF!))) -> 0 | AW19: =IF(ISERROR(LOOKUP(AW$10,$R19:$AT19,#REF!)),0,(LOOKUP(AW$10,$R19:$AT19,#REF!))) -> 0 | AX19: =IF(ISERROR(LOOKUP(AX$10,$R19:$AT19,#REF!)),0,(LOOKUP(AX$10,$R19:$AT19,#REF!))) -> 0 | AY19: =IF(ISERROR(LOOKUP(AY$10,$R19:$AT19,#REF!)),0,(LOOKUP(AY$10,$R19:$AT19,#REF!))) -> 0 | AZ19: =IF(ISERROR(LOOKUP(AZ$10,$R19:$AT19,#REF!)),0,(LOOKUP(AZ$10,$R19:$AT19,#REF!))) -> 0 | BA19: =IF(ISERROR(LOOKUP(BA$10,$R19:$AT19,#REF!)),0,(LOOKUP(BA$10,$R19:$AT19,#REF!))) -> 0 | BB19: =IF(ISERROR(LOOKUP(BB$10,$R19:$AT19,#REF!)),0,(LOOKUP(BB$10,$R19:$AT19,#REF!))) -> 0 | ... BE19: =IF(ISERROR(LOOKUP(BE$10,$R19:$AT19,#REF!)),0,(LOOKUP(BE$10,$R19:$AT19,#REF!))) -> 0 | BI19: Plate:45-60days
B20: MM-ZTK-1F-GEN-MEC-MR-0002 | C20: RFQ-MA-002-1 | D20: Closed Drain Sump Vessel | E20: 4-10 | F20: MA | G20: Y | H20: L3 | I20: LA | J20: ZM169-WP1-PO-MEC-002 | P20: SH | Q20: F | AE20: 46289 | AF20: =AE20+60 -> 46349 | AG20: =AF20+2 -> 46351 | AH20: =AG20+2 -> 46353 | AI20: =AJ20-15 -> 46417 | AJ20: =AK20-1 -> 46432 | AK20: =AP20 -> 46433 | AL20: =AP19+3 -> 46436 | AM20: =AP19+30 -> 46463 | AP20: =AP19 -> 46433 | AS20: DDP Yard | AU20: =IF(ISERROR(LOOKUP(AU$10,$R20:$AT20,#REF!)),0,(LOOKUP(AU$10,$R20:$AT20,#REF!))) -> 0 | AV20: =IF(ISERROR(LOOKUP(AV$10,$R20:$AT20,#REF!)),0,(LOOKUP(AV$10,$R20:$AT20,#REF!))) -> 0 | AW20: =IF(ISERROR(LOOKUP(AW$10,$R20:$AT20,#REF!)),0,(LOOKUP(AW$10,$R20:$AT20,#REF!))) -> 0 | AX20: =IF(ISERROR(LOOKUP(AX$10,$R20:$AT20,#REF!)),0,(LOOKUP(AX$10,$R20:$AT20,#REF!))) -> 0 | AY20: =IF(ISERROR(LOOKUP(AY$10,$R20:$AT20,#REF!)),0,(LOOKUP(AY$10,$R20:$AT20,#REF!))) -> 0 | AZ20: =IF(ISERROR(LOOKUP(AZ$10,$R20:$AT20,#REF!)),0,(LOOKUP(AZ$10,$R20:$AT20,#REF!))) -> 0 | BA20: =IF(ISERROR(LOOKUP(BA$10,$R20:$AT20,#REF!)),0,(LOOKUP(BA$10,$R20:$AT20,#REF!))) -> 0 | BB20: =IF(ISERROR(LOOKUP(BB$10,$R20:$AT20,#REF!)),0,(LOOKUP(BB$10,$R20:$AT20,#REF!))) -> 0 | ... BE20: =IF(ISERROR(LOOKUP(BE$10,$R20:$AT20,#REF!)),0,(LOOKUP(BE$10,$R20:$AT20,#REF!))) -> 0 | BG20: 46433 | BI20: 3.2 certificate: 15days
B21: MM-ZTK-1F-GEN-MEC-MR-0002 | C21: RFQ-MA-002-1 | D21: Closed Drain Sump Vessel | E21: 4-10 | F21: MA | G21: Y | H21: L3 | I21: LA | P21: SH | Q21: A | S21: 46129 | T21: 46143 | U21: 46148 | V21: =U21 -> 46148 | W21: 46183 | X21: 46200 | Y21: 46211 | Z21: N/A | AA21: 46217 | AB21: 46218 | AC21: 46220 | AD21: 46244 | AU21: =IF(ISERROR(LOOKUP(AU$10,$R21:$AT21,#REF!)),0,(LOOKUP(AU$10,$R21:$AT21,#REF!))) -> 0 | AV21: =IF(ISERROR(LOOKUP(AV$10,$R21:$AT21,#REF!)),0,(LOOKUP(AV$10,$R21:$AT21,#REF!))) -> 0 | AW21: =IF(ISERROR(LOOKUP(AW$10,$R21:$AT21,#REF!)),0,(LOOKUP(AW$10,$R21:$AT21,#REF!))) -> 0 | AX21: =IF(ISERROR(LOOKUP(AX$10,$R21:$AT21,#REF!)),0,(LOOKUP(AX$10,$R21:$AT21,#REF!))) -> 0 | AY21: =IF(ISERROR(LOOKUP(AY$10,$R21:$AT21,#REF!)),0,(LOOKUP(AY$10,$R21:$AT21,#REF!))) -> 0 | AZ21: =IF(ISERROR(LOOKUP(AZ$10,$R21:$AT21,#REF!)),0,(LOOKUP(AZ$10,$R21:$AT21,#REF!))) -> 0 | BA21: =IF(ISERROR(LOOKUP(BA$10,$R21:$AT21,#REF!)),0,(LOOKUP(BA$10,$R21:$AT21,#REF!))) -> 0 | BB21: =IF(ISERROR(LOOKUP(BB$10,$R21:$AT21,#REF!)),0,(LOOKUP(BB$10,$R21:$AT21,#REF!))) -> 0 | ... BE21: =IF(ISERROR(LOOKUP(BE$10,$R21:$AT21,#REF!)),0,(LOOKUP(BE$10,$R21:$AT21,#REF!))) -> 0
A22: =A19+1 -> 3 | B22: MM-ZTK-1F-GEN-MEC-MR-0002 | C22: RFQ-MA-002-2 | D22: Test Separator | E22: 4-8 | F22: MA | G22: Y | H22: L2 | I22: LA | J22: Zhuhai Jutal | K22: Zhuhai Jutal | P22: SH | Q22: P | R22: 46135 | S22: 46136 | T22: 46147 | U22: 46148 | V22: 46155 | W22: 46197 | X22: 46197 | Y22: 46211 | AA22: 46218 | AB22: 46220 | AC22: 46227 | AD22: 46255 | AE22: 46269 | AF22: 46329 | AG22: 46331 | AH22: 46333 | AI22: 46429 | AJ22: 46444 | AK22: 46449 | AL22: 46452 | AM22: 46479 | AN22: 33 | AO22: 231 | AP22: 46449 | AQ22: 46489 | AR22: =AQ22-AP23 -> 14 | AS22: HuangWei | AT22: 2026.5.6 Issued RFQ to Zhuhai yard 2026.8.24 GA drawing and CAL report are submitted to D2 2026.9.8 GA drawing and CAL report are approved | AU22: =IF(ISERROR(LOOKUP(AU$10,$R22:$AT22,#REF!)),0,(LOOKUP(AU$10,$R22:$AT22,#REF!))) -> 0 | AV22: =IF(ISERROR(LOOKUP(AV$10,$R22:$AT22,#REF!)),0,(LOOKUP(AV$10,$R22:$AT22,#REF!))) -> 0 | AW22: =IF(ISERROR(LOOKUP(AW$10,$R22:$AT22,#REF!)),0,(LOOKUP(AW$10,$R22:$AT22,#REF!))) -> 0 | AX22: =IF(ISERROR(LOOKUP(AX$10,$R22:$AT22,#REF!)),0,(LOOKUP(AX$10,$R22:$AT22,#REF!))) -> 0 | AY22: =IF(ISERROR(LOOKUP(AY$10,$R22:$AT22,#REF!)),0,(LOOKUP(AY$10,$R22:$AT22,#REF!))) -> 0 | AZ22: =IF(ISERROR(LOOKUP(AZ$10,$R22:$AT22,#REF!)),0,(LOOKUP(AZ$10,$R22:$AT22,#REF!))) -> 0 | BA22: =IF(ISERROR(LOOKUP(BA$10,$R22:$AT22,#REF!)),0,(LOOKUP(BA$10,$R22:$AT22,#REF!))) -> 0 | BB22: =IF(ISERROR(LOOKUP(BB$10,$R22:$AT22,#REF!)),0,(LOOKUP(BB$10,$R22:$AT22,#REF!))) -> 0 | ... BE22: =IF(ISERROR(LOOKUP(BE$10,$R22:$AT22,#REF!)),0,(LOOKUP(BE$10,$R22:$AT22,#REF!))) -> 0
B23: MM-ZTK-1F-GEN-MEC-MR-0002 | C23: RFQ-MA-002-2 | D23: Test Separator | E23: 4-8 | F23: MA | G23: Y | H23: L2 | I23: LA | J23: ZM169-WP1-PO-MEC-002 | P23: SH | Q23: F | AE23: 46289 | AF23: =AE23+60 -> 46349 | AG23: =AF23+2 -> 46351 | AH23: =AG23+2 -> 46353 | AI23: =AJ23-15 -> 46460 | AJ23: =AK23 -> 46475 | AK23: =AP23 -> 46475 | AL23: =AP22+3 -> 46452 | AM23: =AP22+30 -> 46479 | AP23: 46475 | AS23: DDP Yard | AU23: =IF(ISERROR(LOOKUP(AU$10,$R23:$AT23,#REF!)),0,(LOOKUP(AU$10,$R23:$AT23,#REF!))) -> 0 | AV23: =IF(ISERROR(LOOKUP(AV$10,$R23:$AT23,#REF!)),0,(LOOKUP(AV$10,$R23:$AT23,#REF!))) -> 0 | AW23: =IF(ISERROR(LOOKUP(AW$10,$R23:$AT23,#REF!)),0,(LOOKUP(AW$10,$R23:$AT23,#REF!))) -> 0 | AX23: =IF(ISERROR(LOOKUP(AX$10,$R23:$AT23,#REF!)),0,(LOOKUP(AX$10,$R23:$AT23,#REF!))) -> 0 | AY23: =IF(ISERROR(LOOKUP(AY$10,$R23:$AT23,#REF!)),0,(LOOKUP(AY$10,$R23:$AT23,#REF!))) -> 0 | AZ23: =IF(ISERROR(LOOKUP(AZ$10,$R23:$AT23,#REF!)),0,(LOOKUP(AZ$10,$R23:$AT23,#REF!))) -> 0 | BA23: =IF(ISERROR(LOOKUP(BA$10,$R23:$AT23,#REF!)),0,(LOOKUP(BA$10,$R23:$AT23,#REF!))) -> 0 | BB23: =IF(ISERROR(LOOKUP(BB$10,$R23:$AT23,#REF!)),0,(LOOKUP(BB$10,$R23:$AT23,#REF!))) -> 0 | ... BE23: =IF(ISERROR(LOOKUP(BE$10,$R23:$AT23,#REF!)),0,(LOOKUP(BE$10,$R23:$AT23,#REF!))) -> 0 | BG23: 46475
B24: MM-ZTK-1F-GEN-MEC-MR-0002 | C24: RFQ-MA-002-2 | D24: Test Separator | E24: 4-8 | F24: MA | G24: Y | H24: L2 | I24: LA | P24: SH | Q24: A | S24: 46129 | T24: 46143 | U24: 46148 | V24: =U24 -> 46148 | W24: 46183 | X24: 46200 | Y24: 46211 | Z24: N/A | AA24: 46217 | AB24: 46218 | AC24: 46220 | AD24: 46240 | AE24: GA:8-Sep-26 CAL:8-Sep-26 | AU24: =IF(ISERROR(LOOKUP(AU$10,$R24:$AT24,#REF!)),0,(LOOKUP(AU$10,$R24:$AT24,#REF!))) -> 0 | AV24: =IF(ISERROR(LOOKUP(AV$10,$R24:$AT24,#REF!)),0,(LOOKUP(AV$10,$R24:$AT24,#REF!))) -> 0 | AW24: =IF(ISERROR(LOOKUP(AW$10,$R24:$AT24,#REF!)),0,(LOOKUP(AW$10,$R24:$AT24,#REF!))) -> 0 | AX24: =IF(ISERROR(LOOKUP(AX$10,$R24:$AT24,#REF!)),0,(LOOKUP(AX$10,$R24:$AT24,#REF!))) -> 0 | AY24: =IF(ISERROR(LOOKUP(AY$10,$R24:$AT24,#REF!)),0,(LOOKUP(AY$10,$R24:$AT24,#REF!))) -> 0 | AZ24: =IF(ISERROR(LOOKUP(AZ$10,$R24:$AT24,#REF!)),0,(LOOKUP(AZ$10,$R24:$AT24,#REF!))) -> 0 | BA24: =IF(ISERROR(LOOKUP(BA$10,$R24:$AT24,#REF!)),0,(LOOKUP(BA$10,$R24:$AT24,#REF!))) -> 0 | BB24: =IF(ISERROR(LOOKUP(BB$10,$R24:$AT24,#REF!)),0,(LOOKUP(BB$10,$R24:$AT24,#REF!))) -> 0 | ... BE24: =IF(ISERROR(LOOKUP(BE$10,$R24:$AT24,#REF!)),0,(LOOKUP(BE$10,$R24:$AT24,#REF!))) -> 0
A25: =A22+1 -> 4 | B25: MM-ZTK-1F-GEN-MEC-MR-0002 | C25: RFQ-MA-002-3 | D25: Instrument Gas Filter Coalescer | E25: 4-11 | F25: MA | G25: Y | H25: L2 | I25: LA | J25: Zhuhai Jutal | K25: Zhuhai Jutal | P25: SH | Q25: P | R25: 46177 | S25: 46178 | T25: 46185 | U25: 46188 | V25: 46195 | W25: 46197 | X25: 46197 | Y25: 46211 | AA25: 46218 | AB25: 46220 | AC25: 46227 | AD25: 46255 | AE25: 46269 | AF25: 46329 | AG25: 46331 | AH25: 46333 | AI25: 46408 | AJ25: 46423 | AK25: 46438 | AL25: 46441 | AM25: 46468 | AN25: 26 | AO25: 180 | AP25: 46438 | AQ25: 46491 | AR25: =AQ25-AP26 -> 53 | AS25: HuangWei | AT25: 2026.5.6 Issued RFQ to Zhuhai yard | AU25: =IF(ISERROR(LOOKUP(AU$10,$R25:$AT25,#REF!)),0,(LOOKUP(AU$10,$R25:$AT25,#REF!))) -> 0 | AV25: =IF(ISERROR(LOOKUP(AV$10,$R25:$AT25,#REF!)),0,(LOOKUP(AV$10,$R25:$AT25,#REF!))) -> 0 | AW25: =IF(ISERROR(LOOKUP(AW$10,$R25:$AT25,#REF!)),0,(LOOKUP(AW$10,$R25:$AT25,#REF!))) -> 0 | AX25: =IF(ISERROR(LOOKUP(AX$10,$R25:$AT25,#REF!)),0,(LOOKUP(AX$10,$R25:$AT25,#REF!))) -> 0 | AY25: =IF(ISERROR(LOOKUP(AY$10,$R25:$AT25,#REF!)),0,(LOOKUP(AY$10,$R25:$AT25,#REF!))) -> 0 | AZ25: =IF(ISERROR(LOOKUP(AZ$10,$R25:$AT25,#REF!)),0,(LOOKUP(AZ$10,$R25:$AT25,#REF!))) -> 0 | BA25: =IF(ISERROR(LOOKUP(BA$10,$R25:$AT25,#REF!)),0,(LOOKUP(BA$10,$R25:$AT25,#REF!))) -> 0 | BB25: =IF(ISERROR(LOOKUP(BB$10,$R25:$AT25,#REF!)),0,(LOOKUP(BB$10,$R25:$AT25,#REF!))) -> 0 | ... BE25: =IF(ISERROR(LOOKUP(BE$10,$R25:$AT25,#REF!)),0,(LOOKUP(BE$10,$R25:$AT25,#REF!))) -> 0
B26: MM-ZTK-1F-GEN-MEC-MR-0002 | C26: RFQ-MA-002-3 | D26: Instrument Gas Filter Coalescer | E26: 4-11 | F26: MA | G26: Y | H26: L2 | I26: LA | J26: ZM169-WP1-PO-MEC-002 | P26: SH | Q26: F | AE26: =WORKDAY(AD27, 20, IF(AE12="China",'China Holidays'!$A$2:$A$84,'Thai Holidays'!$A$2:$A$65)) -> 46297 | AF26: =AE26+60 -> 46357 | AG26: =AF26+2 -> 46359 | AH26: =AG26+2 -> 46361 | AI26: =AJ26-15 -> 46408 | AJ26: 46423 | AK26: =AP25 -> 46438 | AL26: =AP25+3 -> 46441 | AM26: =AP25+30 -> 46468 | AP26: =AP25 -> 46438 | AS26: DDP Yard | AU26: =IF(ISERROR(LOOKUP(AU$10,$R26:$AT26,#REF!)),0,(LOOKUP(AU$10,$R26:$AT26,#REF!))) -> 0 | AV26: =IF(ISERROR(LOOKUP(AV$10,$R26:$AT26,#REF!)),0,(LOOKUP(AV$10,$R26:$AT26,#REF!))) -> 0 | AW26: =IF(ISERROR(LOOKUP(AW$10,$R26:$AT26,#REF!)),0,(LOOKUP(AW$10,$R26:$AT26,#REF!))) -> 0 | AX26: =IF(ISERROR(LOOKUP(AX$10,$R26:$AT26,#REF!)),0,(LOOKUP(AX$10,$R26:$AT26,#REF!))) -> 0 | AY26: =IF(ISERROR(LOOKUP(AY$10,$R26:$AT26,#REF!)),0,(LOOKUP(AY$10,$R26:$AT26,#REF!))) -> 0 | AZ26: =IF(ISERROR(LOOKUP(AZ$10,$R26:$AT26,#REF!)),0,(LOOKUP(AZ$10,$R26:$AT26,#REF!))) -> 0 | BA26: =IF(ISERROR(LOOKUP(BA$10,$R26:$AT26,#REF!)),0,(LOOKUP(BA$10,$R26:$AT26,#REF!))) -> 0 | BB26: =IF(ISERROR(LOOKUP(BB$10,$R26:$AT26,#REF!)),0,(LOOKUP(BB$10,$R26:$AT26,#REF!))) -> 0 | ... BE26: =IF(ISERROR(LOOKUP(BE$10,$R26:$AT26,#REF!)),0,(LOOKUP(BE$10,$R26:$AT26,#REF!))) -> 0 | BG26: 46438
B27: MM-ZTK-1F-GEN-MEC-MR-0002 | C27: RFQ-MA-002-3 | D27: Instrument Gas Filter Coalescer | E27: 4-11 | F27: MA | G27: Y | H27: L2 | I27: LA | P27: SH | Q27: A | S27: 46141 | T27: 46143 | U27: 46148 | V27: 46148 | W27: 46191 | X27: 46200 | Y27: 46211 | Z27: N/A | AA27: 46217 | AB27: 46218 | AC27: 46220 | AD27: 46269 | AU27: =IF(ISERROR(LOOKUP(AU$10,$R27:$AT27,#REF!)),0,(LOOKUP(AU$10,$R27:$AT27,#REF!))) -> 0 | AV27: =IF(ISERROR(LOOKUP(AV$10,$R27:$AT27,#REF!)),0,(LOOKUP(AV$10,$R27:$AT27,#REF!))) -> 0 | AW27: =IF(ISERROR(LOOKUP(AW$10,$R27:$AT27,#REF!)),0,(LOOKUP(AW$10,$R27:$AT27,#REF!))) -> 0 | AX27: =IF(ISERROR(LOOKUP(AX$10,$R27:$AT27,#REF!)),0,(LOOKUP(AX$10,$R27:$AT27,#REF!))) -> 0 | AY27: =IF(ISERROR(LOOKUP(AY$10,$R27:$AT27,#REF!)),0,(LOOKUP(AY$10,$R27:$AT27,#REF!))) -> 0 | AZ27: =IF(ISERROR(LOOKUP(AZ$10,$R27:$AT27,#REF!)),0,(LOOKUP(AZ$10,$R27:$AT27,#REF!))) -> 0 | BA27: =IF(ISERROR(LOOKUP(BA$10,$R27:$AT27,#REF!)),0,(LOOKUP(BA$10,$R27:$AT27,#REF!))) -> 0 | BB27: =IF(ISERROR(LOOKUP(BB$10,$R27:$AT27,#REF!)),0,(LOOKUP(BB$10,$R27:$AT27,#REF!))) -> 0 | ... BE27: =IF(ISERROR(LOOKUP(BE$10,$R27:$AT27,#REF!)),0,(LOOKUP(BE$10,$R27:$AT27,#REF!))) -> 0
A28: =A25+1 -> 5 | B28: MM-ZTK-1F-GEN-MEC-MR-0003 | C28: RFQ-MA-003 | D28: Closed Drain Sump Pump skids | E28: 4-18 | F28: MA | G28: Y | H28: L3 | I28: LA | J28: Multipahse | K28: Multipahse | L28: Multipahse | N28: Multipahse | O28: Multipahse | P28: SH | Q28: P | R28: 46140 | S28: 46141 | T28: 46150 | U28: 46153 | V28: 46160 | W28: 46168 | X28: 46195 | Y28: 46209 | AA28: 46220 | AB28: 46224 | AC28: 46231 | AD28: 46259 | AE28: 46273 | AF28: 46363 | AG28: 46363 | AH28: 46366 | AI28: 46401 | AJ28: 46416 | AK28: 46444 | AL28: 46447 | AM28: 46474 | AN28: 32 | AO28: 224 | AP28: 46444 | AQ28: 46467 | AR28: =AQ28-AP29 -> -4 | AS28: Chris | AT28: 2026.5.6 Issued RFQ bid due day:22-May | AU28: =IF(ISERROR(LOOKUP(AU$10,$R28:$AT28,#REF!)),0,(LOOKUP(AU$10,$R28:$AT28,#REF!))) -> 0 | AV28: =IF(ISERROR(LOOKUP(AV$10,$R28:$AT28,#REF!)),0,(LOOKUP(AV$10,$R28:$AT28,#REF!))) -> 0 | AW28: =IF(ISERROR(LOOKUP(AW$10,$R28:$AT28,#REF!)),0,(LOOKUP(AW$10,$R28:$AT28,#REF!))) -> 0 | AX28: =IF(ISERROR(LOOKUP(AX$10,$R28:$AT28,#REF!)),0,(LOOKUP(AX$10,$R28:$AT28,#REF!))) -> 0 | AY28: =IF(ISERROR(LOOKUP(AY$10,$R28:$AT28,#REF!)),0,(LOOKUP(AY$10,$R28:$AT28,#REF!))) -> 0 | AZ28: =IF(ISERROR(LOOKUP(AZ$10,$R28:$AT28,#REF!)),0,(LOOKUP(AZ$10,$R28:$AT28,#REF!))) -> 0 | BA28: =IF(ISERROR(LOOKUP(BA$10,$R28:$AT28,#REF!)),0,(LOOKUP(BA$10,$R28:$AT28,#REF!))) -> 0 | BB28: =IF(ISERROR(LOOKUP(BB$10,$R28:$AT28,#REF!)),0,(LOOKUP(BB$10,$R28:$AT28,#REF!))) -> 0 | ... BE28: =IF(ISERROR(LOOKUP(BE$10,$R28:$AT28,#REF!)),0,(LOOKUP(BE$10,$R28:$AT28,#REF!))) -> 0
B29: MM-ZTK-1F-GEN-MEC-MR-0003 | C29: RFQ-MA-003 | D29: Closed Drain Sump Pump skids | E29: 4-18 | F29: MA | G29: Y | H29: L3 | I29: LA | J29: ZM169-WP1-PO-MEC-003 | K29: PKK | L29: PKK | N29: PKK | O29: PKK | P29: SH | Q29: F | AE29: 46289 | AF29: =AE29+90 -> 46379 | AG29: =AF29 -> 46379 | AH29: =AG29+3 -> 46382 | AI29: =AJ29-15 -> 46435 | AJ29: =AK29-28 -> 46450 | AK29: =AP29+7 -> 46478 | AL29: =AP28+3 -> 46447 | AM29: =AP28+30 -> 46474 | AN29: 32 | AO29: =AN29*7 -> 224 | AP29: =BG29+7 -> 46471 | AS29: CIF Zhuhai Port | AU29: =IF(ISERROR(LOOKUP(AU$10,$R29:$AT29,#REF!)),0,(LOOKUP(AU$10,$R29:$AT29,#REF!))) -> 0 | AV29: =IF(ISERROR(LOOKUP(AV$10,$R29:$AT29,#REF!)),0,(LOOKUP(AV$10,$R29:$AT29,#REF!))) -> 0 | AW29: =IF(ISERROR(LOOKUP(AW$10,$R29:$AT29,#REF!)),0,(LOOKUP(AW$10,$R29:$AT29,#REF!))) -> 0 | AX29: =IF(ISERROR(LOOKUP(AX$10,$R29:$AT29,#REF!)),0,(LOOKUP(AX$10,$R29:$AT29,#REF!))) -> 0 | AY29: =IF(ISERROR(LOOKUP(AY$10,$R29:$AT29,#REF!)),0,(LOOKUP(AY$10,$R29:$AT29,#REF!))) -> 0 | AZ29: =IF(ISERROR(LOOKUP(AZ$10,$R29:$AT29,#REF!)),0,(LOOKUP(AZ$10,$R29:$AT29,#REF!))) -> 0 | BA29: =IF(ISERROR(LOOKUP(BA$10,$R29:$AT29,#REF!)),0,(LOOKUP(BA$10,$R29:$AT29,#REF!))) -> 0 | BB29: =IF(ISERROR(LOOKUP(BB$10,$R29:$AT29,#REF!)),0,(LOOKUP(BB$10,$R29:$AT29,#REF!))) -> 0 | ... BE29: =IF(ISERROR(LOOKUP(BE$10,$R29:$AT29,#REF!)),0,(LOOKUP(BE$10,$R29:$AT29,#REF!))) -> 0 | BF29: ZWP20-23 | BG29: 46464
B30: MM-ZTK-1F-GEN-MEC-MR-0003 | C30: RFQ-MA-003 | D30: Closed Drain Sump Pump skids | E30: 4-18 | F30: MA | G30: Y | H30: L3 | I30: LA | K30: CSI | L30: CSI | N30: CSI | P30: SH | Q30: A | R30: 46133 | S30: 46130 | T30: 46149 | U30: 46150 | V30: 46150 | W30: 46164 | X30: 46206 | Y30: 46220 | Z30: 46238 | AA30: 46245 | AB30: 46267 | AC30: 46241 | AD30: 46262 | AP30: CD+7 | AU30: =IF(ISERROR(LOOKUP(AU$10,$R30:$AT30,#REF!)),0,(LOOKUP(AU$10,$R30:$AT30,#REF!))) -> 0 | AV30: =IF(ISERROR(LOOKUP(AV$10,$R30:$AT30,#REF!)),0,(LOOKUP(AV$10,$R30:$AT30,#REF!))) -> 0 | AW30: =IF(ISERROR(LOOKUP(AW$10,$R30:$AT30,#REF!)),0,(LOOKUP(AW$10,$R30:$AT30,#REF!))) -> 0 | AX30: =IF(ISERROR(LOOKUP(AX$10,$R30:$AT30,#REF!)),0,(LOOKUP(AX$10,$R30:$AT30,#REF!))) -> 0 | AY30: =IF(ISERROR(LOOKUP(AY$10,$R30:$AT30,#REF!)),0,(LOOKUP(AY$10,$R30:$AT30,#REF!))) -> 0 | AZ30: =IF(ISERROR(LOOKUP(AZ$10,$R30:$AT30,#REF!)),0,(LOOKUP(AZ$10,$R30:$AT30,#REF!))) -> 0 | BA30: =IF(ISERROR(LOOKUP(BA$10,$R30:$AT30,#REF!)),0,(LOOKUP(BA$10,$R30:$AT30,#REF!))) -> 0 | BB30: =IF(ISERROR(LOOKUP(BB$10,$R30:$AT30,#REF!)),0,(LOOKUP(BB$10,$R30:$AT30,#REF!))) -> 0 | ... BE30: =IF(ISERROR(LOOKUP(BE$10,$R30:$AT30,#REF!)),0,(LOOKUP(BE$10,$R30:$AT30,#REF!))) -> 0
A31: =A28+1 -> 6 | B31: MM-ZTK-1F-GEN-MEC-MR-0004 | C31: RFQ-MA-004 | D31: Chemical injection pump skids | E31: 4-4 | F31: MA | G31: Y | H31: L3 | I31: LA | J31: Multipahse | K31: Multipahse | L31: Multipahse | N31: Multipahse | O31: Multipahse | P31: SH | Q31: P | R31: 46140 | S31: 46141 | T31: 46150 | U31: 46153 | V31: 46160 | W31: 46168 | X31: 46195 | Y31: 46209 | AA31: 46220 | AB31: 46224 | AC31: 46231 | AD31: 46259 | AE31: 46273 | AF31: 46363 | AG31: 46363 | AH31: 46366 | AI31: 46424 | AJ31: 46439 | AK31: 46444 | AL31: 46447 | AM31: 46474 | AN31: 34 | AO31: 238 | AP31: 46458 | AQ31: 46490 | AR31: =AQ31-AP32 -> 39 | AS31: Chris | AT31: 2026.5.6 Issued RFQ bid due day:22-May 2025.5.31-6.5 TC | AU31: =IF(ISERROR(LOOKUP(AU$10,$R31:$AT31,#REF!)),0,(LOOKUP(AU$10,$R31:$AT31,#REF!))) -> 0 | AV31: =IF(ISERROR(LOOKUP(AV$10,$R31:$AT31,#REF!)),0,(LOOKUP(AV$10,$R31:$AT31,#REF!))) -> 0 | AW31: =IF(ISERROR(LOOKUP(AW$10,$R31:$AT31,#REF!)),0,(LOOKUP(AW$10,$R31:$AT31,#REF!))) -> 0 | AX31: =IF(ISERROR(LOOKUP(AX$10,$R31:$AT31,#REF!)),0,(LOOKUP(AX$10,$R31:$AT31,#REF!))) -> 0 | AY31: =IF(ISERROR(LOOKUP(AY$10,$R31:$AT31,#REF!)),0,(LOOKUP(AY$10,$R31:$AT31,#REF!))) -> 0 | AZ31: =IF(ISERROR(LOOKUP(AZ$10,$R31:$AT31,#REF!)),0,(LOOKUP(AZ$10,$R31:$AT31,#REF!))) -> 0 | BA31: =IF(ISERROR(LOOKUP(BA$10,$R31:$AT31,#REF!)),0,(LOOKUP(BA$10,$R31:$AT31,#REF!))) -> 0 | BB31: =IF(ISERROR(LOOKUP(BB$10,$R31:$AT31,#REF!)),0,(LOOKUP(BB$10,$R31:$AT31,#REF!))) -> 0 | ... BE31: =IF(ISERROR(LOOKUP(BE$10,$R31:$AT31,#REF!)),0,(LOOKUP(BE$10,$R31:$AT31,#REF!))) -> 0
B32: MM-ZTK-1F-GEN-MEC-MR-0004 | C32: RFQ-MA-004 | D32: Chemical injection pump skids | E32: 4-4 | F32: MA | G32: Y | H32: L3 | I32: LA | J32: ZM169-WP1-PO-MEC-003 | K32: PKK | L32: PKK | N32: PKK | O32: PKK | P32: SH | Q32: F | AE32: 46289 | AF32: =AE32+90 -> 46379 | AG32: =AF32 -> 46379 | AH32: =AG32+3 -> 46382 | AI32: =AJ32-15 -> 46415 | AJ32: =AK32-28 -> 46430 | AK32: =AP32+7 -> 46458 | AL32: =AP31+3 -> 46461 | AM32: =AP31+30 -> 46488 | AN32: 28 | AO32: =AN32*7 -> 196 | AP32: =BG32+15 -> 46451 | AS32: CIF Zhuhai Port | AU32: =IF(ISERROR(LOOKUP(AU$10,$R32:$AT32,#REF!)),0,(LOOKUP(AU$10,$R32:$AT32,#REF!))) -> 0 | AV32: =IF(ISERROR(LOOKUP(AV$10,$R32:$AT32,#REF!)),0,(LOOKUP(AV$10,$R32:$AT32,#REF!))) -> 0 | AW32: =IF(ISERROR(LOOKUP(AW$10,$R32:$AT32,#REF!)),0,(LOOKUP(AW$10,$R32:$AT32,#REF!))) -> 0 | AX32: =IF(ISERROR(LOOKUP(AX$10,$R32:$AT32,#REF!)),0,(LOOKUP(AX$10,$R32:$AT32,#REF!))) -> 0 | AY32: =IF(ISERROR(LOOKUP(AY$10,$R32:$AT32,#REF!)),0,(LOOKUP(AY$10,$R32:$AT32,#REF!))) -> 0 | AZ32: =IF(ISERROR(LOOKUP(AZ$10,$R32:$AT32,#REF!)),0,(LOOKUP(AZ$10,$R32:$AT32,#REF!))) -> 0 | BA32: =IF(ISERROR(LOOKUP(BA$10,$R32:$AT32,#REF!)),0,(LOOKUP(BA$10,$R32:$AT32,#REF!))) -> 0 | BB32: =IF(ISERROR(LOOKUP(BB$10,$R32:$AT32,#REF!)),0,(LOOKUP(BB$10,$R32:$AT32,#REF!))) -> 0 | ... BE32: =IF(ISERROR(LOOKUP(BE$10,$R32:$AT32,#REF!)),0,(LOOKUP(BE$10,$R32:$AT32,#REF!))) -> 0 | BF32: ZWP20-23 | BG32: 46436
B33: MM-ZTK-1F-GEN-MEC-MR-0004 | C33: RFQ-MA-004 | D33: Chemical injection pump skids | E33: 4-4 | F33: MA | G33: Y | H33: L3 | I33: LA | K33: CSI | L33: CSI | N33: CSI | O33: CSI | P33: SH | Q33: A | R33: 46133 | S33: 46130 | T33: 46149 | U33: 46150 | V33: 46150 | W33: 46164 | X33: 46202 | Y33: 46241 | Z33: 46238 | AA33: 46245 | AB33: 46267 | AC33: 46241 | AD33: 46268 | AP33: CD+Spring F+15 | AU33: =IF(ISERROR(LOOKUP(AU$10,$R33:$AT33,#REF!)),0,(LOOKUP(AU$10,$R33:$AT33,#REF!))) -> 0 | AV33: =IF(ISERROR(LOOKUP(AV$10,$R33:$AT33,#REF!)),0,(LOOKUP(AV$10,$R33:$AT33,#REF!))) -> 0 | AW33: =IF(ISERROR(LOOKUP(AW$10,$R33:$AT33,#REF!)),0,(LOOKUP(AW$10,$R33:$AT33,#REF!))) -> 0 | AX33: =IF(ISERROR(LOOKUP(AX$10,$R33:$AT33,#REF!)),0,(LOOKUP(AX$10,$R33:$AT33,#REF!))) -> 0 | AY33: =IF(ISERROR(LOOKUP(AY$10,$R33:$AT33,#REF!)),0,(LOOKUP(AY$10,$R33:$AT33,#REF!))) -> 0 | AZ33: =IF(ISERROR(LOOKUP(AZ$10,$R33:$AT33,#REF!)),0,(LOOKUP(AZ$10,$R33:$AT33,#REF!))) -> 0 | BA33: =IF(ISERROR(LOOKUP(BA$10,$R33:$AT33,#REF!)),0,(LOOKUP(BA$10,$R33:$AT33,#REF!))) -> 0 | BB33: =IF(ISERROR(LOOKUP(BB$10,$R33:$AT33,#REF!)),0,(LOOKUP(BB$10,$R33:$AT33,#REF!))) -> 0 | ... BE33: =IF(ISERROR(LOOKUP(BE$10,$R33:$AT33,#REF!)),0,(LOOKUP(BE$10,$R33:$AT33,#REF!))) -> 0
A34: =A31+1 -> 7 | B34: MM-ZTK-1F-GEN-MEC-MR-0005 | C34: RFQ-MA-005 | D34: Chemical storage tank | E34: 4-39 | F34: MA | G34: Y | H34: L3 | I34: LA | J34: Zhuhai Jutal | K34: Zhuhai Jutal | P34: SH | Q34: P | R34: 46153 | S34: 46154 | T34: 46166 | U34: 46166 | V34: 46166 | W34: 46203 | X34: 46203 | Y34: 46217 | AA34: 46230 | AB34: 46232 | AC34: 46239 | AD34: 46267 | AE34: 46281 | AF34: 46311 | AG34: 46314 | AH34: 46317 | AI34: 46387 | AJ34: 46397 | AK34: 46398 | AL34: 46401 | AM34: 46428 | AN34: 24 | AO34: 168 | AP34: 46398 | AQ34: 46492 | AR34: =AQ34-AP35 -> 55 | AS34: HuangWei | AT34: 2026.5.6 Issued RFQ to Zhuhai yard 2026.9.4 GA drawing submitted to D2. | AU34: =IF(ISERROR(LOOKUP(AU$10,$R34:$AT34,#REF!)),0,(LOOKUP(AU$10,$R34:$AT34,#REF!))) -> 0 | AV34: =IF(ISERROR(LOOKUP(AV$10,$R34:$AT34,#REF!)),0,(LOOKUP(AV$10,$R34:$AT34,#REF!))) -> 0 | AW34: =IF(ISERROR(LOOKUP(AW$10,$R34:$AT34,#REF!)),0,(LOOKUP(AW$10,$R34:$AT34,#REF!))) -> 0 | AX34: =IF(ISERROR(LOOKUP(AX$10,$R34:$AT34,#REF!)),0,(LOOKUP(AX$10,$R34:$AT34,#REF!))) -> 0 | AY34: =IF(ISERROR(LOOKUP(AY$10,$R34:$AT34,#REF!)),0,(LOOKUP(AY$10,$R34:$AT34,#REF!))) -> 0 | AZ34: =IF(ISERROR(LOOKUP(AZ$10,$R34:$AT34,#REF!)),0,(LOOKUP(AZ$10,$R34:$AT34,#REF!))) -> 0 | BA34: =IF(ISERROR(LOOKUP(BA$10,$R34:$AT34,#REF!)),0,(LOOKUP(BA$10,$R34:$AT34,#REF!))) -> 0 | BB34: =IF(ISERROR(LOOKUP(BB$10,$R34:$AT34,#REF!)),0,(LOOKUP(BB$10,$R34:$AT34,#REF!))) -> 0 | ... BE34: =IF(ISERROR(LOOKUP(BE$10,$R34:$AT34,#REF!)),0,(LOOKUP(BE$10,$R34:$AT34,#REF!))) -> 0
B35: MM-ZTK-1F-GEN-MEC-MR-0005 | C35: RFQ-MA-005 | D35: Chemical storage tank | E35: 4-39 | F35: MA | G35: Y | H35: L3 | I35: LA | J35: ZM169-WP1-PO-MEC-005 | P35: SH | Q35: F | AE35: 46289 | AF35: =AF34 -> 46311 | AG35: =AF35+3 -> 46314 | AH35: =AG35+3 -> 46317 | AI35: =AJ35-10 -> 46427 | AJ35: =AK35 -> 46437 | AK35: =AP35 -> 46437 | AL35: =AP34+3 -> 46401 | AM35: =AP34+30 -> 46428 | AP35: 46437 | AS35: DDP Yard | AU35: =IF(ISERROR(LOOKUP(AU$10,$R35:$AT35,#REF!)),0,(LOOKUP(AU$10,$R35:$AT35,#REF!))) -> 0 | AV35: =IF(ISERROR(LOOKUP(AV$10,$R35:$AT35,#REF!)),0,(LOOKUP(AV$10,$R35:$AT35,#REF!))) -> 0 | AW35: =IF(ISERROR(LOOKUP(AW$10,$R35:$AT35,#REF!)),0,(LOOKUP(AW$10,$R35:$AT35,#REF!))) -> 0 | AX35: =IF(ISERROR(LOOKUP(AX$10,$R35:$AT35,#REF!)),0,(LOOKUP(AX$10,$R35:$AT35,#REF!))) -> 0 | AY35: =IF(ISERROR(LOOKUP(AY$10,$R35:$AT35,#REF!)),0,(LOOKUP(AY$10,$R35:$AT35,#REF!))) -> 0 | AZ35: =IF(ISERROR(LOOKUP(AZ$10,$R35:$AT35,#REF!)),0,(LOOKUP(AZ$10,$R35:$AT35,#REF!))) -> 0 | BA35: =IF(ISERROR(LOOKUP(BA$10,$R35:$AT35,#REF!)),0,(LOOKUP(BA$10,$R35:$AT35,#REF!))) -> 0 | BB35: =IF(ISERROR(LOOKUP(BB$10,$R35:$AT35,#REF!)),0,(LOOKUP(BB$10,$R35:$AT35,#REF!))) -> 0 | ... BE35: =IF(ISERROR(LOOKUP(BE$10,$R35:$AT35,#REF!)),0,(LOOKUP(BE$10,$R35:$AT35,#REF!))) -> 0
B36: MM-ZTK-1F-GEN-MEC-MR-0005 | C36: RFQ-MA-005 | D36: Chemical storage tank | E36: 4-39 | F36: MA | G36: Y | H36: L3 | I36: LA | P36: SH | Q36: A | S36: 46133 | T36: 46150 | U36: 46150 | V36: 46150 | W36: 46181 | X36: 46204 | Y36: 46211 | Z36: N/A | AA36: 46217 | AB36: 46218 | AC36: 46220 | AD36: 46241 | AU36: =IF(ISERROR(LOOKUP(AU$10,$R36:$AT36,#REF!)),0,(LOOKUP(AU$10,$R36:$AT36,#REF!))) -> 0 | AV36: =IF(ISERROR(LOOKUP(AV$10,$R36:$AT36,#REF!)),0,(LOOKUP(AV$10,$R36:$AT36,#REF!))) -> 0 | AW36: =IF(ISERROR(LOOKUP(AW$10,$R36:$AT36,#REF!)),0,(LOOKUP(AW$10,$R36:$AT36,#REF!))) -> 0 | AX36: =IF(ISERROR(LOOKUP(AX$10,$R36:$AT36,#REF!)),0,(LOOKUP(AX$10,$R36:$AT36,#REF!))) -> 0 | AY36: =IF(ISERROR(LOOKUP(AY$10,$R36:$AT36,#REF!)),0,(LOOKUP(AY$10,$R36:$AT36,#REF!))) -> 0 | AZ36: =IF(ISERROR(LOOKUP(AZ$10,$R36:$AT36,#REF!)),0,(LOOKUP(AZ$10,$R36:$AT36,#REF!))) -> 0 | BA36: =IF(ISERROR(LOOKUP(BA$10,$R36:$AT36,#REF!)),0,(LOOKUP(BA$10,$R36:$AT36,#REF!))) -> 0 | BB36: =IF(ISERROR(LOOKUP(BB$10,$R36:$AT36,#REF!)),0,(LOOKUP(BB$10,$R36:$AT36,#REF!))) -> 0 | ... BE36: =IF(ISERROR(LOOKUP(BE$10,$R36:$AT36,#REF!)),0,(LOOKUP(BE$10,$R36:$AT36,#REF!))) -> 0
A37: =A34+1 -> 8 | B37: MM-ZTK-1F-GEN-MEC-MR-0006 | C37: RFQ-MA-006 | D37: Material Handling Equipment | E37: 4-7 | F37: MA | G37: N | H37: L4 | I37: LC | J37: MGW(Yale) | K37: Weihua, Megaway | L37: Weihua | P37: SH | Q37: P | R37: 46182 | S37: 46182 | T37: 46196 | U37: 46196 | V37: 46196 | W37: 46203 | X37: 46212 | Y37: 46226 | AA37: 46259 | AB37: 46261 | AC37: =AB37 -> 46261 | AD37: 46275 | AE37: 46295 | AF37: 46325 | AG37: 46328 | AH37: 46331 | AI37: 46391 | AJ37: 46406 | AK37: 46434 | AL37: 46437 | AM37: 46464 | AN37: 25 | AO37: 175 | AP37: 46434 | AQ37: 46521 | AR37: =AQ37-AP38 -> 73 | AS37: Chris | AU37: =IF(ISERROR(LOOKUP(AU$10,$R37:$AT37,#REF!)),0,(LOOKUP(AU$10,$R37:$AT37,#REF!))) -> 0 | AV37: =IF(ISERROR(LOOKUP(AV$10,$R37:$AT37,#REF!)),0,(LOOKUP(AV$10,$R37:$AT37,#REF!))) -> 0 | AW37: =IF(ISERROR(LOOKUP(AW$10,$R37:$AT37,#REF!)),0,(LOOKUP(AW$10,$R37:$AT37,#REF!))) -> 0 | AX37: =IF(ISERROR(LOOKUP(AX$10,$R37:$AT37,#REF!)),0,(LOOKUP(AX$10,$R37:$AT37,#REF!))) -> 0 | AY37: =IF(ISERROR(LOOKUP(AY$10,$R37:$AT37,#REF!)),0,(LOOKUP(AY$10,$R37:$AT37,#REF!))) -> 0 | AZ37: =IF(ISERROR(LOOKUP(AZ$10,$R37:$AT37,#REF!)),0,(LOOKUP(AZ$10,$R37:$AT37,#REF!))) -> 0 | BA37: =IF(ISERROR(LOOKUP(BA$10,$R37:$AT37,#REF!)),0,(LOOKUP(BA$10,$R37:$AT37,#REF!))) -> 0 | BB37: =IF(ISERROR(LOOKUP(BB$10,$R37:$AT37,#REF!)),0,(LOOKUP(BB$10,$R37:$AT37,#REF!))) -> 0 | ... BE37: =IF(ISERROR(LOOKUP(BE$10,$R37:$AT37,#REF!)),0,(LOOKUP(BE$10,$R37:$AT37,#REF!))) -> 0
B38: MM-ZTK-1F-GEN-MEC-MR-0006 | C38: RFQ-MA-006 | D38: Material Handling Equipment | E38: 4-7 | F38: MA | G38: N | H38: L4 | I38: LC | J38: ZM169-WP1-PO-MEC-006 | K38: Crosby | L38: Crosby | M38: Crosby(PVL) | N38: Crosby(PVL) | P38: SH | Q38: F | AC38: 46287 | AD38: 46289 | AE38: =AE37 -> 46295 | AF38: =AE38+30 -> 46325 | AG38: =AF38+3 -> 46328 | AH38: =AG38+3 -> 46331 | AI38: =AJ38-15 -> 46391 | AJ38: =AK38-28 -> 46406 | AK38: =AP37 -> 46434 | AL38: =AP37+3 -> 46437 | AM38: =AP37+30 -> 46464 | AN38: 25 | AO38: =AN38*7 -> 175 | AP38: =BG38+7 -> 46448 | AS38: CIF Zhuhai Port | AU38: =IF(ISERROR(LOOKUP(AU$10,$R38:$AT38,#REF!)),0,(LOOKUP(AU$10,$R38:$AT38,#REF!))) -> 0 | AV38: =IF(ISERROR(LOOKUP(AV$10,$R38:$AT38,#REF!)),0,(LOOKUP(AV$10,$R38:$AT38,#REF!))) -> 0 | AW38: =IF(ISERROR(LOOKUP(AW$10,$R38:$AT38,#REF!)),0,(LOOKUP(AW$10,$R38:$AT38,#REF!))) -> 0 | AX38: =IF(ISERROR(LOOKUP(AX$10,$R38:$AT38,#REF!)),0,(LOOKUP(AX$10,$R38:$AT38,#REF!))) -> 0 | AY38: =IF(ISERROR(LOOKUP(AY$10,$R38:$AT38,#REF!)),0,(LOOKUP(AY$10,$R38:$AT38,#REF!))) -> 0 | AZ38: =IF(ISERROR(LOOKUP(AZ$10,$R38:$AT38,#REF!)),0,(LOOKUP(AZ$10,$R38:$AT38,#REF!))) -> 0 | BA38: =IF(ISERROR(LOOKUP(BA$10,$R38:$AT38,#REF!)),0,(LOOKUP(BA$10,$R38:$AT38,#REF!))) -> 0 | BB38: =IF(ISERROR(LOOKUP(BB$10,$R38:$AT38,#REF!)),0,(LOOKUP(BB$10,$R38:$AT38,#REF!))) -> 0 | ... BE38: =IF(ISERROR(LOOKUP(BE$10,$R38:$AT38,#REF!)),0,(LOOKUP(BE$10,$R38:$AT38,#REF!))) -> 0 | BF38: ZWP20-23 | BG38: 46441
B39: MM-ZTK-1F-GEN-MEC-MR-0006 | C39: RFQ-MA-006 | D39: Material Handling Equipment | E39: 4-7 | F39: MA | G39: N | H39: L4 | I39: LC | K39: TOS, Konecranes | L39: Megaway(Yale) | M39: Megaway(Yale) | N39: Megaway(Yale) | O39: Megaway(Yale) | P39: SH | Q39: A | R39: 46192 | S39: 46154 | T39: 46170 | U39: 46196 | V39: 46196 | W39: 46203 | X39: 46220 | Y39: C1:2026/8/12 C2:2026/9/11 | Z39: 46262 | AA39: 46276 | AP39: CD+7 | AU39: =IF(ISERROR(LOOKUP(AU$10,$R39:$AT39,#REF!)),0,(LOOKUP(AU$10,$R39:$AT39,#REF!))) -> 0 | AV39: =IF(ISERROR(LOOKUP(AV$10,$R39:$AT39,#REF!)),0,(LOOKUP(AV$10,$R39:$AT39,#REF!))) -> 0 | AW39: =IF(ISERROR(LOOKUP(AW$10,$R39:$AT39,#REF!)),0,(LOOKUP(AW$10,$R39:$AT39,#REF!))) -> 0 | AX39: =IF(ISERROR(LOOKUP(AX$10,$R39:$AT39,#REF!)),0,(LOOKUP(AX$10,$R39:$AT39,#REF!))) -> 0 | AY39: =IF(ISERROR(LOOKUP(AY$10,$R39:$AT39,#REF!)),0,(LOOKUP(AY$10,$R39:$AT39,#REF!))) -> 0 | AZ39: =IF(ISERROR(LOOKUP(AZ$10,$R39:$AT39,#REF!)),0,(LOOKUP(AZ$10,$R39:$AT39,#REF!))) -> 0 | BA39: =IF(ISERROR(LOOKUP(BA$10,$R39:$AT39,#REF!)),0,(LOOKUP(BA$10,$R39:$AT39,#REF!))) -> 0 | BB39: =IF(ISERROR(LOOKUP(BB$10,$R39:$AT39,#REF!)),0,(LOOKUP(BB$10,$R39:$AT39,#REF!))) -> 0 | ... BE39: =IF(ISERROR(LOOKUP(BE$10,$R39:$AT39,#REF!)),0,(LOOKUP(BE$10,$R39:$AT39,#REF!))) -> 0
A40: =A37+1 -> 9 | B40: MM-ZTK-1F-GEN-SAF-MR-0001 | C40: RFQ-SA-001 | D40: Fire Fighting, Safety Equipment (Including Lifesaving) | E40: 4-38 | F40: SA | G40: N | H40: L3 | I40: LD | K40: AIG | L40: AIG | P40: SH | Q40: P | R40: 46213 | S40: 46201 | T40: 46213 | U40: 46283 | V40: 46283 | W40: 46290 | X40: 46303 | Y40: 46318 | AA40: 46325 | AB40: 46329 | AC40: 46329 | AD40: 46343 | AE40: 46357 | AF40: 46417 | AG40: 46417 | AH40: 46420 | AI40: 46490 | AJ40: 46505 | AK40: 46535 | AL40: 46538 | AM40: 46565 | AN40: 30 | AO40: 210 | AP40: 46535 | AQ40: 46546 | AR40: =AQ40-AP41 -> 4 | AS40: Han Jingxin | AU40: =IF(ISERROR(LOOKUP(AU$10,$R40:$AT40,#REF!)),0,(LOOKUP(AU$10,$R40:$AT40,#REF!))) -> 0 | AV40: =IF(ISERROR(LOOKUP(AV$10,$R40:$AT40,#REF!)),0,(LOOKUP(AV$10,$R40:$AT40,#REF!))) -> 0 | AW40: =IF(ISERROR(LOOKUP(AW$10,$R40:$AT40,#REF!)),0,(LOOKUP(AW$10,$R40:$AT40,#REF!))) -> 0 | AX40: =IF(ISERROR(LOOKUP(AX$10,$R40:$AT40,#REF!)),0,(LOOKUP(AX$10,$R40:$AT40,#REF!))) -> 0 | AY40: =IF(ISERROR(LOOKUP(AY$10,$R40:$AT40,#REF!)),0,(LOOKUP(AY$10,$R40:$AT40,#REF!))) -> 0 | AZ40: =IF(ISERROR(LOOKUP(AZ$10,$R40:$AT40,#REF!)),0,(LOOKUP(AZ$10,$R40:$AT40,#REF!))) -> 0 | BA40: =IF(ISERROR(LOOKUP(BA$10,$R40:$AT40,#REF!)),0,(LOOKUP(BA$10,$R40:$AT40,#REF!))) -> 0 | BB40: =IF(ISERROR(LOOKUP(BB$10,$R40:$AT40,#REF!)),0,(LOOKUP(BB$10,$R40:$AT40,#REF!))) -> 0 | ... BE40: =IF(ISERROR(LOOKUP(BE$10,$R40:$AT40,#REF!)),0,(LOOKUP(BE$10,$R40:$AT40,#REF!))) -> 0
B41: MM-ZTK-1F-GEN-SAF-MR-0001 | C41: RFQ-SA-001 | D41: Fire Fighting, Safety Equipment (Including Lifesaving) | E41: 4-38 | F41: SA | G41: N | H41: L3 | I41: LD | K41: WRLEADING | L41: WRLEADING | P41: SH | Q41: F | X41: =X40 -> 46303 | Y41: =WORKDAY(X41, Y6, IF(Y12="China",'China Holidays'!$A$2:$A$84,'Thai Holidays'!$A$2:$A$65)) -> 46321 | AA41: =WORKDAY(Y41, AA6, IF(AA12="China",'China Holidays'!$A$2:$A$84,'Thai Holidays'!$A$2:$A$65)) -> 46332 | AB41: =WORKDAY(AA41, AB6, IF(AB12="China",'China Holidays'!$A$2:$A$84,'Thai Holidays'!$A$2:$A$65)) -> 46336 | AC41: =WORKDAY(AB41, AC6, IF(AC12="China",'China Holidays'!$A$2:$A$84,'Thai Holidays'!$A$2:$A$65)) -> 46343 | AD41: =WORKDAY(AC41, AD6, IF(AD12="China",'China Holidays'!$A$2:$A$84,'Thai Holidays'!$A$2:$A$65)) -> 46371 | AE41: =WORKDAY(AD41, AE6, IF(AE12="China",'China Holidays'!$A$2:$A$84,'Thai Holidays'!$A$2:$A$65)) -> 46385 | AF41: 46417 | AG41: 46417 | AH41: 46420 | AI41: 46490 | AJ41: 46505 | AK41: 46535 | AL41: 46538 | AM41: 46565 | AP41: =AA41+AO40 -> 46542 | AU41: =IF(ISERROR(LOOKUP(AU$10,$R41:$AT41,#REF!)),0,(LOOKUP(AU$10,$R41:$AT41,#REF!))) -> 0 | AV41: =IF(ISERROR(LOOKUP(AV$10,$R41:$AT41,#REF!)),0,(LOOKUP(AV$10,$R41:$AT41,#REF!))) -> 0 | AW41: =IF(ISERROR(LOOKUP(AW$10,$R41:$AT41,#REF!)),0,(LOOKUP(AW$10,$R41:$AT41,#REF!))) -> 0 | AX41: =IF(ISERROR(LOOKUP(AX$10,$R41:$AT41,#REF!)),0,(LOOKUP(AX$10,$R41:$AT41,#REF!))) -> 0 | AY41: =IF(ISERROR(LOOKUP(AY$10,$R41:$AT41,#REF!)),0,(LOOKUP(AY$10,$R41:$AT41,#REF!))) -> 0 | AZ41: =IF(ISERROR(LOOKUP(AZ$10,$R41:$AT41,#REF!)),0,(LOOKUP(AZ$10,$R41:$AT41,#REF!))) -> 0 | BA41: =IF(ISERROR(LOOKUP(BA$10,$R41:$AT41,#REF!)),0,(LOOKUP(BA$10,$R41:$AT41,#REF!))) -> 0 | BB41: =IF(ISERROR(LOOKUP(BB$10,$R41:$AT41,#REF!)),0,(LOOKUP(BB$10,$R41:$AT41,#REF!))) -> 0 | ... BE41: =IF(ISERROR(LOOKUP(BE$10,$R41:$AT41,#REF!)),0,(LOOKUP(BE$10,$R41:$AT41,#REF!))) -> 0
B42: MM-ZTK-1F-GEN-SAF-MR-0001 | C42: RFQ-SA-001 | D42: Fire Fighting, Safety Equipment (Including Lifesaving) | E42: 4-38 | F42: SA | G42: N | H42: L3 | I42: LD | K42: TPI | L42: TPI | P42: SH | Q42: A | R42: 46230 | S42: 46183 | T42: 46197 | U42: 46231 | V42: 46231 | W42: 46248 | AU42: =IF(ISERROR(LOOKUP(AU$10,$R42:$AT42,#REF!)),0,(LOOKUP(AU$10,$R42:$AT42,#REF!))) -> 0 | AV42: =IF(ISERROR(LOOKUP(AV$10,$R42:$AT42,#REF!)),0,(LOOKUP(AV$10,$R42:$AT42,#REF!))) -> 0 | AW42: =IF(ISERROR(LOOKUP(AW$10,$R42:$AT42,#REF!)),0,(LOOKUP(AW$10,$R42:$AT42,#REF!))) -> 0 | AX42: =IF(ISERROR(LOOKUP(AX$10,$R42:$AT42,#REF!)),0,(LOOKUP(AX$10,$R42:$AT42,#REF!))) -> 0 | AY42: =IF(ISERROR(LOOKUP(AY$10,$R42:$AT42,#REF!)),0,(LOOKUP(AY$10,$R42:$AT42,#REF!))) -> 0 | AZ42: =IF(ISERROR(LOOKUP(AZ$10,$R42:$AT42,#REF!)),0,(LOOKUP(AZ$10,$R42:$AT42,#REF!))) -> 0 | BA42: =IF(ISERROR(LOOKUP(BA$10,$R42:$AT42,#REF!)),0,(LOOKUP(BA$10,$R42:$AT42,#REF!))) -> 0 | BB42: =IF(ISERROR(LOOKUP(BB$10,$R42:$AT42,#REF!)),0,(LOOKUP(BB$10,$R42:$AT42,#REF!))) -> 0 | ... BE42: =IF(ISERROR(LOOKUP(BE$10,$R42:$AT42,#REF!)),0,(LOOKUP(BE$10,$R42:$AT42,#REF!))) -> 0
A43: =A40+1 -> 10 | B43: MM-ZTK-1F-GEN-SAF-MR-0002 | C43: RFQ-SA-002 | D43: Safety Signs | E43: 4-38 | F43: SA | G43: N | H43: L3 | I43: LD | P43: ZH | Q43: P | R43: =S43 -> 46381 | S43: 46381 | T43: 46399 | U43: 46399 | V43: 46399 | W43: 46406 | X43: 46415 | Y43: 46429 | AA43: 46437 | AB43: 46441 | AC43: 46448 | AD43: 46462 | AE43: 46476 | AF43: 46491 | AG43: 46491 | AH43: 46493 | AI43: 46523 | AJ43: 46525 | AK43: 46530 | AL43: 46533 | AM43: 46560 | AN43: 5 | AO43: 35 | AP43: 46530 | AQ43: 46546 | AR43: =AQ43-AP44 -> 74 | AS43: Kuang Cuichang | AT43: 2026.6.10 Issued RFQ to Zhuhai yard | AU43: =IF(ISERROR(LOOKUP(AU$10,$R43:$AT43,#REF!)),0,(LOOKUP(AU$10,$R43:$AT43,#REF!))) -> 0 | AV43: =IF(ISERROR(LOOKUP(AV$10,$R43:$AT43,#REF!)),0,(LOOKUP(AV$10,$R43:$AT43,#REF!))) -> 0 | AW43: =IF(ISERROR(LOOKUP(AW$10,$R43:$AT43,#REF!)),0,(LOOKUP(AW$10,$R43:$AT43,#REF!))) -> 0 | AX43: =IF(ISERROR(LOOKUP(AX$10,$R43:$AT43,#REF!)),0,(LOOKUP(AX$10,$R43:$AT43,#REF!))) -> 0 | AY43: =IF(ISERROR(LOOKUP(AY$10,$R43:$AT43,#REF!)),0,(LOOKUP(AY$10,$R43:$AT43,#REF!))) -> 0 | AZ43: =IF(ISERROR(LOOKUP(AZ$10,$R43:$AT43,#REF!)),0,(LOOKUP(AZ$10,$R43:$AT43,#REF!))) -> 0 | BA43: =IF(ISERROR(LOOKUP(BA$10,$R43:$AT43,#REF!)),0,(LOOKUP(BA$10,$R43:$AT43,#REF!))) -> 0 | BB43: =IF(ISERROR(LOOKUP(BB$10,$R43:$AT43,#REF!)),0,(LOOKUP(BB$10,$R43:$AT43,#REF!))) -> 0 | ... BE43: =IF(ISERROR(LOOKUP(BE$10,$R43:$AT43,#REF!)),0,(LOOKUP(BE$10,$R43:$AT43,#REF!))) -> 0
...

Sheet Brownfield
A1: PROVISION OF ENGINEERING, PROCUREMENT, CONSTRUCTION AND COMMISSIONING FOR WELLHEAD PLATFORMS, ASSOCIATED PIPLINES AND BROWNFIELD MODIFICATIONS FOR ZAWTIKA DEVELOPMENT PROJECT PHASE 1F
A2: Procurement Plan
I6: LA | J6: Most complexity RFQ | S6: 1 | T6: 10 | U6: 0 | V6: 0 | W6: 10 | X6: 17 | Y6: 10 | AA6: 9 | AB6: 2 | AC6: 5 | AD6: 20 | AE6: 10 | AU6: 3 | AW6: 10 | AX6: 2
I7: LB | J7: High complexity RFQ | S7: 1 | T7: 10 | U7: 0 | V7: 0 | W7: 10 | X7: 17 | Y7: 10 | AA7: 9 | AB7: 2 | AC7: 5 | AD7: 20 | AE7: 10 | AU7: 3 | AW7: 10 | AX7: 2
I8: LC | J8: Normal complexity RFQ | S8: 1 | T8: 10 | U8: 0 | V8: 0 | W8: 10 | X8: 13 | Y8: 10 | AA8: 9 | AB8: 2 | AC8: 5 | AD8: 15 | AE8: 10 | AU8: 3 | AW8: 10 | AX8: 2
A9: Contract no: MMC25-5001 | I9: LD | J9: Low complexity RFQ | S9: 1 | T9: 10 | U9: 0 | V9: 0 | W9: 5 | X9: 7 | Y9: 10 | AA9: 5 | AB9: 2 | AC9: 5 | AD9: 10 | AE9: 10 | AT9: Update:11-Sep-2026 | AU9: 2 | AW9: 5 | AX9: 2
A10: No. | B10: MR No. | C10: RFQ No. | D10: Package Name | E10: CODE | F10: DIS | G10: LLI (Y/N) | H10: CR | I10: Priority Level | J10: PO description | K10: Bidders | L10: TC | M10: TBE | N10: Price bid | O10: Price Negotiation | P10: Owner | Q10: P/F/A | R10: Bidder list Approval | S10: MR Issued (IFR) | T10: MR Approved | U10: RFQ Issued | V10: RFQ Approved | W10: Bid Closing Date | X10: TBE Issued | Y10: TBE Approved | Z10: LOA issued | AA10: PO Issued | AB10: Vendor Acknowledgement | AC10: KOM | AD10: VDB Submission | AE10: Approval of Key VP | AF10: Main Material Arrived | AG10: PIM | AH10: Start Production | AI10: FAT | AJ10: Ready for Shipment | AK10: Receipt at WORKSITE | AL10: Punch List Clearance(all punch clearance before Tag Equipment Ready for Shipping ) | AM10: Approval of Final Documentation (To be confirmed later) | AN10: Delivery Duration (Weeks) | AO10: days | AP10: Delivery Date(1st Batch for ZWP21) | AQ10: ROS Date | AR10: Float | AS10: Responder | AT10: Remarks | AU10: 40329 | AV10: 40359 | AW10: 40390 | AX10: 40421 | AY10: 40451 | AZ10: 40482 | BA10: 40512 | BB10: 40543 | BC10: 40574 | BD10: 40602 | BE10: =TODAY() -> 46287 | BF10: Palteform | BG10: PO Delivery date | BH10: Puchase Qty
Q11: Matrix | R11: PTTEP | S11: ENG | T11: PTTEP | U11: TJE PRC | V11: PTTEP | W11: TJE PRC | X11: ENG | Y11: PTTEP | Z11: TJE PRC | AA11: TJE PRC | AB11: BIDDER | AC11: TJE PRC | AD11: Vendor | AE11: ENG | AF11: Vendor | AG11: TJE QA/QC | AH11: Vendor | AI11: TJE QA/QC | AJ11: Vendor | AK11: THE Worksite | AL11: TJE QA/QC | AM11: TJE PRC | AP11: TJE PRC
Q12: Holiday | R12: China | S12: Thai | T12: Thai | U12: China | V12: Thai | W12: China | X12: Thai | Y12: Thai | Z12: China | AA12: China | AB12: China | AC12: China | AD12: China | AE12: Thai | AU12: Thai | AW12: China | AX12: China
A13: 1 | B13: MM-ZTK-1F-ZWP8-INS-MR-0001 | C13: RFQ-IN-B01 | D13: ESDV MODIFICATION | F13: IN | G13: N | I13: LD | P13: SH | Q13: P | AT13: 2026.9.20 ENG team released MR to Procurement
B14: MM-ZTK-1F-ZWP8-INS-MR-0001 | C14: RFQ-IN-B01 | D14: ESDV MODIFICATION | F14: IN | G14: N | I14: LD | P14: SH | Q14: F
B15: MM-ZTK-1F-ZWP8-INS-MR-0001 | C15: RFQ-IN-B01 | D15: ESDV MODIFICATION | F15: IN | G15: N | I15: LD | P15: SH | Q15: A

Sheet Future Well
A1: PROVISION OF ENGINEERING, PROCUREMENT, CONSTRUCTION AND COMMISSIONING FOR WELLHEAD PLATFORMS, ASSOCIATED PIPLINES AND BROWNFIELD MODIFICATIONS FOR ZAWTIKA DEVELOPMENT PROJECT PHASE 1F
A2: Procurement Plan
I6: LA | J6: Most complexity RFQ | S6: 1 | T6: 10 | U6: 0 | V6: 0 | W6: 10 | X6: 17 | Y6: 10 | AA6: 9 | AB6: 2 | AC6: 5 | AD6: 20 | AE6: 10 | AU6: 3 | AW6: 10 | AX6: 2
I7: LB | J7: High complexity RFQ | S7: 1 | T7: 10 | U7: 0 | V7: 0 | W7: 10 | X7: 17 | Y7: 10 | AA7: 9 | AB7: 2 | AC7: 5 | AD7: 20 | AE7: 10 | AU7: 3 | AW7: 10 | AX7: 2
I8: LC | J8: Normal complexity RFQ | S8: 1 | T8: 10 | U8: 0 | V8: 0 | W8: 10 | X8: 13 | Y8: 10 | AA8: 9 | AB8: 2 | AC8: 5 | AD8: 15 | AE8: 10 | AU8: 3 | AW8: 10 | AX8: 2
A9: Contract no: MMC25-5001 | I9: LD | J9: Low complexity RFQ | S9: 1 | T9: 10 | U9: 0 | V9: 0 | W9: 5 | X9: 7 | Y9: 10 | AA9: 5 | AB9: 2 | AC9: 5 | AD9: 10 | AE9: 10 | AT9: Update:11-Sep-2026 | AU9: 2 | AW9: 5 | AX9: 2
A10: No. | B10: MR No. | C10: RFQ No. | D10: Package Name | E10: CODE | F10: DIS | G10: LLI (Y/N) | H10: CR | I10: Priority Level | J10: PO description | K10: Bidders | L10: TC | M10: TBE | N10: Price bid | O10: Price Negotiation | P10: Owner | Q10: P/F/A | R10: Bidder list Approval | S10: MR Issued (IFR) | T10: MR Approved | U10: RFQ Issued | V10: RFQ Approved | W10: Bid Closing Date | X10: TBE Issued | Y10: TBE Approved | Z10: LOA issued | AA10: PO Issued | AB10: Vendor Acknowledgement | AC10: KOM | AD10: VDB Submission | AE10: Approval of Key VP | AF10: Main Material Arrived | AG10: PIM | AH10: Start Production | AI10: FAT | AJ10: Ready for Shipment | AK10: Receipt at WORKSITE | AL10: Punch List Clearance(all punch clearance before Tag Equipment Ready for Shipping ) | AM10: Approval of Final Documentation (To be confirmed later) | AN10: Delivery Duration (Weeks) | AO10: days | AP10: Delivery Date(1st Batch for ZWP21) | AQ10: ROS Date | AR10: Float | AS10: Responder | AT10: Remarks | AU10: 40329 | AV10: 40359 | AW10: 40390 | AX10: 40421 | AY10: 40451 | AZ10: 40482 | BA10: 40512 | BB10: 40543 | BC10: 40574 | BD10: 40602 | BE10: =TODAY() -> 46287 | BF10: Palteform | BG10: PO Delivery date | BH10: Puchase Qty
Q11: Matrix | R11: PTTEP | S11: ENG | T11: PTTEP | U11: TJE PRC | V11: PTTEP | W11: TJE PRC | X11: ENG | Y11: PTTEP | Z11: TJE PRC | AA11: TJE PRC | AB11: BIDDER | AC11: TJE PRC | AD11: Vendor | AE11: ENG | AF11: Vendor | AG11: TJE QA/QC | AH11: Vendor | AI11: TJE QA/QC | AJ11: Vendor | AK11: THE Worksite | AL11: TJE QA/QC | AM11: TJE PRC | AP11: TJE PRC
Q12: Holiday | R12: China | S12: Thai | T12: Thai | U12: China | V12: Thai | W12: China | X12: Thai | Y12: Thai | Z12: China | AA12: China | AB12: China | AC12: China | AD12: China | AE12: Thai | AU12: Thai | AW12: China | AX12: China
A13: 1 | C13: RFQ-IN-F01 | D13: Actuated Choke Valve | E13: 4-20 | F13: IN | G13: Y | H13: L2 | I13: LA | J13: MASTER FLO | K13: FZ | L13: FZ | P13: SH | Q13: P | AN13: 44 | AO13: 308 | AP13: 46482 | AQ13: 46515 | AR13: =AQ13-AP14 -> 54 | AS13: Lin Yazhen
C14: RFQ-IN-F01 | D14: Actuated Choke Valve | E14: 4-20 | F14: IN | G14: Y | H14: L2 | I14: LA | K14: MASTER FLO | L14: MASTER FLO | M14: MASTER FLO | N14: MASTER FLO | O14: MASTER FLO | P14: SH | Q14: F | AN14: 36 | AO14: =AN14*7 -> 252 | AP14: =BG14+7 -> 46461 | AS14: CIF Zhuhai port | BF14: ZWP20-23 | BG14: 46454
C15: RFQ-IN-F01 | D15: Actuated Choke Valve | E15: 4-20 | F15: IN | G15: Y | H15: L2 | I15: LA | K15: Cameron | L15: Cameron | M15: Cameron | P15: SH | Q15: A | AP15: CD+7
A16: =A13+1 -> 2 | C16: RFQ-IN-F02 | D16: Actuated Compact Ball Valve | E16: 4-40 | F16: IN | G16: Y | H16: L2 | I16: LA | J16: OIL STATE | K16: Neway,KCON | L16: KCON | M16: KCON-TNA | P16: SH | Q16: P | AN16: 40 | AO16: 280 | AP16: =AQ16-7 -> 46500 | AQ16: 46507 | AR16: =AQ16-AP17 -> 46507 | AS16: Lin Yazhen
C17: RFQ-IN-F02 | D17: Actuated Compact Ball Valve | E17: 4-40 | F17: IN | G17: Y | H17: L2 | I17: LA | K17: PIPER valve | L17: PIPER | M17: PIPER | N17: PIPER | O17: PIPER | P17: SH | Q17: F | AS17: CIF Zhuhai Airport
C18: RFQ-IN-F02 | D18: Actuated Compact Ball Valve | E18: 4-40 | F18: IN | G18: Y | H18: L2 | I18: LA | K18: FMC,Combet | L18: Combet | M18: Combet-declined | P18: SH | Q18: A | AP18: CD+7

Sheet Thai Holidays
A1: Date | B1: Holiday Name
A2: 45996 | B2: Father's Day
A3: 46001 | B3: Constitution Day
A4: 46020 | B4: New Year's Day
A5: 46021 | B5: New Year's Day
A6: 46022 | B6: New Year's Day
A7: 46023 | B7: New Year's Day
A8: 46024 | B8: New Year's Day
A9: 46065 | B9: The Buddha Day
A10: 46118 | B10: Kutkuri Dynasty Memorial Day
A11: 46125 | B11: Songkran Festival
A12: 46126 | B12: Songkran Festival
A13: 46127 | B13: Songkran Festival
... A17: 46146 | B17: The anniversary of the King's accession to the throne
A18: 46174
A19: 46176
A20: 46231
A21: 46232
A22: 46246 | B22: Mother's Day
A23: 46308 | B23: The anniversary of the death of the 9th King
A24: 46318 | B24: The anniversary of the death of the 5th King Father's Day
A25: 46363 | B25: Father's Day
A26: 46387 | B26: New Year's Day
A27: 46388 | B27: New Year's Day | C27: 佛历节日，日期为预测
A28: 46389
A29: 46439 | B29: The Buddha Day
A30: 46440
A31: 46483 | B31: Kutkuri Dynasty Memorial Day
A32: 46490 | B32: Songkran Festival
A33: 46491 | B33: Songkran Festival
A34: 46492 | B34: Songkran Festival | C34: 佛历节日，日期为预测
A35: 46508 | B35: International Workers' Day
A36: 46511 | B36: The anniversary of the King's accession to the throne
A37: 46527 | B37: Vesak Festival
A38: 46541 | B38: The Birthday Anniversary of the Queen
A39: 46611 | B39: Mother's Day | C39: 佛历节日，日期为预测
A40: 46673 | B40: The anniversary of the death of the 9th King
A41: 46683 | B41: The anniversary of the death of the 5th King Father's Day | D41: The anniversary of the death of the 5th King Father's Day
A42: 46685
A43: 46726 | B43: Father's Day
...

Sheet China Holidays
A1: Date | B1: Holiday Name
A2: 46023 | B2: New Year's Day
A3: 46024 | B3: New Year's Day
A4: 46025 | B4: New Year's Day
A5: 46068 | B5: Spring Festival
A6: 46069 | B6: Spring Festival
A7: 46070 | B7: Spring Festival
A8: 46071 | B8: Spring Festival
A9: 46072 | B9: Spring Festival
A10: 46073 | B10: Spring Festival
A11: 46074 | B11: Spring Festival
A12: 46116 | B12: Qingming Festival
A13: 46117 | B13: Qingming Festival
... A84: 47033 | B84: National Day
