Workbook
Name \c: #N/A
Name \i: #N/A
Name \z: #N/A
Name __material_he_tubes_alternative: #REF!
Name __sf400: '[7]Pull-Down Menus'!$J$2486:$J$2491
Name __sf404: '[7]Pull-Down Menus'!$J$699:$J$701
Name _bal11: [10]bal11!$B$1:$AV$66
Name _bal12: [10]bal12!$B$1:$AU$66
Name _bal6: [10]bal6!$B$1:$CN$66
Name _DESIGN_MAT_SHELL: #REF!
Name _DESIGN_MAT_TUBES: #REF!
Name _DESIGN_TEMP_MAX_1: #REF!
Name _DESIGN_TEMP_MAX_2: #REF!
Name _DESIGN_TEMP_MIN_1: #REF!
Name _DESIGN_TEMP_MIN_2: #REF!
Name _DIMENSIONS_BOT: #REF!
Name _DIMENSIONS_MID: #REF!
Name _DIMENSIONS_PIPE_SHELL: #REF!
Name _DIMENSIONS_PIPE_TUBE: #REF!
Name _DIMENSIONS_TOP_MAIN: #REF!
Name _din24420: #REF!
Name _din28005: #REF!
Name _din28006: #REF!
Name _din28007: #REF!
Name _din28008: #REF!
Name _din28015: #REF!
Name _din28017: #REF!
Name _din28083: #REF!
Name _din28084: #REF!
Name _din28105: #REF!
Name _din28161: #REF!
Name _din28182: #REF!
Name _din4119: #REF!
Name _doc_foundation_plan_loads_digital: #REF!
Name _doc_foundation_plan_loads_paper: #REF!
Name _doc_foundation_plan_loads_week: #REF!
Name _installed_area_per_unit: #REF!
Name _Jos2: #REF!
Name _mat1: #REF!
Name _mat2: #REF!
Name _mat3: #REF!
Name _mat4: #REF!
Name _material_he_tubes: #REF!
Name _mc230: #REF!
Name _mc240: #REF!
Name _mc245: #REF!
Name _mc250: #REF!
Name _mc251: #REF!
Name _mc252: #REF!
Name _mc253: #REF!
Name _mc254: #REF!
Name _mc255: #REF!
Name _mc260: #REF!
Name _mc310: #REF!
Name _mc311: #REF!
Name _mc335: #REF!
Name _mc336: #REF!
Name _mc337: #REF!
Name _mc338: #REF!
Name _mc339: #REF!

Sheet PSR Overall Cycle
B2: Note: | C2: 1. All MR Issuance with Attached File to be used IFR version, some long lead item to be used FEED document as MR Issuance basis which listed in Remark
C3: 2. In principle, Datasheet - IFA version shall be issued before TBE issuance as much as possible to avoid the big gap of changes.
C4: 3.TBE- AFC and MR-AFC should be issued before PO issuance.
C5: 4.For the Steel Structural, TJE will sign the frame agreement with alternative vendors firstly, once the MTO&IFA drawing issuance, TJE will purchase order promptly
C6: 5.The 3rd line of Each procuremnt package with "Proposal from TJE" in column N , has been aligned with GCME about date of MR issuance with atteched relative documents, then forward schedule in procurement and leadtime to ETA, this line is the basis for schedule developing.
L8: LA | O8: 1 | P8: 10 | Q8: 0 | R8: 0 | S8: 0 | T8: 10 | U8: 17 | V8: 10 | W8: 9
L9: LB | O9: 1 | P9: 10 | Q9: 0 | R9: 0 | S9: 0 | T9: 10 | U9: 17 | V9: 10 | W9: 9
L10: LC | O10: 1 | P10: 10 | Q10: 0 | R10: 0 | S10: 0 | T10: 10 | U10: 13 | V10: 10 | W10: 9
L11: LD | O11: 1 | P11: 10 | Q11: 0 | R11: 0 | S11: 0 | T11: 5 | U11: 7 | V11: 10 | W11: 5
B12: ZM167 PTTEPI ASK Procurement Plan | L12: LA | O12: 1 | P12: 5 | Q12: 1 | R12: 5 | T12: 10 | U12: 20 | V12: 3 | W12: 10 | X12: 2 | Y12: 5 | Z12: 20 | AA12: 10 | AE12: 5 | AF12: 5 | AN12: Update
L13: LB | O13: 1 | P13: 5 | Q13: 1 | R13: 5 | T13: 10 | U13: 20 | V13: 3 | W13: 10 | X13: 2 | Y13: 5 | Z13: 20 | AA13: 10 | AE13: 5 | AF13: 5
L14: LC | O14: 3 | P14: 5 | Q14: 1 | R14: 5 | T14: 10 | U14: 15 | V14: 3 | W14: 10 | X14: 2 | Y14: 5 | Z14: 15 | AA14: 10 | AE14: 5 | AF14: 5
L15: LD | O15: 3 | P15: 5 | Q15: 1 | R15: 3 | T15: 5 | U15: 7 | V15: 2 | W15: 5 | X15: 2 | Y15: 5 | Z15: 10 | AA15: 10 | AE15: 5 | AF15: 5
A16: No. | B16: RFQ No. | C16: Package Name | D16: Actual Lead Time | E16: Delivery Duration (Weeks) | F16: Deviation | G16: Float | H16: CODE | I16: Discripline | J16: Long Lead Item (Y/N) | K16: Criticality Rating | L16: Priority Level | N16: Bidder List Approval | O16: MR Issued | P16: MR Approved | Q16: RFQ Issued | R16: RFQ Approved | S16: CFT Issuance | T16: Bid Closing Date | U16: TBE Issued | V16: TBE Approved | W16: PO Issued | X16: Vendor Acknowledgement | Y16: KOM | Z16: VD Submission | AA16: Approval of Key Vendor Documents | AB16: Delivery of Major Materials | AC16: PIM | AD16: Start Production | AE16: FAT | AF16: Ready for Shipment | AG16: Receipt at WORKSITE | AH16: Punch List Clearance | AI16: Approval of Final Documentation (To be confirmed later) | AJ16: Delivery Duration (Weeks) | AK16: Lead Time | AL16: ETA date | AM16: ROS date | AN16: ROS date update | AO16: Construction Date | AP16: Remark | AQ16: Float | AT16: Remark
M17: Matrix | AT17: Installation
M18: Holiday | N18: China | O18: Thai | P18: Thai | Q18: China | R18: Thai | T18: China | U18: Thai | V18: Thai | W18: China | X18: China | Y18: China | Z18: China | AA18: Thai
A19: 1 | B19: RFQ-MEC-001 | C19: Pedestal Crane | D19: 46 | E19: 50 | F19: =E19-D19 -> 4 | I19: Mechanical | J19: Y | K19: =K22 -> 2 | L19: LA | M19: Plan | N19: =WORKDAY.INTL(O19,-INDEX(O$12:O$15,MATCH($L19,$L$12:$L$15,0)),1,IF(N$18="China",'China Holidays'!$A$2:$A$82,'Thai Holidays'!$A$2:$A$63)) -> 46121 | O19: 46122 | P19: 46136 | Q19: 46139 | R19: 46148 | S19: =R19+1 -> 46149 | T19: 46162 | U19: 46192 | V19: 46197 | W19: 46211 | X19: 46213 | Y19: 46220 | Z19: 46248 | AA19: 46262 | AB19: =AA19+45 -> 46307 | AC19: =AB19+3 -> 46310 | AD19: =AC19+3 -> 46313 | AE19: =AF19-30 -> 46517 | AF19: =AG19-14 -> 46547 | AG19: 46561 | AH19: 46575 | AI19: 46591 | AJ19: 47 | AL19: 46561 | AS19: WPA-01 | AT19: 46568
B20: =B19 -> RFQ-MEC-001 | C20: Pedestal Crane | I20: Mechanical | M20: New Plan | O20: 46122 | P20: 46145 | Q20: 46145 | R20: 46145 | S20: 46145 | T20: 46157 | U20: 46184 | V20: 46198 | W20: 46211 | X20: 46213 | Y20: 46220 | Z20: 46248 | AA20: 46262 | AB20: 46307 | AC20: 46310 | AD20: 46313 | AE20: 46496 | AF20: 46526 | AG20: 46540 | AH20: 46554 | AI20: 46570 | AL20: =W20+AK21 -> 46540 | AM20: =AM21 -> 46565 | AQ20: =AM21-AL20 -> 25
B21: =B19 -> RFQ-MEC-001 | C21: Pedestal Crane | G21: 4 | H21: 4-2.1 | I21: Mechanical | J21: Y | K21: =K22 -> 2 | L21: LA | M21: Forecast | N21: 46121 | O21: 46122 | P21: 46145 | Q21: =WORKDAY.INTL(P21,INDEX(Q$8:Q$11,MATCH($L21,$L$8:$L$11,0)),1,IF(Q$18="China",'China Holidays'!$A$2:$A$82,'Thai Holidays'!$A$2:$A$63)) -> 46145 | R21: =WORKDAY.INTL(Q21,INDEX(R$8:R$11,MATCH($L21,$L$8:$L$11,0)),1,IF(R$18="China",'China Holidays'!$A$2:$A$82,'Thai Holidays'!$A$2:$A$63)) -> 46145 | S21: =WORKDAY.INTL(R21,INDEX(S$8:S$11,MATCH($L21,$L$8:$L$11,0)),1,IF(S$18="China",'China Holidays'!$A$2:$A$82,'Thai Holidays'!$A$2:$A$63)) -> 46145 | T21: =WORKDAY.INTL(S21,INDEX(T$8:T$11,MATCH($L21,$L$8:$L$11,0)),1,IF(T$18="China",'China Holidays'!$A$2:$A$82,'Thai Holidays'!$A$2:$A$63)) -> 46157 | U21: =WORKDAY.INTL(T21,INDEX(U$8:U$11,MATCH($L21,$L$8:$L$11,0)),1,IF(U$18="China",'China Holidays'!$A$2:$A$82,'Thai Holidays'!$A$2:$A$63)) -> 46184 | V21: =WORKDAY.INTL(U21,INDEX(V$8:V$11,MATCH($L21,$L$8:$L$11,0)),1,IF(V$18="China",'China Holidays'!$A$2:$A$82,'Thai Holidays'!$A$2:$A$63)) -> 46198 | W21: =WORKDAY.INTL(V21,INDEX(W$8:W$11,MATCH($L21,$L$8:$L$11,0)),1,IF(W$18="China",'China Holidays'!$A$2:$A$82,'Thai Holidays'!$A$2:$A$63)) -> 46211 | X21: =WORKDAY.INTL(W21,INDEX(X$12:X$15,MATCH($L21,$L$12:$L$15,0)),1,IF(X$18="China",'China Holidays'!$A$2:$A$82,'Thai Holidays'!$A$2:$A$63)) -> 46213 | Y21: =WORKDAY.INTL(X21,INDEX(Y$12:Y$15,MATCH($L21,$L$12:$L$15,0)),1,IF(Y$18="China",'China Holidays'!$A$2:$A$82,'Thai Holidays'!$A$2:$A$63)) -> 46220 | Z21: =WORKDAY.INTL(Y21,INDEX(Z$12:Z$15,MATCH($L21,$L$12:$L$15,0)),1,IF(Z$18="China",'China Holidays'!$A$2:$A$82,'Thai Holidays'!$A$2:$A$63)) -> 46248 | AA21: =WORKDAY.INTL(Z21,INDEX(AA$12:AA$15,MATCH($L21,$L$12:$L$15,0)),1,IF(AA$18="China",'China Holidays'!$A$2:$A$82,'Thai Holidays'!$A$2:$A$63)) -> 46262 | AB21: =AA21+45 -> 46307 | AC21: =AB21+3 -> 46310 | AD21: =AC21+3 -> 46313 | AE21: =AF21-30 -> 46496 | AF21: =AG21-14 -> 46526 | AG21: =AL21 -> 46540 | AH21: =AL21+14 -> 46554 | AI21: =AL21+30 -> 46570 | AK21: =AJ19*7 -> 329 | AL21: =W21+AK21 -> 46540 | AM21: =AT19-3 -> 46565 | AN21: =AO21-7 -> 46561 | AO21: 46568 | AQ21: =AM21-AL21 -> 25 | AR21: =AN21-AL21 -> 21 | AS21: WPA-02 | AT21: 46574
B22: =B19 -> RFQ-MEC-001 | C22: Pedestal Crane | I22: Mechanical | J22: Y | K22: 2 | L22: LA | M22: Actual | N22: 46120 | O22: 46122 | P22: 46139 | Q22: =P22 -> 46139 | R22: =Q22 -> 46139 | S22: =R22 -> 46139 | T22: 46143 | U22: 46185 | V22: 46190 | W22: =W19-W21 -> 0 | AP22: Upper Deck
A23: =A19+1 -> 2 | B23: RFQ-MEC-002 | C23: Material Handling Equipment | D23: 14 | E23: 25 | I23: Mechanical | J23: N | K23: =K26 -> 4 | L23: LC | M23: Plan | N23: =WORKDAY.INTL(O23,-INDEX(O$12:O$15,MATCH($L23,$L$12:$L$15,0)),1,IF(N$18="China",'China Holidays'!$A$2:$A$82,'Thai Holidays'!$A$2:$A$63)) -> 46184 | O23: 46189 | P23: 46196 | Q23: 46197 | R23: 46204 | S23: =R23+1 -> 46205 | T23: 46218 | U23: 46241 | V23: 46247 | W23: 46261 | X23: 46265 | Y23: 46272 | Z23: 46293 | AA23: 46307 | AB23: 46352 | AC23: 46355 | AD23: 46356 | AE23: 46392 | AF23: 46422 | AG23: 46436 | AH23: 46450 | AI23: 46466 | AJ23: 25 | AL23: 46436 | AS23: WPA-01 | AT23: 46568
B24: =B23 -> RFQ-MEC-002 | C24: Material Handling Equipment | I24: Mechanical | M24: New Plan | O24: 46203 | P24: 46217 | Q24: 46217 | R24: 46217 | S24: 46217 | T24: 46231 | U24: 46252 | V24: 46266 | W24: 46279 | X24: 46281 | Y24: 46288 | Z24: 46317 | AA24: 46332 | AB24: 46377 | AC24: 46380 | AD24: 46381 | AE24: 46410 | AF24: 46440 | AG24: 46454 | AH24: 46468 | AI24: 46484 | AL24: =W24+AK25 -> 46454 | AQ24: =AM25-AL24 -> 111
B25: =B23 -> RFQ-MEC-002 | C25: Material Handling Equipment | G25: 111 | H25: 4-2.2 | I25: Mechanical | J25: N | K25: =K26 -> 4 | L25: LC | M25: Forecast | N25: =WORKDAY.INTL(O25,-INDEX(O$12:O$15,MATCH($L25,$L$12:$L$15,0)),1,IF(N$18="China",'China Holidays'!$A$2:$A$82,'Thai Holidays'!$A$2:$A$63)) -> 46198 | O25: 46203 | P25: =WORKDAY.INTL(O25,INDEX(P$8:P$11,MATCH($L25,$L$8:$L$11,0)),1,IF(P$18="China",'China Holidays'!$A$2:$A$82,'Thai Holidays'!$A$2:$A$63)) -> 46217 | Q25: =WORKDAY.INTL(P25,INDEX(Q$8:Q$11,MATCH($L25,$L$8:$L$11,0)),1,IF(Q$18="China",'China Holidays'!$A$2:$A$82,'Thai Holidays'!$A$2:$A$63)) -> 46217 | R25: =WORKDAY.INTL(Q25,INDEX(R$8:R$11,MATCH($L25,$L$8:$L$11,0)),1,IF(R$18="China",'China Holidays'!$A$2:$A$82,'Thai Holidays'!$A$2:$A$63)) -> 46217 | S25: =WORKDAY.INTL(R25,INDEX(S$8:S$11,MATCH($L25,$L$8:$L$11,0)),1,IF(S$18="China",'China Holidays'!$A$2:$A$82,'Thai Holidays'!$A$2:$A$63)) -> 46217 | T25: =WORKDAY.INTL(S25,INDEX(T$8:T$11,MATCH($L25,$L$8:$L$11,0)),1,IF(T$18="China",'China Holidays'!$A$2:$A$82,'Thai Holidays'!$A$2:$A$63)) -> 46231 | U25: =WORKDAY.INTL(T25,INDEX(U$8:U$11,MATCH($L25,$L$8:$L$11,0)),1,IF(U$18="China",'China Holidays'!$A$2:$A$82,'Thai Holidays'!$A$2:$A$63)) -> 46252 | V25: =WORKDAY.INTL(U25,INDEX(V$8:V$11,MATCH($L25,$L$8:$L$11,0)),1,IF(V$18="China",'China Holidays'!$A$2:$A$82,'Thai Holidays'!$A$2:$A$63)) -> 46266 | W25: =WORKDAY.INTL(V25,INDEX(W$8:W$11,MATCH($L25,$L$8:$L$11,0)),1,IF(W$18="China",'China Holidays'!$A$2:$A$82,'Thai Holidays'!$A$2:$A$63)) -> 46279 | X25: =WORKDAY.INTL(W25,INDEX(X$12:X$15,MATCH($L25,$L$12:$L$15,0)),1,IF(X$18="China",'China Holidays'!$A$2:$A$82,'Thai Holidays'!$A$2:$A$63)) -> 46281 | Y25: =WORKDAY.INTL(X25,INDEX(Y$12:Y$15,MATCH($L25,$L$12:$L$15,0)),1,IF(Y$18="China",'China Holidays'!$A$2:$A$82,'Thai Holidays'!$A$2:$A$63)) -> 46288 | Z25: =WORKDAY.INTL(Y25,INDEX(Z$12:Z$15,MATCH($L25,$L$12:$L$15,0)),1,IF(Z$18="China",'China Holidays'!$A$2:$A$82,'Thai Holidays'!$A$2:$A$63)) -> 46317 | AA25: =WORKDAY.INTL(Z25,INDEX(AA$12:AA$15,MATCH($L25,$L$12:$L$15,0)),1,IF(AA$18="China",'China Holidays'!$A$2:$A$82,'Thai Holidays'!$A$2:$A$63)) -> 46332 | AB25: =AA25+45 -> 46377 | AC25: =AB25+3 -> 46380 | AD25: =AC25+1 -> 46381 | AE25: =AF25-30 -> 46410 | AF25: =AG25-14 -> 46440 | AG25: =AL25 -> 46454 | AH25: =AL25+14 -> 46468 | AI25: =AL25+30 -> 46484 | AK25: =AJ23*7 -> 175 | AL25: =W25+AK25 -> 46454 | AM25: =AT23-3 -> 46565 | AP25: check Location | AQ25: =AM25-AL25 -> 111 | AS25: WPA-02 | AT25: 46574
B26: =B23 -> RFQ-MEC-002 | C26: Material Handling Equipment | I26: Mechanical | J26: N | K26: 4 | L26: LC | M26: Actual | O26: 46170 | P26: 46188 | Q26: 46188 | R26: 46188 | S26: 46191 | W26: =W23-W25 -> -18
A27: =A23+1 -> 3 | B27: RFQ-MEC-003 | C27: Instrument Gas Filter Coalescer | D27: 26 | E27: 25.714286 | F27: =E27-D27 -> -0.28571429 | I27: Mechanical | J27: Y | K27: =K30 -> 3 | L27: LA | M27: Plan | N27: =WORKDAY.INTL(O27,-INDEX(O$12:O$15,MATCH($L27,$L$12:$L$15,0)),1,IF(N$18="China",'China Holidays'!$A$2:$A$82,'Thai Holidays'!$A$2:$A$63)) -> 46169 | O27: 46170 | P27: 46181 | Q27: 46182 | R27: 46189 | S27: =R27+1 -> 46190 | T27: 46204 | U27: 46234 | V27: 46239 | W27: 46253 | X27: 46255 | Y27: 46262 | Z27: 46290 | AA27: 46304 | AB27: 46364 | AC27: 46367 | AD27: 46368 | AE27: 46402 | AF27: 46432 | AG27: 46433 | AH27: 46447 | AI27: 46463 | AJ27: 25.714286 | AL27: 46433 | AS27: WPA-01 | AT27: 46443
B28: =B27 -> RFQ-MEC-003 | C28: Instrument Gas Filter Coalescer | I28: Mechanical | M28: New Plan | O28: 46170 | P28: 46181 | Q28: 46182 | R28: 46189 | S28: 46190 | T28: 46204 | U28: 46224 | V28: 46240 | W28: 46253 | X28: 46255 | Y28: 46262 | Z28: 46293 | AA28: 46307 | AB28: 46367 | AC28: 46370 | AD28: 46371 | AE28: 46402 | AF28: 46432 | AG28: 46433 | AH28: 46447 | AI28: 46463 | AL28: =W28+AK29 -> 46433 | AQ28: =AM29-AL28 -> 7
B29: =B27 -> RFQ-MEC-003 | C29: Instrument Gas Filter Coalescer | G29: 7 | H29: 4-2.4 | I29: Mechanical | J29: Y | K29: =K30 -> 3 | L29: LA | M29: Forecast | O29: 46168 | P29: =WORKDAY.INTL(O29,INDEX(P$8:P$11,MATCH($L29,$L$8:$L$11,0)),1,IF(P$18="China",'China Holidays'!$A$2:$A$82,'Thai Holidays'!$A$2:$A$63)) -> 46184 | Q29: =WORKDAY.INTL(P29,INDEX(Q$8:Q$11,MATCH($L29,$L$8:$L$11,0)),1,IF(Q$18="China",'China Holidays'!$A$2:$A$82,'Thai Holidays'!$A$2:$A$63)) -> 46184 | R29: =WORKDAY.INTL(Q29,INDEX(R$8:R$11,MATCH($L29,$L$8:$L$11,0)),1,IF(R$18="China",'China Holidays'!$A$2:$A$82,'Thai Holidays'!$A$2:$A$63)) -> 46184 | S29: =WORKDAY.INTL(R29,INDEX(S$8:S$11,MATCH($L29,$L$8:$L$11,0)),1,IF(S$18="China",'China Holidays'!$A$2:$A$82,'Thai Holidays'!$A$2:$A$63)) -> 46184 | T29: =WORKDAY.INTL(S29,INDEX(T$8:T$11,MATCH($L29,$L$8:$L$11,0)),1,IF(T$18="China",'China Holidays'!$A$2:$A$82,'Thai Holidays'!$A$2:$A$63)) -> 46199 | U29: =WORKDAY.INTL(T29,INDEX(U$8:U$11,MATCH($L29,$L$8:$L$11,0)),1,IF(U$18="China",'China Holidays'!$A$2:$A$82,'Thai Holidays'!$A$2:$A$63)) -> 46224 | V29: =WORKDAY.INTL(U29,INDEX(V$8:V$11,MATCH($L29,$L$8:$L$11,0)),1,IF(V$18="China",'China Holidays'!$A$2:$A$82,'Thai Holidays'!$A$2:$A$63)) -> 46240 | W29: =WORKDAY.INTL(V29,INDEX(W$8:W$11,MATCH($L29,$L$8:$L$11,0)),1,IF(W$18="China",'China Holidays'!$A$2:$A$82,'Thai Holidays'!$A$2:$A$63)) -> 46253 | X29: =WORKDAY.INTL(W29,INDEX(X$12:X$15,MATCH($L29,$L$12:$L$15,0)),1,IF(X$18="China",'China Holidays'!$A$2:$A$82,'Thai Holidays'!$A$2:$A$63)) -> 46255 | Y29: =WORKDAY.INTL(X29,INDEX(Y$12:Y$15,MATCH($L29,$L$12:$L$15,0)),1,IF(Y$18="China",'China Holidays'!$A$2:$A$82,'Thai Holidays'!$A$2:$A$63)) -> 46262 | Z29: =WORKDAY.INTL(Y29,INDEX(Z$12:Z$15,MATCH($L29,$L$12:$L$15,0)),1,IF(Z$18="China",'China Holidays'!$A$2:$A$82,'Thai Holidays'!$A$2:$A$63)) -> 46293 | AA29: =WORKDAY.INTL(Z29,INDEX(AA$12:AA$15,MATCH($L29,$L$12:$L$15,0)),1,IF(AA$18="China",'China Holidays'!$A$2:$A$82,'Thai Holidays'!$A$2:$A$63)) -> 46307 | AB29: =AA29+60 -> 46367 | AC29: =AB29+3 -> 46370 | AD29: =AC29+1 -> 46371 | AE29: =AF29-30 -> 46402 | AF29: =AG29-1 -> 46432 | AG29: =AL29 -> 46433 | AH29: =AL29+14 -> 46447 | AI29: =AL29+30 -> 46463 | AK29: =AJ27*7 -> 180 | AL29: =W29+AK29 -> 46433 | AM29: =AT27-3 -> 46440 | AN29: =AO29-7 -> 46440 | AO29: 46447 | AQ29: =AM29-AL29 -> 7 | AS29: WPA-02 | AT29: 46464
B30: =B27 -> RFQ-MEC-003 | C30: Instrument Gas Filter Coalescer | I30: Mechanical | J30: Y | K30: 3 | L30: LA | M30: Actual | N30: 46136 | O30: 46165 | P30: 46183 | Q30: 46183 | R30: 46183 | S30: 46183 | T30: 46192 | W30: =W27-W29 -> 0 | AP30: Lower Deck
A31: =A27+1 -> 4 | B31: RFQ-MEC-004 | C31: Production & Test Seperator | D31: 34 | E31: 30 | F31: =E31-D31 -> -4 | I31: Mechanical | J31: Y | K31: =K34 -> 2 | L31: LA | M31: Plan | N31: =WORKDAY.INTL(O31,-INDEX(O$12:O$15,MATCH($L31,$L$12:$L$15,0)),1,IF(N$18="China",'China Holidays'!$A$2:$A$82,'Thai Holidays'!$A$2:$A$63)) -> 46153 | O31: 46154 | P31: 46161 | Q31: 46162 | R31: 46169 | S31: =R31+1 -> 46170 | T31: 46183 | U31: 46211 | V31: 46216 | W31: 46230 | X31: 46232 | Y31: 46239 | Z31: 46267 | AA31: 46281 | AB31: 46341 | AC31: 46344 | AD31: 46345 | AE31: 46430 | AF31: 46460 | AG31: 46461 | AH31: 46475 | AI31: 46491 | AJ31: 30 | AL31: =TEXT(AL33,"dd-mmm-yy") -> 22-Feb-27 | AS31: WPA-01 | AT31: 46450
B32: =B31 -> RFQ-MEC-004 | C32: Production & Test Seperator | I32: Mechanical | M32: New Plan | O32: 46154 | P32: 46161 | Q32: 46162 | R32: 46169 | S32: 46170 | T32: 46183 | U32: 46211 | V32: 46216 | W32: 46230 | X32: 46232 | Y32: 46239 | Z32: 46267 | AA32: 46281 | AB32: 46341 | AC32: 46344 | AD32: 46345 | AE32: 46430 | AF32: 46460 | AG32: 46461 | AH32: 46475 | AI32: 46491 | AL32: =W32+AK33 -> 46440 | AQ32: =AM33-AL32 -> 7
B33: =B31 -> RFQ-MEC-004 | C33: Production & Test Seperator | G33: 7 | H33: 4-2.3 | I33: Mechanical | J33: Y | K33: =K34 -> 2 | L33: LA | M33: Forecast | O33: 46154 | P33: =WORKDAY.INTL(O33,INDEX(P$8:P$11,MATCH($L33,$L$8:$L$11,0)),1,IF(P$18="China",'China Holidays'!$A$2:$A$82,'Thai Holidays'!$A$2:$A$63)) -> 46168 | Q33: =WORKDAY.INTL(P33,INDEX(Q$8:Q$11,MATCH($L33,$L$8:$L$11,0)),1,IF(Q$18="China",'China Holidays'!$A$2:$A$82,'Thai Holidays'!$A$2:$A$63)) -> 46168 | R33: =WORKDAY.INTL(Q33,INDEX(R$8:R$11,MATCH($L33,$L$8:$L$11,0)),1,IF(R$18="China",'China Holidays'!$A$2:$A$82,'Thai Holidays'!$A$2:$A$63)) -> 46168 | S33: =WORKDAY.INTL(R33,INDEX(S$8:S$11,MATCH($L33,$L$8:$L$11,0)),1,IF(S$18="China",'China Holidays'!$A$2:$A$82,'Thai Holidays'!$A$2:$A$63)) -> 46168 | T33: =WORKDAY.INTL(S33,INDEX(T$8:T$11,MATCH($L33,$L$8:$L$11,0)),1,IF(T$18="China",'China Holidays'!$A$2:$A$82,'Thai Holidays'!$A$2:$A$63)) -> 46182 | U33: 46203 | V33: =WORKDAY.INTL(U33,INDEX(V$8:V$11,MATCH($L33,$L$8:$L$11,0)),1,IF(V$18="China",'China Holidays'!$A$2:$A$82,'Thai Holidays'!$A$2:$A$63)) -> 46217 | W33: =WORKDAY.INTL(V33,INDEX(W$8:W$11,MATCH($L33,$L$8:$L$11,0)),1,IF(W$18="China",'China Holidays'!$A$2:$A$82,'Thai Holidays'!$A$2:$A$63)) -> 46230 | X33: =WORKDAY.INTL(W33,INDEX(X$12:X$15,MATCH($L33,$L$12:$L$15,0)),1,IF(X$18="China",'China Holidays'!$A$2:$A$82,'Thai Holidays'!$A$2:$A$63)) -> 46232 | Y33: =WORKDAY.INTL(X33,INDEX(Y$12:Y$15,MATCH($L33,$L$12:$L$15,0)),1,IF(Y$18="China",'China Holidays'!$A$2:$A$82,'Thai Holidays'!$A$2:$A$63)) -> 46239 | Z33: =WORKDAY.INTL(Y33,INDEX(Z$12:Z$15,MATCH($L33,$L$12:$L$15,0)),1,IF(Z$18="China",'China Holidays'!$A$2:$A$82,'Thai Holidays'!$A$2:$A$63)) -> 46267 | AA33: =WORKDAY.INTL(Z33,INDEX(AA$12:AA$15,MATCH($L33,$L$12:$L$15,0)),1,IF(AA$18="China",'China Holidays'!$A$2:$A$82,'Thai Holidays'!$A$2:$A$63)) -> 46281 | AB33: =AA33+60 -> 46341 | AC33: =AB33+3 -> 46344 | AD33: =AC33+1 -> 46345 | AE33: =AF33-30 -> 46409 | AF33: =AG33-1 -> 46439 | AG33: =AL33 -> 46440 | AH33: =AL33+14 -> 46454 | AI33: =AL33+30 -> 46470 | AK33: =AJ31*7 -> 210 | AL33: =W33+AK33 -> 46440 | AM33: =AT31-3 -> 46447 | AN33: =AO33-7 -> 46440 | AO33: 46447 | AQ33: =AM33-AL33 -> 7 | AS33: WPA-02 | AT33: 46464
B34: =B31 -> RFQ-MEC-004 | C34: Production & Test Seperator | I34: Mechanical | J34: Y | K34: 2 | L34: LA | M34: Actual | N34: 46136 | O34: 46157 | P34: 46182 | Q34: 46182 | R34: 46182 | S34: 46182 | T34: 46190 | U34: 46206 | W34: =W31-W33 -> 0 | AP34: Lower Deck
A35: =A31+1 -> 5 | B35: RFQ-PIP-005 | C35: QUICK OPENING CLOSURE | E35: 32 | I35: Piping | J35: Y | K35: =K38 -> 2 | L35: LA | M35: Plan | N35: =WORKDAY.INTL(O35,-INDEX(O$12:O$15,MATCH($L35,$L$12:$L$15,0)),1,IF(N$18="China",'China Holidays'!$A$2:$A$82,'Thai Holidays'!$A$2:$A$63)) -> 46156 | O35: 46157 | P35: 46164 | Q35: 46167 | R35: 46175 | S35: =R35+1 -> 46176 | T35: 46189 | U35: 46217 | V35: 46220 | W35: 46234 | X35: 46238 | Y35: 46245 | Z35: 46273 | AA35: 46287 | AB35: 46347 | AC35: 46350 | AD35: 46351 | AE35: 46427 | AF35: 46457 | AG35: 46458 | AH35: 46472 | AI35: 46488 | AJ35: 32 | AL35: =TEXT(AL37,"dd-mmm-yy") -> 12-Mar-27 | AS35: WPA-01 | AT35: 46471
B36: =B35 -> RFQ-PIP-005 | C36: QUICK OPENING CLOSURE | I36: Piping | M36: New Plan | O36: 46157 | P36: 46164 | Q36: 46167 | R36: 46175 | S36: 46176 | T36: 46189 | U36: 46217 | V36: 46220 | W36: 46234 | X36: 46238 | Y36: 46245 | Z36: 46273 | AA36: 46287 | AB36: 46347 | AC36: 46350 | AD36: 46351 | AE36: 46427 | AF36: 46457 | AG36: 46458 | AH36: 46472 | AI36: 46488 | AL36: =W36+AK37 -> 46458 | AQ36: =AM37-AL36 -> 10
B37: =B35 -> RFQ-PIP-005 | C37: QUICK OPENING CLOSURE | G37: 10 | H37: 4-2.6 | I37: Piping | J37: Y | K37: =K38 -> 2 | L37: LA | M37: Forecast | N37: =N35 -> 46156 | O37: =WORKDAY.INTL(N37,INDEX(O$8:O$11,MATCH($L37,$L$8:$L$11,0)),1,IF(O$18="China",'China Holidays'!$A$2:$A$82,'Thai Holidays'!$A$2:$A$63)) -> 46157 | P37: =WORKDAY.INTL(O37,INDEX(P$8:P$11,MATCH($L37,$L$8:$L$11,0)),1,IF(P$18="China",'China Holidays'!$A$2:$A$82,'Thai Holidays'!$A$2:$A$63)) -> 46171 | Q37: =WORKDAY.INTL(P37,INDEX(Q$8:Q$11,MATCH($L37,$L$8:$L$11,0)),1,IF(Q$18="China",'China Holidays'!$A$2:$A$82,'Thai Holidays'!$A$2:$A$63)) -> 46171 | R37: =WORKDAY.INTL(Q37,INDEX(R$8:R$11,MATCH($L37,$L$8:$L$11,0)),1,IF(R$18="China",'China Holidays'!$A$2:$A$82,'Thai Holidays'!$A$2:$A$63)) -> 46171 | S37: =WORKDAY.INTL(R37,INDEX(S$8:S$11,MATCH($L37,$L$8:$L$11,0)),1,IF(S$18="China",'China Holidays'!$A$2:$A$82,'Thai Holidays'!$A$2:$A$63)) -> 46171 | T37: =WORKDAY.INTL(S37,INDEX(T$8:T$11,MATCH($L37,$L$8:$L$11,0)),1,IF(T$18="China",'China Holidays'!$A$2:$A$82,'Thai Holidays'!$A$2:$A$63)) -> 46185 | U37: 46209 | V37: =WORKDAY.INTL(U37,INDEX(V$8:V$11,MATCH($L37,$L$8:$L$11,0)),1,IF(V$18="China",'China Holidays'!$A$2:$A$82,'Thai Holidays'!$A$2:$A$63)) -> 46223 | W37: =WORKDAY.INTL(V37,INDEX(W$8:W$11,MATCH($L37,$L$8:$L$11,0)),1,IF(W$18="China",'China Holidays'!$A$2:$A$82,'Thai Holidays'!$A$2:$A$63)) -> 46234 | X37: =WORKDAY.INTL(W37,INDEX(X$12:X$15,MATCH($L37,$L$12:$L$15,0)),1,IF(X$18="China",'China Holidays'!$A$2:$A$82,'Thai Holidays'!$A$2:$A$63)) -> 46238 | Y37: =WORKDAY.INTL(X37,INDEX(Y$12:Y$15,MATCH($L37,$L$12:$L$15,0)),1,IF(Y$18="China",'China Holidays'!$A$2:$A$82,'Thai Holidays'!$A$2:$A$63)) -> 46245 | Z37: =WORKDAY.INTL(Y37,INDEX(Z$12:Z$15,MATCH($L37,$L$12:$L$15,0)),1,IF(Z$18="China",'China Holidays'!$A$2:$A$82,'Thai Holidays'!$A$2:$A$63)) -> 46273 | AA37: =WORKDAY.INTL(Z37,INDEX(AA$12:AA$15,MATCH($L37,$L$12:$L$15,0)),1,IF(AA$18="China",'China Holidays'!$A$2:$A$82,'Thai Holidays'!$A$2:$A$63)) -> 46287 | AB37: =AA37+60 -> 46347 | AC37: =AB37+3 -> 46350 | AD37: =AC37+1 -> 46351 | AE37: =AF37-30 -> 46427 | AF37: =AG37-1 -> 46457 | AG37: =AL37 -> 46458 | AH37: =AL37+14 -> 46472 | AI37: =AL37+30 -> 46488 | AK37: =AJ35*7 -> 224 | AL37: =W37+AK37 -> 46458 | AM37: =AT35-3 -> 46468 | AN37: =AO37-7 -> 46464 | AO37: 46471 | AP37: Lower Deck | AQ37: =AM37-AL37 -> 10 | AS37: WPA-02 | AT37: 46472
B38: =B35 -> RFQ-PIP-005 | C38: QUICK OPENING CLOSURE | I38: Piping | J38: Y | K38: 2 | L38: LA | M38: Actual | N38: 46136 | O38: 46163 | P38: 46182 | Q38: 46182 | R38: 46182 | S38: 46182 | T38: 46206 | W38: =W35-W37 -> 0
A39: =A35+1 -> 6 | B39: RFQ-MEC-006 | C39: Chemical Injection Pump | D39: 32 | E39: 34 | F39: =E39-D39 -> 2 | I39: Mechanical | J39: Y | K39: =K42 -> 3 | L39: LA | M39: Plan | N39: =WORKDAY.INTL(O39,-INDEX(O$12:O$15,MATCH($L39,$L$12:$L$15,0)),1,IF(N$18="China",'China Holidays'!$A$2:$A$82,'Thai Holidays'!$A$2:$A$63)) -> 46150 | O39: 46153 | P39: 46160 | Q39: 46161 | R39: 46168 | S39: =R39+1 -> 46169 | T39: 46182 | U39: 46210 | V39: 46213 | W39: 46227 | X39: 46231 | Y39: 46238 | Z39: 46266 | AA39: 46280 | AB39: 46392 | AC39: 46395 | AD39: 46396 | AE39: 46421 | AF39: 46451 | AG39: 46465 | AH39: 46479 | AI39: 46495 | AJ39: 32 | AL39: =TEXT(AL41,"dd-mmm-yy") -> 05-Mar-27 | AS39: WPA-01 | AT39: 46472
B40: =B39 -> RFQ-MEC-006 | C40: Chemical Injection Pump | I40: Mechanical | M40: New Plan | O40: 46153 | P40: 46160 | Q40: 46161 | R40: 46168 | S40: 46169 | T40: 46182 | U40: 46210 | V40: 46213 | W40: 46227 | X40: 46231 | Y40: 46238 | Z40: 46266 | AA40: 46280 | AB40: 46392 | AC40: 46395 | AD40: 46396 | AE40: 46421 | AF40: 46451 | AG40: 46465 | AH40: 46479 | AI40: 46495 | AL40: =W40+AK41 -> 46451 | AQ40: =AM41-AL40 -> 18
B41: =B39 -> RFQ-MEC-006 | C41: Chemical Injection Pump | G41: 4 | H41: 4-2.8 | I41: Mechanical | J41: Y | K41: =K42 -> 3 | L41: LA | M41: Forecast | O41: 46157 | P41: =WORKDAY.INTL(O41,INDEX(P$8:P$11,MATCH($L41,$L$8:$L$11,0)),1,IF(P$18="China",'China Holidays'!$A$2:$A$82,'Thai Holidays'!$A$2:$A$63)) -> 46171 | Q41: =WORKDAY.INTL(P41,INDEX(Q$8:Q$11,MATCH($L41,$L$8:$L$11,0)),1,IF(Q$18="China",'China Holidays'!$A$2:$A$82,'Thai Holidays'!$A$2:$A$63)) -> 46171 | R41: =WORKDAY.INTL(Q41,INDEX(R$8:R$11,MATCH($L41,$L$8:$L$11,0)),1,IF(R$18="China",'China Holidays'!$A$2:$A$82,'Thai Holidays'!$A$2:$A$63)) -> 46171 | S41: =WORKDAY.INTL(R41,INDEX(S$8:S$11,MATCH($L41,$L$8:$L$11,0)),1,IF(S$18="China",'China Holidays'!$A$2:$A$82,'Thai Holidays'!$A$2:$A$63)) -> 46171 | T41: =WORKDAY.INTL(S41,INDEX(T$8:T$11,MATCH($L41,$L$8:$L$11,0)),1,IF(T$18="China",'China Holidays'!$A$2:$A$82,'Thai Holidays'!$A$2:$A$63)) -> 46185 | U41: 46202 | V41: =WORKDAY.INTL(U41,INDEX(V$8:V$11,MATCH($L41,$L$8:$L$11,0)),1,IF(V$18="China",'China Holidays'!$A$2:$A$82,'Thai Holidays'!$A$2:$A$63)) -> 46216 | W41: =WORKDAY.INTL(V41,INDEX(W$8:W$11,MATCH($L41,$L$8:$L$11,0)),1,IF(W$18="China",'China Holidays'!$A$2:$A$82,'Thai Holidays'!$A$2:$A$63)) -> 46227 | X41: =WORKDAY.INTL(W41,INDEX(X$12:X$15,MATCH($L41,$L$12:$L$15,0)),1,IF(X$18="China",'China Holidays'!$A$2:$A$82,'Thai Holidays'!$A$2:$A$63)) -> 46231 | Y41: =WORKDAY.INTL(X41,INDEX(Y$12:Y$15,MATCH($L41,$L$12:$L$15,0)),1,IF(Y$18="China",'China Holidays'!$A$2:$A$82,'Thai Holidays'!$A$2:$A$63)) -> 46238 | Z41: =WORKDAY.INTL(Y41,INDEX(Z$12:Z$15,MATCH($L41,$L$12:$L$15,0)),1,IF(Z$18="China",'China Holidays'!$A$2:$A$82,'Thai Holidays'!$A$2:$A$63)) -> 46266 | AA41: =WORKDAY.INTL(Z41,INDEX(AA$12:AA$15,MATCH($L41,$L$12:$L$15,0)),1,IF(AA$18="China",'China Holidays'!$A$2:$A$82,'Thai Holidays'!$A$2:$A$63)) -> 46280 | AB41: =AA41+16*7 -> 46392 | AC41: =AB41+3 -> 46395 | AD41: =AC41+1 -> 46396 | AE41: =AF41-30 -> 46407 | AF41: =AG41-14 -> 46437 | AG41: =AL41 -> 46451 | AH41: =AL41+14 -> 46465 | AI41: =AL41+30 -> 46481 | AK41: =AJ39*7 -> 224 | AL41: =W41+AK41 -> 46451 | AM41: =AT39-3 -> 46469 | AN41: =AO41-7 -> 46465 | AO41: 46472 | AQ41: =AM41-AL41 -> 18 | AS41: WPA-02 | AT41: 46477
B42: =B39 -> RFQ-MEC-006 | C42: Chemical Injection Pump | I42: Mechanical | J42: Y | K42: 3 | L42: LA | M42: Actual | N42: 46133 | O42: 46157 | P42: 46182 | Q42: 46182 | R42: 46182 | S42: 46182 | T42: 46183 | U42: 46206 | W42: =W39-W41 -> 0 | AP42: Lower Deck
...

Sheet Sheet1
D3: 46054
D4: 46082 | E4: 1
D5: 46113 | E5: 2
D6: 46143 | E6: 3
D7: 46174 | E7: 4
D8: 46204 | E8: 5
D9: 46235 | E9: 6
D10: 46266 | E10: 7
D11: 46296 | E11: 8
D12: 46327 | E12: 9
D13: 46357 | E13: 10
D14: 46388 | E14: 11
D15: 46419 | E15: 12
... D22: 46631 | E22: 19

Sheet P6
A1: ActivityID | B1: Activity Name | C1: Planned Duration | D1: Start | E1: Finish | F1: Total Float | G1: Calendar
A2: DETAILENGINEERINGFORWELLHEADPLATFORMS(WPA01ANDWPA02)(ASKPROJECT) | C2: 211 | D2: 46085 | E2: 46405 | F2: 0 | G2: PTTME Office 5dx8h
A3: PROJECTMILESTONE | C3: 211 | D3: 46085 | E3: 46405 | F3: 0 | G3: PTTME Office 5dx8h
A4: MI-1000 | B4: Project Start, KOM | C4: 0 | D4: 46085 | F4: -47 | G4: PTTME Office 5dx8h
A5: MI-1010 | B5: P&ID Issue for Review | C5: 0 | E5: 27-Apr-26* | F5: -7 | G5: PTTME Office 5dx8h
A6: MI-1020 | B6: 30% Model Review | C6: 2 | D6: 46155 | E6: 46156 | F6: 10 | G6: PTTME Office 5dx8h
A7: MI-1030 | B7: P&ID issue for HAZOP | C7: 0 | E7: 46170 | F7: 22 | G7: PTTME Office 5dx8h
A8: MI-1040 | B8: HAZID Review Meeting | C8: 2 | D8: 46162 | E8: 46163 | F8: 105 | G8: PTTME Office 5dx8h
A9: MI-1050 | B9: HAZOP Review Meeting | C9: 5 | D9: 46178 | E9: 46184 | F9: 22 | G9: PTTME Office 5dx8h
A10: MI-1060 | B10: SIL Review Meeting | C10: 2 | D10: 46192 | E10: 46195 | F10: 75 | G10: PTTME Office 5dx8h
A11: MI-1070 | B11: Structural - Primary MTO Issue for review | C11: 0 | E11: 26-May-26* | F11: 0 | G11: PTTME Office 5dx8h
A12: MI-1080 | B12: 60% Model Review | C12: 5 | D12: 46258 | E12: 46262 | F12: 0 | G12: PTTME Office 5dx8h
A13: MI-1090 | B13: 90% Model Review | C13: 1 | D13: 46321 | E13: 46321 | F13: 11 | G13: PTTME Office 5dx8h
A14: MI-1100 | B14: Issue all AFC Documents /Drawing | C14: 0 | E14: 46392 | F14: 0 | G14: PTTME Office 5dx8h
A15: MI-1110 | B15: Design Engineering Compilation | C15: 0 | E15: 46405 | F15: 0 | G15: PTTME Office 5dx8h
A16: GENERALSTUDIES | C16: 35 | D16: 46086 | E16: 46140 | F16: 166 | G16: PTTME Office 5dx8h
A17: PJ-1000 | B17: Master Deliverable Register - IFR | C17: 10 | D17: 46086 | E17: 46099 | F17: 166 | G17: PTTME Office 5dx8h
A18: PJ-1010 | B18: Master Deliverable Register - AFC | C18: 5 | D18: 46114 | E18: 46121 | F18: 171 | G18: PTTME Office 5dx8h
A19: PJ-1020 | B19: Engineering Master Schedule - IFR | C19: 10 | D19: 46100 | E19: 46113 | F19: 166 | G19: PTTME Office 5dx8h
A20: PJ-1030 | B20: Engineering Master Schedule - AFC | C20: 5 | D20: 46134 | E20: 46140 | F20: 166 | G20: PTTME Office 5dx8h
A21: PROCESSANDUTILITIESENGINEERING | C21: 80 | D21: 46106 | E21: 46226 | F21: 107 | G21: PTTME Office 5dx8h
A22: PR-1000 | B22: Process Basis of Design - IFR | C22: 10 | D22: 46113 | E22: 46132 | F22: 33 | G22: PTTME Office 5dx8h
A23: PR-1010 | B23: Process Basis of Design - IFA | C23: 5 | D23: 46148 | E23: 46154 | F23: 33 | G23: PTTME Office 5dx8h
A24: PR-1020 | B24: Process Basis of Design - AFC | C24: 5 | D24: 46169 | E24: 46177 | F24: 33 | G24: PTTME Office 5dx8h
A25: PR-1090 | B25: Process Simulation Report - IFR | C25: 5 | D25: 46185 | E25: 46191 | F25: 117 | G25: PTTME Office 5dx8h
A26: PR-1100 | B26: Process Simulation Report - AFC | C26: 5 | D26: 46206 | E26: 46212 | F26: 117 | G26: PTTME Office 5dx8h
A27: PR-1110 | B27: Utility Balance and Consumption Report - IFR | C27: 10 | D27: 46185 | E27: 46198 | F27: 112 | G27: PTTME Office 5dx8h
A28: PR-1120 | B28: Utility Balance and Consumption Report - AFC | C28: 5 | D28: 46213 | E28: 46219 | F28: 112 | G28: PTTME Office 5dx8h
A29: PR-1130 | B29: AIV And FIV Study Report - IFR | C29: 15 | D29: 46162 | E29: 46184 | F29: 109 | G29: PTTME Office 5dx8h
A30: PR-1140 | B30: AIV And FIV Study Report - AFC | C30: 5 | D30: 46199 | E30: 46205 | F30: 122 | G30: PTTME Office 5dx8h
A31: PR-1150 | B31: Depressurization and Low Temperature Study Report - IFR | C31: 20 | D31: 46175 | E31: 46203 | F31: 109 | G31: PTTME Office 5dx8h
A32: PR-1160 | B32: Depressurization and Low Temperature Study Report - AFC | C32: 5 | D32: 46218 | E32: 46224 | F32: 109 | G32: PTTME Office 5dx8h
A33: PR-1170 | B33: Vent Sizing and Relief Load Report - IFR | C33: 13 | D33: 46175 | E33: 46192 | F33: 116 | G33: PTTME Office 5dx8h
... A83: PR-1650 | B83: Transient Flow Assurance Study Report - AFC | C83: 5 | D83: 46220 | E83: 46226 | F83: 107 | G83: PTTME Office 5dx8h
A84: ProcessCalculationNote | C84: 45 | D84: 46140 | E84: 46205 | F84: -17 | G84: PTTME Office 5dx8h
A85: PR-1660 | B85: Process Calculation Note for Line Sizing - IFR | C85: 23 | D85: 46140 | E85: 46171 | F85: -10 | G85: PTTME Office 5dx8h
A86: PR-1670 | B86: Process Calculation Note for Line Sizing - AFC | C86: 5 | D86: 46199 | E86: 46205 | F86: -17 | G86: PTTME Office 5dx8h
A87: PR-1680 | B87: Process Calculation Note for Test Separator Sizing - IFR | C87: 15 | D87: 46140 | E87: 46161 | F87: -2 | G87: PTTME Office 5dx8h
A88: PR-1690 | B88: Process Calculation Note for Test Separator Sizing - AFC | C88: 5 | D88: 46199 | E88: 46205 | F88: -17 | G88: PTTME Office 5dx8h
A89: PR-1700 | B89: Process Calculation Note for Production Separator (V-01001) - IFR | C89: 15 | D89: 46140 | E89: 46161 | F89: -2 | G89: PTTME Office 5dx8h
...

Sheet Before Award
A1: ZM167 PTTEPI ASK Procurement Plan - Before Award
I12: LA | L12: 1 | M12: 5 | N12: 1 | O12: 5 | R12: 10 | S12: 20 | T12: 3 | U12: 10 | V12: 2 | W12: =SUM(L12:V12) -> 57 | AP12: 2 | AQ12: 4 | AR12: 5
I13: LB | L13: 1 | M13: 5 | N13: 1 | O13: 5 | R13: 10 | S13: 20 | T13: 3 | U13: 10 | V13: 2 | W13: =SUM(L13:V13) -> 57 | AP13: 2 | AQ13: 4 | AR13: 5
I14: LC | L14: 3 | M14: 10 | N14: 1 | O14: 10 | R14: 10 | S14: 15 | T14: 10 | U14: 10 | V14: 2 | W14: =SUM(L14:V14) -> 71 | AP14: 2 | AQ14: 2 | AR14: 5
I15: LD | L15: 3 | M15: 5 | N15: 1 | O15: 3 | R15: 5 | S15: 7 | T15: 2 | U15: 5 | V15: 2 | W15: =SUM(L15:V15) -> 33 | AP15: 2 | AQ15: 2 | AR15: 5
A16: No. | B16: MR.No | C16: RFQ No. | D16: Package Name | E16: PO NO. | F16: Discripline | G16: Long Lead Item (Y/N) | H16: Criticality Rating | I16: Priority Level | K16: Bidder List Approval | L16: MR Issued | M16: MR Approved | N16: RFQ Issued | O16: RFQ Approved | P16: Bidding Duration | Q16: CFT Issuance | R16: Bid Closing Date | S16: TBE Issued | T16: TBE Approved | U16: PO Issued | V16: Vendor Acknowledgement | W16: Delivery Duration (Weeks) | X16: Delivery Date | Y16: Lead Time (Days) | Z16: ROS date | AA16: Earlier ROS date | AB16: Float (Day) | AC16: 40329 | AD16: 40359 | AE16: 40390 | AF16: 40421 | AG16: 40451 | AH16: 40482 | AI16: 40512 | AJ16: 40543 | AK16: 40574 | AL16: 40602 | AM16: =TODAY() -> 46209 | AP16: Final&Best Proposal Submission | AQ16: TJE CBE approval (LOI Issue) | AR16: MRP | AS16: Transportation time
A17: 1 | C17: RFQ-001 | D17: Pedestal Crane | F17: Mechanical | G17: =IF(_xlfn.XLOOKUP(C17,'[35]Before Award'!D:D,'[35]Before Award'!AV:AV,"N/A")="N/A","N","Y") -> N | I17: LA | J17: Plan | K17: =WORKDAY(L17,-INDEX(L$12:L$15,MATCH($I17,$I$12:$I$15,0))) -> 46140 | L17: =WORKDAY(M17,-INDEX(M$12:M$15,MATCH($I17,$I$12:$I$15,0))) -> 46141 | M17: =WORKDAY(N17,-INDEX(N$12:N$15,MATCH($I17,$I$12:$I$15,0))) -> 46148 | N17: =WORKDAY(O17,-INDEX(O$12:O$15,MATCH($I17,$I$12:$I$15,0))) -> 46149 | O17: =WORKDAY(R17,-INDEX(R$12:R$15,MATCH($I17,$I$12:$I$15,0))) -> 46156 | P17: =U17-L17 -> 76 | R17: =WORKDAY(S17,-INDEX(S$12:S$15,MATCH($I17,$I$12:$I$15,0))) -> 46170 | S17: =WORKDAY(T17,-INDEX(T$12:T$15,MATCH($I17,$I$12:$I$15,0))) -> 46198 | T17: =WORKDAY(U17,-INDEX(U$12:U$15,MATCH($I17,$I$12:$I$15,0))) -> 46203 | U17: =X17-Y17 -> 46217 | V17: =WORKDAY(U17,INDEX(V$12:V$15,MATCH($I17,$I$12:$I$15,0))) -> 46219 | W17: =Y17/7 -> 50 | X17: =Z17 -> 46567 | Y17: 350 | Z17: 46567 | AA17: 46567 | AB17: =Z17-X18 -> 0 | AC17: =IF(ISERROR(LOOKUP(AC$16,$L17:$X17,#REF!)),0,(LOOKUP(AC$16,$L17:$X17,#REF!))) -> 0 | AD17: =IF(ISERROR(LOOKUP(AD$16,$L17:$X17,#REF!)),0,(LOOKUP(AD$16,$L17:$X17,#REF!))) -> 0 | AE17: =IF(ISERROR(LOOKUP(AE$16,$L17:$X17,#REF!)),0,(LOOKUP(AE$16,$L17:$X17,#REF!))) -> 0 | AF17: =IF(ISERROR(LOOKUP(AF$16,$L17:$X17,#REF!)),0,(LOOKUP(AF$16,$L17:$X17,#REF!))) -> 0 | AG17: =IF(ISERROR(LOOKUP(AG$16,$L17:$X17,#REF!)),0,(LOOKUP(AG$16,$L17:$X17,#REF!))) -> 0 | AH17: =IF(ISERROR(LOOKUP(AH$16,$L17:$X17,#REF!)),0,(LOOKUP(AH$16,$L17:$X17,#REF!))) -> 0 | AI17: =IF(ISERROR(LOOKUP(AI$16,$L17:$X17,#REF!)),0,(LOOKUP(AI$16,$L17:$X17,#REF!))) -> 0 | AJ17: =IF(ISERROR(LOOKUP(AJ$16,$L17:$X17,#REF!)),0,(LOOKUP(AJ$16,$L17:$X17,#REF!))) -> 0 | ... AM17: =IF(ISERROR(LOOKUP(AM$16,$L17:$X17,#REF!)),0,(LOOKUP(AM$16,$L17:$X17,#REF!))) -> 0 | AO17: =U17-T17 -> 14 | AP17: =WORKDAY(AQ17,-INDEX(AQ$12:AQ$15,MATCH($I17,$I$12:$I$15,0)),$AW$17:$AW$148) -> #REF! | AQ17: =WORKDAY(U17,-INDEX(U$12:U$15,MATCH($I17,$I$12:$I$15,0)),$AW$17:$AW$148) -> #REF! | AR17: =WORKDAY(U17,-INDEX(U$12:U$15,MATCH($I17,$I$12:$I$15,0)),$AW$17:$AW$148) -> #REF! | AS17: 14 | AW17: {='[35]Equipment List and MR List (3)'!$A$2:$A$80} -> #REF!
C18: =C17 -> RFQ-001 | D18: =D17 -> Pedestal Crane | I18: =I17 -> LA | J18: Forecast | K18: =K17 -> 46140 | L18: =WORKDAY(IF(K19="",K18,K19),INDEX(L$12:L$15,MATCH($I17,$I$12:$I$15,0))) -> 46141 | M18: =WORKDAY(IF(L19="",L18,L19),INDEX(M$12:M$15,MATCH($I17,$I$12:$I$15,0))) -> 46148 | N18: =WORKDAY(IF(M19="",M18,M19),INDEX(N$12:N$15,MATCH($I17,$I$12:$I$15,0))) -> 46149 | O18: =WORKDAY(IF(N19="",N18,N19),INDEX(O$12:O$15,MATCH($I17,$I$12:$I$15,0))) -> 46156 | R18: =WORKDAY(IF(O19="",O18,O19),INDEX(R$12:R$15,MATCH($I17,$I$12:$I$15,0))) -> 46170 | S18: =WORKDAY(IF(R19="",R18,R19),INDEX(S$12:S$15,MATCH($I17,$I$12:$I$15,0))) -> 46198 | T18: =WORKDAY(IF(S19="",S18,S19),INDEX(T$12:T$15,MATCH($I17,$I$12:$I$15,0))) -> 46203 | U18: =WORKDAY(IF(T19="",T18,T19),INDEX(U$12:U$15,MATCH($I17,$I$12:$I$15,0))) -> 46217 | V18: =WORKDAY(IF(U19="",U18,U19),INDEX(V$12:V$15,MATCH($I17,$I$12:$I$15,0))) -> 46219 | X18: =U18+Y17 -> 46567 | AC18: =IF(ISERROR(LOOKUP(AC$16,$L18:$X18,#REF!)),0,(LOOKUP(AC$16,$L18:$X18,#REF!))) -> 0 | AD18: =IF(ISERROR(LOOKUP(AD$16,$L18:$X18,#REF!)),0,(LOOKUP(AD$16,$L18:$X18,#REF!))) -> 0 | AE18: =IF(ISERROR(LOOKUP(AE$16,$L18:$X18,#REF!)),0,(LOOKUP(AE$16,$L18:$X18,#REF!))) -> 0 | AF18: =IF(ISERROR(LOOKUP(AF$16,$L18:$X18,#REF!)),0,(LOOKUP(AF$16,$L18:$X18,#REF!))) -> 0 | AG18: =IF(ISERROR(LOOKUP(AG$16,$L18:$X18,#REF!)),0,(LOOKUP(AG$16,$L18:$X18,#REF!))) -> 0 | AH18: =IF(ISERROR(LOOKUP(AH$16,$L18:$X18,#REF!)),0,(LOOKUP(AH$16,$L18:$X18,#REF!))) -> 0 | AI18: =IF(ISERROR(LOOKUP(AI$16,$L18:$X18,#REF!)),0,(LOOKUP(AI$16,$L18:$X18,#REF!))) -> 0 | AJ18: =IF(ISERROR(LOOKUP(AJ$16,$L18:$X18,#REF!)),0,(LOOKUP(AJ$16,$L18:$X18,#REF!))) -> 0 | ... AM18: =IF(ISERROR(LOOKUP(AM$16,$L18:$X18,#REF!)),0,(LOOKUP(AM$16,$L18:$X18,#REF!))) -> 0 | AO18: =U18-T18 -> 14 | AP18: =WORKDAY(IF(T19="",T18,T19),INDEX(AP$12:AP$15,MATCH($I17,$I$12:$I$15,0)),$AW$17:$AW$148) -> #REF! | AQ18: =WORKDAY(IF(AP19="",AP18,AP19),INDEX(AQ$12:AQ$15,MATCH($I17,$I$12:$I$15,0)),$AW$17:$AW$148) -> #REF! | AR18: =WORKDAY(IF(AQ19="",AQ18,AQ19),INDEX(AR$12:AR$15,MATCH($I17,$I$12:$I$15,0)),$AW$17:$AW$148) -> #REF! | AW18: #REF!
C19: =C17 -> RFQ-001 | D19: =D17 -> Pedestal Crane | I19: =I17 -> LA | J19: Actual | AC19: =IF(ISERROR(LOOKUP(AC$16,$L19:$X19,#REF!)),0,(LOOKUP(AC$16,$L19:$X19,#REF!))) -> 0 | AD19: =IF(ISERROR(LOOKUP(AD$16,$L19:$X19,#REF!)),0,(LOOKUP(AD$16,$L19:$X19,#REF!))) -> 0 | AE19: =IF(ISERROR(LOOKUP(AE$16,$L19:$X19,#REF!)),0,(LOOKUP(AE$16,$L19:$X19,#REF!))) -> 0 | AF19: =IF(ISERROR(LOOKUP(AF$16,$L19:$X19,#REF!)),0,(LOOKUP(AF$16,$L19:$X19,#REF!))) -> 0 | AG19: =IF(ISERROR(LOOKUP(AG$16,$L19:$X19,#REF!)),0,(LOOKUP(AG$16,$L19:$X19,#REF!))) -> 0 | AH19: =IF(ISERROR(LOOKUP(AH$16,$L19:$X19,#REF!)),0,(LOOKUP(AH$16,$L19:$X19,#REF!))) -> 0 | AI19: =IF(ISERROR(LOOKUP(AI$16,$L19:$X19,#REF!)),0,(LOOKUP(AI$16,$L19:$X19,#REF!))) -> 0 | AJ19: =IF(ISERROR(LOOKUP(AJ$16,$L19:$X19,#REF!)),0,(LOOKUP(AJ$16,$L19:$X19,#REF!))) -> 0 | ... AM19: =IF(ISERROR(LOOKUP(AM$16,$L19:$X19,#REF!)),0,(LOOKUP(AM$16,$L19:$X19,#REF!))) -> 0 | AO19: =U19-T19 -> 0 | AW19: #REF!
A20: =A17+1 -> 2 | C20: RFQ-002 | D20: Material Handling Equipment | F20: Mechanical | G20: N | I20: LC | J20: Plan | K20: =WORKDAY(L20,-INDEX(L$12:L$15,MATCH($I20,$I$12:$I$15,0))) -> 46296 | L20: =WORKDAY(M20,-INDEX(M$12:M$15,MATCH($I20,$I$12:$I$15,0))) -> 46301 | M20: =WORKDAY(N20,-INDEX(N$12:N$15,MATCH($I20,$I$12:$I$15,0))) -> 46315 | N20: =WORKDAY(O20,-INDEX(O$12:O$15,MATCH($I20,$I$12:$I$15,0))) -> 46316 | O20: =WORKDAY(R20,-INDEX(R$12:R$15,MATCH($I20,$I$12:$I$15,0))) -> 46330 | P20: =U20-L20 -> 92 | R20: =WORKDAY(S20,-INDEX(S$12:S$15,MATCH($I20,$I$12:$I$15,0))) -> 46344 | S20: =WORKDAY(T20,-INDEX(T$12:T$15,MATCH($I20,$I$12:$I$15,0))) -> 46365 | T20: =WORKDAY(U20,-INDEX(U$12:U$15,MATCH($I20,$I$12:$I$15,0))) -> 46379 | U20: =X20-Y20 -> 46393 | V20: =WORKDAY(U20,INDEX(V$12:V$15,MATCH($I20,$I$12:$I$15,0))) -> 46395 | W20: =Y20/7 -> 25 | X20: =Z20 -> 46568 | Y20: 175 | Z20: 46568 | AA20: 46568 | AB20: =Z20-X21 -> 0 | AC20: =IF(ISERROR(LOOKUP(AC$16,$L20:$X20,#REF!)),0,(LOOKUP(AC$16,$L20:$X20,#REF!))) -> 0 | AD20: =IF(ISERROR(LOOKUP(AD$16,$L20:$X20,#REF!)),0,(LOOKUP(AD$16,$L20:$X20,#REF!))) -> 0 | AE20: =IF(ISERROR(LOOKUP(AE$16,$L20:$X20,#REF!)),0,(LOOKUP(AE$16,$L20:$X20,#REF!))) -> 0 | AF20: =IF(ISERROR(LOOKUP(AF$16,$L20:$X20,#REF!)),0,(LOOKUP(AF$16,$L20:$X20,#REF!))) -> 0 | AG20: =IF(ISERROR(LOOKUP(AG$16,$L20:$X20,#REF!)),0,(LOOKUP(AG$16,$L20:$X20,#REF!))) -> 0 | AH20: =IF(ISERROR(LOOKUP(AH$16,$L20:$X20,#REF!)),0,(LOOKUP(AH$16,$L20:$X20,#REF!))) -> 0 | AI20: =IF(ISERROR(LOOKUP(AI$16,$L20:$X20,#REF!)),0,(LOOKUP(AI$16,$L20:$X20,#REF!))) -> 0 | AJ20: =IF(ISERROR(LOOKUP(AJ$16,$L20:$X20,#REF!)),0,(LOOKUP(AJ$16,$L20:$X20,#REF!))) -> 0 | ... AM20: =IF(ISERROR(LOOKUP(AM$16,$L20:$X20,#REF!)),0,(LOOKUP(AM$16,$L20:$X20,#REF!))) -> 0 | AO20: =U20-T20 -> 14 | AP20: =WORKDAY(AQ20,-INDEX(AQ$12:AQ$15,MATCH($I20,$I$12:$I$15,0)),$AW$17:$AW$148) -> #REF! | AQ20: =WORKDAY(U20,-INDEX(U$12:U$15,MATCH($I20,$I$12:$I$15,0)),$AW$17:$AW$148) -> #REF! | AR20: =WORKDAY(U20,-INDEX(U$12:U$15,MATCH($I20,$I$12:$I$15,0)),$AW$17:$AW$148) -> #REF! | AS20: 14 | AW20: #REF!
C21: =C20 -> RFQ-002 | D21: =D20 -> Material Handling Equipment | G21: =G20 -> N | I21: =I20 -> LC | J21: Forecast | K21: =K20 -> 46296 | L21: =WORKDAY(IF(K22="",K21,K22),INDEX(L$12:L$15,MATCH($I20,$I$12:$I$15,0))) -> 46301 | M21: =WORKDAY(IF(L22="",L21,L22),INDEX(M$12:M$15,MATCH($I20,$I$12:$I$15,0))) -> 46315 | N21: =WORKDAY(IF(M22="",M21,M22),INDEX(N$12:N$15,MATCH($I20,$I$12:$I$15,0))) -> 46316 | O21: =WORKDAY(IF(N22="",N21,N22),INDEX(O$12:O$15,MATCH($I20,$I$12:$I$15,0))) -> 46330 | R21: =WORKDAY(IF(O22="",O21,O22),INDEX(R$12:R$15,MATCH($I20,$I$12:$I$15,0))) -> 46344 | S21: =WORKDAY(IF(R22="",R21,R22),INDEX(S$12:S$15,MATCH($I20,$I$12:$I$15,0))) -> 46365 | T21: =WORKDAY(IF(S22="",S21,S22),INDEX(T$12:T$15,MATCH($I20,$I$12:$I$15,0))) -> 46379 | U21: =WORKDAY(IF(T22="",T21,T22),INDEX(U$12:U$15,MATCH($I20,$I$12:$I$15,0))) -> 46393 | V21: =WORKDAY(IF(U22="",U21,U22),INDEX(V$12:V$15,MATCH($I20,$I$12:$I$15,0))) -> 46395 | X21: =U21+Y20 -> 46568 | AC21: =IF(ISERROR(LOOKUP(AC$16,$L21:$X21,#REF!)),0,(LOOKUP(AC$16,$L21:$X21,#REF!))) -> 0 | AD21: =IF(ISERROR(LOOKUP(AD$16,$L21:$X21,#REF!)),0,(LOOKUP(AD$16,$L21:$X21,#REF!))) -> 0 | AE21: =IF(ISERROR(LOOKUP(AE$16,$L21:$X21,#REF!)),0,(LOOKUP(AE$16,$L21:$X21,#REF!))) -> 0 | AF21: =IF(ISERROR(LOOKUP(AF$16,$L21:$X21,#REF!)),0,(LOOKUP(AF$16,$L21:$X21,#REF!))) -> 0 | AG21: =IF(ISERROR(LOOKUP(AG$16,$L21:$X21,#REF!)),0,(LOOKUP(AG$16,$L21:$X21,#REF!))) -> 0 | AH21: =IF(ISERROR(LOOKUP(AH$16,$L21:$X21,#REF!)),0,(LOOKUP(AH$16,$L21:$X21,#REF!))) -> 0 | AI21: =IF(ISERROR(LOOKUP(AI$16,$L21:$X21,#REF!)),0,(LOOKUP(AI$16,$L21:$X21,#REF!))) -> 0 | AJ21: =IF(ISERROR(LOOKUP(AJ$16,$L21:$X21,#REF!)),0,(LOOKUP(AJ$16,$L21:$X21,#REF!))) -> 0 | ... AM21: =IF(ISERROR(LOOKUP(AM$16,$L21:$X21,#REF!)),0,(LOOKUP(AM$16,$L21:$X21,#REF!))) -> 0 | AO21: =U21-T21 -> 14 | AP21: =WORKDAY(IF(T22="",T21,T22),INDEX(AP$12:AP$15,MATCH($I20,$I$12:$I$15,0)),$AW$17:$AW$148) -> #REF! | AQ21: =WORKDAY(IF(AP22="",AP21,AP22),INDEX(AQ$12:AQ$15,MATCH($I20,$I$12:$I$15,0)),$AW$17:$AW$148) -> #REF! | AR21: =WORKDAY(IF(AQ22="",AQ21,AQ22),INDEX(AR$12:AR$15,MATCH($I20,$I$12:$I$15,0)),$AW$17:$AW$148) -> #REF! | AW21: #REF!
C22: =C20 -> RFQ-002 | D22: =D20 -> Material Handling Equipment | G22: =G20 -> N | I22: =I20 -> LC | J22: Actual | AC22: =IF(ISERROR(LOOKUP(AC$16,$L22:$X22,#REF!)),0,(LOOKUP(AC$16,$L22:$X22,#REF!))) -> 0 | AD22: =IF(ISERROR(LOOKUP(AD$16,$L22:$X22,#REF!)),0,(LOOKUP(AD$16,$L22:$X22,#REF!))) -> 0 | AE22: =IF(ISERROR(LOOKUP(AE$16,$L22:$X22,#REF!)),0,(LOOKUP(AE$16,$L22:$X22,#REF!))) -> 0 | AF22: =IF(ISERROR(LOOKUP(AF$16,$L22:$X22,#REF!)),0,(LOOKUP(AF$16,$L22:$X22,#REF!))) -> 0 | AG22: =IF(ISERROR(LOOKUP(AG$16,$L22:$X22,#REF!)),0,(LOOKUP(AG$16,$L22:$X22,#REF!))) -> 0 | AH22: =IF(ISERROR(LOOKUP(AH$16,$L22:$X22,#REF!)),0,(LOOKUP(AH$16,$L22:$X22,#REF!))) -> 0 | AI22: =IF(ISERROR(LOOKUP(AI$16,$L22:$X22,#REF!)),0,(LOOKUP(AI$16,$L22:$X22,#REF!))) -> 0 | AJ22: =IF(ISERROR(LOOKUP(AJ$16,$L22:$X22,#REF!)),0,(LOOKUP(AJ$16,$L22:$X22,#REF!))) -> 0 | ... AM22: =IF(ISERROR(LOOKUP(AM$16,$L22:$X22,#REF!)),0,(LOOKUP(AM$16,$L22:$X22,#REF!))) -> 0 | AO22: =U22-T22 -> 0 | AW22: #REF!
A23: =A20+1 -> 3 | C23: RFQ-003 | D23: Instrument Gas Filter Coalescer | F23: Mechanical | G23: Y | I23: LA | J23: Plan | K23: =WORKDAY(L23,-INDEX(L$12:L$15,MATCH($I23,$I$12:$I$15,0))) -> 46209 | L23: =WORKDAY(M23,-INDEX(M$12:M$15,MATCH($I23,$I$12:$I$15,0))) -> 46210 | M23: =WORKDAY(N23,-INDEX(N$12:N$15,MATCH($I23,$I$12:$I$15,0))) -> 46217 | N23: =WORKDAY(O23,-INDEX(O$12:O$15,MATCH($I23,$I$12:$I$15,0))) -> 46218 | O23: =WORKDAY(R23,-INDEX(R$12:R$15,MATCH($I23,$I$12:$I$15,0))) -> 46225 | P23: =U23-L23 -> 76 | R23: =WORKDAY(S23,-INDEX(S$12:S$15,MATCH($I23,$I$12:$I$15,0))) -> 46239 | S23: =WORKDAY(T23,-INDEX(T$12:T$15,MATCH($I23,$I$12:$I$15,0))) -> 46267 | T23: =WORKDAY(U23,-INDEX(U$12:U$15,MATCH($I23,$I$12:$I$15,0))) -> 46272 | U23: =X23-Y23 -> 46286 | V23: =WORKDAY(U23,INDEX(V$12:V$15,MATCH($I23,$I$12:$I$15,0))) -> 46288 | W23: =Y23/7 -> 25.714286 | X23: =Z23 -> 46466 | Y23: 180 | Z23: 46466 | AA23: 46466 | AB23: =Z23-X24 -> 0 | AC23: =IF(ISERROR(LOOKUP(AC$16,$L23:$X23,#REF!)),0,(LOOKUP(AC$16,$L23:$X23,#REF!))) -> 0 | AD23: =IF(ISERROR(LOOKUP(AD$16,$L23:$X23,#REF!)),0,(LOOKUP(AD$16,$L23:$X23,#REF!))) -> 0 | AE23: =IF(ISERROR(LOOKUP(AE$16,$L23:$X23,#REF!)),0,(LOOKUP(AE$16,$L23:$X23,#REF!))) -> 0 | AF23: =IF(ISERROR(LOOKUP(AF$16,$L23:$X23,#REF!)),0,(LOOKUP(AF$16,$L23:$X23,#REF!))) -> 0 | AG23: =IF(ISERROR(LOOKUP(AG$16,$L23:$X23,#REF!)),0,(LOOKUP(AG$16,$L23:$X23,#REF!))) -> 0 | AH23: =IF(ISERROR(LOOKUP(AH$16,$L23:$X23,#REF!)),0,(LOOKUP(AH$16,$L23:$X23,#REF!))) -> 0 | AI23: =IF(ISERROR(LOOKUP(AI$16,$L23:$X23,#REF!)),0,(LOOKUP(AI$16,$L23:$X23,#REF!))) -> 0 | AJ23: =IF(ISERROR(LOOKUP(AJ$16,$L23:$X23,#REF!)),0,(LOOKUP(AJ$16,$L23:$X23,#REF!))) -> 0 | ... AM23: =IF(ISERROR(LOOKUP(AM$16,$L23:$X23,#REF!)),0,(LOOKUP(AM$16,$L23:$X23,#REF!))) -> 0 | AO23: =U23-T23 -> 14 | AP23: =WORKDAY(AQ23,-INDEX(AQ$12:AQ$15,MATCH($I23,$I$12:$I$15,0)),$AW$17:$AW$148) -> #REF! | AQ23: =WORKDAY(U23,-INDEX(U$12:U$15,MATCH($I23,$I$12:$I$15,0)),$AW$17:$AW$148) -> #REF! | AR23: =WORKDAY(U23,-INDEX(U$12:U$15,MATCH($I23,$I$12:$I$15,0)),$AW$17:$AW$148) -> #REF! | AS23: 7 | AW23: #REF!
C24: =C23 -> RFQ-003 | D24: =D23 -> Instrument Gas Filter Coalescer | G24: =G23 -> Y | I24: =I23 -> LA | J24: Forecast | K24: =K23 -> 46209 | L24: =WORKDAY(IF(K25="",K24,K25),INDEX(L$12:L$15,MATCH($I23,$I$12:$I$15,0))) -> 46210 | M24: =WORKDAY(IF(L25="",L24,L25),INDEX(M$12:M$15,MATCH($I23,$I$12:$I$15,0))) -> 46217 | N24: =WORKDAY(IF(M25="",M24,M25),INDEX(N$12:N$15,MATCH($I23,$I$12:$I$15,0))) -> 46218 | O24: =WORKDAY(IF(N25="",N24,N25),INDEX(O$12:O$15,MATCH($I23,$I$12:$I$15,0))) -> 46225 | R24: =WORKDAY(IF(O25="",O24,O25),INDEX(R$12:R$15,MATCH($I23,$I$12:$I$15,0))) -> 46239 | S24: =WORKDAY(IF(R25="",R24,R25),INDEX(S$12:S$15,MATCH($I23,$I$12:$I$15,0))) -> 46267 | T24: =WORKDAY(IF(S25="",S24,S25),INDEX(T$12:T$15,MATCH($I23,$I$12:$I$15,0))) -> 46272 | U24: =WORKDAY(IF(T25="",T24,T25),INDEX(U$12:U$15,MATCH($I23,$I$12:$I$15,0))) -> 46286 | V24: =WORKDAY(IF(U25="",U24,U25),INDEX(V$12:V$15,MATCH($I23,$I$12:$I$15,0))) -> 46288 | X24: =U24+Y23 -> 46466 | AC24: =IF(ISERROR(LOOKUP(AC$16,$L24:$X24,#REF!)),0,(LOOKUP(AC$16,$L24:$X24,#REF!))) -> 0 | AD24: =IF(ISERROR(LOOKUP(AD$16,$L24:$X24,#REF!)),0,(LOOKUP(AD$16,$L24:$X24,#REF!))) -> 0 | AE24: =IF(ISERROR(LOOKUP(AE$16,$L24:$X24,#REF!)),0,(LOOKUP(AE$16,$L24:$X24,#REF!))) -> 0 | AF24: =IF(ISERROR(LOOKUP(AF$16,$L24:$X24,#REF!)),0,(LOOKUP(AF$16,$L24:$X24,#REF!))) -> 0 | AG24: =IF(ISERROR(LOOKUP(AG$16,$L24:$X24,#REF!)),0,(LOOKUP(AG$16,$L24:$X24,#REF!))) -> 0 | AH24: =IF(ISERROR(LOOKUP(AH$16,$L24:$X24,#REF!)),0,(LOOKUP(AH$16,$L24:$X24,#REF!))) -> 0 | AI24: =IF(ISERROR(LOOKUP(AI$16,$L24:$X24,#REF!)),0,(LOOKUP(AI$16,$L24:$X24,#REF!))) -> 0 | AJ24: =IF(ISERROR(LOOKUP(AJ$16,$L24:$X24,#REF!)),0,(LOOKUP(AJ$16,$L24:$X24,#REF!))) -> 0 | ... AM24: =IF(ISERROR(LOOKUP(AM$16,$L24:$X24,#REF!)),0,(LOOKUP(AM$16,$L24:$X24,#REF!))) -> 0 | AO24: =U24-T24 -> 14 | AP24: =WORKDAY(IF(T25="",T24,T25),INDEX(AP$12:AP$15,MATCH($I23,$I$12:$I$15,0)),$AW$17:$AW$148) -> #REF! | AQ24: =WORKDAY(IF(AP25="",AP24,AP25),INDEX(AQ$12:AQ$15,MATCH($I23,$I$12:$I$15,0)),$AW$17:$AW$148) -> #REF! | AR24: =WORKDAY(IF(AQ25="",AQ24,AQ25),INDEX(AR$12:AR$15,MATCH($I23,$I$12:$I$15,0)),$AW$17:$AW$148) -> #REF! | AW24: #REF!
C25: =C23 -> RFQ-003 | D25: =D23 -> Instrument Gas Filter Coalescer | G25: =G23 -> Y | I25: =I23 -> LA | J25: Actual | AC25: =IF(ISERROR(LOOKUP(AC$16,$L25:$X25,#REF!)),0,(LOOKUP(AC$16,$L25:$X25,#REF!))) -> 0 | AD25: =IF(ISERROR(LOOKUP(AD$16,$L25:$X25,#REF!)),0,(LOOKUP(AD$16,$L25:$X25,#REF!))) -> 0 | AE25: =IF(ISERROR(LOOKUP(AE$16,$L25:$X25,#REF!)),0,(LOOKUP(AE$16,$L25:$X25,#REF!))) -> 0 | AF25: =IF(ISERROR(LOOKUP(AF$16,$L25:$X25,#REF!)),0,(LOOKUP(AF$16,$L25:$X25,#REF!))) -> 0 | AG25: =IF(ISERROR(LOOKUP(AG$16,$L25:$X25,#REF!)),0,(LOOKUP(AG$16,$L25:$X25,#REF!))) -> 0 | AH25: =IF(ISERROR(LOOKUP(AH$16,$L25:$X25,#REF!)),0,(LOOKUP(AH$16,$L25:$X25,#REF!))) -> 0 | AI25: =IF(ISERROR(LOOKUP(AI$16,$L25:$X25,#REF!)),0,(LOOKUP(AI$16,$L25:$X25,#REF!))) -> 0 | AJ25: =IF(ISERROR(LOOKUP(AJ$16,$L25:$X25,#REF!)),0,(LOOKUP(AJ$16,$L25:$X25,#REF!))) -> 0 | ... AM25: =IF(ISERROR(LOOKUP(AM$16,$L25:$X25,#REF!)),0,(LOOKUP(AM$16,$L25:$X25,#REF!))) -> 0 | AO25: =U25-T25 -> 0 | AW25: #REF!
A26: =A23+1 -> 4 | C26: RFQ-004 | D26: Production & Test Seperator | F26: Mechanical | G26: =IF(_xlfn.XLOOKUP(C26,'[35]Before Award'!D:D,'[35]Before Award'!AV:AV,"N/A")="N/A","N","Y") -> N | I26: LA | J26: Plan | K26: 46211 | L26: 46212 | M26: 46217 | N26: 46218 | O26: 46223 | P26: =U26-L26 -> 71 | R26: 46237 | S26: 46265 | T26: 46268 | U26: 46283 | V26: 46290 | W26: 26 | X26: 46466 | Y26: =W26*7 -> 182 | Z26: 46466 | AA26: 46466 | AB26: =Z26-X27 -> 0 | AC26: =IF(ISERROR(LOOKUP(AC$16,$L26:$X26,#REF!)),0,(LOOKUP(AC$16,$L26:$X26,#REF!))) -> 0 | AD26: =IF(ISERROR(LOOKUP(AD$16,$L26:$X26,#REF!)),0,(LOOKUP(AD$16,$L26:$X26,#REF!))) -> 0 | AE26: =IF(ISERROR(LOOKUP(AE$16,$L26:$X26,#REF!)),0,(LOOKUP(AE$16,$L26:$X26,#REF!))) -> 0 | AF26: =IF(ISERROR(LOOKUP(AF$16,$L26:$X26,#REF!)),0,(LOOKUP(AF$16,$L26:$X26,#REF!))) -> 0 | AG26: =IF(ISERROR(LOOKUP(AG$16,$L26:$X26,#REF!)),0,(LOOKUP(AG$16,$L26:$X26,#REF!))) -> 0 | AH26: =IF(ISERROR(LOOKUP(AH$16,$L26:$X26,#REF!)),0,(LOOKUP(AH$16,$L26:$X26,#REF!))) -> 0 | AI26: =IF(ISERROR(LOOKUP(AI$16,$L26:$X26,#REF!)),0,(LOOKUP(AI$16,$L26:$X26,#REF!))) -> 0 | AJ26: =IF(ISERROR(LOOKUP(AJ$16,$L26:$X26,#REF!)),0,(LOOKUP(AJ$16,$L26:$X26,#REF!))) -> 0 | ... AM26: =IF(ISERROR(LOOKUP(AM$16,$L26:$X26,#REF!)),0,(LOOKUP(AM$16,$L26:$X26,#REF!))) -> 0 | AO26: =U26-T26 -> 15 | AP26: 46272 | AQ26: 46276 | AR26: 46276 | AS26: 14 | AW26: #REF!
C27: =C26 -> RFQ-004 | D27: =D26 -> Production & Test Seperator | G27: =G26 -> N | I27: =I26 -> LA | J27: Forecast | K27: 46211 | L27: 46212 | M27: 46217 | N27: 46218 | O27: 46223 | R27: 46237 | S27: 46265 | T27: 46268 | U27: 46283 | V27: 46290 | X27: 46466 | AC27: =IF(ISERROR(LOOKUP(AC$16,$L27:$X27,#REF!)),0,(LOOKUP(AC$16,$L27:$X27,#REF!))) -> 0 | AD27: =IF(ISERROR(LOOKUP(AD$16,$L27:$X27,#REF!)),0,(LOOKUP(AD$16,$L27:$X27,#REF!))) -> 0 | AE27: =IF(ISERROR(LOOKUP(AE$16,$L27:$X27,#REF!)),0,(LOOKUP(AE$16,$L27:$X27,#REF!))) -> 0 | AF27: =IF(ISERROR(LOOKUP(AF$16,$L27:$X27,#REF!)),0,(LOOKUP(AF$16,$L27:$X27,#REF!))) -> 0 | AG27: =IF(ISERROR(LOOKUP(AG$16,$L27:$X27,#REF!)),0,(LOOKUP(AG$16,$L27:$X27,#REF!))) -> 0 | AH27: =IF(ISERROR(LOOKUP(AH$16,$L27:$X27,#REF!)),0,(LOOKUP(AH$16,$L27:$X27,#REF!))) -> 0 | AI27: =IF(ISERROR(LOOKUP(AI$16,$L27:$X27,#REF!)),0,(LOOKUP(AI$16,$L27:$X27,#REF!))) -> 0 | AJ27: =IF(ISERROR(LOOKUP(AJ$16,$L27:$X27,#REF!)),0,(LOOKUP(AJ$16,$L27:$X27,#REF!))) -> 0 | ... AM27: =IF(ISERROR(LOOKUP(AM$16,$L27:$X27,#REF!)),0,(LOOKUP(AM$16,$L27:$X27,#REF!))) -> 0 | AO27: =U27-T27 -> 15 | AP27: 46272 | AQ27: 46276 | AR27: 46283 | AW27: #REF!
C28: =C26 -> RFQ-004 | D28: =D26 -> Production & Test Seperator | G28: =G26 -> N | I28: =I26 -> LA | J28: Actual | AC28: =IF(ISERROR(LOOKUP(AC$16,$L28:$X28,#REF!)),0,(LOOKUP(AC$16,$L28:$X28,#REF!))) -> 0 | AD28: =IF(ISERROR(LOOKUP(AD$16,$L28:$X28,#REF!)),0,(LOOKUP(AD$16,$L28:$X28,#REF!))) -> 0 | AE28: =IF(ISERROR(LOOKUP(AE$16,$L28:$X28,#REF!)),0,(LOOKUP(AE$16,$L28:$X28,#REF!))) -> 0 | AF28: =IF(ISERROR(LOOKUP(AF$16,$L28:$X28,#REF!)),0,(LOOKUP(AF$16,$L28:$X28,#REF!))) -> 0 | AG28: =IF(ISERROR(LOOKUP(AG$16,$L28:$X28,#REF!)),0,(LOOKUP(AG$16,$L28:$X28,#REF!))) -> 0 | AH28: =IF(ISERROR(LOOKUP(AH$16,$L28:$X28,#REF!)),0,(LOOKUP(AH$16,$L28:$X28,#REF!))) -> 0 | AI28: =IF(ISERROR(LOOKUP(AI$16,$L28:$X28,#REF!)),0,(LOOKUP(AI$16,$L28:$X28,#REF!))) -> 0 | AJ28: =IF(ISERROR(LOOKUP(AJ$16,$L28:$X28,#REF!)),0,(LOOKUP(AJ$16,$L28:$X28,#REF!))) -> 0 | ... AM28: =IF(ISERROR(LOOKUP(AM$16,$L28:$X28,#REF!)),0,(LOOKUP(AM$16,$L28:$X28,#REF!))) -> 0 | AO28: =U28-T28 -> 0 | AW28: #REF!
A29: =A26+1 -> 5 | C29: RFQ-005 | D29: Pig Launcher and Receiver | F29: Piping | G29: Y | I29: LA | J29: Plan | K29: 46176 | L29: 46177 | M29: 46182 | N29: 46183 | O29: 46188 | P29: =U29-L29 -> 71 | R29: 46202 | S29: 46230 | T29: 46233 | U29: 46248 | V29: 46255 | W29: 32 | X29: 46472 | Y29: =W29*7 -> 224 | Z29: 46472 | AA29: 46472 | AB29: =Z29-X30 -> 0 | AC29: =IF(ISERROR(LOOKUP(AC$16,$L29:$X29,#REF!)),0,(LOOKUP(AC$16,$L29:$X29,#REF!))) -> 0 | AD29: =IF(ISERROR(LOOKUP(AD$16,$L29:$X29,#REF!)),0,(LOOKUP(AD$16,$L29:$X29,#REF!))) -> 0 | AE29: =IF(ISERROR(LOOKUP(AE$16,$L29:$X29,#REF!)),0,(LOOKUP(AE$16,$L29:$X29,#REF!))) -> 0 | AF29: =IF(ISERROR(LOOKUP(AF$16,$L29:$X29,#REF!)),0,(LOOKUP(AF$16,$L29:$X29,#REF!))) -> 0 | AG29: =IF(ISERROR(LOOKUP(AG$16,$L29:$X29,#REF!)),0,(LOOKUP(AG$16,$L29:$X29,#REF!))) -> 0 | AH29: =IF(ISERROR(LOOKUP(AH$16,$L29:$X29,#REF!)),0,(LOOKUP(AH$16,$L29:$X29,#REF!))) -> 0 | AI29: =IF(ISERROR(LOOKUP(AI$16,$L29:$X29,#REF!)),0,(LOOKUP(AI$16,$L29:$X29,#REF!))) -> 0 | AJ29: =IF(ISERROR(LOOKUP(AJ$16,$L29:$X29,#REF!)),0,(LOOKUP(AJ$16,$L29:$X29,#REF!))) -> 0 | ... AM29: =IF(ISERROR(LOOKUP(AM$16,$L29:$X29,#REF!)),0,(LOOKUP(AM$16,$L29:$X29,#REF!))) -> 0 | AO29: =U29-T29 -> 15 | AP29: 46237 | AQ29: 46241 | AR29: 46241 | AS29: 14 | AW29: #REF!
C30: =C29 -> RFQ-005 | D30: =D29 -> Pig Launcher and Receiver | F30: =F29 -> Piping | G30: =G29 -> Y | I30: =I29 -> LA | J30: Forecast | K30: 46176 | L30: 46177 | M30: 46182 | N30: 46183 | O30: 46188 | R30: 46202 | S30: 46230 | T30: 46233 | U30: 46248 | V30: 46255 | X30: 46472 | AC30: =IF(ISERROR(LOOKUP(AC$16,$L30:$X30,#REF!)),0,(LOOKUP(AC$16,$L30:$X30,#REF!))) -> 0 | AD30: =IF(ISERROR(LOOKUP(AD$16,$L30:$X30,#REF!)),0,(LOOKUP(AD$16,$L30:$X30,#REF!))) -> 0 | AE30: =IF(ISERROR(LOOKUP(AE$16,$L30:$X30,#REF!)),0,(LOOKUP(AE$16,$L30:$X30,#REF!))) -> 0 | AF30: =IF(ISERROR(LOOKUP(AF$16,$L30:$X30,#REF!)),0,(LOOKUP(AF$16,$L30:$X30,#REF!))) -> 0 | AG30: =IF(ISERROR(LOOKUP(AG$16,$L30:$X30,#REF!)),0,(LOOKUP(AG$16,$L30:$X30,#REF!))) -> 0 | AH30: =IF(ISERROR(LOOKUP(AH$16,$L30:$X30,#REF!)),0,(LOOKUP(AH$16,$L30:$X30,#REF!))) -> 0 | AI30: =IF(ISERROR(LOOKUP(AI$16,$L30:$X30,#REF!)),0,(LOOKUP(AI$16,$L30:$X30,#REF!))) -> 0 | AJ30: =IF(ISERROR(LOOKUP(AJ$16,$L30:$X30,#REF!)),0,(LOOKUP(AJ$16,$L30:$X30,#REF!))) -> 0 | ... AM30: =IF(ISERROR(LOOKUP(AM$16,$L30:$X30,#REF!)),0,(LOOKUP(AM$16,$L30:$X30,#REF!))) -> 0 | AO30: =U30-T30 -> 15 | AP30: 46237 | AQ30: 46241 | AR30: 46248 | AW30: #REF!
C31: =C29 -> RFQ-005 | D31: =D29 -> Pig Launcher and Receiver | F31: =F29 -> Piping | G31: =G29 -> Y | I31: =I29 -> LA | J31: Actual | AC31: =IF(ISERROR(LOOKUP(AC$16,$L31:$X31,#REF!)),0,(LOOKUP(AC$16,$L31:$X31,#REF!))) -> 0 | AD31: =IF(ISERROR(LOOKUP(AD$16,$L31:$X31,#REF!)),0,(LOOKUP(AD$16,$L31:$X31,#REF!))) -> 0 | AE31: =IF(ISERROR(LOOKUP(AE$16,$L31:$X31,#REF!)),0,(LOOKUP(AE$16,$L31:$X31,#REF!))) -> 0 | AF31: =IF(ISERROR(LOOKUP(AF$16,$L31:$X31,#REF!)),0,(LOOKUP(AF$16,$L31:$X31,#REF!))) -> 0 | AG31: =IF(ISERROR(LOOKUP(AG$16,$L31:$X31,#REF!)),0,(LOOKUP(AG$16,$L31:$X31,#REF!))) -> 0 | AH31: =IF(ISERROR(LOOKUP(AH$16,$L31:$X31,#REF!)),0,(LOOKUP(AH$16,$L31:$X31,#REF!))) -> 0 | AI31: =IF(ISERROR(LOOKUP(AI$16,$L31:$X31,#REF!)),0,(LOOKUP(AI$16,$L31:$X31,#REF!))) -> 0 | AJ31: =IF(ISERROR(LOOKUP(AJ$16,$L31:$X31,#REF!)),0,(LOOKUP(AJ$16,$L31:$X31,#REF!))) -> 0 | ... AM31: =IF(ISERROR(LOOKUP(AM$16,$L31:$X31,#REF!)),0,(LOOKUP(AM$16,$L31:$X31,#REF!))) -> 0 | AO31: =U31-T31 -> 0 | AW31: #REF!
A32: =A29+1 -> 6 | C32: RFQ-006 | D32: Corrosion Inhibitor Injection Pump | F32: Mechanical | G32: N | I32: LA | J32: Plan | K32: =WORKDAY(L32,-INDEX(L$12:L$15,MATCH($I32,$I$12:$I$15,0))) -> 46143 | L32: =WORKDAY(M32,-INDEX(M$12:M$15,MATCH($I32,$I$12:$I$15,0))) -> 46146 | M32: =WORKDAY(N32,-INDEX(N$12:N$15,MATCH($I32,$I$12:$I$15,0))) -> 46153 | N32: =WORKDAY(O32,-INDEX(O$12:O$15,MATCH($I32,$I$12:$I$15,0))) -> 46154 | O32: =WORKDAY(R32,-INDEX(R$12:R$15,MATCH($I32,$I$12:$I$15,0))) -> 46161 | P32: =U32-L32 -> 74 | R32: =WORKDAY(S32,-INDEX(S$12:S$15,MATCH($I32,$I$12:$I$15,0))) -> 46175 | S32: =WORKDAY(T32,-INDEX(T$12:T$15,MATCH($I32,$I$12:$I$15,0))) -> 46203 | T32: =WORKDAY(U32,-INDEX(U$12:U$15,MATCH($I32,$I$12:$I$15,0))) -> 46206 | U32: =X32-Y32 -> 46220 | V32: =WORKDAY(U32,INDEX(V$12:V$15,MATCH($I32,$I$12:$I$15,0))) -> 46224 | W32: =Y32/7 -> 32 | X32: =Z32 -> 46444 | Y32: =32*7 -> 224 | Z32: 46444 | AA32: 46444 | AB32: =Z32-X33 -> 0 | AC32: =IF(ISERROR(LOOKUP(AC$16,$L32:$X32,#REF!)),0,(LOOKUP(AC$16,$L32:$X32,#REF!))) -> 0 | AD32: =IF(ISERROR(LOOKUP(AD$16,$L32:$X32,#REF!)),0,(LOOKUP(AD$16,$L32:$X32,#REF!))) -> 0 | AE32: =IF(ISERROR(LOOKUP(AE$16,$L32:$X32,#REF!)),0,(LOOKUP(AE$16,$L32:$X32,#REF!))) -> 0 | AF32: =IF(ISERROR(LOOKUP(AF$16,$L32:$X32,#REF!)),0,(LOOKUP(AF$16,$L32:$X32,#REF!))) -> 0 | AG32: =IF(ISERROR(LOOKUP(AG$16,$L32:$X32,#REF!)),0,(LOOKUP(AG$16,$L32:$X32,#REF!))) -> 0 | AH32: =IF(ISERROR(LOOKUP(AH$16,$L32:$X32,#REF!)),0,(LOOKUP(AH$16,$L32:$X32,#REF!))) -> 0 | AI32: =IF(ISERROR(LOOKUP(AI$16,$L32:$X32,#REF!)),0,(LOOKUP(AI$16,$L32:$X32,#REF!))) -> 0 | AJ32: =IF(ISERROR(LOOKUP(AJ$16,$L32:$X32,#REF!)),0,(LOOKUP(AJ$16,$L32:$X32,#REF!))) -> 0 | ... AM32: =IF(ISERROR(LOOKUP(AM$16,$L32:$X32,#REF!)),0,(LOOKUP(AM$16,$L32:$X32,#REF!))) -> 0 | AO32: =U32-T32 -> 14 | AP32: =WORKDAY(AQ32,-INDEX(AQ$12:AQ$15,MATCH($I32,$I$12:$I$15,0)),$AW$17:$AW$148) -> #REF! | AQ32: =WORKDAY(U32,-INDEX(U$12:U$15,MATCH($I32,$I$12:$I$15,0)),$AW$17:$AW$148) -> #REF! | AR32: =WORKDAY(U32,-INDEX(U$12:U$15,MATCH($I32,$I$12:$I$15,0)),$AW$17:$AW$148) -> #REF! | AS32: 14 | AW32: #REF!
