Workbook
Name \c: #N/A
Name \i: #N/A
Name \z: #N/A
Name __material_he_tubes_alternative: #REF!
Name __sf400: '[7]Pull-Down Menus'!$J$2486:$J$2491
Name __sf404: '[7]Pull-Down Menus'!$J$699:$J$701
Name _bal11: [10]bal11!$B$1:$AV$66
Name _bal12: [10]bal12!$B$1:$AU$66
Name _bal6: [10]bal6!$B$1:$CN$66
Name _DESIGN_MAT_SHELL: #REF!
Name _DESIGN_MAT_TUBES: #REF!
Name _DESIGN_TEMP_MAX_1: #REF!
Name _DESIGN_TEMP_MAX_2: #REF!
Name _DESIGN_TEMP_MIN_1: #REF!
Name _DESIGN_TEMP_MIN_2: #REF!
Name _DIMENSIONS_BOT: #REF!
Name _DIMENSIONS_MID: #REF!
Name _DIMENSIONS_PIPE_SHELL: #REF!
Name _DIMENSIONS_PIPE_TUBE: #REF!
Name _DIMENSIONS_TOP_MAIN: #REF!
Name _din24420: #REF!
Name _din28005: #REF!
Name _din28006: #REF!
Name _din28007: #REF!
Name _din28008: #REF!
Name _din28015: #REF!
Name _din28017: #REF!
Name _din28083: #REF!
Name _din28084: #REF!
Name _din28105: #REF!
Name _din28161: #REF!
Name _din28182: #REF!
Name _din4119: #REF!
Name _doc_foundation_plan_loads_digital: #REF!
Name _doc_foundation_plan_loads_paper: #REF!
Name _doc_foundation_plan_loads_week: #REF!
Name _installed_area_per_unit: #REF!
Name _Jos2: #REF!
Name _mat1: #REF!
Name _mat2: #REF!
Name _mat3: #REF!
Name _mat4: #REF!
Name _material_he_tubes: #REF!
Name _mc230: #REF!
Name _mc240: #REF!
Name _mc245: #REF!
Name _mc250: #REF!
Name _mc251: #REF!
Name _mc252: #REF!
Name _mc253: #REF!
Name _mc254: #REF!
Name _mc255: #REF!
Name _mc260: #REF!
Name _mc310: #REF!
Name _mc311: #REF!
Name _mc335: #REF!
Name _mc336: #REF!
Name _mc337: #REF!
Name _mc338: #REF!
Name _mc339: #REF!

Sheet PSR Overall Cycle
B2: Note: | C2: 1. All MR Issuance with Attached File to be used IFR version, some long lead item to be used FEED document as MR Issuance basis which listed in Remark
C3: 2. In principle, Datasheet - IFA version shall be issued before TBE issuance as much as possible to avoid the big gap of changes.
C4: 3.TBE- AFC and MR-AFC should be issued before PO issuance.
C5: 4.For the Steel Structural, TJE will sign the frame agreement with alternative vendors firstly, once the MTO&IFA drawing issuance, TJE will purchase order promptly
C6: 5.The 3rd line of Each procuremnt package with "Proposal from TJE" in column N , has been aligned with GCME about date of MR issuance with atteched relative documents, then forward schedule in procurement and leadtime to ETA, this line is the basis for schedule developing.
L8: LA | O8: 1 | P8: 10 | Q8: 0 | R8: 0 | S8: 0 | T8: 10 | U8: 17 | V8: 10 | X8: 9
L9: LB | O9: 1 | P9: 10 | Q9: 0 | R9: 0 | S9: 0 | T9: 10 | U9: 17 | V9: 10 | X9: 9
L10: LC | O10: 1 | P10: 10 | Q10: 0 | R10: 0 | S10: 0 | T10: 10 | U10: 13 | V10: 10 | X10: 9
L11: LD | O11: 1 | P11: 10 | Q11: 0 | R11: 0 | S11: 0 | T11: 5 | U11: 7 | V11: 10 | X11: 5
B12: ZM167 PTTEPI ASK Procurement Plan | L12: LA | O12: 1 | P12: 5 | Q12: 1 | R12: 5 | T12: 10 | U12: 20 | V12: 3 | X12: 10 | Y12: 2 | Z12: 5 | AA12: 20 | AB12: 10 | AF12: 5 | AG12: 5
L13: LB | O13: 1 | P13: 5 | Q13: 1 | R13: 5 | T13: 10 | U13: 20 | V13: 3 | X13: 10 | Y13: 2 | Z13: 5 | AA13: 20 | AB13: 10 | AF13: 5 | AG13: 5
L14: LC | O14: 3 | P14: 5 | Q14: 1 | R14: 5 | T14: 10 | U14: 15 | V14: 3 | X14: 10 | Y14: 2 | Z14: 5 | AA14: 15 | AB14: 10 | AF14: 5 | AG14: 5
L15: LD | O15: 3 | P15: 5 | Q15: 1 | R15: 3 | T15: 5 | U15: 7 | V15: 2 | X15: 5 | Y15: 2 | Z15: 5 | AA15: 10 | AB15: 10 | AF15: 5 | AG15: 5
A16: No. | B16: RFQ No. | C16: Package Name | D16: Actual Lead Time | E16: Delivery Duration (Weeks) | F16: Deviation | G16: Total Weight | H16: CODE | I16: Discripline | J16: Long Lead Item (Y/N) | K16: Criticality Rating | L16: Priority Level | N16: Bidder List Approval | O16: MR Issued | P16: MR Approved | Q16: RFQ Issued | R16: RFQ Approved | S16: CFT Issuance | T16: Bid Closing Date | U16: TBE Issued | V16: TBE Approved | W16: LOA SIGN | X16: PO Issued | Y16: Vendor Acknowledgement | Z16: KOM | AA16: VD Submission | AB16: Approval of Key Vendor Documents | AC16: Delivery of Major Materials | AD16: PIM | AE16: Start Production | AF16: FAT | AG16: Ready for Shipment | AH16: Receipt at WORKSITE | AI16: Punch List Clearance | AJ16: Approval of Final Documentation (To be confirmed later) | AK16: Delivery Duration (Weeks) | AL16: Lead Time | AM16: ETA date | AN16: ROS date | AO16: Float | AR16: Remark | AS16: Remark2
M17: Matrix | AR17: Installation
M18: Holiday | N18: China | O18: Thai | P18: Thai | Q18: China | R18: Thai | T18: China | U18: Thai | V18: Thai | W18: China | X18: China | Y18: China | Z18: China | AA18: China | AB18: Thai
A19: 1 | B19: RFQ-MEC-001 | C19: Offshore Pedestal Crane | I19: Mechanical | L19: LA | M19: New Plan | O19: 46122 | P19: 46142 | Q19: 46142 | R19: 46142 | S19: 46145 | T19: 46157 | U19: 46184 | V19: 46198 | X19: 46211 | Y19: 46213 | Z19: 46220 | AA19: 46248 | AB19: 46262 | AC19: 46307 | AD19: 46310 | AE19: 46313 | AF19: 46496 | AG19: 46526 | AH19: 46540 | AI19: 46554 | AJ19: 46570 | AK19: 47 | AL19: =AK19*7 -> 329 | AM19: =X19+AL19 -> 46540 | AN19: =AN20 -> 46540 | AO19: =AN20-AM19 -> 0 | AP19: Long Lead | AQ19: WPA-01 | AR19: 46543
B20: RFQ-MEC-001 | C20: Offshore Pedestal Crane | H20: 4-2.1 | I20: Mechanical | J20: Y | K20: 2 | L20: LA | M20: Forecast | AB20: 46331 | AC20: 46300 | AD20: 46258 | AE20: 46301 | AF20: 46497 | AG20: 46521 | AH20: 46533 | AI20: 46547 | AJ20: 46563 | AK20: 47 | AL20: 329 | AM20: 46533 | AN20: =AR19-3 -> 46540 | AO20: =AN20-AM20 -> 7 | AP20: =AP19 -> Long Lead | AQ20: WPA-02 | AR20: 46553
B21: RFQ-MEC-001 | C21: Offshore Pedestal Crane | I21: Mechanical | J21: Y | K21: 2 | L21: LA | M21: Actual | N21: 46120 | O21: 46122 | P21: 46139 | Q21: =P21 -> 46139 | R21: =Q21 -> 46139 | S21: =R21 -> 46139 | T21: 46143 | U21: 46185 | V21: 46190 | W21: 46204 | X21: 46240 | Y21: 46240 | Z21: 46213 | AA21: =Z21+1 -> 46214 | AP21: =AP19 -> Long Lead | AR21: UPO-0003 | AS21: Upper Deck
A22: 2 | B22: RFQ-MEC-002 | C22: Material Handling Equipment | I22: Mechanical | L22: LC | M22: New Plan | O22: 46203 | P22: 46217 | Q22: 46217 | R22: 46217 | S22: 46217 | T22: 46231 | U22: 46252 | V22: 46266 | X22: 46279 | Y22: 46281 | Z22: 46288 | AA22: 46317 | AB22: 46332 | AC22: 46377 | AD22: 46380 | AE22: 46381 | AF22: 46410 | AG22: 46440 | AH22: 46454 | AI22: 46468 | AJ22: 46484 | AK22: 25 | AL22: =AK22*7 -> 175 | AM22: =X22+AL22 -> 46454 | AN22: =AN23 -> 46459 | AO22: =AN23-AM22 -> 5 | AQ22: WPA-01 | AR22: 46462
B23: RFQ-MEC-002 | C23: Material Handling Equipment | H23: 4-2.2 | I23: Mechanical | J23: N | K23: 4 | L23: LC | M23: Forecast | X23: 46279 | Z23: 46288 | AA23: 46317 | AB23: 46332 | AC23: 46377 | AD23: 46380 | AE23: 46381 | AF23: 46391 | AG23: 46421 | AH23: 46435 | AI23: 46449 | AJ23: 46465 | AK23: 25 | AL23: 175 | AM23: 46435 | AN23: =AR22-3 -> 46459 | AO23: =AN23-AM23 -> 24 | AQ23: WPA-02 | AR23: 46490 | AS23: check Location
B24: RFQ-MEC-002 | C24: Material Handling Equipment | I24: Mechanical | J24: N | K24: 4 | L24: LC | M24: Actual | O24: 46170 | P24: 46188 | Q24: 46188 | R24: 46188 | S24: 46191 | T24: 46204 | U24: 46242 | V24: 46255 | W24: 46260 | Y24: 46260 | AR24: UPO-0025
A25: 3 | B25: RFQ-MEC-003 | C25: Instrument Gas Filter Coalescer | I25: Mechanical | L25: LA | M25: New Plan | O25: 46170 | P25: 46182 | Q25: 46182 | R25: 46182 | S25: 46190 | T25: 46204 | U25: 46224 | V25: 46240 | X25: 46253 | Y25: 46255 | Z25: 46262 | AA25: 46293 | AB25: 46307 | AC25: 46367 | AD25: 46370 | AE25: 46371 | AF25: 46402 | AG25: 46432 | AH25: 46433 | AI25: 46447 | AJ25: 46463 | AK25: 25.714286 | AL25: =AK25*7 -> 180 | AM25: =X25+AL25 -> 46433 | AN25: =AN26 -> 46444 | AO25: =AN26-AM25 -> 11 | AQ25: WPA-01 | AR25: 46447
B26: RFQ-MEC-003 | C26: Instrument Gas Filter Coalescer | H26: 4-2.4 | I26: Mechanical | J26: Y | K26: 3 | L26: LA | M26: Forecast | AB26: 46336 | AC26: 46345 | AD26: 46346 | AE26: 46347 | AF26: 46415 | AG26: 46417 | AH26: 46417 | AI26: 46431 | AJ26: 46447 | AK26: 28.285714 | AL26: 198 | AM26: 46417 | AN26: =AR25-3 -> 46444 | AO26: =AN26-AM26 -> 27 | AQ26: WPA-02 | AR26: 46472
B27: RFQ-MEC-003 | C27: Instrument Gas Filter Coalescer | I27: Mechanical | J27: Y | K27: 3 | L27: LA | M27: Actual | N27: 46136 | O27: 46165 | P27: 46183 | Q27: 46183 | R27: 46183 | S27: 46183 | T27: 46192 | U27: 46220 | V27: 46224 | W27: 46219 | X27: 46219 | Y27: 46219 | Z27: 46226 | AA27: =Z27+1 -> 46227 | AR27: UPO-0004 | AS27: Lower Deck
A28: 4 | B28: RFQ-MEC-004 | C28: TEST AND PRODUCTION SEPARATOR | I28: Mechanical | L28: LA | M28: New Plan | O28: 46154 | P28: 46162 | Q28: 46162 | R28: 46162 | S28: 46170 | T28: 46183 | U28: 46211 | V28: 46216 | X28: 46230 | Y28: 46232 | Z28: 46239 | AA28: 46267 | AB28: 46281 | AC28: 46341 | AD28: 46344 | AE28: 46345 | AF28: 46430 | AG28: 46433 | AH28: 46440 | AI28: 46454 | AJ28: 46470 | AK28: 30 | AL28: =AK28*7 -> 210 | AM28: =X28+AL28 -> 46440 | AN28: =AN29 -> 46448 | AO28: =AN29-AM28 -> 8 | AP28: Long Lead | AQ28: WPA-01 | AR28: 46451
B29: RFQ-MEC-004 | C29: TEST AND PRODUCTION SEPARATOR | H29: 4-2.3 | I29: Mechanical | J29: Y | K29: 2 | L29: LA | M29: Forecast | AB29: 46336 | AC29: 46343 | AD29: 46344 | AE29: 46345 | AF29: 46430 | AG29: 46433 | AH29: 46433 | AI29: 46447 | AJ29: 46463 | AK29: 30.571429 | AL29: 214 | AM29: 46433 | AN29: =AR28-3 -> 46448 | AO29: =AN29-AM29 -> 15 | AP29: =AP28 -> Long Lead | AQ29: WPA-02 | AR29: 46472
B30: RFQ-MEC-004 | C30: TEST AND PRODUCTION SEPARATOR | I30: Mechanical | J30: Y | K30: 2 | L30: LA | M30: Actual | N30: 46136 | O30: 46157 | P30: 46182 | Q30: 46182 | R30: 46182 | S30: 46182 | T30: 46190 | U30: 46206 | V30: 46210 | W30: 46219 | X30: 46219 | Y30: 46219 | Z30: 46226 | AA30: 46260 | AP30: =AP28 -> Long Lead | AR30: UPO-0004 | AS30: Lower Deck
A31: 5 | B31: RFQ-PIP-005 | C31: QUICK OPENING CLOSURE | I31: Piping | L31: LA | M31: New Plan | O31: 46157 | P31: 46175 | Q31: 46175 | R31: 46175 | S31: 46176 | T31: 46189 | U31: 46217 | V31: 46227 | X31: 46234 | Y31: 46238 | Z31: 46245 | AA31: 46273 | AB31: 46287 | AC31: 46347 | AD31: 46350 | AE31: 46351 | AF31: 46427 | AG31: 46457 | AH31: 46458 | AI31: 46472 | AJ31: 46488 | AK31: 32 | AL31: =AK31*7 -> 224 | AM31: =X31+AL31 -> 46458 | AN31: =AN32 -> 46466 | AO31: =AN32-AM31 -> 8 | AQ31: WPA-01 | AR31: 46469
B32: RFQ-PIP-005 | C32: QUICK OPENING CLOSURE | H32: 4-2.6 | I32: Piping | J32: Y | K32: 2 | L32: LA | M32: Forecast | AB32: 46290 | AC32: 46350 | AD32: 46353 | AE32: 46354 | AF32: 46350 | AG32: 46380 | AH32: 46381 | AI32: 46395 | AJ32: 46411 | AK32: 20 | AL32: 140 | AM32: =W33+AL32 -> 46381 | AN32: =AR31-3 -> 46466 | AO32: =AN32-AM32 -> 85 | AQ32: WPA-02 | AR32: 46472 | AS32: Lower Deck
B33: RFQ-PIP-005 | C33: QUICK OPENING CLOSURE | I33: Piping | J33: Y | K33: 2 | L33: LA | M33: Actual | N33: 46136 | O33: 46163 | P33: 46182 | Q33: 46182 | R33: 46182 | S33: 46182 | T33: 46199 | U33: 46225 | V33: 46240 | W33: 46241 | Y33: 46241 | Z33: 46248 | AA33: =Z33+1 -> 46249 | AR33: UPO-0020
A34: 6 | B34: RFQ-MEC-006 | C34: CHEMICAL INJECTION PUMPS PACKAGE | I34: Mechanical | L34: LA | M34: New Plan | O34: 46153 | P34: 46182 | Q34: 46182 | R34: 46182 | S34: 46169 | T34: 46183 | U34: 46210 | V34: 46213 | X34: 46227 | Y34: 46231 | Z34: 46238 | AA34: 46266 | AB34: 46280 | AC34: 46392 | AD34: 46395 | AE34: 46396 | AF34: 46421 | AG34: 46437 | AH34: 46451 | AI34: 46465 | AJ34: 46481 | AK34: 32 | AL34: =AK34*7 -> 224 | AM34: =X34+AL34 -> 46451 | AN34: =AN35 -> 46451 | AO34: =AN35-AM34 -> 0 | AP34: Long Lead | AQ34: WPA-01 | AR34: 46454
B35: RFQ-MEC-006 | C35: CHEMICAL INJECTION PUMPS PACKAGE | H35: 4-2.8 | I35: Mechanical | J35: Y | K35: 3 | L35: LA | M35: Forecast | AB35: 46339 | AC35: 46366 | AD35: 46366 | AE35: 46366 | AF35: 46469 | AG35: 46471 | AH35: 46476 | AI35: 46490 | AJ35: 46506 | AK35: 35.142857 | AL35: 246 | AM35: 46476 | AN35: =AR34-3 -> 46451 | AO35: =AN35-AM35 -> -25 | AP35: =AP34 -> Long Lead | AQ35: WPA-02 | AR35: 46472
B36: RFQ-MEC-006 | C36: CHEMICAL INJECTION PUMPS PACKAGE | I36: Mechanical | J36: Y | K36: 3 | L36: LA | M36: Actual | N36: 46133 | O36: 46157 | P36: 46182 | Q36: 46182 | R36: 46182 | S36: 46182 | T36: 46183 | U36: 46206 | V36: 46210 | W36: 46230 | Y36: 46230 | Z36: 46237 | AA36: 46262 | AP36: =AP34 -> Long Lead | AR36: UPO-0008，RFQ-007 De-mulsifier / Water Clarifier Injection Pump & RFQ-044 Flow switch combined with RFQ-006 | AS36: Lower Deck
A37: 8 | B37: RFQ-MEC-008 | C37: DEOILER HYDRO CYCLONE PACKAGE | I37: Mechanical | L37: LA | M37: New Plan | O37: 46141 | P37: 46153 | Q37: 46153 | R37: 46161 | S37: 46161 | T37: 46183 | U37: 46203 | V37: 46206 | X37: 46220 | Y37: 46224 | Z37: 46231 | AA37: 46259 | AB37: 46273 | AC37: 46340 | AD37: 46340 | AE37: 46340 | AF37: 46457 | AG37: 46461 | AH37: =AG37+3 -> 46464 | AI37: =AH37+14 -> 46478 | AJ37: =AM37+30 -> 46494 | AK37: 34 | AL37: =AK37*7 -> 238 | AM37: =AH37 -> 46464 | AN37: =AN38 -> 46469 | AO37: =AN38-AM37 -> 5 | AQ37: WPA-01 | AR37: NA
B38: RFQ-MEC-008 | C38: DEOILER HYDRO CYCLONE PACKAGE | H38: 4-2.10 | I38: Mechanical | J38: Y | K38: 2 | L38: LA | M38: Forecast | AB38: 46380 | AC38: 46329 | AD38: 46329 | AE38: 46340 | AF38: 46461 | AG38: 46461 | AH38: 46461 | AI38: 46475 | AJ38: 46491 | AK38: 34.571429 | AL38: 242 | AM38: 46461 | AN38: =AR38-3 -> 46469 | AO38: =AN38-AM38 -> 8 | AQ38: WPA-02 | AR38: 46472 | AS38: only WPA02
B39: RFQ-MEC-008 | C39: DEOILER HYDRO CYCLONE PACKAGE | I39: Mechanical | J39: Y | K39: 2 | L39: LA | M39: Actual | N39: 46136 | O39: 46139 | P39: 46153 | Q39: 46153 | R39: =P39 -> 46153 | S39: =P39 -> 46153 | T39: 46182 | U39: 46200 | V39: 46202 | W39: 46219 | X39: 46219 | Y39: 46219 | Z39: 46226 | AA39: 46260 | AR39: UPO-0004 | AS39: Lower Deck
A40: 9 | B40: RFQ-MEC-009 | C40: DEGASSER DRUM | I40: Mechanical | L40: LA | M40: New Plan | O40: 46134 | P40: 46153 | Q40: 46153 | R40: 46153 | S40: 46154 | T40: 46167 | U40: 46197 | V40: 46202 | X40: 46216 | Y40: 46218 | Z40: 46225 | AA40: 46253 | AB40: 46267 | AC40: 46340 | AD40: 46340 | AE40: 46343 | AF40: 46453 | AG40: 46456 | AH40: =AG40+3 -> 46459 | AI40: =AH40+14 -> 46473 | AJ40: =AM40+30 -> 46489 | AK40: 34 | AL40: =AK40*7 -> 238 | AM40: =AH40 -> 46459 | AN40: =AN41 -> 46470 | AO40: =AN41-AM40 -> 11 | AQ40: WPA-01 | AR40: NA
B41: RFQ-MEC-009 | C41: DEGASSER DRUM | H41: 4-2.11 | I41: Mechanical | J41: Y | K41: 2 | L41: LA | M41: Forecast | AB41: 46380 | AC41: 46280 | AD41: 46281 | AE41: 46282 | AF41: 46451 | AG41: 46456 | AH41: 46456 | AI41: 46470 | AJ41: 46486 | AK41: 33.857143 | AL41: 237 | AM41: 46456 | AN41: =AR41-3 -> 46470 | AO41: =AN41-AM41 -> 14 | AQ41: WPA-02 | AR41: 46473 | AS41: only WPA02
B42: RFQ-MEC-009 | C42: DEGASSER DRUM | I42: Mechanical | J42: Y | K42: 2 | L42: LA | M42: Actual | N42: 46135 | O42: 46135 | P42: 46151 | Q42: 46151 | R42: =P42 -> 46151 | S42: =P42 -> 46151 | T42: 46181 | U42: 46202 | V42: 46204 | W42: 46219 | X42: 46219 | Y42: 46219 | Z42: 46226 | AA42: 46260 | AR42: UPO-0004 | AS42: Lower Deck
...

Sheet frmASKCons_0820
AM1: A | AV1: B=A-4 | AW1: C=B-10 | AX1: D=C-E | AY1: E
B3: JACKET FABRICATION | H3: MAIN STRUCTURE OF JACKET | L3: ERECT | M3: 片吊装焊接 | P3: QTY Proposal | R3: 接长 | S3: 组片 | T3: 总装 | U3: 接长 | V3: 组片 | W3: 总装 | X3: COAT | Y3: 片体涂装 | AA3: ASSY | AB3: 片预制 | AE3: QTY Proposal | AG3: FAB/SPL | AH3: 片体管接长 | AK3: QTY Proposal | AM3: CAN | AN3: 下料、卷制 | AP3: QTY Proposal | AS3: 3 | AT3: 60 | AU3: 15 | AV3: 4 | AW3: 10 | AX3: Dur for SD | AY3: DETAIL DESIGN WP01&WP02
B4: UNIT | C4: WF | D4: IWP | E4: PHASE | F4: CWP | H4: N° | I4: Task /Activity Group | J4: W-T | L4: P Start | M4: P Finish | N4: Dur | O4: 焊口(W) | P4: 填充量 | Q4: 管径范围 | X4: P Start | Y4: P Finish | Z4: Dur | AA4: P Start | AB4: P Finish | AC4: Dur | AD4: 焊口(W) | AE4: 填充量 | AF4: 管径范围 | AG4: P Start | AH4: P Finish | AI4: Dur | AJ4: 焊口(W) | AK4: 填充量 | AL4: 管径范围 | AM4: P Start | AN4: P Finish | AO4: Dur | AP4: 管段数 | AQ4: 管径范围 | AR4: PR-ID | AS4: ETA | AT4: PO | AU4: MTO | AV4: IWP | AW4: CPY | AX4: SD | AY4: AFC | AZ4: EN-ID | BA4: DWG DESC
B5: WPA01 | H5: WPA01 MAIN STRUCTURE OF JACKET | L5: =MIN(L6:L18) -> 46393 | M5: =MAX(M6:M18) -> 46524 | N5: =M5-L5+1 -> 132 | X5: =MIN(X6:X18) -> 46401 | Y5: =MAX(Y6:Y18) -> 46503 | Z5: =Y5-X5+1 -> 103 | AA5: =MIN(AA6:AA18) -> 46357 | AB5: =MAX(AB6:AB18) -> 46478 | AC5: =AB5-AA5+1 -> 122 | AG5: =MIN(AG6:AG18) -> 46322 | AH5: =MAX(AH6:AH18) -> 46422 | AI5: =AH5-AG5+1 -> 101 | AM5: =MIN(AM6:AM18) -> 46291 | AN5: =MAX(AN6:AN18) -> 46403 | AO5: =AN5-AM5+1 -> 113 | AS5: =MIN(AS6:AS18) -> 46288 | AT5: =MIN(AT6:AT18) -> 46228 | AU5: =MIN(AU6:AU18) -> 46213 | AV5: =MIN(AV6:AV18) -> 46287 | AW5: =MIN(AW6:AW18) -> 46277 | AY5: =MIN(AY6:AY18) -> 46269
B6: JKT | C6: S01 | D6: JKT-01 | F6: 01J | G6: =F6&C6 -> 01JS01 | H6: 1 | I6: S1 Layout Construction Support | L6: =SUMIFS('[36]frm P6'!$J:$J,'[36]frm P6'!D:D,[36]Schedule!B6,'[36]frm P6'!E:E,[36]Schedule!C6,'[36]frm P6'!F:F,[36]Schedule!D6,'[36]frm P6'!G:G,[36]Schedule!$K$3,'[36]frm P6'!H:H,[36]Schedule!F6) -> 46393 | M6: =SUMIFS('[36]frm P6'!$K:$K,'[36]frm P6'!D:D,[36]Schedule!B6,'[36]frm P6'!E:E,[36]Schedule!C6,'[36]frm P6'!F:F,[36]Schedule!D6,'[36]frm P6'!G:G,[36]Schedule!$K$3,'[36]frm P6'!H:H,[36]Schedule!F6) -> 46396 | N6: =M6-L6+1 -> 4 | X6: N/A | Y6: N/A | Z6: N/A | AA6: N/A | AB6: N/A | AC6: N/A | AD6: N/A | AE6: N/A | AF6: N/A | AG6: =SUMIFS('[36]frm P6'!$J:$J,'[36]frm P6'!D:D,[36]Schedule!B6,'[36]frm P6'!E:E,[36]Schedule!C6,'[36]frm P6'!F:F,[36]Schedule!D6,'[36]frm P6'!G:G,[36]Schedule!$AF$3,'[36]frm P6'!H:H,[36]Schedule!F6) -> 46322 | AH6: =SUMIFS('[36]frm P6'!$K:$K,'[36]frm P6'!D:D,[36]Schedule!B6,'[36]frm P6'!E:E,[36]Schedule!C6,'[36]frm P6'!F:F,[36]Schedule!D6,'[36]frm P6'!G:G,[36]Schedule!$AF$3,'[36]frm P6'!H:H,[36]Schedule!F6) -> 46358 | AI6: =AH6-AG6+1 -> 37 | AM6: N/A | AN6: N/A | AO6: N/A | AR6: N/A | AS6: N/A | AT6: N/A | AU6: N/A | AV6: N/A | AW6: N/A | AX6: N/A | AY6: N/A | AZ6: N/A | BA6: N/A
B7: JKT | C7: S02A | D7: JKT-01 | F7: 01J | G7: =F7&C7 -> 01JS02A | H7: 2 | I7: S2 1H-Panel | J7: 16.2 | K7: =L7-AB7 -> 3 | L7: =SUMIFS('[36]frm P6'!$J:$J,'[36]frm P6'!D:D,[36]Schedule!B7,'[36]frm P6'!E:E,[36]Schedule!C7,'[36]frm P6'!F:F,[36]Schedule!D7,'[36]frm P6'!G:G,[36]Schedule!$K$3,'[36]frm P6'!H:H,[36]Schedule!F7) -> 46396 | M7: =SUMIFS('[36]frm P6'!$K:$K,'[36]frm P6'!D:D,[36]Schedule!B7,'[36]frm P6'!E:E,[36]Schedule!C7,'[36]frm P6'!F:F,[36]Schedule!D7,'[36]frm P6'!G:G,[36]Schedule!$K$3,'[36]frm P6'!H:H,[36]Schedule!F7) -> 46407 | N7: =M7-L7+1 -> 12 | O7: 4 | Q7: 450-500 | R7: =VLOOKUP(Q7,[37]导管架!N$2:Q$9,2,0) -> 1.2968666 | S7: =VLOOKUP(Q7,[37]导管架!N$2:Q$9,3,0) -> 2.4732262 | T7: =VLOOKUP(Q7,[37]导管架!N$2:Q$9,4,0) -> 4.6220437 | U7: =R7*AJ7*8 -> 124.49919 | V7: =S7*AD7*8 -> 79.14324 | W7: =T7*O7*8 -> 147.9054 | X7: N/A | Y7: N/A | Z7: N/A | AA7: =SUMIFS('[36]frm P6'!$J:$J,'[36]frm P6'!D:D,[36]Schedule!B7,'[36]frm P6'!E:E,[36]Schedule!C7,'[36]frm P6'!F:F,[36]Schedule!D7,'[36]frm P6'!G:G,[36]Schedule!$Z$3,'[36]frm P6'!H:H,[36]Schedule!F7) -> 46364 | AB7: =SUMIFS('[36]frm P6'!$K:$K,'[36]frm P6'!D:D,[36]Schedule!B7,'[36]frm P6'!E:E,[36]Schedule!C7,'[36]frm P6'!F:F,[36]Schedule!D7,'[36]frm P6'!G:G,[36]Schedule!$Z$3,'[36]frm P6'!H:H,[36]Schedule!F7) -> 46393 | AC7: =AB7-AA7+1 -> 30 | AD7: 4 | AE7: 16.78 | AF7: 406.4 | AG7: =SUMIFS('[36]frm P6'!$J:$J,'[36]frm P6'!D:D,[36]Schedule!B7,'[36]frm P6'!E:E,[36]Schedule!C7,'[36]frm P6'!F:F,[36]Schedule!D7,'[36]frm P6'!G:G,[36]Schedule!$AF$3,'[36]frm P6'!H:H,[36]Schedule!F7) -> 46335 | AH7: =SUMIFS('[36]frm P6'!$K:$K,'[36]frm P6'!D:D,[36]Schedule!B7,'[36]frm P6'!E:E,[36]Schedule!C7,'[36]frm P6'!F:F,[36]Schedule!D7,'[36]frm P6'!G:G,[36]Schedule!$AF$3,'[36]frm P6'!H:H,[36]Schedule!F7) -> 46358 | AI7: =AH7-AG7+1 -> 24 | AJ7: 12 | AK7: 52.15 | AL7: 406.4-500 | AM7: =SUMIFS('[36]frm P6'!$J:$J,'[36]frm P6'!D:D,[36]Schedule!B7,'[36]frm P6'!E:E,[36]Schedule!C7,'[36]frm P6'!F:F,[36]Schedule!D7,'[36]frm P6'!G:G,[36]Schedule!$AL$3,'[36]frm P6'!H:H,[36]Schedule!F7) -> 46295 | AN7: =SUMIFS('[36]frm P6'!$K:$K,'[36]frm P6'!D:D,[36]Schedule!B7,'[36]frm P6'!E:E,[36]Schedule!C7,'[36]frm P6'!F:F,[36]Schedule!D7,'[36]frm P6'!G:G,[36]Schedule!$AL$3,'[36]frm P6'!H:H,[36]Schedule!F7) -> 46331 | AO7: =AN7-AM7+1 -> 37 | AP7: 6 | AQ7: 500 | AR7: 62 | AS7: =AM7-$AS$3 -> 46292 | AT7: =AS7-$AT$3 -> 46232 | AU7: =AT7-$AU$3 -> 46217 | AV7: =AM7-$AV$3 -> 46291 | AW7: =AV7-$AW$3 -> 46281 | AX7: =AW7-AY7 -> 7 | AY7: 46274 | AZ7: JK01-1830 | BA7: Horizontal Framing Plan
B8: JKT | C8: S04A | D8: JKT-01 | F8: 01J | G8: =F8&C8 -> 01JS04A | H8: 4 | I8: S4A Row1 | J8: 105 | K8: =L8-Y8 -> 6 | L8: =SUMIFS('[36]frm P6'!$J:$J,'[36]frm P6'!D:D,[36]Schedule!B8,'[36]frm P6'!E:E,[36]Schedule!C8,'[36]frm P6'!F:F,[36]Schedule!D8,'[36]frm P6'!G:G,[36]Schedule!$K$3,'[36]frm P6'!H:H,[36]Schedule!F8) -> 46422 | M8: =SUMIFS('[36]frm P6'!$K:$K,'[36]frm P6'!D:D,[36]Schedule!B8,'[36]frm P6'!E:E,[36]Schedule!C8,'[36]frm P6'!F:F,[36]Schedule!D8,'[36]frm P6'!G:G,[36]Schedule!$K$3,'[36]frm P6'!H:H,[36]Schedule!F8) -> 46441 | N8: =M8-L8+1 -> 20 | O8: 8 | P8: 35.37 | Q8: 406.4-500 | R8: =VLOOKUP(Q8,[37]导管架!N$2:Q$9,2,0) -> 1.2968666 | S8: =VLOOKUP(Q8,[37]导管架!N$2:Q$9,3,0) -> 2.4732262 | T8: =VLOOKUP(Q8,[37]导管架!N$2:Q$9,4,0) -> 4.6220437 | U8: =R8*AJ8*8 -> 248.99839 | V8: =S8*AD8*8 -> 672.71754 | W8: =T8*O8*8 -> 295.8108 | X8: =SUMIFS('[36]frm P6'!$J:$J,'[36]frm P6'!D:D,[36]Schedule!B8,'[36]frm P6'!E:E,[36]Schedule!C8,'[36]frm P6'!G:G,[36]Schedule!$W$3,'[36]frm P6'!H:H,[36]Schedule!F8) -> 46401 | Y8: =SUMIFS('[36]frm P6'!$K:$K,'[36]frm P6'!D:D,[36]Schedule!B8,'[36]frm P6'!E:E,[36]Schedule!C8,'[36]frm P6'!G:G,[36]Schedule!$W$3,'[36]frm P6'!H:H,[36]Schedule!F8) -> 46416 | Z8: =Y8-X8+1 -> 16 | AA8: =SUMIFS('[36]frm P6'!$J:$J,'[36]frm P6'!D:D,[36]Schedule!B8,'[36]frm P6'!E:E,[36]Schedule!C8,'[36]frm P6'!F:F,[36]Schedule!D8,'[36]frm P6'!G:G,[36]Schedule!$Z$3,'[36]frm P6'!H:H,[36]Schedule!F8) -> 46357 | AB8: =SUMIFS('[36]frm P6'!$K:$K,'[36]frm P6'!D:D,[36]Schedule!B8,'[36]frm P6'!E:E,[36]Schedule!C8,'[36]frm P6'!F:F,[36]Schedule!D8,'[36]frm P6'!G:G,[36]Schedule!$Z$3,'[36]frm P6'!H:H,[36]Schedule!F8) -> 46398 | AC8: =AB8-AA8+1 -> 42 | AD8: 34 | AE8: 359.28 | AF8: 500-1524 | AG8: =SUMIFS('[36]frm P6'!$J:$J,'[36]frm P6'!D:D,[36]Schedule!B8,'[36]frm P6'!E:E,[36]Schedule!C8,'[36]frm P6'!F:F,[36]Schedule!D8,'[36]frm P6'!G:G,[36]Schedule!$AF$3,'[36]frm P6'!H:H,[36]Schedule!F8) -> 46322 | AH8: =SUMIFS('[36]frm P6'!$K:$K,'[36]frm P6'!D:D,[36]Schedule!B8,'[36]frm P6'!E:E,[36]Schedule!C8,'[36]frm P6'!F:F,[36]Schedule!D8,'[36]frm P6'!G:G,[36]Schedule!$AF$3,'[36]frm P6'!H:H,[36]Schedule!F8) -> 46353 | AI8: =AH8-AG8+1 -> 32 | AJ8: 24 | AK8: 1101.48 | AL8: 500-1524 | AM8: =SUMIFS('[36]frm P6'!$J:$J,'[36]frm P6'!D:D,[36]Schedule!B8,'[36]frm P6'!E:E,[36]Schedule!C8,'[36]frm P6'!F:F,[36]Schedule!D8,'[36]frm P6'!G:G,[36]Schedule!$AL$3,'[36]frm P6'!H:H,[36]Schedule!F8) -> 46291 | AN8: =SUMIFS('[36]frm P6'!$K:$K,'[36]frm P6'!D:D,[36]Schedule!B8,'[36]frm P6'!E:E,[36]Schedule!C8,'[36]frm P6'!F:F,[36]Schedule!D8,'[36]frm P6'!G:G,[36]Schedule!$AL$3,'[36]frm P6'!H:H,[36]Schedule!F8) -> 46335 | AO8: =AN8-AM8+1 -> 45 | AP8: 41 | AQ8: 500-1549.4 | AR8: 62 | AS8: =AM8-$AS$3 -> 46288 | AT8: =AS8-$AT$3 -> 46228 | AU8: =AT8-$AU$3 -> 46213 | AV8: =AM8-$AV$3 -> 46287 | AW8: =AV8-$AW$3 -> 46277 | AX8: =AW8-AY8 -> 8 | AY8: 46269 | AZ8: JK01-1800 | BA8: Elevation Row A, B, 1, 2
B9: JKT | C9: S04B | D9: JKT-01 | F9: 01J | G9: =F9&C9 -> 01JS04B | H9: 5 | I9: S4B X Braces of RowA (1H~2H) | J9: 5.5 | K9: =L9-AB9 -> 30 | L9: =SUMIFS('[36]frm P6'!$J:$J,'[36]frm P6'!D:D,[36]Schedule!B9,'[36]frm P6'!E:E,[36]Schedule!C9,'[36]frm P6'!F:F,[36]Schedule!D9,'[36]frm P6'!G:G,[36]Schedule!$K$3,'[36]frm P6'!H:H,[36]Schedule!F9) -> 46445 | M9: =SUMIFS('[36]frm P6'!$K:$K,'[36]frm P6'!D:D,[36]Schedule!B9,'[36]frm P6'!E:E,[36]Schedule!C9,'[36]frm P6'!F:F,[36]Schedule!D9,'[36]frm P6'!G:G,[36]Schedule!$K$3,'[36]frm P6'!H:H,[36]Schedule!F9) -> 46449 | N9: =M9-L9+1 -> 5 | O9: 2 | P9: 21.085908 | Q9: 750 | R9: =VLOOKUP(Q9,[37]导管架!N$2:Q$9,2,0) -> 2.1138766 | S9: =VLOOKUP(Q9,[37]导管架!N$2:Q$9,3,0) -> 4.0638078 | T9: =VLOOKUP(Q9,[37]导管架!N$2:Q$9,4,0) -> 6.4396796 | U9: =R9*AJ9*8 -> 33.822026 | V9: =S9*AD9*8 -> 65.020925 | W9: =T9*O9*8 -> 103.03487 | X9: N/A | Y9: N/A | Z9: N/A | AA9: =SUMIFS('[36]frm P6'!$J:$J,'[36]frm P6'!D:D,[36]Schedule!B9,'[36]frm P6'!E:E,[36]Schedule!C9,'[36]frm P6'!F:F,[36]Schedule!D9,'[36]frm P6'!G:G,[36]Schedule!$Z$3,'[36]frm P6'!H:H,[36]Schedule!F9) -> 46399 | AB9: =SUMIFS('[36]frm P6'!$K:$K,'[36]frm P6'!D:D,[36]Schedule!B9,'[36]frm P6'!E:E,[36]Schedule!C9,'[36]frm P6'!F:F,[36]Schedule!D9,'[36]frm P6'!G:G,[36]Schedule!$Z$3,'[36]frm P6'!H:H,[36]Schedule!F9) -> 46415 | AC9: =AB9-AA9+1 -> 17 | AD9: 2 | AE9: 21.09 | AF9: 750 | AG9: =SUMIFS('[36]frm P6'!$J:$J,'[36]frm P6'!D:D,[36]Schedule!B9,'[36]frm P6'!E:E,[36]Schedule!C9,'[36]frm P6'!F:F,[36]Schedule!D9,'[36]frm P6'!G:G,[36]Schedule!$AF$3,'[36]frm P6'!H:H,[36]Schedule!F9) -> 46368 | AH9: =SUMIFS('[36]frm P6'!$K:$K,'[36]frm P6'!D:D,[36]Schedule!B9,'[36]frm P6'!E:E,[36]Schedule!C9,'[36]frm P6'!F:F,[36]Schedule!D9,'[36]frm P6'!G:G,[36]Schedule!$AF$3,'[36]frm P6'!H:H,[36]Schedule!F9) -> 46391 | AI9: =AH9-AG9+1 -> 24 | AJ9: 2 | AK9: 21.085 | AL9: 750 | AM9: =SUMIFS('[36]frm P6'!$J:$J,'[36]frm P6'!D:D,[36]Schedule!B9,'[36]frm P6'!E:E,[36]Schedule!C9,'[36]frm P6'!F:F,[36]Schedule!D9,'[36]frm P6'!G:G,[36]Schedule!$AL$3,'[36]frm P6'!H:H,[36]Schedule!F9) -> 46314 | AN9: =SUMIFS('[36]frm P6'!$K:$K,'[36]frm P6'!D:D,[36]Schedule!B9,'[36]frm P6'!E:E,[36]Schedule!C9,'[36]frm P6'!F:F,[36]Schedule!D9,'[36]frm P6'!G:G,[36]Schedule!$AL$3,'[36]frm P6'!H:H,[36]Schedule!F9) -> 46343 | AO9: =AN9-AM9+1 -> 30 | AP9: 5 | AQ9: 750 | AR9: 62 | AS9: =AM9-$AS$3 -> 46311 | AT9: =AS9-$AT$3 -> 46251 | AU9: =AT9-$AU$3 -> 46236 | AV9: =AM9-$AV$3 -> 46310 | AW9: =AV9-$AW$3 -> 46300 | AX9: =AW9-AY9 -> 31 | AY9: 46269 | AZ9: JK01-1800 | BA9: Elevation Row A, B, 1, 2
B10: JKT | C10: S04C | D10: JKT-01 | F10: 01J | H10: 6 | I10: S4C X Braces of RowB (1H~2H) | J10: 5.5 | K10: =L10-AB10 -> 14 | L10: =SUMIFS('[36]frm P6'!$J:$J,'[36]frm P6'!D:D,[36]Schedule!B10,'[36]frm P6'!E:E,[36]Schedule!C10,'[36]frm P6'!F:F,[36]Schedule!D10,'[36]frm P6'!G:G,[36]Schedule!$K$3,'[36]frm P6'!H:H,[36]Schedule!F10) -> 46449 | M10: =SUMIFS('[36]frm P6'!$K:$K,'[36]frm P6'!D:D,[36]Schedule!B10,'[36]frm P6'!E:E,[36]Schedule!C10,'[36]frm P6'!F:F,[36]Schedule!D10,'[36]frm P6'!G:G,[36]Schedule!$K$3,'[36]frm P6'!H:H,[36]Schedule!F10) -> 46454 | N10: =M10-L10+1 -> 6 | O10: 2 | P10: 21.085908 | Q10: 750 | R10: =VLOOKUP(Q10,[37]导管架!N$2:Q$9,2,0) -> 2.1138766 | S10: =VLOOKUP(Q10,[37]导管架!N$2:Q$9,3,0) -> 4.0638078 | T10: =VLOOKUP(Q10,[37]导管架!N$2:Q$9,4,0) -> 6.4396796 | U10: =R10*AJ10*8 -> 33.822026 | V10: =S10*AD10*8 -> 65.020925 | W10: =T10*O10*8 -> 103.03487 | X10: N/A | Y10: N/A | Z10: N/A | AA10: =SUMIFS('[36]frm P6'!$J:$J,'[36]frm P6'!D:D,[36]Schedule!B10,'[36]frm P6'!E:E,[36]Schedule!C10,'[36]frm P6'!F:F,[36]Schedule!D10,'[36]frm P6'!G:G,[36]Schedule!$Z$3,'[36]frm P6'!H:H,[36]Schedule!F10) -> 46409 | AB10: =SUMIFS('[36]frm P6'!$K:$K,'[36]frm P6'!D:D,[36]Schedule!B10,'[36]frm P6'!E:E,[36]Schedule!C10,'[36]frm P6'!F:F,[36]Schedule!D10,'[36]frm P6'!G:G,[36]Schedule!$Z$3,'[36]frm P6'!H:H,[36]Schedule!F10) -> 46435 | AC10: =AB10-AA10+1 -> 27 | AD10: 2 | AE10: 21.09 | AF10: 750 | AG10: =SUMIFS('[36]frm P6'!$J:$J,'[36]frm P6'!D:D,[36]Schedule!B10,'[36]frm P6'!E:E,[36]Schedule!C10,'[36]frm P6'!F:F,[36]Schedule!D10,'[36]frm P6'!G:G,[36]Schedule!$AF$3,'[36]frm P6'!H:H,[36]Schedule!F10) -> 46368 | AH10: =SUMIFS('[36]frm P6'!$K:$K,'[36]frm P6'!D:D,[36]Schedule!B10,'[36]frm P6'!E:E,[36]Schedule!C10,'[36]frm P6'!F:F,[36]Schedule!D10,'[36]frm P6'!G:G,[36]Schedule!$AF$3,'[36]frm P6'!H:H,[36]Schedule!F10) -> 46391 | AI10: =AH10-AG10+1 -> 24 | AJ10: 2 | AK10: 21.085 | AL10: 750 | AM10: =SUMIFS('[36]frm P6'!$J:$J,'[36]frm P6'!D:D,[36]Schedule!B10,'[36]frm P6'!E:E,[36]Schedule!C10,'[36]frm P6'!F:F,[36]Schedule!D10,'[36]frm P6'!G:G,[36]Schedule!$AL$3,'[36]frm P6'!H:H,[36]Schedule!F10) -> 46325 | AN10: =SUMIFS('[36]frm P6'!$K:$K,'[36]frm P6'!D:D,[36]Schedule!B10,'[36]frm P6'!E:E,[36]Schedule!C10,'[36]frm P6'!F:F,[36]Schedule!D10,'[36]frm P6'!G:G,[36]Schedule!$AL$3,'[36]frm P6'!H:H,[36]Schedule!F10) -> 46354 | AO10: =AN10-AM10+1 -> 30 | AP10: 5 | AQ10: 750 | AR10: 62 | AS10: =AM10-$AS$3 -> 46322 | AT10: =AS10-$AT$3 -> 46262 | AU10: =AT10-$AU$3 -> 46247 | AV10: =AM10-$AV$3 -> 46321 | AW10: =AV10-$AW$3 -> 46311 | AX10: =AW10-AY10 -> 42 | AY10: 46269 | AZ10: JK01-1800 | BA10: Elevation Row A, B, 1, 2
B11: JKT | C11: S05 | D11: JKT-01 | F11: 01J | H11: 7 | I11: S5 2H-Panel | J11: 18 | K11: =L11-AB11 -> 13 | L11: =SUMIFS('[36]frm P6'!$J:$J,'[36]frm P6'!D:D,[36]Schedule!B11,'[36]frm P6'!E:E,[36]Schedule!C11,'[36]frm P6'!F:F,[36]Schedule!D11,'[36]frm P6'!G:G,[36]Schedule!$K$3,'[36]frm P6'!H:H,[36]Schedule!F11) -> 46456 | M11: =SUMIFS('[36]frm P6'!$K:$K,'[36]frm P6'!D:D,[36]Schedule!B11,'[36]frm P6'!E:E,[36]Schedule!C11,'[36]frm P6'!F:F,[36]Schedule!D11,'[36]frm P6'!G:G,[36]Schedule!$K$3,'[36]frm P6'!H:H,[36]Schedule!F11) -> 46466 | N11: =M11-L11+1 -> 11 | O11: 4 | P11: 20.09 | Q11: 400-450 | R11: =VLOOKUP(Q11,[37]导管架!N$2:Q$9,2,0) -> 1.2794121 | S11: =VLOOKUP(Q11,[37]导管架!N$2:Q$9,3,0) -> 2.4401354 | T11: =VLOOKUP(Q11,[37]导管架!N$2:Q$9,4,0) -> 4.5668923 | U11: =R11*AJ11*8 -> 20.470593 | V11: =S11*AD11*8 -> 429.46383 | W11: =T11*O11*8 -> 146.14055 | X11: N/A | Y11: N/A | Z11: N/A | AA11: =SUMIFS('[36]frm P6'!$J:$J,'[36]frm P6'!D:D,[36]Schedule!B11,'[36]frm P6'!E:E,[36]Schedule!C11,'[36]frm P6'!F:F,[36]Schedule!D11,'[36]frm P6'!G:G,[36]Schedule!$Z$3,'[36]frm P6'!H:H,[36]Schedule!F11) -> 46401 | AB11: =SUMIFS('[36]frm P6'!$K:$K,'[36]frm P6'!D:D,[36]Schedule!B11,'[36]frm P6'!E:E,[36]Schedule!C11,'[36]frm P6'!F:F,[36]Schedule!D11,'[36]frm P6'!G:G,[36]Schedule!$Z$3,'[36]frm P6'!H:H,[36]Schedule!F11) -> 46443 | AC11: =AB11-AA11+1 -> 43 | AD11: 22 | AE11: 58.93 | AF11: 323.9-450 | AG11: =SUMIFS('[36]frm P6'!$J:$J,'[36]frm P6'!D:D,[36]Schedule!B11,'[36]frm P6'!E:E,[36]Schedule!C11,'[36]frm P6'!F:F,[36]Schedule!D11,'[36]frm P6'!G:G,[36]Schedule!$AF$3,'[36]frm P6'!H:H,[36]Schedule!F11) -> 46360 | AH11: =SUMIFS('[36]frm P6'!$K:$K,'[36]frm P6'!D:D,[36]Schedule!B11,'[36]frm P6'!E:E,[36]Schedule!C11,'[36]frm P6'!F:F,[36]Schedule!D11,'[36]frm P6'!G:G,[36]Schedule!$AF$3,'[36]frm P6'!H:H,[36]Schedule!F11) -> 46389 | AI11: =AH11-AG11+1 -> 30 | AJ11: 2 | AK11: 12.65 | AL11: 450 | AM11: =SUMIFS('[36]frm P6'!$J:$J,'[36]frm P6'!D:D,[36]Schedule!B11,'[36]frm P6'!E:E,[36]Schedule!C11,'[36]frm P6'!F:F,[36]Schedule!D11,'[36]frm P6'!G:G,[36]Schedule!$AL$3,'[36]frm P6'!H:H,[36]Schedule!F11) -> 46331 | AN11: =SUMIFS('[36]frm P6'!$K:$K,'[36]frm P6'!D:D,[36]Schedule!B11,'[36]frm P6'!E:E,[36]Schedule!C11,'[36]frm P6'!F:F,[36]Schedule!D11,'[36]frm P6'!G:G,[36]Schedule!$AL$3,'[36]frm P6'!H:H,[36]Schedule!F11) -> 46354 | AO11: =AN11-AM11+1 -> 24 | AP11: 7 | AQ11: 450-500 | AR11: 62 | AS11: =AM11-$AS$3 -> 46328 | AT11: =AS11-$AT$3 -> 46268 | AU11: =AT11-$AU$3 -> 46253 | AV11: =AM11-$AV$3 -> 46327 | AW11: =AV11-$AW$3 -> 46317 | AX11: =AW11-AY11 -> 43 | AY11: 46274 | AZ11: JK01-1830 | BA11: Horizontal Framing Plan
B12: JKT | C12: S06A | D12: JKT-01 | F12: 01J | H12: 8 | I12: S6A X Braces of RowA (2H~3H) | J12: 2.75 | K12: =L12-Y12 -> 0 | L12: =SUMIFS('[36]frm P6'!$J:$J,'[36]frm P6'!D:D,[36]Schedule!B12,'[36]frm P6'!E:E,[36]Schedule!C12,'[36]frm P6'!F:F,[36]Schedule!D12,'[36]frm P6'!G:G,[36]Schedule!$K$3,'[36]frm P6'!H:H,[36]Schedule!F12) -> 46468 | M12: =SUMIFS('[36]frm P6'!$K:$K,'[36]frm P6'!D:D,[36]Schedule!B12,'[36]frm P6'!E:E,[36]Schedule!C12,'[36]frm P6'!F:F,[36]Schedule!D12,'[36]frm P6'!G:G,[36]Schedule!$K$3,'[36]frm P6'!H:H,[36]Schedule!F12) -> 46471 | N12: =M12-L12+1 -> 4 | O12: 2 | P12: 10.23 | Q12: 550 | R12: =VLOOKUP(Q12,[37]导管架!N$2:Q$9,2,0) -> 1.3143211 | S12: =VLOOKUP(Q12,[37]导管架!N$2:Q$9,3,0) -> 2.5063171 | T12: =VLOOKUP(Q12,[37]导管架!N$2:Q$9,4,0) -> 4.6771951 | U12: =R12*AJ12*8 -> 31.543706 | V12: =S12*AD12*8 -> 40.101073 | W12: =T12*O12*8 -> 74.835122 | X12: =SUMIFS('[36]frm P6'!$J:$J,'[36]frm P6'!D:D,[36]Schedule!B12,'[36]frm P6'!E:E,[36]Schedule!C12,'[36]frm P6'!G:G,[36]Schedule!$W$3,'[36]frm P6'!H:H,[36]Schedule!F12) -> 46451 | Y12: =SUMIFS('[36]frm P6'!$K:$K,'[36]frm P6'!D:D,[36]Schedule!B12,'[36]frm P6'!E:E,[36]Schedule!C12,'[36]frm P6'!G:G,[36]Schedule!$W$3,'[36]frm P6'!H:H,[36]Schedule!F12) -> 46468 | Z12: =Y12-X12+1 -> 18 | AA12: =SUMIFS('[36]frm P6'!$J:$J,'[36]frm P6'!D:D,[36]Schedule!B12,'[36]frm P6'!E:E,[36]Schedule!C12,'[36]frm P6'!F:F,[36]Schedule!D12,'[36]frm P6'!G:G,[36]Schedule!$Z$3,'[36]frm P6'!H:H,[36]Schedule!F12) -> 46402 | AB12: =SUMIFS('[36]frm P6'!$K:$K,'[36]frm P6'!D:D,[36]Schedule!B12,'[36]frm P6'!E:E,[36]Schedule!C12,'[36]frm P6'!F:F,[36]Schedule!D12,'[36]frm P6'!G:G,[36]Schedule!$Z$3,'[36]frm P6'!H:H,[36]Schedule!F12) -> 46419 | AC12: =AB12-AA12+1 -> 18 | AD12: 2 | AE12: 10.23 | AF12: 550 | AG12: =SUMIFS('[36]frm P6'!$J:$J,'[36]frm P6'!D:D,[36]Schedule!B12,'[36]frm P6'!E:E,[36]Schedule!C12,'[36]frm P6'!F:F,[36]Schedule!D12,'[36]frm P6'!G:G,[36]Schedule!$AF$3,'[36]frm P6'!H:H,[36]Schedule!F12) -> 46373 | AH12: =SUMIFS('[36]frm P6'!$K:$K,'[36]frm P6'!D:D,[36]Schedule!B12,'[36]frm P6'!E:E,[36]Schedule!C12,'[36]frm P6'!F:F,[36]Schedule!D12,'[36]frm P6'!G:G,[36]Schedule!$AF$3,'[36]frm P6'!H:H,[36]Schedule!F12) -> 46395 | AI12: =AH12-AG12+1 -> 23 | AJ12: 3 | AK12: 15.34 | AL12: 550 | AM12: =SUMIFS('[36]frm P6'!$J:$J,'[36]frm P6'!D:D,[36]Schedule!B12,'[36]frm P6'!E:E,[36]Schedule!C12,'[36]frm P6'!F:F,[36]Schedule!D12,'[36]frm P6'!G:G,[36]Schedule!$AL$3,'[36]frm P6'!H:H,[36]Schedule!F12) -> 46339 | AN12: =SUMIFS('[36]frm P6'!$K:$K,'[36]frm P6'!D:D,[36]Schedule!B12,'[36]frm P6'!E:E,[36]Schedule!C12,'[36]frm P6'!F:F,[36]Schedule!D12,'[36]frm P6'!G:G,[36]Schedule!$AL$3,'[36]frm P6'!H:H,[36]Schedule!F12) -> 46365 | AO12: =AN12-AM12+1 -> 27 | AP12: 6 | AQ12: 550 | AR12: 62 | AS12: =AM12-$AS$3 -> 46336 | AT12: =AS12-$AT$3 -> 46276 | AU12: =AT12-$AU$3 -> 46261 | AV12: =AM12-$AV$3 -> 46335 | AW12: =AV12-$AW$3 -> 46325 | AX12: =AW12-AY12 -> 56 | AY12: 46269 | AZ12: JK01-1800 | BA12: Elevation Row A, B, 1, 2
B13: JKT | C13: S06B | D13: JKT-01 | F13: 01J | H13: 9 | I13: S6B X Braces of RowB (2H~3H) | J13: 2.75 | K13: =L13-Y13 -> 0 | L13: =SUMIFS('[36]frm P6'!$J:$J,'[36]frm P6'!D:D,[36]Schedule!B13,'[36]frm P6'!E:E,[36]Schedule!C13,'[36]frm P6'!F:F,[36]Schedule!D13,'[36]frm P6'!G:G,[36]Schedule!$K$3,'[36]frm P6'!H:H,[36]Schedule!F13) -> 46471 | M13: =SUMIFS('[36]frm P6'!$K:$K,'[36]frm P6'!D:D,[36]Schedule!B13,'[36]frm P6'!E:E,[36]Schedule!C13,'[36]frm P6'!F:F,[36]Schedule!D13,'[36]frm P6'!G:G,[36]Schedule!$K$3,'[36]frm P6'!H:H,[36]Schedule!F13) -> 46476 | N13: =M13-L13+1 -> 6 | O13: 2 | P13: 10.23 | Q13: 550 | R13: =VLOOKUP(Q13,[37]导管架!N$2:Q$9,2,0) -> 1.3143211 | S13: =VLOOKUP(Q13,[37]导管架!N$2:Q$9,3,0) -> 2.5063171 | T13: =VLOOKUP(Q13,[37]导管架!N$2:Q$9,4,0) -> 4.6771951 | U13: =R13*AJ13*8 -> 31.543706 | V13: =S13*AD13*8 -> 40.101073 | W13: =T13*O13*8 -> 74.835122 | X13: =SUMIFS('[36]frm P6'!$J:$J,'[36]frm P6'!D:D,[36]Schedule!B13,'[36]frm P6'!E:E,[36]Schedule!C13,'[36]frm P6'!G:G,[36]Schedule!$W$3,'[36]frm P6'!H:H,[36]Schedule!F13) -> 46455 | Y13: =SUMIFS('[36]frm P6'!$K:$K,'[36]frm P6'!D:D,[36]Schedule!B13,'[36]frm P6'!E:E,[36]Schedule!C13,'[36]frm P6'!G:G,[36]Schedule!$W$3,'[36]frm P6'!H:H,[36]Schedule!F13) -> 46471 | Z13: =Y13-X13+1 -> 17 | AA13: =SUMIFS('[36]frm P6'!$J:$J,'[36]frm P6'!D:D,[36]Schedule!B13,'[36]frm P6'!E:E,[36]Schedule!C13,'[36]frm P6'!F:F,[36]Schedule!D13,'[36]frm P6'!G:G,[36]Schedule!$Z$3,'[36]frm P6'!H:H,[36]Schedule!F13) -> 46409 | AB13: =SUMIFS('[36]frm P6'!$K:$K,'[36]frm P6'!D:D,[36]Schedule!B13,'[36]frm P6'!E:E,[36]Schedule!C13,'[36]frm P6'!F:F,[36]Schedule!D13,'[36]frm P6'!G:G,[36]Schedule!$Z$3,'[36]frm P6'!H:H,[36]Schedule!F13) -> 46437 | AC13: =AB13-AA13+1 -> 29 | AD13: 2 | AE13: 10.23 | AF13: 550 | AG13: =SUMIFS('[36]frm P6'!$J:$J,'[36]frm P6'!D:D,[36]Schedule!B13,'[36]frm P6'!E:E,[36]Schedule!C13,'[36]frm P6'!F:F,[36]Schedule!D13,'[36]frm P6'!G:G,[36]Schedule!$AF$3,'[36]frm P6'!H:H,[36]Schedule!F13) -> 46381 | AH13: =SUMIFS('[36]frm P6'!$K:$K,'[36]frm P6'!D:D,[36]Schedule!B13,'[36]frm P6'!E:E,[36]Schedule!C13,'[36]frm P6'!F:F,[36]Schedule!D13,'[36]frm P6'!G:G,[36]Schedule!$AF$3,'[36]frm P6'!H:H,[36]Schedule!F13) -> 46403 | AI13: =AH13-AG13+1 -> 23 | AJ13: 3 | AK13: 15.34 | AL13: 550 | AM13: =SUMIFS('[36]frm P6'!$J:$J,'[36]frm P6'!D:D,[36]Schedule!B13,'[36]frm P6'!E:E,[36]Schedule!C13,'[36]frm P6'!F:F,[36]Schedule!D13,'[36]frm P6'!G:G,[36]Schedule!$AL$3,'[36]frm P6'!H:H,[36]Schedule!F13) -> 46347 | AN13: =SUMIFS('[36]frm P6'!$K:$K,'[36]frm P6'!D:D,[36]Schedule!B13,'[36]frm P6'!E:E,[36]Schedule!C13,'[36]frm P6'!F:F,[36]Schedule!D13,'[36]frm P6'!G:G,[36]Schedule!$AL$3,'[36]frm P6'!H:H,[36]Schedule!F13) -> 46373 | AO13: =AN13-AM13+1 -> 27 | AP13: 6 | AQ13: 550 | AR13: 62 | AS13: =AM13-$AS$3 -> 46344 | AT13: =AS13-$AT$3 -> 46284 | AU13: =AT13-$AU$3 -> 46269 | AV13: =AM13-$AV$3 -> 46343 | AW13: =AV13-$AW$3 -> 46333 | AX13: =AW13-AY13 -> 64 | AY13: 46269 | AZ13: JK01-1800 | BA13: Elevation Row A, B, 1, 2
B14: JKT | C14: S07 | D14: JKT-01 | F14: 01J | H14: 10 | I14: S7 3H-Panel | J14: 15 | K14: =L14-Y14 -> 7 | L14: =SUMIFS('[36]frm P6'!$J:$J,'[36]frm P6'!D:D,[36]Schedule!B14,'[36]frm P6'!E:E,[36]Schedule!C14,'[36]frm P6'!F:F,[36]Schedule!D14,'[36]frm P6'!G:G,[36]Schedule!$K$3,'[36]frm P6'!H:H,[36]Schedule!F14) -> 46476 | M14: =SUMIFS('[36]frm P6'!$K:$K,'[36]frm P6'!D:D,[36]Schedule!B14,'[36]frm P6'!E:E,[36]Schedule!C14,'[36]frm P6'!F:F,[36]Schedule!D14,'[36]frm P6'!G:G,[36]Schedule!$K$3,'[36]frm P6'!H:H,[36]Schedule!F14) -> 46486 | N14: =M14-L14+1 -> 11 | O14: 4 | P14: 31.04 | Q14: 450-500 | R14: =VLOOKUP(Q14,[37]导管架!N$2:Q$9,2,0) -> 1.2968666 | S14: =VLOOKUP(Q14,[37]导管架!N$2:Q$9,3,0) -> 2.4732262 | T14: =VLOOKUP(Q14,[37]导管架!N$2:Q$9,4,0) -> 4.6220437 | U14: =R14*AJ14*8 -> 41.499731 | V14: =S14*AD14*8 -> 435.28782 | W14: =T14*O14*8 -> 147.9054 | X14: =SUMIFS('[36]frm P6'!$J:$J,'[36]frm P6'!D:D,[36]Schedule!B14,'[36]frm P6'!E:E,[36]Schedule!C14,'[36]frm P6'!G:G,[36]Schedule!$W$3,'[36]frm P6'!H:H,[36]Schedule!F14) -> 46452 | Y14: =SUMIFS('[36]frm P6'!$K:$K,'[36]frm P6'!D:D,[36]Schedule!B14,'[36]frm P6'!E:E,[36]Schedule!C14,'[36]frm P6'!G:G,[36]Schedule!$W$3,'[36]frm P6'!H:H,[36]Schedule!F14) -> 46469 | Z14: =Y14-X14+1 -> 18 | AA14: =SUMIFS('[36]frm P6'!$J:$J,'[36]frm P6'!D:D,[36]Schedule!B14,'[36]frm P6'!E:E,[36]Schedule!C14,'[36]frm P6'!F:F,[36]Schedule!D14,'[36]frm P6'!G:G,[36]Schedule!$Z$3,'[36]frm P6'!H:H,[36]Schedule!F14) -> 46406 | AB14: =SUMIFS('[36]frm P6'!$K:$K,'[36]frm P6'!D:D,[36]Schedule!B14,'[36]frm P6'!E:E,[36]Schedule!C14,'[36]frm P6'!F:F,[36]Schedule!D14,'[36]frm P6'!G:G,[36]Schedule!$Z$3,'[36]frm P6'!H:H,[36]Schedule!F14) -> 46448 | AC14: =AB14-AA14+1 -> 43 | AD14: 22 | AE14: 70.12 | AF14: 323.9-450 | AG14: =SUMIFS('[36]frm P6'!$J:$J,'[36]frm P6'!D:D,[36]Schedule!B14,'[36]frm P6'!E:E,[36]Schedule!C14,'[36]frm P6'!F:F,[36]Schedule!D14,'[36]frm P6'!G:G,[36]Schedule!$AF$3,'[36]frm P6'!H:H,[36]Schedule!F14) -> 46365 | AH14: =SUMIFS('[36]frm P6'!$K:$K,'[36]frm P6'!D:D,[36]Schedule!B14,'[36]frm P6'!E:E,[36]Schedule!C14,'[36]frm P6'!F:F,[36]Schedule!D14,'[36]frm P6'!G:G,[36]Schedule!$AF$3,'[36]frm P6'!H:H,[36]Schedule!F14) -> 46394 | AI14: =AH14-AG14+1 -> 30 | AJ14: 4 | AK14: 31.04 | AL14: 450-500 | AM14: =SUMIFS('[36]frm P6'!$J:$J,'[36]frm P6'!D:D,[36]Schedule!B14,'[36]frm P6'!E:E,[36]Schedule!C14,'[36]frm P6'!F:F,[36]Schedule!D14,'[36]frm P6'!G:G,[36]Schedule!$AL$3,'[36]frm P6'!H:H,[36]Schedule!F14) -> 46339 | AN14: =SUMIFS('[36]frm P6'!$K:$K,'[36]frm P6'!D:D,[36]Schedule!B14,'[36]frm P6'!E:E,[36]Schedule!C14,'[36]frm P6'!F:F,[36]Schedule!D14,'[36]frm P6'!G:G,[36]Schedule!$AL$3,'[36]frm P6'!H:H,[36]Schedule!F14) -> 46365 | AO14: =AN14-AM14+1 -> 27 | AP14: 9 | AQ14: 450-500 | AR14: 62 | AS14: =AM14-$AS$3 -> 46336 | AT14: =AS14-$AT$3 -> 46276 | AU14: =AT14-$AU$3 -> 46261 | AV14: =AM14-$AV$3 -> 46335 | AW14: =AV14-$AW$3 -> 46325 | AX14: =AW14-AY14 -> 51 | AY14: 46274 | AZ14: JK01-1830 | BA14: Horizontal Framing Plan
B15: JKT | C15: S08A | D15: JKT-01 | F15: 01J | H15: 11 | I15: S8A X Braces of RowA (3H~4H) | J15: 2 | K15: =L15-Y15 -> 17 | L15: =SUMIFS('[36]frm P6'!$J:$J,'[36]frm P6'!D:D,[36]Schedule!B15,'[36]frm P6'!E:E,[36]Schedule!C15,'[36]frm P6'!F:F,[36]Schedule!D15,'[36]frm P6'!G:G,[36]Schedule!$K$3,'[36]frm P6'!H:H,[36]Schedule!F15) -> 46486 | M15: =SUMIFS('[36]frm P6'!$K:$K,'[36]frm P6'!D:D,[36]Schedule!B15,'[36]frm P6'!E:E,[36]Schedule!C15,'[36]frm P6'!F:F,[36]Schedule!D15,'[36]frm P6'!G:G,[36]Schedule!$K$3,'[36]frm P6'!H:H,[36]Schedule!F15) -> 46490 | N15: =M15-L15+1 -> 5 | O15: 2 | P15: 7.33 | Q15: 550 | R15: =VLOOKUP(Q15,[37]导管架!N$2:Q$9,2,0) -> 1.3143211 | S15: =VLOOKUP(Q15,[37]导管架!N$2:Q$9,3,0) -> 2.5063171 | T15: =VLOOKUP(Q15,[37]导管架!N$2:Q$9,4,0) -> 4.6771951 | U15: =R15*AJ15*8 -> 21.029138 | V15: =S15*AD15*8 -> 40.101073 | W15: =T15*O15*8 -> 74.835122 | X15: =SUMIFS('[36]frm P6'!$J:$J,'[36]frm P6'!D:D,[36]Schedule!B15,'[36]frm P6'!E:E,[36]Schedule!C15,'[36]frm P6'!G:G,[36]Schedule!$W$3,'[36]frm P6'!H:H,[36]Schedule!F15) -> 46452 | Y15: =SUMIFS('[36]frm P6'!$K:$K,'[36]frm P6'!D:D,[36]Schedule!B15,'[36]frm P6'!E:E,[36]Schedule!C15,'[36]frm P6'!G:G,[36]Schedule!$W$3,'[36]frm P6'!H:H,[36]Schedule!F15) -> 46469 | Z15: =Y15-X15+1 -> 18 | AA15: =SUMIFS('[36]frm P6'!$J:$J,'[36]frm P6'!D:D,[36]Schedule!B15,'[36]frm P6'!E:E,[36]Schedule!C15,'[36]frm P6'!F:F,[36]Schedule!D15,'[36]frm P6'!G:G,[36]Schedule!$Z$3,'[36]frm P6'!H:H,[36]Schedule!F15) -> 46419 | AB15: =SUMIFS('[36]frm P6'!$K:$K,'[36]frm P6'!D:D,[36]Schedule!B15,'[36]frm P6'!E:E,[36]Schedule!C15,'[36]frm P6'!F:F,[36]Schedule!D15,'[36]frm P6'!G:G,[36]Schedule!$Z$3,'[36]frm P6'!H:H,[36]Schedule!F15) -> 46444 | AC15: =AB15-AA15+1 -> 26 | AD15: 2 | AE15: 7.33 | AF15: 550 | AG15: =SUMIFS('[36]frm P6'!$J:$J,'[36]frm P6'!D:D,[36]Schedule!B15,'[36]frm P6'!E:E,[36]Schedule!C15,'[36]frm P6'!F:F,[36]Schedule!D15,'[36]frm P6'!G:G,[36]Schedule!$AF$3,'[36]frm P6'!H:H,[36]Schedule!F15) -> 46385 | AH15: =SUMIFS('[36]frm P6'!$K:$K,'[36]frm P6'!D:D,[36]Schedule!B15,'[36]frm P6'!E:E,[36]Schedule!C15,'[36]frm P6'!F:F,[36]Schedule!D15,'[36]frm P6'!G:G,[36]Schedule!$AF$3,'[36]frm P6'!H:H,[36]Schedule!F15) -> 46407 | AI15: =AH15-AG15+1 -> 23 | AJ15: 2 | AK15: 7.33 | AL15: 550 | AM15: =SUMIFS('[36]frm P6'!$J:$J,'[36]frm P6'!D:D,[36]Schedule!B15,'[36]frm P6'!E:E,[36]Schedule!C15,'[36]frm P6'!F:F,[36]Schedule!D15,'[36]frm P6'!G:G,[36]Schedule!$AL$3,'[36]frm P6'!H:H,[36]Schedule!F15) -> 46347 | AN15: =SUMIFS('[36]frm P6'!$K:$K,'[36]frm P6'!D:D,[36]Schedule!B15,'[36]frm P6'!E:E,[36]Schedule!C15,'[36]frm P6'!F:F,[36]Schedule!D15,'[36]frm P6'!G:G,[36]Schedule!$AL$3,'[36]frm P6'!H:H,[36]Schedule!F15) -> 46377 | AO15: =AN15-AM15+1 -> 31 | AP15: 5 | AQ15: 550 | AR15: 62 | AS15: =AM15-$AS$3 -> 46344 | AT15: =AS15-$AT$3 -> 46284 | AU15: =AT15-$AU$3 -> 46269 | AV15: =AM15-$AV$3 -> 46343 | AW15: =AV15-$AW$3 -> 46333 | AX15: =AW15-AY15 -> 64 | AY15: 46269 | AZ15: JK01-1800 | BA15: Elevation Row A, B, 1, 2
B16: JKT | C16: S08B | D16: JKT-01 | F16: 01J | H16: 12 | I16: S8B X Braces of RowB (3H~4H) | J16: 2 | K16: =L16-Y16 -> 6 | L16: =SUMIFS('[36]frm P6'!$J:$J,'[36]frm P6'!D:D,[36]Schedule!B16,'[36]frm P6'!E:E,[36]Schedule!C16,'[36]frm P6'!F:F,[36]Schedule!D16,'[36]frm P6'!G:G,[36]Schedule!$K$3,'[36]frm P6'!H:H,[36]Schedule!F16) -> 46490 | M16: =SUMIFS('[36]frm P6'!$K:$K,'[36]frm P6'!D:D,[36]Schedule!B16,'[36]frm P6'!E:E,[36]Schedule!C16,'[36]frm P6'!F:F,[36]Schedule!D16,'[36]frm P6'!G:G,[36]Schedule!$K$3,'[36]frm P6'!H:H,[36]Schedule!F16) -> 46494 | N16: =M16-L16+1 -> 5 | O16: 2 | P16: 7.33 | Q16: 550 | R16: =VLOOKUP(Q16,[37]导管架!N$2:Q$9,2,0) -> 1.3143211 | S16: =VLOOKUP(Q16,[37]导管架!N$2:Q$9,3,0) -> 2.5063171 | T16: =VLOOKUP(Q16,[37]导管架!N$2:Q$9,4,0) -> 4.6771951 | U16: =R16*AJ16*8 -> 21.029138 | V16: =S16*AD16*8 -> 40.101073 | W16: =T16*O16*8 -> 74.835122 | X16: =SUMIFS('[36]frm P6'!$J:$J,'[36]frm P6'!D:D,[36]Schedule!B16,'[36]frm P6'!E:E,[36]Schedule!C16,'[36]frm P6'!G:G,[36]Schedule!$W$3,'[36]frm P6'!H:H,[36]Schedule!F16) -> 46466 | Y16: =SUMIFS('[36]frm P6'!$K:$K,'[36]frm P6'!D:D,[36]Schedule!B16,'[36]frm P6'!E:E,[36]Schedule!C16,'[36]frm P6'!G:G,[36]Schedule!$W$3,'[36]frm P6'!H:H,[36]Schedule!F16) -> 46484 | Z16: =Y16-X16+1 -> 19 | AA16: =SUMIFS('[36]frm P6'!$J:$J,'[36]frm P6'!D:D,[36]Schedule!B16,'[36]frm P6'!E:E,[36]Schedule!C16,'[36]frm P6'!F:F,[36]Schedule!D16,'[36]frm P6'!G:G,[36]Schedule!$Z$3,'[36]frm P6'!H:H,[36]Schedule!F16) -> 46437 | AB16: =SUMIFS('[36]frm P6'!$K:$K,'[36]frm P6'!D:D,[36]Schedule!B16,'[36]frm P6'!E:E,[36]Schedule!C16,'[36]frm P6'!F:F,[36]Schedule!D16,'[36]frm P6'!G:G,[36]Schedule!$Z$3,'[36]frm P6'!H:H,[36]Schedule!F16) -> 46458 | AC16: =AB16-AA16+1 -> 22 | AD16: 2 | AE16: 7.33 | AF16: 550 | AG16: =SUMIFS('[36]frm P6'!$J:$J,'[36]frm P6'!D:D,[36]Schedule!B16,'[36]frm P6'!E:E,[36]Schedule!C16,'[36]frm P6'!F:F,[36]Schedule!D16,'[36]frm P6'!G:G,[36]Schedule!$AF$3,'[36]frm P6'!H:H,[36]Schedule!F16) -> 46399 | AH16: =SUMIFS('[36]frm P6'!$K:$K,'[36]frm P6'!D:D,[36]Schedule!B16,'[36]frm P6'!E:E,[36]Schedule!C16,'[36]frm P6'!F:F,[36]Schedule!D16,'[36]frm P6'!G:G,[36]Schedule!$AF$3,'[36]frm P6'!H:H,[36]Schedule!F16) -> 46422 | AI16: =AH16-AG16+1 -> 24 | AJ16: 2 | AK16: 7.33 | AL16: 550 | AM16: =SUMIFS('[36]frm P6'!$J:$J,'[36]frm P6'!D:D,[36]Schedule!B16,'[36]frm P6'!E:E,[36]Schedule!C16,'[36]frm P6'!F:F,[36]Schedule!D16,'[36]frm P6'!G:G,[36]Schedule!$AL$3,'[36]frm P6'!H:H,[36]Schedule!F16) -> 46356 | AN16: =SUMIFS('[36]frm P6'!$K:$K,'[36]frm P6'!D:D,[36]Schedule!B16,'[36]frm P6'!E:E,[36]Schedule!C16,'[36]frm P6'!F:F,[36]Schedule!D16,'[36]frm P6'!G:G,[36]Schedule!$AL$3,'[36]frm P6'!H:H,[36]Schedule!F16) -> 46385 | AO16: =AN16-AM16+1 -> 30 | AP16: 5 | AQ16: 550 | AR16: 62 | AS16: =AM16-$AS$3 -> 46353 | AT16: =AS16-$AT$3 -> 46293 | AU16: =AT16-$AU$3 -> 46278 | AV16: =AM16-$AV$3 -> 46352 | AW16: =AV16-$AW$3 -> 46342 | AX16: =AW16-AY16 -> 73 | AY16: 46269 | AZ16: JK01-1800 | BA16: Elevation Row A, B, 1, 2
B17: JKT | C17: S09A | D17: JKT-01 | F17: 01J | H17: 13 | I17: S9 4H-Panel | J17: 14.7 | K17: =L17-Y17 -> 9 | L17: =SUMIFS('[36]frm P6'!$J:$J,'[36]frm P6'!D:D,[36]Schedule!B17,'[36]frm P6'!E:E,[36]Schedule!C17,'[36]frm P6'!F:F,[36]Schedule!D17,'[36]frm P6'!G:G,[36]Schedule!$K$3,'[36]frm P6'!H:H,[36]Schedule!F17) -> 46494 | M17: =SUMIFS('[36]frm P6'!$K:$K,'[36]frm P6'!D:D,[36]Schedule!B17,'[36]frm P6'!E:E,[36]Schedule!C17,'[36]frm P6'!F:F,[36]Schedule!D17,'[36]frm P6'!G:G,[36]Schedule!$K$3,'[36]frm P6'!H:H,[36]Schedule!F17) -> 46504 | N17: =M17-L17+1 -> 11 | O17: 4 | P17: 17.69 | Q17: 406.4-500 | R17: =VLOOKUP(Q17,[37]导管架!N$2:Q$9,2,0) -> 1.2968666 | S17: =VLOOKUP(Q17,[37]导管架!N$2:Q$9,3,0) -> 2.4732262 | T17: =VLOOKUP(Q17,[37]导管架!N$2:Q$9,4,0) -> 4.6220437 | U17: =R17*AJ17*8 -> 41.499731 | V17: =S17*AD17*8 -> 435.28782 | W17: =T17*O17*8 -> 147.9054 | X17: =SUMIFS('[36]frm P6'!$J:$J,'[36]frm P6'!D:D,[36]Schedule!B17,'[36]frm P6'!E:E,[36]Schedule!C17,'[36]frm P6'!G:G,[36]Schedule!$W$3,'[36]frm P6'!H:H,[36]Schedule!F17) -> 46468 | Y17: =SUMIFS('[36]frm P6'!$K:$K,'[36]frm P6'!D:D,[36]Schedule!B17,'[36]frm P6'!E:E,[36]Schedule!C17,'[36]frm P6'!G:G,[36]Schedule!$W$3,'[36]frm P6'!H:H,[36]Schedule!F17) -> 46485 | Z17: =Y17-X17+1 -> 18 | AA17: =SUMIFS('[36]frm P6'!$J:$J,'[36]frm P6'!D:D,[36]Schedule!B17,'[36]frm P6'!E:E,[36]Schedule!C17,'[36]frm P6'!F:F,[36]Schedule!D17,'[36]frm P6'!G:G,[36]Schedule!$Z$3,'[36]frm P6'!H:H,[36]Schedule!F17) -> 46421 | AB17: =SUMIFS('[36]frm P6'!$K:$K,'[36]frm P6'!D:D,[36]Schedule!B17,'[36]frm P6'!E:E,[36]Schedule!C17,'[36]frm P6'!F:F,[36]Schedule!D17,'[36]frm P6'!G:G,[36]Schedule!$Z$3,'[36]frm P6'!H:H,[36]Schedule!F17) -> 46463 | AC17: =AB17-AA17+1 -> 43 | AD17: 22 | AE17: 54.67 | AF17: 323.9-406.4 | AG17: =SUMIFS('[36]frm P6'!$J:$J,'[36]frm P6'!D:D,[36]Schedule!B17,'[36]frm P6'!E:E,[36]Schedule!C17,'[36]frm P6'!F:F,[36]Schedule!D17,'[36]frm P6'!G:G,[36]Schedule!$AF$3,'[36]frm P6'!H:H,[36]Schedule!F17) -> 46385 | AH17: =SUMIFS('[36]frm P6'!$K:$K,'[36]frm P6'!D:D,[36]Schedule!B17,'[36]frm P6'!E:E,[36]Schedule!C17,'[36]frm P6'!F:F,[36]Schedule!D17,'[36]frm P6'!G:G,[36]Schedule!$AF$3,'[36]frm P6'!H:H,[36]Schedule!F17) -> 46414 | AI17: =AH17-AG17+1 -> 30 | AJ17: 4 | AK17: 17.69 | AL17: 406.4-500 | AM17: =SUMIFS('[36]frm P6'!$J:$J,'[36]frm P6'!D:D,[36]Schedule!B17,'[36]frm P6'!E:E,[36]Schedule!C17,'[36]frm P6'!F:F,[36]Schedule!D17,'[36]frm P6'!G:G,[36]Schedule!$AL$3,'[36]frm P6'!H:H,[36]Schedule!F17) -> 46344 | AN17: =SUMIFS('[36]frm P6'!$K:$K,'[36]frm P6'!D:D,[36]Schedule!B17,'[36]frm P6'!E:E,[36]Schedule!C17,'[36]frm P6'!F:F,[36]Schedule!D17,'[36]frm P6'!G:G,[36]Schedule!$AL$3,'[36]frm P6'!H:H,[36]Schedule!F17) -> 46367 | AO17: =AN17-AM17+1 -> 24 | AP17: 4 | AQ17: 500 | AR17: 62 | AS17: =AM17-$AS$3 -> 46341 | AT17: =AS17-$AT$3 -> 46281 | AU17: =AT17-$AU$3 -> 46266 | AV17: =AM17-$AV$3 -> 46340 | AW17: =AV17-$AW$3 -> 46330 | AX17: =AW17-AY17 -> 56 | AY17: 46274 | AZ17: JK01-1830 | BA17: Horizontal Framing Plan
B18: JKT | C18: S10A | D18: JKT-01 | F18: 01J | H18: 14 | I18: S10 Row2 | J18: 115 | K18: =L18-Y18 -> 1 | L18: =SUMIFS('[36]frm P6'!$J:$J,'[36]frm P6'!D:D,[36]Schedule!B18,'[36]frm P6'!E:E,[36]Schedule!C18,'[36]frm P6'!F:F,[36]Schedule!D18,'[36]frm P6'!G:G,[36]Schedule!$K$3,'[36]frm P6'!H:H,[36]Schedule!F18) -> 46504 | M18: =SUMIFS('[36]frm P6'!$K:$K,'[36]frm P6'!D:D,[36]Schedule!B18,'[36]frm P6'!E:E,[36]Schedule!C18,'[36]frm P6'!F:F,[36]Schedule!D18,'[36]frm P6'!G:G,[36]Schedule!$K$3,'[36]frm P6'!H:H,[36]Schedule!F18) -> 46524 | N18: =M18-L18+1 -> 21 | O18: 32 | P18: 181.47 | Q18: 400-750 | R18: =VLOOKUP(Q18,[37]导管架!N$2:Q$9,2,0) -> 1.6966444 | S18: =VLOOKUP(Q18,[37]导管架!N$2:Q$9,3,0) -> 3.2519716 | T18: =VLOOKUP(Q18,[37]导管架!N$2:Q$9,4,0) -> 5.503286 | U18: =R18*AJ18*8 -> 407.19465 | V18: =S18*AD18*8 -> 884.53627 | W18: =T18*O18*8 -> 1408.8412 | X18: =SUMIFS('[36]frm P6'!$J:$J,'[36]frm P6'!D:D,[36]Schedule!B18,'[36]frm P6'!E:E,[36]Schedule!C18,'[36]frm P6'!G:G,[36]Schedule!$W$3,'[36]frm P6'!H:H,[36]Schedule!F18) -> 46486 | Y18: =SUMIFS('[36]frm P6'!$K:$K,'[36]frm P6'!D:D,[36]Schedule!B18,'[36]frm P6'!E:E,[36]Schedule!C18,'[36]frm P6'!G:G,[36]Schedule!$W$3,'[36]frm P6'!H:H,[36]Schedule!F18) -> 46503 | Z18: =Y18-X18+1 -> 18 | AA18: =SUMIFS('[36]frm P6'!$J:$J,'[36]frm P6'!D:D,[36]Schedule!B18,'[36]frm P6'!E:E,[36]Schedule!C18,'[36]frm P6'!F:F,[36]Schedule!D18,'[36]frm P6'!G:G,[36]Schedule!$Z$3,'[36]frm P6'!H:H,[36]Schedule!F18) -> 46437 | AB18: =SUMIFS('[36]frm P6'!$K:$K,'[36]frm P6'!D:D,[36]Schedule!B18,'[36]frm P6'!E:E,[36]Schedule!C18,'[36]frm P6'!F:F,[36]Schedule!D18,'[36]frm P6'!G:G,[36]Schedule!$Z$3,'[36]frm P6'!H:H,[36]Schedule!F18) -> 46478 | AC18: =AB18-AA18+1 -> 42 | AD18: 34 | AE18: 359.28 | AF18: 355.6-1524 | AG18: =SUMIFS('[36]frm P6'!$J:$J,'[36]frm P6'!D:D,[36]Schedule!B18,'[36]frm P6'!E:E,[36]Schedule!C18,'[36]frm P6'!F:F,[36]Schedule!D18,'[36]frm P6'!G:G,[36]Schedule!$AF$3,'[36]frm P6'!H:H,[36]Schedule!F18) -> 46393 | AH18: =SUMIFS('[36]frm P6'!$K:$K,'[36]frm P6'!D:D,[36]Schedule!B18,'[36]frm P6'!E:E,[36]Schedule!C18,'[36]frm P6'!F:F,[36]Schedule!D18,'[36]frm P6'!G:G,[36]Schedule!$AF$3,'[36]frm P6'!H:H,[36]Schedule!F18) -> 46422 | AI18: =AH18-AG18+1 -> 30 | AJ18: 30 | AK18: 1130.3 | AL18: 500-1524 | AM18: =SUMIFS('[36]frm P6'!$J:$J,'[36]frm P6'!D:D,[36]Schedule!B18,'[36]frm P6'!E:E,[36]Schedule!C18,'[36]frm P6'!F:F,[36]Schedule!D18,'[36]frm P6'!G:G,[36]Schedule!$AL$3,'[36]frm P6'!H:H,[36]Schedule!F18) -> 46365 | AN18: =SUMIFS('[36]frm P6'!$K:$K,'[36]frm P6'!D:D,[36]Schedule!B18,'[36]frm P6'!E:E,[36]Schedule!C18,'[36]frm P6'!F:F,[36]Schedule!D18,'[36]frm P6'!G:G,[36]Schedule!$AL$3,'[36]frm P6'!H:H,[36]Schedule!F18) -> 46403 | AO18: =AN18-AM18+1 -> 39 | AP18: 47 | AQ18: 500-1549.4 | AR18: 62 | AS18: =AM18-$AS$3 -> 46362 | AT18: =AS18-$AT$3 -> 46302 | AU18: =AT18-$AU$3 -> 46287 | AV18: =AM18-$AV$3 -> 46361 | AW18: =AV18-$AW$3 -> 46351 | AX18: =AW18-AY18 -> 82 | AY18: 46269 | AZ18: JK01-1800 | BA18: Elevation Row A, B, 1, 2
B19: WPA02 | H19: WPA02 MAIN STRUCTURE OF JACKET | L19: =MIN(L20:L33) -> 46442 | M19: =MAX(M20:M33) -> 46563 | N19: =M19-L19+1 -> 122 | X19: =MIN(X20:X32) -> 46452 | Y19: =MAX(Y20:Y33) -> 46528 | Z19: =Y19-X19+1 -> 77 | AA19: =MIN(AA20:AA33) -> 46401 | AB19: =MAX(AB20:AB33) -> 46506 | AC19: =AB19-AA19+1 -> 106 | AG19: =MIN(AG20:AG33) -> 46367 | AH19: =MAX(AH20:AH33) -> 46476 | AI19: =AH19-AG19+1 -> 110 | AM19: =MIN(AM20:AM33) -> 46332 | AN19: =MAX(AN20:AN33) -> 46417 | AO19: =AN19-AM19+1 -> 86 | AS19: =MIN(AS20:AS32) -> 46329 | AT19: =MIN(AT20:AT32) -> 46269 | AU19: =MIN(AU20:AU32) -> 46254 | AV19: =MIN(AV20:AV32) -> 46328 | AW19: =MIN(AW20:AW32) -> 46318
B20: JKT | C20: S01 | D20: JKT-01 | F20: 02J | H20: 1 | I20: S1 Layout Construction Support | L20: =SUMIFS('[36]frm P6'!$J:$J,'[36]frm P6'!D:D,[36]Schedule!B20,'[36]frm P6'!E:E,[36]Schedule!C20,'[36]frm P6'!F:F,[36]Schedule!D20,'[36]frm P6'!G:G,$L$3,'[36]frm P6'!H:H,[36]Schedule!F20) -> 46442 | M20: =SUMIFS('[36]frm P6'!$K:$K,'[36]frm P6'!D:D,[36]Schedule!B20,'[36]frm P6'!E:E,[36]Schedule!C20,'[36]frm P6'!F:F,[36]Schedule!D20,'[36]frm P6'!G:G,$L$3,'[36]frm P6'!H:H,[36]Schedule!F20) -> 46445 | N20: =M20-L20+1 -> 4 | X20: N/A | Y20: N/A | Z20: N/A | AA20: N/A | AB20: N/A | AC20: N/A | AD20: N/A | AE20: N/A | AF20: N/A | AG20: =SUMIFS('[36]frm P6'!$J:$J,'[36]frm P6'!D:D,[36]Schedule!B20,'[36]frm P6'!E:E,[36]Schedule!C20,'[36]frm P6'!F:F,[36]Schedule!D20,'[36]frm P6'!G:G,[36]Schedule!$AF$3,'[36]frm P6'!H:H,[36]Schedule!F20) -> 46384 | AH20: =SUMIFS('[36]frm P6'!$K:$K,'[36]frm P6'!D:D,[36]Schedule!B20,'[36]frm P6'!E:E,[36]Schedule!C20,'[36]frm P6'!F:F,[36]Schedule!D20,'[36]frm P6'!G:G,[36]Schedule!$AF$3,'[36]frm P6'!H:H,[36]Schedule!F20) -> 46421 | AI20: N/A | AM20: N/A | AN20: N/A | AO20: N/A | AR20: N/A | AS20: N/A | AT20: N/A | AU20: N/A | AV20: N/A | AW20: N/A | AX20: N/A | AZ20: N/A | BA20: N/A
B21: JKT | C21: S02A | D21: JKT-01 | F21: 02J | H21: 2 | I21: S2 1H-Panel | J21: 16.2 | K21: =L21-AB21 -> 3 | L21: =SUMIFS('[36]frm P6'!$J:$J,'[36]frm P6'!D:D,[36]Schedule!B21,'[36]frm P6'!E:E,[36]Schedule!C21,'[36]frm P6'!F:F,[36]Schedule!D21,'[36]frm P6'!G:G,$L$3,'[36]frm P6'!H:H,[36]Schedule!F21) -> 46445 | M21: =SUMIFS('[36]frm P6'!$K:$K,'[36]frm P6'!D:D,[36]Schedule!B21,'[36]frm P6'!E:E,[36]Schedule!C21,'[36]frm P6'!F:F,[36]Schedule!D21,'[36]frm P6'!G:G,$L$3,'[36]frm P6'!H:H,[36]Schedule!F21) -> 46456 | N21: =M21-L21+1 -> 12 | O21: 4 | Q21: 450-500 | R21: =VLOOKUP(Q21,[37]导管架!N$2:Q$9,2,0) -> 1.2968666 | S21: =VLOOKUP(Q21,[37]导管架!N$2:Q$9,3,0) -> 2.4732262 | T21: =VLOOKUP(Q21,[37]导管架!N$2:Q$9,4,0) -> 4.6220437 | U21: =R21*AJ21*8 -> 124.49919 | V21: =S21*8*AD21 -> 79.14324 | W21: =T21*O21*8 -> 147.9054 | X21: N/A | Y21: N/A | Z21: N/A | AA21: =SUMIFS('[36]frm P6'!$J:$J,'[36]frm P6'!D:D,[36]Schedule!B21,'[36]frm P6'!E:E,[36]Schedule!C21,'[36]frm P6'!F:F,[36]Schedule!D21,'[36]frm P6'!G:G,[36]Schedule!$Z$3,'[36]frm P6'!H:H,[36]Schedule!F21) -> 46405 | AB21: =SUMIFS('[36]frm P6'!$K:$K,'[36]frm P6'!D:D,[36]Schedule!B21,'[36]frm P6'!E:E,[36]Schedule!C21,'[36]frm P6'!F:F,[36]Schedule!D21,'[36]frm P6'!G:G,[36]Schedule!$Z$3,'[36]frm P6'!H:H,[36]Schedule!F21) -> 46442 | AC21: =AB21-AA21+1 -> 38 | AD21: 4 | AE21: 16.78 | AF21: 406.4 | AG21: =SUMIFS('[36]frm P6'!$J:$J,'[36]frm P6'!D:D,[36]Schedule!B21,'[36]frm P6'!E:E,[36]Schedule!C21,'[36]frm P6'!F:F,[36]Schedule!D21,'[36]frm P6'!G:G,[36]Schedule!$AF$3,'[36]frm P6'!H:H,[36]Schedule!F21) -> 46373 | AH21: =SUMIFS('[36]frm P6'!$K:$K,'[36]frm P6'!D:D,[36]Schedule!B21,'[36]frm P6'!E:E,[36]Schedule!C21,'[36]frm P6'!F:F,[36]Schedule!D21,'[36]frm P6'!G:G,[36]Schedule!$AF$3,'[36]frm P6'!H:H,[36]Schedule!F21) -> 46400 | AI21: =AH21-AG21+1 -> 28 | AJ21: 12 | AK21: 52.15 | AL21: 406.4-500 | AM21: =SUMIFS('[36]frm P6'!$J:$J,'[36]frm P6'!D:D,[36]Schedule!B21,'[36]frm P6'!E:E,[36]Schedule!C21,'[36]frm P6'!F:F,[36]Schedule!D21,'[36]frm P6'!G:G,[36]Schedule!$AL$3,'[36]frm P6'!H:H,[36]Schedule!F21) -> 46336 | AN21: =SUMIFS('[36]frm P6'!$K:$K,'[36]frm P6'!D:D,[36]Schedule!B21,'[36]frm P6'!E:E,[36]Schedule!C21,'[36]frm P6'!F:F,[36]Schedule!D21,'[36]frm P6'!G:G,[36]Schedule!$AL$3,'[36]frm P6'!H:H,[36]Schedule!F21) -> 46365 | AO21: =AN21-AM21+1 -> 30 | AP21: 6 | AQ21: 500 | AR21: 62 | AS21: =AM21-$AS$3 -> 46333 | AT21: =AS21-$AT$3 -> 46273 | AU21: =AT21-$AU$3 -> 46258 | AV21: =AM21-$AV$3 -> 46332 | AW21: =AV21-$AW$3 -> 46322 | AX21: =AW21-AY21 -> 48 | AY21: 46274 | AZ21: JK02-1590 | BA21: Horizontal Framing Plan
B22: JKT | C22: S04A | D22: JKT-01 | F22: 02J | H22: 4 | I22: S4A Row1 | J22: 105 | K22: =L22-Y22 -> 3 | L22: =SUMIFS('[36]frm P6'!$J:$J,'[36]frm P6'!D:D,[36]Schedule!B22,'[36]frm P6'!E:E,[36]Schedule!C22,'[36]frm P6'!F:F,[36]Schedule!D22,'[36]frm P6'!G:G,$L$3,'[36]frm P6'!H:H,[36]Schedule!F22) -> 46471 | M22: =SUMIFS('[36]frm P6'!$K:$K,'[36]frm P6'!D:D,[36]Schedule!B22,'[36]frm P6'!E:E,[36]Schedule!C22,'[36]frm P6'!F:F,[36]Schedule!D22,'[36]frm P6'!G:G,$L$3,'[36]frm P6'!H:H,[36]Schedule!F22) -> 46480 | N22: =M22-L22+1 -> 10 | O22: 8 | P22: 35.37 | Q22: 406.4-500 | R22: =VLOOKUP(Q22,[37]导管架!N$2:Q$9,2,0) -> 1.2968666 | S22: =VLOOKUP(Q22,[37]导管架!N$2:Q$9,3,0) -> 2.4732262 | T22: =VLOOKUP(Q22,[37]导管架!N$2:Q$9,4,0) -> 4.6220437 | U22: =R22*AJ22*8 -> 248.99839 | V22: =S22*8*AD22 -> 672.71754 | W22: =T22*O22*8 -> 295.8108 | X22: =SUMIFS('[36]frm P6'!$J:$J,'[36]frm P6'!D:D,[36]Schedule!B22,'[36]frm P6'!E:E,[36]Schedule!C22,'[36]frm P6'!G:G,[36]Schedule!$W$3,'[36]frm P6'!H:H,[36]Schedule!F22) -> 46452 | Y22: =SUMIFS('[36]frm P6'!$K:$K,'[36]frm P6'!D:D,[36]Schedule!B22,'[36]frm P6'!E:E,[36]Schedule!C22,'[36]frm P6'!G:G,[36]Schedule!$W$3,'[36]frm P6'!H:H,[36]Schedule!F22) -> 46468 | Z22: =Y22-X22+1 -> 17 | AA22: =SUMIFS('[36]frm P6'!$J:$J,'[36]frm P6'!D:D,[36]Schedule!B22,'[36]frm P6'!E:E,[36]Schedule!C22,'[36]frm P6'!F:F,[36]Schedule!D22,'[36]frm P6'!G:G,[36]Schedule!$Z$3,'[36]frm P6'!H:H,[36]Schedule!F22) -> 46401 | AB22: =SUMIFS('[36]frm P6'!$K:$K,'[36]frm P6'!D:D,[36]Schedule!B22,'[36]frm P6'!E:E,[36]Schedule!C22,'[36]frm P6'!F:F,[36]Schedule!D22,'[36]frm P6'!G:G,[36]Schedule!$Z$3,'[36]frm P6'!H:H,[36]Schedule!F22) -> 46450 | AC22: =AB22-AA22+1 -> 50 | AD22: 34 | AE22: 359.28 | AF22: 500-1524 | AG22: =SUMIFS('[36]frm P6'!$J:$J,'[36]frm P6'!D:D,[36]Schedule!B22,'[36]frm P6'!E:E,[36]Schedule!C22,'[36]frm P6'!F:F,[36]Schedule!D22,'[36]frm P6'!G:G,[36]Schedule!$AF$3,'[36]frm P6'!H:H,[36]Schedule!F22) -> 46367 | AH22: =SUMIFS('[36]frm P6'!$K:$K,'[36]frm P6'!D:D,[36]Schedule!B22,'[36]frm P6'!E:E,[36]Schedule!C22,'[36]frm P6'!F:F,[36]Schedule!D22,'[36]frm P6'!G:G,[36]Schedule!$AF$3,'[36]frm P6'!H:H,[36]Schedule!F22) -> 46400 | AI22: =AH22-AG22+1 -> 34 | AJ22: 24 | AK22: 1101.48 | AL22: 500-1524 | AM22: =SUMIFS('[36]frm P6'!$J:$J,'[36]frm P6'!D:D,[36]Schedule!B22,'[36]frm P6'!E:E,[36]Schedule!C22,'[36]frm P6'!F:F,[36]Schedule!D22,'[36]frm P6'!G:G,[36]Schedule!$AL$3,'[36]frm P6'!H:H,[36]Schedule!F22) -> 46332 | AN22: =SUMIFS('[36]frm P6'!$K:$K,'[36]frm P6'!D:D,[36]Schedule!B22,'[36]frm P6'!E:E,[36]Schedule!C22,'[36]frm P6'!F:F,[36]Schedule!D22,'[36]frm P6'!G:G,[36]Schedule!$AL$3,'[36]frm P6'!H:H,[36]Schedule!F22) -> 46366 | AO22: =AN22-AM22+1 -> 35 | AP22: 41 | AQ22: 500-1549.4 | AR22: 62 | AS22: =AM22-$AS$3 -> 46329 | AT22: =AS22-$AT$3 -> 46269 | AU22: =AT22-$AU$3 -> 46254 | AV22: =AM22-$AV$3 -> 46328 | AW22: =AV22-$AW$3 -> 46318 | AX22: =AW22-AY22 -> 49 | AY22: 46269 | AZ22: JK02-1560 | BA22: Elevation Row A, B, 1, 2
